<robot name="onshape">
    <mujoco>
        <compiler fusestatic="false"/>
    </mujoco>
    <link name="trunk_assembly">
        <visual>
            <origin xyz="-0.019000000000000002998 0 0.06489093881237623096" rpy="0 -0 0" />
            <geometry>
                <mesh filename="package:///body_front.stl"/>
            </geometry>
            <material name="body_front_material">
                <color rgba="0.91764705882352937127 0.91764705882352937127 0.91764705882352937127 1.0"/>
            </material>
        </visual>
        <collision>
            <origin xyz="-0.019000000000000002998 0 0.06489093881237623096" rpy="0 -0 0" />
            <geometry>
                <mesh filename="package:///body_front.stl"/>
            </geometry>
        </collision>
        <visual>
            <origin xyz="-0.12630000000000002336 -0.025700000000000007561 0.057607885438805628286" rpy="1.570796326794896558 -1.570796326794896558 0" />
            <geometry>
                <mesh filename="package:///usb_c_charger.stl"/>
            </geometry>
            <material name="usb_c_charger_material">
                <color rgba="0.61568627450980395466 0.81176470588235294379 0.92941176470588238168 1.0"/>
            </material>
        </visual>
        <collision>
            <origin xyz="-0.12630000000000002336 -0.025700000000000007561 0.057607885438805628286" rpy="1.570796326794896558 -1.570796326794896558 0" />
            <geometry>
                <mesh filename="package:///usb_c_charger.stl"/>
            </geometry>
        </collision>
        <visual>
            <origin xyz="-0.019000000000000030753 3.4694469519536141888e-18 0.064890938812376217082" rpy="0 -0 0" />
            <geometry>
                <mesh filename="package:///body_back.stl"/>
            </geometry>
            <material name="body_back_material">
                <color rgba="0.91764705882352937127 0.91764705882352937127 0.91764705882352937127 1.0"/>
            </material>
        </visual>
        <collision>
            <origin xyz="-0.019000000000000030753 3.4694469519536141888e-18 0.064890938812376217082" rpy="0 -0 0" />
            <geometry>
                <mesh filename="package:///body_back.stl"/>
            </geometry>
        </collision>
        <visual>
            <origin xyz="-0.019000000000000002998 -3.4694469519536141888e-18 0.064890938812376217082" rpy="0 -0 0" />
            <geometry>
                <mesh filename="package:///body_middle_bottom.stl"/>
            </geometry>
            <material name="body_middle_bottom_material">
                <color rgba="0.91764705882352937127 0.91764705882352937127 0.91764705882352937127 1.0"/>
            </material>
        </visual>
        <collision>
            <origin xyz="-0.019000000000000002998 -3.4694469519536141888e-18 0.064890938812376217082" rpy="0 -0 0" />
            <geometry>
                <mesh filename="package:///body_middle_bottom.stl"/>
            </geometry>
        </collision>
        <visual>
            <origin xyz="-0.12034034238515370352 -2.7755575615628913511e-17 0.089912605778164178538" rpy="6.6215498863017844842e-16 -0.89605538457133859787 -5.1705617763838667614e-16" />
            <geometry>
                <mesh filename="package:///power_switch.stl"/>
            </geometry>
            <material name="power_switch_material">
                <color rgba="0.90196078431372550543 0.90196078431372550543 0.90196078431372550543 1.0"/>
            </material>
        </visual>
        <collision>
            <origin xyz="-0.12034034238515370352 -2.7755575615628913511e-17 0.089912605778164178538" rpy="6.6215498863017844842e-16 -0.89605538457133859787 -5.1705617763838667614e-16" />
            <geometry>
                <mesh filename="package:///power_switch.stl"/>
            </geometry>
        </collision>
        <visual>
            <origin xyz="-0.075202758552571302708 -0.024900000000000005462 0.029489945907002490522" rpy="1.570796326794896558 1.570796326794896336 0" />
            <geometry>
                <mesh filename="package:///bms.stl"/>
            </geometry>
            <material name="bms_material">
                <color rgba="0.2313725490196078538 0.38039215686274507888 0.7058823529411765163 1.0"/>
            </material>
        </visual>
        <collision>
            <origin xyz="-0.075202758552571302708 -0.024900000000000005462 0.029489945907002490522" rpy="1.570796326794896558 1.570796326794896336 0" />
            <geometry>
                <mesh filename="package:///bms.stl"/>
            </geometry>
        </collision>
        <visual>
            <origin xyz="-0.018999999999999683808 0 0.064890938812376189326" rpy="-3.3848262945888805998e-16 -0 0" />
            <geometry>
                <mesh filename="package:///battery_pack_lid.stl"/>
            </geometry>
            <material name="battery_pack_lid_material">
                <color rgba="0.2313725490196078538 0.38039215686274507888 0.7058823529411765163 1.0"/>
            </material>
        </visual>
        <collision>
            <origin xyz="-0.018999999999999683808 0 0.064890938812376189326" rpy="-3.3848262945888805998e-16 -0 0" />
            <geometry>
                <mesh filename="package:///battery_pack_lid.stl"/>
            </geometry>
        </collision>
        <visual>
            <origin xyz="-0.019000000000000002998 0 0.064890938812376217082" rpy="0 -0 0" />
            <geometry>
                <mesh filename="package:///body_middle_top.stl"/>
            </geometry>
            <material name="body_middle_top_material">
                <color rgba="0.91764705882352937127 0.91764705882352937127 0.91764705882352937127 1.0"/>
            </material>
        </visual>
        <collision>
            <origin xyz="-0.019000000000000002998 0 0.064890938812376217082" rpy="0 -0 0" />
            <geometry>
                <mesh filename="package:///body_middle_top.stl"/>
            </geometry>
        </collision>
        <visual>
            <origin xyz="-0.087109999999999535025 1.3010426069826053208e-16 0.041790938812376283995" rpy="-1.4062102177136728734e-16 2.5389959684908792913e-51 7.8060348058444099458e-33" />
            <geometry>
                <mesh filename="package:///bno055.stl"/>
            </geometry>
            <material name="bno055_material">
                <color rgba="0.61568627450980395466 0.81176470588235294379 0.92941176470588238168 1.0"/>
            </material>
        </visual>
        <collision>
            <origin xyz="-0.087109999999999535025 1.3010426069826053208e-16 0.041790938812376283995" rpy="-1.4062102177136728734e-16 2.5389959684908792913e-51 7.8060348058444099458e-33" />
            <geometry>
                <mesh filename="package:///bno055.stl"/>
            </geometry>
        </collision>
        <visual>
            <origin xyz="-0.018999999999999999528 -6.9388939039072283776e-18 0.06489093881237623096" rpy="0 -0 0" />
            <geometry>
                <mesh filename="package:///roll_bearing.stl"/>
            </geometry>
            <material name="roll_bearing_material">
                <color rgba="0.5999999999999999778 0.5999999999999999778 0.5999999999999999778 1.0"/>
            </material>
        </visual>
        <collision>
            <origin xyz="-0.018999999999999999528 -6.9388939039072283776e-18 0.06489093881237623096" rpy="0 -0 0" />
            <geometry>
                <mesh filename="package:///roll_bearing.stl"/>
            </geometry>
        </collision>
        <visual>
            <origin xyz="-0.01899999999999998912 9.1072982488782372457e-18 0.06489093881237623096" rpy="-1.4062102177136726269e-16 7.6230808650822444942e-36 1.0842021724854837303e-19" />
            <geometry>
                <mesh filename="package:///trunk_bottom.stl"/>
            </geometry>
            <material name="trunk_bottom_material">
                <color rgba="0.18039215686274509554 0.18039215686274509554 0.18039215686274509554 1.0"/>
            </material>
        </visual>
        <collision>
            <origin xyz="-0.01899999999999998912 9.1072982488782372457e-18 0.06489093881237623096" rpy="-1.4062102177136726269e-16 7.6230808650822444942e-36 1.0842021724854837303e-19" />
            <geometry>
                <mesh filename="package:///trunk_bottom.stl"/>
            </geometry>
        </collision>
        <visual>
            <origin xyz="-0.019000000000000322187 -2.4242760576775879144e-16 0.06489093881237648076" rpy="-4.8355416892852906111e-17 5.5511151231258122844e-17 0" />
            <geometry>
                <mesh filename="package:///trunk_top.stl"/>
            </geometry>
            <material name="trunk_top_material">
                <color rgba="0.18039215686274509554 0.18039215686274509554 0.18039215686274509554 1.0"/>
            </material>
        </visual>
        <collision>
            <origin xyz="-0.019000000000000322187 -2.4242760576775879144e-16 0.06489093881237648076" rpy="-4.8355416892852906111e-17 5.5511151231258122844e-17 0" />
            <geometry>
                <mesh filename="package:///trunk_top.stl"/>
            </geometry>
        </collision>
        <visual>
            <origin xyz="-0.063490012619999952603 0.016499992339999228208 0.060390938152376505421" rpy="1.406210217713636142e-16 2.220446049250285944e-14 -3.141592653589793116" />
            <geometry>
                <mesh filename="package:///board.stl"/>
            </geometry>
            <material name="board_material">
                <color rgba="0 0.50196078431372548323 0 1.0"/>
            </material>
        </visual>
        <collision>
            <origin xyz="-0.063490012619999952603 0.016499992339999228208 0.060390938152376505421" rpy="1.406210217713636142e-16 2.220446049250285944e-14 -3.141592653589793116" />
            <geometry>
                <mesh filename="package:///board.stl"/>
            </geometry>
        </collision>
        <visual>
            <origin xyz="-0.018999999999999999528 -0.070000000000000034417 0.06489093881237623096" rpy="0 -0 0" />
            <geometry>
                <mesh filename="package:///roll_bearing.stl"/>
            </geometry>
            <material name="roll_bearing_material">
                <color rgba="0.5999999999999999778 0.5999999999999999778 0.5999999999999999778 1.0"/>
            </material>
        </visual>
        <collision>
            <origin xyz="-0.018999999999999999528 -0.070000000000000034417 0.06489093881237623096" rpy="0 -0 0" />
            <geometry>
                <mesh filename="package:///roll_bearing.stl"/>
            </geometry>
        </collision>
        <visual>
            <origin xyz="-0.12962456815639683549 -0.010499999999999986774 0.065013432174047369738" rpy="-3.141592653589793116 7.1750566777276333942e-17 2.1913059978610238687" />
            <geometry>
                <mesh filename="package:///cell.stl"/>
            </geometry>
            <material name="cell_material">
                <color rgba="0.61568627450980395466 0.81176470588235294379 0.92941176470588238168 1.0"/>
            </material>
        </visual>
        <collision>
            <origin xyz="-0.12962456815639683549 -0.010499999999999986774 0.065013432174047369738" rpy="-3.141592653589793116 7.1750566777276333942e-17 2.1913059978610238687" />
            <geometry>
                <mesh filename="package:///cell.stl"/>
            </geometry>
        </collision>
        <visual>
            <origin xyz="-0.13962456815639684438 -0.063524458557367310951 0.031454953764361824609" rpy="-1.3044563776959597654e-16 1.570796326794896336 0" />
            <geometry>
                <mesh filename="package:///holder.stl"/>
            </geometry>
            <material name="holder_material">
                <color rgba="0.64705882352941179736 0.64705882352941179736 0.64705882352941179736 1.0"/>
            </material>
        </visual>
        <collision>
            <origin xyz="-0.13962456815639684438 -0.063524458557367310951 0.031454953764361824609" rpy="-1.3044563776959597654e-16 1.570796326794896336 0" />
            <geometry>
                <mesh filename="package:///holder.stl"/>
            </geometry>
        </collision>
        <visual>
            <origin xyz="-0.12962456815639683549 0.010500000000000004122 1.3432174047381232902e-05" rpy="8.3177805134519239719e-17 2.7557624392889133747e-16 0.75026546877138966529" />
            <geometry>
                <mesh filename="package:///cell.stl"/>
            </geometry>
            <material name="cell_material">
                <color rgba="0.61568627450980395466 0.81176470588235294379 0.92941176470588238168 1.0"/>
            </material>
        </visual>
        <collision>
            <origin xyz="-0.12962456815639683549 0.010500000000000004122 1.3432174047381232902e-05" rpy="8.3177805134519239719e-17 2.7557624392889133747e-16 0.75026546877138966529" />
            <geometry>
                <mesh filename="package:///cell.stl"/>
            </geometry>
        </collision>
        <visual>
            <origin xyz="0.00099999999999953077812 0.0097000000000003246819 0.064500938812376201748" rpy="1.0972295724176328418e-22 1.5707963267948743535 0" />
            <geometry>
                <mesh filename="package:///wj-wk00-0123middlecase_56.stl"/>
            </geometry>
            <material name="wj-wk00-0123middlecase_56_material">
                <color rgba="0.24705882352941177516 0.24313725490196078094 0.24313725490196078094 1.0"/>
            </material>
        </visual>
        <collision>
            <origin xyz="0.00099999999999953077812 0.0097000000000003246819 0.064500938812376201748" rpy="1.0972295724176328418e-22 1.5707963267948743535 0" />
            <geometry>
                <mesh filename="package:///wj-wk00-0123middlecase_56.stl"/>
            </geometry>
        </collision>
        <visual>
            <origin xyz="0.00099999999999953077812 0.0097000000000003246819 0.064500938812376201748" rpy="1.0972295724176328418e-22 1.5707963267948743535 0" />
            <geometry>
                <mesh filename="package:///drive_palonier.stl"/>
            </geometry>
            <material name="drive_palonier_material">
                <color rgba="0.62352941176470588758 0.66666666666666662966 0.70196078431372543882 1.0"/>
            </material>
        </visual>
        <collision>
            <origin xyz="0.00099999999999953077812 0.0097000000000003246819 0.064500938812376201748" rpy="1.0972295724176328418e-22 1.5707963267948743535 0" />
            <geometry>
                <mesh filename="package:///drive_palonier.stl"/>
            </geometry>
        </collision>
        <visual>
            <origin xyz="0.00099999999999953077812 0.0097000000000003246819 0.064500938812376201748" rpy="1.0972295724176328418e-22 1.5707963267948743535 0" />
            <geometry>
                <mesh filename="package:///wj-wk00-0124bottomcase_45.stl"/>
            </geometry>
            <material name="wj-wk00-0124bottomcase_45_material">
                <color rgba="0.24705882352941177516 0.24313725490196078094 0.24313725490196078094 1.0"/>
            </material>
        </visual>
        <collision>
            <origin xyz="0.00099999999999953077812 0.0097000000000003246819 0.064500938812376201748" rpy="1.0972295724176328418e-22 1.5707963267948743535 0" />
            <geometry>
                <mesh filename="package:///wj-wk00-0124bottomcase_45.stl"/>
            </geometry>
        </collision>
        <visual>
            <origin xyz="0.00099999999999953077812 0.0097000000000003246819 0.064500938812376201748" rpy="1.0972295724176328418e-22 1.5707963267948743535 0" />
            <geometry>
                <mesh filename="package:///wj-wk00-0122topcabinetcase_95.stl"/>
            </geometry>
            <material name="wj-wk00-0122topcabinetcase_95_material">
                <color rgba="0.24705882352941177516 0.24313725490196078094 0.24313725490196078094 1.0"/>
            </material>
        </visual>
        <collision>
            <origin xyz="0.00099999999999953077812 0.0097000000000003246819 0.064500938812376201748" rpy="1.0972295724176328418e-22 1.5707963267948743535 0" />
            <geometry>
                <mesh filename="package:///wj-wk00-0122topcabinetcase_95.stl"/>
            </geometry>
        </collision>
        <visual>
            <origin xyz="0.00099999999999958585559 0.012600000000000624589 0.064500938812376257259" rpy="1.0972295724176328418e-22 1.5707963267948743535 0" />
            <geometry>
                <mesh filename="package:///passive_palonier.stl"/>
            </geometry>
            <material name="passive_palonier_material">
                <color rgba="0.62352941176470588758 0.66666666666666662966 0.70196078431372543882 1.0"/>
            </material>
        </visual>
        <collision>
            <origin xyz="0.00099999999999958585559 0.012600000000000624589 0.064500938812376257259" rpy="1.0972295724176328418e-22 1.5707963267948743535 0" />
            <geometry>
                <mesh filename="package:///passive_palonier.stl"/>
            </geometry>
        </collision>
        <visual>
            <origin xyz="-0.044499999999999630129 -0.035000000000001522948 0.055390938812376840084" rpy="-1.570796326794896336 2.2204460492502903617e-14 3.141592653589793116" />
            <geometry>
                <mesh filename="package:///wj-wk00-0123middlecase_56.stl"/>
            </geometry>
            <material name="wj-wk00-0123middlecase_56_material">
                <color rgba="0.24705882352941177516 0.24313725490196078094 0.24313725490196078094 1.0"/>
            </material>
        </visual>
        <collision>
            <origin xyz="-0.044499999999999630129 -0.035000000000001522948 0.055390938812376840084" rpy="-1.570796326794896336 2.2204460492502903617e-14 3.141592653589793116" />
            <geometry>
                <mesh filename="package:///wj-wk00-0123middlecase_56.stl"/>
            </geometry>
        </collision>
        <visual>
            <origin xyz="-0.044499999999999630129 -0.035000000000001522948 0.055390938812376840084" rpy="-1.570796326794896336 2.2204460492502903617e-14 3.141592653589793116" />
            <geometry>
                <mesh filename="package:///drive_palonier.stl"/>
            </geometry>
            <material name="drive_palonier_material">
                <color rgba="0.62352941176470588758 0.66666666666666662966 0.70196078431372543882 1.0"/>
            </material>
        </visual>
        <collision>
            <origin xyz="-0.044499999999999630129 -0.035000000000001522948 0.055390938812376840084" rpy="-1.570796326794896336 2.2204460492502903617e-14 3.141592653589793116" />
            <geometry>
                <mesh filename="package:///drive_palonier.stl"/>
            </geometry>
        </collision>
        <visual>
            <origin xyz="-0.044499999999999630129 -0.035000000000001522948 0.055390938812376840084" rpy="-1.570796326794896336 2.2204460492502903617e-14 3.141592653589793116" />
            <geometry>
                <mesh filename="package:///wj-wk00-0124bottomcase_45.stl"/>
            </geometry>
            <material name="wj-wk00-0124bottomcase_45_material">
                <color rgba="0.24705882352941177516 0.24313725490196078094 0.24313725490196078094 1.0"/>
            </material>
        </visual>
        <collision>
            <origin xyz="-0.044499999999999630129 -0.035000000000001522948 0.055390938812376840084" rpy="-1.570796326794896336 2.2204460492502903617e-14 3.141592653589793116" />
            <geometry>
                <mesh filename="package:///wj-wk00-0124bottomcase_45.stl"/>
            </geometry>
        </collision>
        <visual>
            <origin xyz="-0.044499999999999630129 -0.035000000000001522948 0.055390938812376840084" rpy="-1.570796326794896336 2.2204460492502903617e-14 3.141592653589793116" />
            <geometry>
                <mesh filename="package:///wj-wk00-0122topcabinetcase_95.stl"/>
            </geometry>
            <material name="wj-wk00-0122topcabinetcase_95_material">
                <color rgba="0.24705882352941177516 0.24313725490196078094 0.24313725490196078094 1.0"/>
            </material>
        </visual>
        <collision>
            <origin xyz="-0.044499999999999630129 -0.035000000000001522948 0.055390938812376840084" rpy="-1.570796326794896336 2.2204460492502903617e-14 3.141592653589793116" />
            <geometry>
                <mesh filename="package:///wj-wk00-0122topcabinetcase_95.stl"/>
            </geometry>
        </collision>
        <visual>
            <origin xyz="-0.044499999999999546862 -0.035000000000001536826 0.052490938812376819467" rpy="-1.570796326794896336 2.2204460492502903617e-14 3.141592653589793116" />
            <geometry>
                <mesh filename="package:///passive_palonier.stl"/>
            </geometry>
            <material name="passive_palonier_material">
                <color rgba="0.62352941176470588758 0.66666666666666662966 0.70196078431372543882 1.0"/>
            </material>
        </visual>
        <collision>
            <origin xyz="-0.044499999999999546862 -0.035000000000001536826 0.052490938812376819467" rpy="-1.570796326794896336 2.2204460492502903617e-14 3.141592653589793116" />
            <geometry>
                <mesh filename="package:///passive_palonier.stl"/>
            </geometry>
        </collision>
        <visual>
            <origin xyz="-0.044499999999999921563 0.035000000000001384171 0.055390938812376840084" rpy="-1.570796326794896558 2.220446049250285944e-14 -3.141592653589793116" />
            <geometry>
                <mesh filename="package:///wj-wk00-0123middlecase_56.stl"/>
            </geometry>
            <material name="wj-wk00-0123middlecase_56_material">
                <color rgba="0.24705882352941177516 0.24313725490196078094 0.24313725490196078094 1.0"/>
            </material>
        </visual>
        <collision>
            <origin xyz="-0.044499999999999921563 0.035000000000001384171 0.055390938812376840084" rpy="-1.570796326794896558 2.220446049250285944e-14 -3.141592653589793116" />
            <geometry>
                <mesh filename="package:///wj-wk00-0123middlecase_56.stl"/>
            </geometry>
        </collision>
        <visual>
            <origin xyz="-0.044499999999999921563 0.035000000000001384171 0.055390938812376840084" rpy="-1.570796326794896558 2.220446049250285944e-14 -3.141592653589793116" />
            <geometry>
                <mesh filename="package:///drive_palonier.stl"/>
            </geometry>
            <material name="drive_palonier_material">
                <color rgba="0.62352941176470588758 0.66666666666666662966 0.70196078431372543882 1.0"/>
            </material>
        </visual>
        <collision>
            <origin xyz="-0.044499999999999921563 0.035000000000001384171 0.055390938812376840084" rpy="-1.570796326794896558 2.220446049250285944e-14 -3.141592653589793116" />
            <geometry>
                <mesh filename="package:///drive_palonier.stl"/>
            </geometry>
        </collision>
        <visual>
            <origin xyz="-0.044499999999999921563 0.035000000000001384171 0.055390938812376840084" rpy="-1.570796326794896558 2.220446049250285944e-14 -3.141592653589793116" />
            <geometry>
                <mesh filename="package:///wj-wk00-0124bottomcase_45.stl"/>
            </geometry>
            <material name="wj-wk00-0124bottomcase_45_material">
                <color rgba="0.24705882352941177516 0.24313725490196078094 0.24313725490196078094 1.0"/>
            </material>
        </visual>
        <collision>
            <origin xyz="-0.044499999999999921563 0.035000000000001384171 0.055390938812376840084" rpy="-1.570796326794896558 2.220446049250285944e-14 -3.141592653589793116" />
            <geometry>
                <mesh filename="package:///wj-wk00-0124bottomcase_45.stl"/>
            </geometry>
        </collision>
        <visual>
            <origin xyz="-0.044499999999999921563 0.035000000000001384171 0.055390938812376840084" rpy="-1.570796326794896558 2.220446049250285944e-14 -3.141592653589793116" />
            <geometry>
                <mesh filename="package:///wj-wk00-0122topcabinetcase_95.stl"/>
            </geometry>
            <material name="wj-wk00-0122topcabinetcase_95_material">
                <color rgba="0.24705882352941177516 0.24313725490196078094 0.24313725490196078094 1.0"/>
            </material>
        </visual>
        <collision>
            <origin xyz="-0.044499999999999921563 0.035000000000001384171 0.055390938812376840084" rpy="-1.570796326794896558 2.220446049250285944e-14 -3.141592653589793116" />
            <geometry>
                <mesh filename="package:///wj-wk00-0122topcabinetcase_95.stl"/>
            </geometry>
        </collision>
        <visual>
            <origin xyz="-0.04449999999999981054 0.035000000000001238454 0.052490938812376632117" rpy="-1.570796326794896558 2.220446049250285944e-14 -3.141592653589793116" />
            <geometry>
                <mesh filename="package:///passive_palonier.stl"/>
            </geometry>
            <material name="passive_palonier_material">
                <color rgba="0.62352941176470588758 0.66666666666666662966 0.70196078431372543882 1.0"/>
            </material>
        </visual>
        <collision>
            <origin xyz="-0.04449999999999981054 0.035000000000001238454 0.052490938812376632117" rpy="-1.570796326794896558 2.220446049250285944e-14 -3.141592653589793116" />
            <geometry>
                <mesh filename="package:///passive_palonier.stl"/>
            </geometry>
        </collision>
        <inertial>
            <origin xyz="-0.048325895233303065024 -9.9782299489528555577e-05 0.038497067106456790697" rpy="0 0 0"/>
            <mass value="0.69852641931996084512" />
            <inertia ixx="0.0016770053685612820466" ixy="-1.3166218023193000783e-05"  ixz="-3.2495310924311613049e-05" iyy="0.0034447879527285743539" iyz="-2.1558142480798317799e-06" izz="0.0029263533437058372559" />
        </inertial>
    </link>
    <link name="trunk">
        <inertial>
            <origin xyz="0 0 0" rpy="0 0 0" />
            <mass value="1e-9" />
            <inertia ixx="0" ixy="0" ixz="0" iyy="0" iyz="0" izz="0" />
        </inertial>
    </link>
    <joint name="trunk_frame" type="fixed">
        <origin xyz="-0.024000000000000760308 -2.4112656316077618612e-16 0.088190938812376745704" rpy="-1.4062102177136726269e-16 -9.4252837597218562265e-17 7.8061435390716270015e-33" />
        <parent link="trunk_assembly" />
        <child link="trunk" />
        <axis xyz="0 0 0"/>
    </joint>
    <link name="hip_roll_assembly">
        <visual>
            <origin xyz="-3.3306690738754696213e-16 -0.034999999999999101274 0.019049999999999983613" rpy="-8.7699839287071152073e-16 7.0914210924513341518e-16 -6.6960326172708786896e-16" />
            <geometry>
                <mesh filename="package:///roll_motor_bottom.stl"/>
            </geometry>
            <material name="roll_motor_bottom_material">
                <color rgba="0.64705882352941179736 0.64705882352941179736 0.64705882352941179736 1.0"/>
            </material>
        </visual>
        <collision>
            <origin xyz="-3.3306690738754696213e-16 -0.034999999999999101274 0.019049999999999983613" rpy="-8.7699839287071152073e-16 7.0914210924513341518e-16 -6.6960326172708786896e-16" />
            <geometry>
                <mesh filename="package:///roll_motor_bottom.stl"/>
            </geometry>
        </collision>
        <visual>
            <origin xyz="0 -0.034999999999999989453 0.019050000000000011369" rpy="-3.2139686811656498914e-33 -1.4298103907199264377e-30 3.250599675800221937e-43" />
            <geometry>
                <mesh filename="package:///roll_motor_top.stl"/>
            </geometry>
            <material name="roll_motor_top_material">
                <color rgba="0.90196078431372550543 0.90196078431372550543 0.90196078431372550543 1.0"/>
            </material>
        </visual>
        <collision>
            <origin xyz="0 -0.034999999999999989453 0.019050000000000011369" rpy="-3.2139686811656498914e-33 -1.4298103907199264377e-30 3.250599675800221937e-43" />
            <geometry>
                <mesh filename="package:///roll_motor_top.stl"/>
            </geometry>
        </collision>
        <visual>
            <origin xyz="0.0096000000000019836827 7.3691053259494765371e-15 -0.020515000000001309965" rpy="-1.5707963267951907671 -1.5707963267947837593 0" />
            <geometry>
                <mesh filename="package:///wj-wk00-0123middlecase_56.stl"/>
            </geometry>
            <material name="wj-wk00-0123middlecase_56_material">
                <color rgba="0.24705882352941177516 0.24313725490196078094 0.24313725490196078094 1.0"/>
            </material>
        </visual>
        <collision>
            <origin xyz="0.0096000000000019836827 7.3691053259494765371e-15 -0.020515000000001309965" rpy="-1.5707963267951907671 -1.5707963267947837593 0" />
            <geometry>
                <mesh filename="package:///wj-wk00-0123middlecase_56.stl"/>
            </geometry>
        </collision>
        <visual>
            <origin xyz="0.0096000000000019836827 7.3691053259494765371e-15 -0.020515000000001309965" rpy="-1.5707963267951907671 -1.5707963267947837593 0" />
            <geometry>
                <mesh filename="package:///drive_palonier.stl"/>
            </geometry>
            <material name="drive_palonier_material">
                <color rgba="0.62352941176470588758 0.66666666666666662966 0.70196078431372543882 1.0"/>
            </material>
        </visual>
        <collision>
            <origin xyz="0.0096000000000019836827 7.3691053259494765371e-15 -0.020515000000001309965" rpy="-1.5707963267951907671 -1.5707963267947837593 0" />
            <geometry>
                <mesh filename="package:///drive_palonier.stl"/>
            </geometry>
        </collision>
        <visual>
            <origin xyz="0.0096000000000019836827 7.3691053259494765371e-15 -0.020515000000001309965" rpy="-1.5707963267951907671 -1.5707963267947837593 0" />
            <geometry>
                <mesh filename="package:///wj-wk00-0124bottomcase_45.stl"/>
            </geometry>
            <material name="wj-wk00-0124bottomcase_45_material">
                <color rgba="0.24705882352941177516 0.24313725490196078094 0.24313725490196078094 1.0"/>
            </material>
        </visual>
        <collision>
            <origin xyz="0.0096000000000019836827 7.3691053259494765371e-15 -0.020515000000001309965" rpy="-1.5707963267951907671 -1.5707963267947837593 0" />
            <geometry>
                <mesh filename="package:///wj-wk00-0124bottomcase_45.stl"/>
            </geometry>
        </collision>
        <visual>
            <origin xyz="0.0096000000000019836827 7.3691053259494765371e-15 -0.020515000000001309965" rpy="-1.5707963267951907671 -1.5707963267947837593 0" />
            <geometry>
                <mesh filename="package:///wj-wk00-0122topcabinetcase_95.stl"/>
            </geometry>
            <material name="wj-wk00-0122topcabinetcase_95_material">
                <color rgba="0.24705882352941177516 0.24313725490196078094 0.24313725490196078094 1.0"/>
            </material>
        </visual>
        <collision>
            <origin xyz="0.0096000000000019836827 7.3691053259494765371e-15 -0.020515000000001309965" rpy="-1.5707963267951907671 -1.5707963267947837593 0" />
            <geometry>
                <mesh filename="package:///wj-wk00-0122topcabinetcase_95.stl"/>
            </geometry>
        </collision>
        <visual>
            <origin xyz="0.012500000000002495226 5.9882654390719380899e-15 -0.02051500000000196916" rpy="-1.5707963267951907671 -1.5707963267947837593 0" />
            <geometry>
                <mesh filename="package:///passive_palonier.stl"/>
            </geometry>
            <material name="passive_palonier_material">
                <color rgba="0.62352941176470588758 0.66666666666666662966 0.70196078431372543882 1.0"/>
            </material>
        </visual>
        <collision>
            <origin xyz="0.012500000000002495226 5.9882654390719380899e-15 -0.02051500000000196916" rpy="-1.5707963267951907671 -1.5707963267947837593 0" />
            <geometry>
                <mesh filename="package:///passive_palonier.stl"/>
            </geometry>
        </collision>
        <inertial>
            <origin xyz="0.00079508052674466121908 -5.4654095770169530693e-06 -0.033060020136905461652" rpy="0 0 0"/>
            <mass value="0.06648000000000005294" />
            <inertia ixx="2.4441098454925410787e-05" ixy="2.3565814729744234821e-09"  ixz="-3.8105868119091993457e-07" iyy="2.8181841945864030474e-05" iyz="-7.5003565219383821109e-09" izz="1.4268673550007194114e-05" />
        </inertial>
    </link>
    <link name="left_roll_to_pitch_assembly">
        <visual>
            <origin xyz="-0.03500000000000001027 -0.06500000000000000222 0.019050000000000021777" rpy="1.570796326794896558 1.570796326794896336 0" />
            <geometry>
                <mesh filename="package:///left_roll_to_pitch.stl"/>
            </geometry>
            <material name="left_roll_to_pitch_material">
                <color rgba="0.90980392156862743835 0.57254901960784310155 0.16470588235294117418 1.0"/>
            </material>
        </visual>
        <collision>
            <origin xyz="-0.03500000000000001027 -0.06500000000000000222 0.019050000000000021777" rpy="1.570796326794896558 1.570796326794896336 0" />
            <geometry>
                <mesh filename="package:///left_roll_to_pitch.stl"/>
            </geometry>
        </collision>
        <visual>
            <origin xyz="0.064699999999999840972 -1.4826464708739273135e-17 0.0096099999999999796696" rpy="1.5707963267948956698 1.5707963267948954478 0" />
            <geometry>
                <mesh filename="package:///wj-wk00-0123middlecase_56.stl"/>
            </geometry>
            <material name="wj-wk00-0123middlecase_56_material">
                <color rgba="0.24705882352941177516 0.24313725490196078094 0.24313725490196078094 1.0"/>
            </material>
        </visual>
        <collision>
            <origin xyz="0.064699999999999840972 -1.4826464708739273135e-17 0.0096099999999999796696" rpy="1.5707963267948956698 1.5707963267948954478 0" />
            <geometry>
                <mesh filename="package:///wj-wk00-0123middlecase_56.stl"/>
            </geometry>
        </collision>
        <visual>
            <origin xyz="0.064699999999999840972 -1.4826464708739273135e-17 0.0096099999999999796696" rpy="1.5707963267948956698 1.5707963267948954478 0" />
            <geometry>
                <mesh filename="package:///drive_palonier.stl"/>
            </geometry>
            <material name="drive_palonier_material">
                <color rgba="0.62352941176470588758 0.66666666666666662966 0.70196078431372543882 1.0"/>
            </material>
        </visual>
        <collision>
            <origin xyz="0.064699999999999840972 -1.4826464708739273135e-17 0.0096099999999999796696" rpy="1.5707963267948956698 1.5707963267948954478 0" />
            <geometry>
                <mesh filename="package:///drive_palonier.stl"/>
            </geometry>
        </collision>
        <visual>
            <origin xyz="0.064699999999999840972 -1.4826464708739273135e-17 0.0096099999999999796696" rpy="1.5707963267948956698 1.5707963267948954478 0" />
            <geometry>
                <mesh filename="package:///wj-wk00-0124bottomcase_45.stl"/>
            </geometry>
            <material name="wj-wk00-0124bottomcase_45_material">
                <color rgba="0.24705882352941177516 0.24313725490196078094 0.24313725490196078094 1.0"/>
            </material>
        </visual>
        <collision>
            <origin xyz="0.064699999999999840972 -1.4826464708739273135e-17 0.0096099999999999796696" rpy="1.5707963267948956698 1.5707963267948954478 0" />
            <geometry>
                <mesh filename="package:///wj-wk00-0124bottomcase_45.stl"/>
            </geometry>
        </collision>
        <visual>
            <origin xyz="0.064699999999999840972 -1.4826464708739273135e-17 0.0096099999999999796696" rpy="1.5707963267948956698 1.5707963267948954478 0" />
            <geometry>
                <mesh filename="package:///wj-wk00-0122topcabinetcase_95.stl"/>
            </geometry>
            <material name="wj-wk00-0122topcabinetcase_95_material">
                <color rgba="0.24705882352941177516 0.24313725490196078094 0.24313725490196078094 1.0"/>
            </material>
        </visual>
        <collision>
            <origin xyz="0.064699999999999840972 -1.4826464708739273135e-17 0.0096099999999999796696" rpy="1.5707963267948956698 1.5707963267948954478 0" />
            <geometry>
                <mesh filename="package:///wj-wk00-0122topcabinetcase_95.stl"/>
            </geometry>
        </collision>
        <visual>
            <origin xyz="0.067600000000001769784 3.657284978336727832e-16 0.0096099999999997767069" rpy="1.5707963267948956698 1.5707963267948954478 0" />
            <geometry>
                <mesh filename="package:///passive_palonier.stl"/>
            </geometry>
            <material name="passive_palonier_material">
                <color rgba="0.62352941176470588758 0.66666666666666662966 0.70196078431372543882 1.0"/>
            </material>
        </visual>
        <collision>
            <origin xyz="0.067600000000001769784 3.657284978336727832e-16 0.0096099999999997767069" rpy="1.5707963267948956698 1.5707963267948954478 0" />
            <geometry>
                <mesh filename="package:///passive_palonier.stl"/>
            </geometry>
        </collision>
        <inertial>
            <origin xyz="0.050804245437506757865 -0.00041104958524988720932 0.020470437421083776536" rpy="0 0 0"/>
            <mass value="0.075160000000000060094" />
            <inertia ixx="2.5233522240271823986e-05" ixy="1.2213346145566614239e-07"  ixz="-5.9049889515449490736e-07" iyy="4.1385485577274770804e-05" iyz="-1.0754428972189030398e-07" izz="2.8126993683182125925e-05" />
        </inertial>
    </link>
    <link name="knee_and_ankle_assembly">
        <visual>
            <origin xyz="0.016059999999998214593 0.065000000000001986744 0.10914999999999977498" rpy="-1.570796326794896336 2.4194302416514655778e-29 0" />
            <geometry>
                <mesh filename="package:///left_cache.stl"/>
            </geometry>
            <material name="left_cache_material">
                <color rgba="0.91764705882352937127 0.91764705882352937127 0.91764705882352937127 1.0"/>
            </material>
        </visual>
        <collision>
            <origin xyz="0.016059999999998214593 0.065000000000001986744 0.10914999999999977498" rpy="-1.570796326794896336 2.4194302416514655778e-29 0" />
            <geometry>
                <mesh filename="package:///left_cache.stl"/>
            </geometry>
        </collision>
        <visual>
            <origin xyz="0.016059999999999997888 0.1436499999999999444 0.10924999999999998601" rpy="-1.570796326794896558 5.1567714115613726028e-27 1.6653345369377348106e-16" />
            <geometry>
                <mesh filename="package:///leg_spacer.stl"/>
            </geometry>
            <material name="leg_spacer_material">
                <color rgba="0.64705882352941179736 0.64705882352941179736 0.64705882352941179736 1.0"/>
            </material>
        </visual>
        <collision>
            <origin xyz="0.016059999999999997888 0.1436499999999999444 0.10924999999999998601" rpy="-1.570796326794896558 5.1567714115613726028e-27 1.6653345369377348106e-16" />
            <geometry>
                <mesh filename="package:///leg_spacer.stl"/>
            </geometry>
        </collision>
        <visual>
            <origin xyz="0.016060000000000018705 0.14364999999999997216 0.10914999999999995539" rpy="-1.57079632679489678 -1.8345638269942055852e-28 5.5511151231283095222e-17" />
            <geometry>
                <mesh filename="package:///left_knee_to_ankle_right_sheet.stl"/>
            </geometry>
            <material name="left_knee_to_ankle_right_sheet_material">
                <color rgba="0.22352941176470589313 0.21960784313725489891 0.21960784313725489891 1.0"/>
            </material>
        </visual>
        <collision>
            <origin xyz="0.016060000000000018705 0.14364999999999997216 0.10914999999999995539" rpy="-1.57079632679489678 -1.8345638269942055852e-28 5.5511151231283095222e-17" />
            <geometry>
                <mesh filename="package:///left_knee_to_ankle_right_sheet.stl"/>
            </geometry>
        </collision>
        <visual>
            <origin xyz="0.016060000000000001358 0.14365000000000002767 0.10914999999999992764" rpy="-1.57079632679489678 2.4194302416433997039e-29 0" />
            <geometry>
                <mesh filename="package:///left_knee_to_ankle_left_sheet.stl"/>
            </geometry>
            <material name="left_knee_to_ankle_left_sheet_material">
                <color rgba="0.22352941176470589313 0.21960784313725489891 0.21960784313725489891 1.0"/>
            </material>
        </visual>
        <collision>
            <origin xyz="0.016060000000000001358 0.14365000000000002767 0.10914999999999992764" rpy="-1.57079632679489678 2.4194302416433997039e-29 0" />
            <geometry>
                <mesh filename="package:///left_knee_to_ankle_left_sheet.stl"/>
            </geometry>
        </collision>
        <visual>
            <origin xyz="4.4408920985006261617e-16 -0.053150000000001439149 0.009549999999999739253" rpy="-1.570796326794896558 2.6413756779272067634e-16 1.570796326794896558" />
            <geometry>
                <mesh filename="package:///wj-wk00-0123middlecase_56.stl"/>
            </geometry>
            <material name="wj-wk00-0123middlecase_56_material">
                <color rgba="0.24705882352941177516 0.24313725490196078094 0.24313725490196078094 1.0"/>
            </material>
        </visual>
        <collision>
            <origin xyz="4.4408920985006261617e-16 -0.053150000000001439149 0.009549999999999739253" rpy="-1.570796326794896558 2.6413756779272067634e-16 1.570796326794896558" />
            <geometry>
                <mesh filename="package:///wj-wk00-0123middlecase_56.stl"/>
            </geometry>
        </collision>
        <visual>
            <origin xyz="4.4408920985006261617e-16 -0.053150000000001439149 0.009549999999999739253" rpy="-1.570796326794896558 2.6413756779272067634e-16 1.570796326794896558" />
            <geometry>
                <mesh filename="package:///drive_palonier.stl"/>
            </geometry>
            <material name="drive_palonier_material">
                <color rgba="0.62352941176470588758 0.66666666666666662966 0.70196078431372543882 1.0"/>
            </material>
        </visual>
        <collision>
            <origin xyz="4.4408920985006261617e-16 -0.053150000000001439149 0.009549999999999739253" rpy="-1.570796326794896558 2.6413756779272067634e-16 1.570796326794896558" />
            <geometry>
                <mesh filename="package:///drive_palonier.stl"/>
            </geometry>
        </collision>
        <visual>
            <origin xyz="4.4408920985006261617e-16 -0.053150000000001439149 0.009549999999999739253" rpy="-1.570796326794896558 2.6413756779272067634e-16 1.570796326794896558" />
            <geometry>
                <mesh filename="package:///wj-wk00-0124bottomcase_45.stl"/>
            </geometry>
            <material name="wj-wk00-0124bottomcase_45_material">
                <color rgba="0.24705882352941177516 0.24313725490196078094 0.24313725490196078094 1.0"/>
            </material>
        </visual>
        <collision>
            <origin xyz="4.4408920985006261617e-16 -0.053150000000001439149 0.009549999999999739253" rpy="-1.570796326794896558 2.6413756779272067634e-16 1.570796326794896558" />
            <geometry>
                <mesh filename="package:///wj-wk00-0124bottomcase_45.stl"/>
            </geometry>
        </collision>
        <visual>
            <origin xyz="4.4408920985006261617e-16 -0.053150000000001439149 0.009549999999999739253" rpy="-1.570796326794896558 2.6413756779272067634e-16 1.570796326794896558" />
            <geometry>
                <mesh filename="package:///wj-wk00-0122topcabinetcase_95.stl"/>
            </geometry>
            <material name="wj-wk00-0122topcabinetcase_95_material">
                <color rgba="0.24705882352941177516 0.24313725490196078094 0.24313725490196078094 1.0"/>
            </material>
        </visual>
        <collision>
            <origin xyz="4.4408920985006261617e-16 -0.053150000000001439149 0.009549999999999739253" rpy="-1.570796326794896558 2.6413756779272067634e-16 1.570796326794896558" />
            <geometry>
                <mesh filename="package:///wj-wk00-0122topcabinetcase_95.stl"/>
            </geometry>
        </collision>
        <visual>
            <origin xyz="7.3552275381416620803e-16 -0.05315000000000136976 0.0066499999999972136955" rpy="-1.570796326794896558 2.6413756779272067634e-16 1.570796326794896558" />
            <geometry>
                <mesh filename="package:///passive_palonier.stl"/>
            </geometry>
            <material name="passive_palonier_material">
                <color rgba="0.62352941176470588758 0.66666666666666662966 0.70196078431372543882 1.0"/>
            </material>
        </visual>
        <collision>
            <origin xyz="7.3552275381416620803e-16 -0.05315000000000136976 0.0066499999999972136955" rpy="-1.570796326794896558 2.6413756779272067634e-16 1.570796326794896558" />
            <geometry>
                <mesh filename="package:///passive_palonier.stl"/>
            </geometry>
        </collision>
        <inertial>
            <origin xyz="0.0025336932086845848598 -0.039063625582320897489 0.010277553221843004072" rpy="0 0 0"/>
            <mass value="0.12407000000000001361" />
            <inertia ixx="0.00021140643070753165349" ixy="-2.6870571086842151711e-05"  ixz="3.8190626605767761411e-06" iyy="7.8375946578579673476e-05" iyz="2.080093901334335342e-05" izz="0.00022561934195592411694" />
        </inertial>
    </link>
    <link name="knee_and_ankle_assembly_2">
        <visual>
            <origin xyz="0.016059999999998287451 0.14365000000000685554 0.10924999999999794598" rpy="-1.5707963267948970021 2.2013640908009679411e-15 3.571962178840912929e-27" />
            <geometry>
                <mesh filename="package:///leg_spacer.stl"/>
            </geometry>
            <material name="leg_spacer_material">
                <color rgba="0.64705882352941179736 0.64705882352941179736 0.64705882352941179736 1.0"/>
            </material>
        </visual>
        <collision>
            <origin xyz="0.016059999999998287451 0.14365000000000685554 0.10924999999999794598" rpy="-1.5707963267948970021 2.2013640908009679411e-15 3.571962178840912929e-27" />
            <geometry>
                <mesh filename="package:///leg_spacer.stl"/>
            </geometry>
        </collision>
        <visual>
            <origin xyz="0.016060000000000060338 0.14365000000000138769 0.10914999999999996927" rpy="-1.57079632679489678 1.1670253415690752805e-27 -1.0223637331664162331e-27" />
            <geometry>
                <mesh filename="package:///left_knee_to_ankle_right_sheet.stl"/>
            </geometry>
            <material name="left_knee_to_ankle_right_sheet_material">
                <color rgba="0.22352941176470589313 0.21960784313725489891 0.21960784313725489891 1.0"/>
            </material>
        </visual>
        <collision>
            <origin xyz="0.016060000000000060338 0.14365000000000138769 0.10914999999999996927" rpy="-1.57079632679489678 1.1670253415690752805e-27 -1.0223637331664162331e-27" />
            <geometry>
                <mesh filename="package:///left_knee_to_ankle_right_sheet.stl"/>
            </geometry>
        </collision>
        <visual>
            <origin xyz="0.016060000000000004827 0.14364999999999999991 0.10914999999999994151" rpy="-1.57079632679489678 5.822089083762987569e-30 0" />
            <geometry>
                <mesh filename="package:///left_knee_to_ankle_left_sheet.stl"/>
            </geometry>
            <material name="left_knee_to_ankle_left_sheet_material">
                <color rgba="0.22352941176470589313 0.21960784313725489891 0.21960784313725489891 1.0"/>
            </material>
        </visual>
        <collision>
            <origin xyz="0.016060000000000004827 0.14364999999999999991 0.10914999999999994151" rpy="-1.57079632679489678 5.822089083762987569e-30 0" />
            <geometry>
                <mesh filename="package:///left_knee_to_ankle_left_sheet.stl"/>
            </geometry>
        </collision>
        <visual>
            <origin xyz="-2.7755575615628913511e-17 -0.053150000000000072187 0.0095499999999999751754" rpy="-1.570796326794896558 2.6413756771629933241e-16 1.570796326794896558" />
            <geometry>
                <mesh filename="package:///wj-wk00-0123middlecase_56.stl"/>
            </geometry>
            <material name="wj-wk00-0123middlecase_56_material">
                <color rgba="0.24705882352941177516 0.24313725490196078094 0.24313725490196078094 1.0"/>
            </material>
        </visual>
        <collision>
            <origin xyz="-2.7755575615628913511e-17 -0.053150000000000072187 0.0095499999999999751754" rpy="-1.570796326794896558 2.6413756771629933241e-16 1.570796326794896558" />
            <geometry>
                <mesh filename="package:///wj-wk00-0123middlecase_56.stl"/>
            </geometry>
        </collision>
        <visual>
            <origin xyz="-2.7755575615628913511e-17 -0.053150000000000072187 0.0095499999999999751754" rpy="-1.570796326794896558 2.6413756771629933241e-16 1.570796326794896558" />
            <geometry>
                <mesh filename="package:///drive_palonier.stl"/>
            </geometry>
            <material name="drive_palonier_material">
                <color rgba="0.62352941176470588758 0.66666666666666662966 0.70196078431372543882 1.0"/>
            </material>
        </visual>
        <collision>
            <origin xyz="-2.7755575615628913511e-17 -0.053150000000000072187 0.0095499999999999751754" rpy="-1.570796326794896558 2.6413756771629933241e-16 1.570796326794896558" />
            <geometry>
                <mesh filename="package:///drive_palonier.stl"/>
            </geometry>
        </collision>
        <visual>
            <origin xyz="-2.7755575615628913511e-17 -0.053150000000000072187 0.0095499999999999751754" rpy="-1.570796326794896558 2.6413756771629933241e-16 1.570796326794896558" />
            <geometry>
                <mesh filename="package:///wj-wk00-0124bottomcase_45.stl"/>
            </geometry>
            <material name="wj-wk00-0124bottomcase_45_material">
                <color rgba="0.24705882352941177516 0.24313725490196078094 0.24313725490196078094 1.0"/>
            </material>
        </visual>
        <collision>
            <origin xyz="-2.7755575615628913511e-17 -0.053150000000000072187 0.0095499999999999751754" rpy="-1.570796326794896558 2.6413756771629933241e-16 1.570796326794896558" />
            <geometry>
                <mesh filename="package:///wj-wk00-0124bottomcase_45.stl"/>
            </geometry>
        </collision>
        <visual>
            <origin xyz="-2.7755575615628913511e-17 -0.053150000000000072187 0.0095499999999999751754" rpy="-1.570796326794896558 2.6413756771629933241e-16 1.570796326794896558" />
            <geometry>
                <mesh filename="package:///wj-wk00-0122topcabinetcase_95.stl"/>
            </geometry>
            <material name="wj-wk00-0122topcabinetcase_95_material">
                <color rgba="0.24705882352941177516 0.24313725490196078094 0.24313725490196078094 1.0"/>
            </material>
        </visual>
        <collision>
            <origin xyz="-2.7755575615628913511e-17 -0.053150000000000072187 0.0095499999999999751754" rpy="-1.570796326794896558 2.6413756771629933241e-16 1.570796326794896558" />
            <geometry>
                <mesh filename="package:///wj-wk00-0122topcabinetcase_95.stl"/>
            </geometry>
        </collision>
        <visual>
            <origin xyz="-7.0082828429463006614e-16 -0.053150000000000099942 0.0066499999999981157517" rpy="-1.570796326794896558 2.6413756771629933241e-16 1.570796326794896558" />
            <geometry>
                <mesh filename="package:///passive_palonier.stl"/>
            </geometry>
            <material name="passive_palonier_material">
                <color rgba="0.62352941176470588758 0.66666666666666662966 0.70196078431372543882 1.0"/>
            </material>
        </visual>
        <collision>
            <origin xyz="-7.0082828429463006614e-16 -0.053150000000000099942 0.0066499999999981157517" rpy="-1.570796326794896558 2.6413756771629933241e-16 1.570796326794896558" />
            <geometry>
                <mesh filename="package:///passive_palonier.stl"/>
            </geometry>
        </collision>
        <inertial>
            <origin xyz="5.0185935256645920267e-06 -0.057746501775911777965 0.018113576234400546872" rpy="0 0 0"/>
            <mass value="0.072590000000000057256" />
            <inertia ixx="4.9957470488425233766e-05" ixy="1.0381659904814674936e-08"  ixz="2.2517542781916217196e-09" iyy="1.8727312047200110276e-05" iyz="8.8104946302399228986e-08" izz="4.2393204018240234713e-05" />
        </inertial>
    </link>
    <link name="foot_assembly">
        <visual>
            <origin xyz="0.016060000000000015236 0.22230000000000008087 0.10905000000000000804" rpy="-1.570796326794896558 -1.5415933572433602064e-29 0" />
            <geometry>
                <mesh filename="package:///foot_side.stl"/>
            </geometry>
            <material name="foot_side_material">
                <color rgba="0.98039215686274505668 0.71372549019607844922 0.0039215686274509803377 1.0"/>
            </material>
        </visual>
        <collision>
            <origin xyz="0.016060000000000015236 0.22230000000000008087 0.10905000000000000804" rpy="-1.570796326794896558 -1.5415933572433602064e-29 0" />
            <geometry>
                <mesh filename="package:///foot_side.stl"/>
            </geometry>
        </collision>
        <visual>
            <origin xyz="0.016559999999999977516 0.2228000000000002756 0.1095500000000003693" rpy="-1.570796326794896558 4.8789097761693540394e-18 0" />
            <geometry>
                <mesh filename="package:///foot_bottom_tpu.stl"/>
            </geometry>
            <material name="foot_bottom_tpu_material">
                <color rgba="0.3058823529411764941 0.29803921568627450567 0.27843137254901961786 1.0"/>
            </material>
        </visual>
        <collision>
            <origin xyz="0.016559999999999977516 0.2228000000000002756 0.1095500000000003693" rpy="-1.570796326794896558 4.8789097761693540394e-18 0" />
            <geometry>
                <mesh filename="package:///foot_bottom_tpu.stl"/>
            </geometry>
        </collision>
        <visual>
            <origin xyz="0.016559999999999963638 0.22280000000000038662 0.1095500000000003693" rpy="-1.570796326794896558 4.8789097761693540394e-18 0" />
            <geometry>
                <mesh filename="package:///foot_bottom_pla.stl"/>
            </geometry>
            <material name="foot_bottom_pla_material">
                <color rgba="0.3058823529411764941 0.29803921568627450567 0.27843137254901961786 1.0"/>
            </material>
        </visual>
        <collision>
            <origin xyz="0.016559999999999963638 0.22280000000000038662 0.1095500000000003693" rpy="-1.570796326794896558 4.8789097761693540394e-18 0" />
            <geometry>
                <mesh filename="package:///foot_bottom_pla.stl"/>
            </geometry>
        </collision>
        <visual>
            <origin xyz="0.016060000000000015236 0.22230000000000008087 0.10905000000000000804" rpy="-1.570796326794896558 -1.5415933572433602064e-29 0" />
            <geometry>
                <mesh filename="package:///foot_top.stl"/>
            </geometry>
            <material name="foot_top_material">
                <color rgba="0.98039215686274505668 0.71372549019607844922 0.0039215686274509803377 1.0"/>
            </material>
        </visual>
        <collision>
            <origin xyz="0.016060000000000015236 0.22230000000000008087 0.10905000000000000804" rpy="-1.570796326794896558 -1.5415933572433602064e-29 0" />
            <geometry>
                <mesh filename="package:///foot_top.stl"/>
            </geometry>
        </collision>
        <inertial>
            <origin xyz="0.011071805405810810838 -0.024660828914054331445 0.019062631505101720886" rpy="0 0 0"/>
            <mass value="0.075240000000000001323" />
            <inertia ixx="1.8748234895611842787e-05" ixy="1.5883913417291485579e-06"  ixz="-6.5235393392554439271e-09" iyy="6.7442711017631486138e-05" iyz="5.6739084804828818974e-08" izz="6.0609999941114232999e-05" />
        </inertial>
    </link>
    <link name="left_foot">
        <inertial>
            <origin xyz="0 0 0" rpy="0 0 0" />
            <mass value="1e-9" />
            <inertia ixx="0" ixy="0" ixz="0" iyy="0" iyz="0" izz="0" />
        </inertial>
    </link>
    <joint name="left_foot_frame" type="fixed">
        <origin xyz="0.00049999999999996574962 -0.036224999999999729638 0.01955000000000034488" rpy="-1.570796326794896558 4.8789097742003279458e-18 8.5828066488045564267e-28" />
        <parent link="foot_assembly" />
        <child link="left_foot" />
        <axis xyz="0 0 0"/>
    </joint>
    <joint name="left_ankle" type="revolute">
        <origin xyz="-3.4694469519536141888e-17 -0.078650000000000178102 9.99999999999751088e-05" rpy="-2.6413756774523519415e-16 1.2220841311108591179e-26 2.7755576181993178136e-17" />
        <parent link="knee_and_ankle_assembly_2" />
        <child link="foot_assembly" />
        <axis xyz="0 0 1"/>
        <limit effort="1" velocity="20" lower="-1.570796326794896558" upper="1.570796326794896558"/>
        <joint_properties friction="0.0"/>
    </joint>
    <joint name="left_knee" type="revolute">
        <origin xyz="1.3877787807814456755e-17 -0.078650000000000011569 9.9999999999961231012e-05" rpy="-2.6413756781799972404e-16 -2.7339812777890022088e-26 0" />
        <parent link="knee_and_ankle_assembly" />
        <child link="knee_and_ankle_assembly_2" />
        <axis xyz="0 0 1"/>
        <limit effort="1" velocity="20" lower="-1.570796326794896558" upper="1.570796326794896558"/>
        <joint_properties friction="0.0"/>
    </joint>
    <joint name="left_hip_pitch" type="revolute">
        <origin xyz="0.074149999999999799405 1.3959102970750869588e-18 0.035109999999999912113" rpy="3.141592653589793116 1.5707963267948952257 0" />
        <parent link="left_roll_to_pitch_assembly" />
        <child link="knee_and_ankle_assembly" />
        <axis xyz="0 0 1"/>
        <limit effort="1" velocity="20" lower="-1.2217304763960306069" upper="0.52359877559829881566"/>
        <joint_properties friction="0.0"/>
    </joint>
    <joint name="left_hip_roll" type="revolute">
        <origin xyz="0.019050000000003241424 2.0469737016526323714e-15 -0.046015000000000895464" rpy="-1.5707963267949442976 1.0251581517556108667e-13 1.5707963267946023489" />
        <parent link="hip_roll_assembly" />
        <child link="left_roll_to_pitch_assembly" />
        <axis xyz="0 0 1"/>
        <limit effort="1" velocity="20" lower="-0.43633231299858238339" upper="0.43633231299858238339"/>
        <joint_properties friction="0.0"/>
    </joint>
    <joint name="left_hip_yaw" type="revolute">
        <origin xyz="-0.019000000000000290962 0.035000000000001273148 0.045940938812378845357" rpy="-2.0757017677015319346e-16 -2.1982415887547258194e-14 -7.6136910267405882653e-27" />
        <parent link="trunk_assembly" />
        <child link="hip_roll_assembly" />
        <axis xyz="0 0 1"/>
        <limit effort="1" velocity="20" lower="-0.52359877559829881566" upper="0.52359877559829881566"/>
        <joint_properties friction="0.0"/>
    </joint>
    <link name="hip_roll_assembly_2">
        <visual>
            <origin xyz="-3.6429192995512948983e-16 -0.034999999999999351075 0.019050000000000018308" rpy="4.4170622972759838776e-18 -5.5503510379569914253e-17 -3.0531133177191770349e-16" />
            <geometry>
                <mesh filename="package:///roll_motor_bottom.stl"/>
            </geometry>
            <material name="roll_motor_bottom_material">
                <color rgba="0.64705882352941179736 0.64705882352941179736 0.64705882352941179736 1.0"/>
            </material>
        </visual>
        <collision>
            <origin xyz="-3.6429192995512948983e-16 -0.034999999999999351075 0.019050000000000018308" rpy="4.4170622972759838776e-18 -5.5503510379569914253e-17 -3.0531133177191770349e-16" />
            <geometry>
                <mesh filename="package:///roll_motor_bottom.stl"/>
            </geometry>
        </collision>
        <visual>
            <origin xyz="3.4694469519536141888e-18 -0.035000000000000017208 0.019050000000000018308" rpy="8.064977813604698211e-33 3.2047474275637062212e-31 -1.1957048213566483917e-32" />
            <geometry>
                <mesh filename="package:///roll_motor_top.stl"/>
            </geometry>
            <material name="roll_motor_top_material">
                <color rgba="0.90196078431372550543 0.90196078431372550543 0.90196078431372550543 1.0"/>
            </material>
        </visual>
        <collision>
            <origin xyz="3.4694469519536141888e-18 -0.035000000000000017208 0.019050000000000018308" rpy="8.064977813604698211e-33 3.2047474275637062212e-31 -1.1957048213566483917e-32" />
            <geometry>
                <mesh filename="package:///roll_motor_top.stl"/>
            </geometry>
        </collision>
        <visual>
            <origin xyz="0.009600000000011033735 3.8517800060589024724e-14 -0.020515000000002000385" rpy="-1.5707963267951956521 -1.5707963267947591124 0" />
            <geometry>
                <mesh filename="package:///wj-wk00-0123middlecase_56.stl"/>
            </geometry>
            <material name="wj-wk00-0123middlecase_56_material">
                <color rgba="0.24705882352941177516 0.24313725490196078094 0.24313725490196078094 1.0"/>
            </material>
        </visual>
        <collision>
            <origin xyz="0.009600000000011033735 3.8517800060589024724e-14 -0.020515000000002000385" rpy="-1.5707963267951956521 -1.5707963267947591124 0" />
            <geometry>
                <mesh filename="package:///wj-wk00-0123middlecase_56.stl"/>
            </geometry>
        </collision>
        <visual>
            <origin xyz="0.009600000000011033735 3.8517800060589024724e-14 -0.020515000000002000385" rpy="-1.5707963267951956521 -1.5707963267947591124 0" />
            <geometry>
                <mesh filename="package:///drive_palonier.stl"/>
            </geometry>
            <material name="drive_palonier_material">
                <color rgba="0.62352941176470588758 0.66666666666666662966 0.70196078431372543882 1.0"/>
            </material>
        </visual>
        <collision>
            <origin xyz="0.009600000000011033735 3.8517800060589024724e-14 -0.020515000000002000385" rpy="-1.5707963267951956521 -1.5707963267947591124 0" />
            <geometry>
                <mesh filename="package:///drive_palonier.stl"/>
            </geometry>
        </collision>
        <visual>
            <origin xyz="0.009600000000011033735 3.8517800060589024724e-14 -0.020515000000002000385" rpy="-1.5707963267951956521 -1.5707963267947591124 0" />
            <geometry>
                <mesh filename="package:///wj-wk00-0124bottomcase_45.stl"/>
            </geometry>
            <material name="wj-wk00-0124bottomcase_45_material">
                <color rgba="0.24705882352941177516 0.24313725490196078094 0.24313725490196078094 1.0"/>
            </material>
        </visual>
        <collision>
            <origin xyz="0.009600000000011033735 3.8517800060589024724e-14 -0.020515000000002000385" rpy="-1.5707963267951956521 -1.5707963267947591124 0" />
            <geometry>
                <mesh filename="package:///wj-wk00-0124bottomcase_45.stl"/>
            </geometry>
        </collision>
        <visual>
            <origin xyz="0.009600000000011033735 3.8517800060589024724e-14 -0.020515000000002000385" rpy="-1.5707963267951956521 -1.5707963267947591124 0" />
            <geometry>
                <mesh filename="package:///wj-wk00-0122topcabinetcase_95.stl"/>
            </geometry>
            <material name="wj-wk00-0122topcabinetcase_95_material">
                <color rgba="0.24705882352941177516 0.24313725490196078094 0.24313725490196078094 1.0"/>
            </material>
        </visual>
        <collision>
            <origin xyz="0.009600000000011033735 3.8517800060589024724e-14 -0.020515000000002000385" rpy="-1.5707963267951956521 -1.5707963267947591124 0" />
            <geometry>
                <mesh filename="package:///wj-wk00-0122topcabinetcase_95.stl"/>
            </geometry>
        </collision>
        <visual>
            <origin xyz="0.012500000000016761592 3.9114544936325046365e-14 -0.020515000000002069774" rpy="-1.5707963267951956521 -1.5707963267947591124 0" />
            <geometry>
                <mesh filename="package:///passive_palonier.stl"/>
            </geometry>
            <material name="passive_palonier_material">
                <color rgba="0.62352941176470588758 0.66666666666666662966 0.70196078431372543882 1.0"/>
            </material>
        </visual>
        <collision>
            <origin xyz="0.012500000000016761592 3.9114544936325046365e-14 -0.020515000000002069774" rpy="-1.5707963267951956521 -1.5707963267947591124 0" />
            <geometry>
                <mesh filename="package:///passive_palonier.stl"/>
            </geometry>
        </collision>
        <inertial>
            <origin xyz="0.00079508052675062086158 -5.4654095489695737564e-06 -0.033060020136904864907" rpy="0 0 0"/>
            <mass value="0.06648000000000005294" />
            <inertia ixx="2.444109845492506181e-05" ixy="2.3565814728317993465e-09"  ixz="-3.810586811908133143e-07" iyy="2.8181841945863342683e-05" iyz="-7.5003565177856955535e-09" izz="1.426867355000683836e-05" />
        </inertial>
    </link>
    <link name="right_roll_to_pitch_assembly">
        <visual>
            <origin xyz="0.03500000000000001027 -0.065000000000000016098 0.019050000000000021777" rpy="1.570796326794896558 1.570796326794896336 0" />
            <geometry>
                <mesh filename="package:///right_roll_to_pitch.stl"/>
            </geometry>
            <material name="right_roll_to_pitch_material">
                <color rgba="0.90980392156862743835 0.57254901960784310155 0.16470588235294117418 1.0"/>
            </material>
        </visual>
        <collision>
            <origin xyz="0.03500000000000001027 -0.065000000000000016098 0.019050000000000021777" rpy="1.570796326794896558 1.570796326794896336 0" />
            <geometry>
                <mesh filename="package:///right_roll_to_pitch.stl"/>
            </geometry>
        </collision>
        <visual>
            <origin xyz="-0.06469999999999997975 1.0421893383016911372e-17 0.0096099999999999918127" rpy="-1.570796326794896558 1.570796326794896336 0" />
            <geometry>
                <mesh filename="package:///wj-wk00-0123middlecase_56.stl"/>
            </geometry>
            <material name="wj-wk00-0123middlecase_56_material">
                <color rgba="0.24705882352941177516 0.24313725490196078094 0.24313725490196078094 1.0"/>
            </material>
        </visual>
        <collision>
            <origin xyz="-0.06469999999999997975 1.0421893383016911372e-17 0.0096099999999999918127" rpy="-1.570796326794896558 1.570796326794896336 0" />
            <geometry>
                <mesh filename="package:///wj-wk00-0123middlecase_56.stl"/>
            </geometry>
        </collision>
        <visual>
            <origin xyz="-0.06469999999999997975 1.0421893383016911372e-17 0.0096099999999999918127" rpy="-1.570796326794896558 1.570796326794896336 0" />
            <geometry>
                <mesh filename="package:///drive_palonier.stl"/>
            </geometry>
            <material name="drive_palonier_material">
                <color rgba="0.62352941176470588758 0.66666666666666662966 0.70196078431372543882 1.0"/>
            </material>
        </visual>
        <collision>
            <origin xyz="-0.06469999999999997975 1.0421893383016911372e-17 0.0096099999999999918127" rpy="-1.570796326794896558 1.570796326794896336 0" />
            <geometry>
                <mesh filename="package:///drive_palonier.stl"/>
            </geometry>
        </collision>
        <visual>
            <origin xyz="-0.06469999999999997975 1.0421893383016911372e-17 0.0096099999999999918127" rpy="-1.570796326794896558 1.570796326794896336 0" />
            <geometry>
                <mesh filename="package:///wj-wk00-0124bottomcase_45.stl"/>
            </geometry>
            <material name="wj-wk00-0124bottomcase_45_material">
                <color rgba="0.24705882352941177516 0.24313725490196078094 0.24313725490196078094 1.0"/>
            </material>
        </visual>
        <collision>
            <origin xyz="-0.06469999999999997975 1.0421893383016911372e-17 0.0096099999999999918127" rpy="-1.570796326794896558 1.570796326794896336 0" />
            <geometry>
                <mesh filename="package:///wj-wk00-0124bottomcase_45.stl"/>
            </geometry>
        </collision>
        <visual>
            <origin xyz="-0.06469999999999997975 1.0421893383016911372e-17 0.0096099999999999918127" rpy="-1.570796326794896558 1.570796326794896336 0" />
            <geometry>
                <mesh filename="package:///wj-wk00-0122topcabinetcase_95.stl"/>
            </geometry>
            <material name="wj-wk00-0122topcabinetcase_95_material">
                <color rgba="0.24705882352941177516 0.24313725490196078094 0.24313725490196078094 1.0"/>
            </material>
        </visual>
        <collision>
            <origin xyz="-0.06469999999999997975 1.0421893383016911372e-17 0.0096099999999999918127" rpy="-1.570796326794896558 1.570796326794896336 0" />
            <geometry>
                <mesh filename="package:///wj-wk00-0122topcabinetcase_95.stl"/>
            </geometry>
        </collision>
        <visual>
            <origin xyz="-0.067600000000005655565 9.5220055798539426917e-17 0.0096099999999999848738" rpy="-1.570796326794896558 1.570796326794896336 0" />
            <geometry>
                <mesh filename="package:///passive_palonier.stl"/>
            </geometry>
            <material name="passive_palonier_material">
                <color rgba="0.62352941176470588758 0.66666666666666662966 0.70196078431372543882 1.0"/>
            </material>
        </visual>
        <collision>
            <origin xyz="-0.067600000000005655565 9.5220055798539426917e-17 0.0096099999999999848738" rpy="-1.570796326794896558 1.570796326794896336 0" />
            <geometry>
                <mesh filename="package:///passive_palonier.stl"/>
            </geometry>
        </collision>
        <inertial>
            <origin xyz="-0.050804245559722800707 -0.00042074186984666911556 0.02047043747768734559" rpy="0 0 0"/>
            <mass value="0.075160000000000060094" />
            <inertia ixx="2.5232917470048167705e-05" ixy="-1.305278601732912787e-07"  ixz="5.9049873224165432398e-07" iyy="4.1385487041400236094e-05" iyz="-9.1342675969409102721e-08" izz="2.8126389586193964503e-05" />
        </inertial>
    </link>
    <link name="knee_and_ankle_assembly_3">
        <visual>
            <origin xyz="0.016060000000000060338 -0.06500000000000000222 0.10919999999999911722" rpy="1.570796326794896336 -6.0962253877159143412e-26 -5.1246376555419674487e-28" />
            <geometry>
                <mesh filename="package:///right_cache.stl"/>
            </geometry>
            <material name="right_cache_material">
                <color rgba="0.91764705882352937127 0.91764705882352937127 0.91764705882352937127 1.0"/>
            </material>
        </visual>
        <collision>
            <origin xyz="0.016060000000000060338 -0.06500000000000000222 0.10919999999999911722" rpy="1.570796326794896336 -6.0962253877159143412e-26 -5.1246376555419674487e-28" />
            <geometry>
                <mesh filename="package:///right_cache.stl"/>
            </geometry>
        </collision>
        <visual>
            <origin xyz="0.0160600000000000534 -0.1436499999999996946 -0.072149999999999658851" rpy="1.570796326794896558 -6.5506092691232114014e-26 -5.1246376555419674487e-28" />
            <geometry>
                <mesh filename="package:///leg_spacer.stl"/>
            </geometry>
            <material name="leg_spacer_material">
                <color rgba="0.64705882352941179736 0.64705882352941179736 0.64705882352941179736 1.0"/>
            </material>
        </visual>
        <collision>
            <origin xyz="0.0160600000000000534 -0.1436499999999996946 -0.072149999999999658851" rpy="1.570796326794896558 -6.5506092691232114014e-26 -5.1246376555419674487e-28" />
            <geometry>
                <mesh filename="package:///leg_spacer.stl"/>
            </geometry>
        </collision>
        <visual>
            <origin xyz="0.016060000000000008297 -0.14365000000000002767 -0.072049999999999891909" rpy="1.570796326794896336 -2.4326670647182607238e-29 5.0289882707839502595e-30" />
            <geometry>
                <mesh filename="package:///left_knee_to_ankle_right_sheet.stl"/>
            </geometry>
            <material name="left_knee_to_ankle_right_sheet_material">
                <color rgba="0.22352941176470589313 0.21960784313725489891 0.21960784313725489891 1.0"/>
            </material>
        </visual>
        <collision>
            <origin xyz="0.016060000000000008297 -0.14365000000000002767 -0.072049999999999891909" rpy="1.570796326794896336 -2.4326670647182607238e-29 5.0289882707839502595e-30" />
            <geometry>
                <mesh filename="package:///left_knee_to_ankle_right_sheet.stl"/>
            </geometry>
        </collision>
        <visual>
            <origin xyz="0.016060000000000015236 -0.14364999999999930602 -0.072049999999999558842" rpy="1.570796326794896336 6.8715723720396827557e-28 5.5511151231262510883e-17" />
            <geometry>
                <mesh filename="package:///left_knee_to_ankle_left_sheet.stl"/>
            </geometry>
            <material name="left_knee_to_ankle_left_sheet_material">
                <color rgba="0.22352941176470589313 0.21960784313725489891 0.21960784313725489891 1.0"/>
            </material>
        </visual>
        <collision>
            <origin xyz="0.016060000000000015236 -0.14364999999999930602 -0.072049999999999558842" rpy="1.570796326794896336 6.8715723720396827557e-28 5.5511151231262510883e-17" />
            <geometry>
                <mesh filename="package:///left_knee_to_ankle_left_sheet.stl"/>
            </geometry>
        </collision>
        <visual>
            <origin xyz="-1.3877787807814456755e-17 0.053149999999999530953 0.027549999999999699729" rpy="1.570796326794896558 -2.6413756807534671101e-16 -1.570796326794896558" />
            <geometry>
                <mesh filename="package:///wj-wk00-0123middlecase_56.stl"/>
            </geometry>
            <material name="wj-wk00-0123middlecase_56_material">
                <color rgba="0.24705882352941177516 0.24313725490196078094 0.24313725490196078094 1.0"/>
            </material>
        </visual>
        <collision>
            <origin xyz="-1.3877787807814456755e-17 0.053149999999999530953 0.027549999999999699729" rpy="1.570796326794896558 -2.6413756807534671101e-16 -1.570796326794896558" />
            <geometry>
                <mesh filename="package:///wj-wk00-0123middlecase_56.stl"/>
            </geometry>
        </collision>
        <visual>
            <origin xyz="-1.3877787807814456755e-17 0.053149999999999530953 0.027549999999999699729" rpy="1.570796326794896558 -2.6413756807534671101e-16 -1.570796326794896558" />
            <geometry>
                <mesh filename="package:///drive_palonier.stl"/>
            </geometry>
            <material name="drive_palonier_material">
                <color rgba="0.62352941176470588758 0.66666666666666662966 0.70196078431372543882 1.0"/>
            </material>
        </visual>
        <collision>
            <origin xyz="-1.3877787807814456755e-17 0.053149999999999530953 0.027549999999999699729" rpy="1.570796326794896558 -2.6413756807534671101e-16 -1.570796326794896558" />
            <geometry>
                <mesh filename="package:///drive_palonier.stl"/>
            </geometry>
        </collision>
        <visual>
            <origin xyz="-1.3877787807814456755e-17 0.053149999999999530953 0.027549999999999699729" rpy="1.570796326794896558 -2.6413756807534671101e-16 -1.570796326794896558" />
            <geometry>
                <mesh filename="package:///wj-wk00-0124bottomcase_45.stl"/>
            </geometry>
            <material name="wj-wk00-0124bottomcase_45_material">
                <color rgba="0.24705882352941177516 0.24313725490196078094 0.24313725490196078094 1.0"/>
            </material>
        </visual>
        <collision>
            <origin xyz="-1.3877787807814456755e-17 0.053149999999999530953 0.027549999999999699729" rpy="1.570796326794896558 -2.6413756807534671101e-16 -1.570796326794896558" />
            <geometry>
                <mesh filename="package:///wj-wk00-0124bottomcase_45.stl"/>
            </geometry>
        </collision>
        <visual>
            <origin xyz="-1.3877787807814456755e-17 0.053149999999999530953 0.027549999999999699729" rpy="1.570796326794896558 -2.6413756807534671101e-16 -1.570796326794896558" />
            <geometry>
                <mesh filename="package:///wj-wk00-0122topcabinetcase_95.stl"/>
            </geometry>
            <material name="wj-wk00-0122topcabinetcase_95_material">
                <color rgba="0.24705882352941177516 0.24313725490196078094 0.24313725490196078094 1.0"/>
            </material>
        </visual>
        <collision>
            <origin xyz="-1.3877787807814456755e-17 0.053149999999999530953 0.027549999999999699729" rpy="1.570796326794896558 -2.6413756807534671101e-16 -1.570796326794896558" />
            <geometry>
                <mesh filename="package:///wj-wk00-0122topcabinetcase_95.stl"/>
            </geometry>
        </collision>
        <visual>
            <origin xyz="-3.3306690738754696213e-16 0.053149999999998955025 0.030449999999998561551" rpy="1.570796326794896558 -2.6413756807534671101e-16 -1.570796326794896558" />
            <geometry>
                <mesh filename="package:///passive_palonier.stl"/>
            </geometry>
            <material name="passive_palonier_material">
                <color rgba="0.62352941176470588758 0.66666666666666662966 0.70196078431372543882 1.0"/>
            </material>
        </visual>
        <collision>
            <origin xyz="-3.3306690738754696213e-16 0.053149999999998955025 0.030449999999998561551" rpy="1.570796326794896558 -2.6413756807534671101e-16 -1.570796326794896558" />
            <geometry>
                <mesh filename="package:///passive_palonier.stl"/>
            </geometry>
        </collision>
        <inertial>
            <origin xyz="0.0025336932086842409509 0.039063625582319495833 0.010808979048309722351" rpy="0 0 0"/>
            <mass value="0.12407000000000001361" />
            <inertia ixx="0.00021236292317843469572" ixy="2.6870571086840894714e-05"  ixz="3.9655981569112408721e-06" iyy="7.9332439049479978096e-05" iyz="-2.1740666699998260165e-05" izz="0.00022561934195591912961" />
        </inertial>
    </link>
    <link name="knee_and_ankle_assembly_4">
        <visual>
            <origin xyz="0.016060000000000192177 0.14364999999999975011 0.10925000000000001377" rpy="-1.570796326794896558 -6.9397465996678598963e-25 -5.5511151231283082896e-17" />
            <geometry>
                <mesh filename="package:///leg_spacer.stl"/>
            </geometry>
            <material name="leg_spacer_material">
                <color rgba="0.64705882352941179736 0.64705882352941179736 0.64705882352941179736 1.0"/>
            </material>
        </visual>
        <collision>
            <origin xyz="0.016060000000000192177 0.14364999999999975011 0.10925000000000001377" rpy="-1.570796326794896558 -6.9397465996678598963e-25 -5.5511151231283082896e-17" />
            <geometry>
                <mesh filename="package:///leg_spacer.stl"/>
            </geometry>
        </collision>
        <visual>
            <origin xyz="0.016060000000000022174 0.14364999999999811253 0.10914999999999996927" rpy="-1.57079632679489678 -1.69557309379293477e-27 -5.5511151233026009436e-17" />
            <geometry>
                <mesh filename="package:///left_knee_to_ankle_right_sheet.stl"/>
            </geometry>
            <material name="left_knee_to_ankle_right_sheet_material">
                <color rgba="0.22352941176470589313 0.21960784313725489891 0.21960784313725489891 1.0"/>
            </material>
        </visual>
        <collision>
            <origin xyz="0.016060000000000022174 0.14364999999999811253 0.10914999999999996927" rpy="-1.57079632679489678 -1.69557309379293477e-27 -5.5511151233026009436e-17" />
            <geometry>
                <mesh filename="package:///left_knee_to_ankle_right_sheet.stl"/>
            </geometry>
        </collision>
        <visual>
            <origin xyz="0.016060000000000008297 0.14365000000000005542 0.10914999999999994151" rpy="-1.57079632679489678 -2.4848987773340104688e-29 0" />
            <geometry>
                <mesh filename="package:///left_knee_to_ankle_left_sheet.stl"/>
            </geometry>
            <material name="left_knee_to_ankle_left_sheet_material">
                <color rgba="0.22352941176470589313 0.21960784313725489891 0.21960784313725489891 1.0"/>
            </material>
        </visual>
        <collision>
            <origin xyz="0.016060000000000008297 0.14365000000000005542 0.10914999999999994151" rpy="-1.57079632679489678 -2.4848987773340104688e-29 0" />
            <geometry>
                <mesh filename="package:///left_knee_to_ankle_left_sheet.stl"/>
            </geometry>
        </collision>
        <visual>
            <origin xyz="0 -0.053150000000000016676 0.0095499999999999751754" rpy="-1.570796326794896558 2.6413757060755072442e-16 1.570796326794896558" />
            <geometry>
                <mesh filename="package:///wj-wk00-0123middlecase_56.stl"/>
            </geometry>
            <material name="wj-wk00-0123middlecase_56_material">
                <color rgba="0.24705882352941177516 0.24313725490196078094 0.24313725490196078094 1.0"/>
            </material>
        </visual>
        <collision>
            <origin xyz="0 -0.053150000000000016676 0.0095499999999999751754" rpy="-1.570796326794896558 2.6413757060755072442e-16 1.570796326794896558" />
            <geometry>
                <mesh filename="package:///wj-wk00-0123middlecase_56.stl"/>
            </geometry>
        </collision>
        <visual>
            <origin xyz="0 -0.053150000000000016676 0.0095499999999999751754" rpy="-1.570796326794896558 2.6413757060755072442e-16 1.570796326794896558" />
            <geometry>
                <mesh filename="package:///drive_palonier.stl"/>
            </geometry>
            <material name="drive_palonier_material">
                <color rgba="0.62352941176470588758 0.66666666666666662966 0.70196078431372543882 1.0"/>
            </material>
        </visual>
        <collision>
            <origin xyz="0 -0.053150000000000016676 0.0095499999999999751754" rpy="-1.570796326794896558 2.6413757060755072442e-16 1.570796326794896558" />
            <geometry>
                <mesh filename="package:///drive_palonier.stl"/>
            </geometry>
        </collision>
        <visual>
            <origin xyz="0 -0.053150000000000016676 0.0095499999999999751754" rpy="-1.570796326794896558 2.6413757060755072442e-16 1.570796326794896558" />
            <geometry>
                <mesh filename="package:///wj-wk00-0124bottomcase_45.stl"/>
            </geometry>
            <material name="wj-wk00-0124bottomcase_45_material">
                <color rgba="0.24705882352941177516 0.24313725490196078094 0.24313725490196078094 1.0"/>
            </material>
        </visual>
        <collision>
            <origin xyz="0 -0.053150000000000016676 0.0095499999999999751754" rpy="-1.570796326794896558 2.6413757060755072442e-16 1.570796326794896558" />
            <geometry>
                <mesh filename="package:///wj-wk00-0124bottomcase_45.stl"/>
            </geometry>
        </collision>
        <visual>
            <origin xyz="0 -0.053150000000000016676 0.0095499999999999751754" rpy="-1.570796326794896558 2.6413757060755072442e-16 1.570796326794896558" />
            <geometry>
                <mesh filename="package:///wj-wk00-0122topcabinetcase_95.stl"/>
            </geometry>
            <material name="wj-wk00-0122topcabinetcase_95_material">
                <color rgba="0.24705882352941177516 0.24313725490196078094 0.24313725490196078094 1.0"/>
            </material>
        </visual>
        <collision>
            <origin xyz="0 -0.053150000000000016676 0.0095499999999999751754" rpy="-1.570796326794896558 2.6413757060755072442e-16 1.570796326794896558" />
            <geometry>
                <mesh filename="package:///wj-wk00-0122topcabinetcase_95.stl"/>
            </geometry>
        </collision>
        <visual>
            <origin xyz="2.7061686225238190673e-16 -0.053150000000000099942 0.006650000000000974576" rpy="-1.570796326794896558 2.6413757060755072442e-16 1.570796326794896558" />
            <geometry>
                <mesh filename="package:///passive_palonier.stl"/>
            </geometry>
            <material name="passive_palonier_material">
                <color rgba="0.62352941176470588758 0.66666666666666662966 0.70196078431372543882 1.0"/>
            </material>
        </visual>
        <collision>
            <origin xyz="2.7061686225238190673e-16 -0.053150000000000099942 0.006650000000000974576" rpy="-1.570796326794896558 2.6413757060755072442e-16 1.570796326794896558" />
            <geometry>
                <mesh filename="package:///passive_palonier.stl"/>
            </geometry>
        </collision>
        <inertial>
            <origin xyz="5.0185935258263388972e-06 -0.057746501775911528165 0.018113576234400654424" rpy="0 0 0"/>
            <mass value="0.072590000000000057256" />
            <inertia ixx="4.9957470488426087576e-05" ixy="1.0381659904669149051e-08"  ixz="2.2517542780730561322e-09" iyy="1.8727312047200333892e-05" iyz="8.81049463023687358e-08" izz="4.2393204018240885234e-05" />
        </inertial>
    </link>
    <link name="foot_assembly_2">
        <visual>
            <origin xyz="0.016060000000000011766 0.22230000000000005311 0.10905000000000002192" rpy="-1.570796326794896558 -6.3235055153876968389e-30 0" />
            <geometry>
                <mesh filename="package:///foot_side.stl"/>
            </geometry>
            <material name="foot_side_material">
                <color rgba="0.98039215686274505668 0.71372549019607844922 0.0039215686274509803377 1.0"/>
            </material>
        </visual>
        <collision>
            <origin xyz="0.016060000000000011766 0.22230000000000005311 0.10905000000000002192" rpy="-1.570796326794896558 -6.3235055153876968389e-30 0" />
            <geometry>
                <mesh filename="package:///foot_side.stl"/>
            </geometry>
        </collision>
        <visual>
            <origin xyz="0.016560000000000230785 0.22280000000000016458 0.10955000000000063298" rpy="-1.570796326794896558 -6.3235055153876968389e-30 0" />
            <geometry>
                <mesh filename="package:///foot_bottom_tpu.stl"/>
            </geometry>
            <material name="foot_bottom_tpu_material">
                <color rgba="0.3058823529411764941 0.29803921568627450567 0.27843137254901961786 1.0"/>
            </material>
        </visual>
        <collision>
            <origin xyz="0.016560000000000230785 0.22280000000000016458 0.10955000000000063298" rpy="-1.570796326794896558 -6.3235055153876968389e-30 0" />
            <geometry>
                <mesh filename="package:///foot_bottom_tpu.stl"/>
            </geometry>
        </collision>
        <visual>
            <origin xyz="0.016560000000000230785 0.22280000000000016458 0.10955000000000063298" rpy="-1.570796326794896558 -6.3235055153876968389e-30 0" />
            <geometry>
                <mesh filename="package:///foot_bottom_pla.stl"/>
            </geometry>
            <material name="foot_bottom_pla_material">
                <color rgba="0.3058823529411764941 0.29803921568627450567 0.27843137254901961786 1.0"/>
            </material>
        </visual>
        <collision>
            <origin xyz="0.016560000000000230785 0.22280000000000016458 0.10955000000000063298" rpy="-1.570796326794896558 -6.3235055153876968389e-30 0" />
            <geometry>
                <mesh filename="package:///foot_bottom_pla.stl"/>
            </geometry>
        </collision>
        <visual>
            <origin xyz="0.016060000000000011766 0.22230000000000005311 0.10905000000000002192" rpy="-1.570796326794896558 -6.3235055153876968389e-30 0" />
            <geometry>
                <mesh filename="package:///foot_top.stl"/>
            </geometry>
            <material name="foot_top_material">
                <color rgba="0.98039215686274505668 0.71372549019607844922 0.0039215686274509803377 1.0"/>
            </material>
        </visual>
        <collision>
            <origin xyz="0.016060000000000011766 0.22230000000000005311 0.10905000000000002192" rpy="-1.570796326794896558 -6.3235055153876968389e-30 0" />
            <geometry>
                <mesh filename="package:///foot_top.stl"/>
            </geometry>
        </collision>
        <inertial>
            <origin xyz="0.011071805405810940942 -0.02466082891405442859 0.019062631505101859664" rpy="0 0 0"/>
            <mass value="0.075240000000000001323" />
            <inertia ixx="1.8748234895611886832e-05" ixy="1.5883913417292040386e-06"  ixz="-6.5235393392663494763e-09" iyy="6.7442711017631513243e-05" iyz="5.6739084804884087874e-08" izz="6.0609999941114287209e-05" />
        </inertial>
    </link>
    <link name="right_foot">
        <inertial>
            <origin xyz="0 0 0" rpy="0 0 0" />
            <mass value="1e-9" />
            <inertia ixx="0" ixy="0" ixz="0" iyy="0" iyz="0" izz="0" />
        </inertial>
    </link>
    <joint name="right_foot_frame" type="fixed">
        <origin xyz="0.0005000000000002155498 -0.036224999999999840661 0.019550000000000664069" rpy="-1.570796326794896558 9.1691846176123393012e-16 1.3322725304659061714e-15" />
        <parent link="foot_assembly_2" />
        <child link="right_foot" />
        <axis xyz="0 0 0"/>
    </joint>
    <joint name="right_ankle" type="revolute">
        <origin xyz="-6.9388939039072283776e-18 -0.078650000000000039324 9.9999999999961231012e-05" rpy="-2.6413756984180028828e-16 -6.9382288127881716121e-25 -5.1722034616178551878e-17" />
        <parent link="knee_and_ankle_assembly_4" />
        <child link="foot_assembly_2" />
        <axis xyz="0 0 1"/>
        <limit effort="1" velocity="20" lower="-1.570796326794896558" upper="1.570796326794896558"/>
        <joint_properties friction="0.0"/>
    </joint>
    <joint name="right_knee" type="revolute">
        <origin xyz="-6.9388939039072283776e-18 0.078649999999999414824 0.036999999999999658162" rpy="3.141592653589793116 -2.0819102970830263503e-24 5.0289882707839502595e-30" />
        <parent link="knee_and_ankle_assembly_3" />
        <child link="knee_and_ankle_assembly_4" />
        <axis xyz="0 0 1"/>
        <limit effort="1" velocity="20" lower="-1.570796326794896558" upper="1.570796326794896558"/>
        <joint_properties friction="0.0"/>
    </joint>
    <joint name="right_hip_pitch" type="revolute">
        <origin xyz="-0.074149999999999799405 3.1868767607495795957e-16 0.035110000000000016196" rpy="-2.3836094894413110414e-24 1.570796326794896336 0" />
        <parent link="right_roll_to_pitch_assembly" />
        <child link="knee_and_ankle_assembly_3" />
        <axis xyz="0 0 1"/>
        <limit effort="1" velocity="20" lower="-0.52359877559829881566" upper="1.2217304763960306069"/>
        <joint_properties friction="0.0"/>
    </joint>
    <joint name="right_hip_roll" type="revolute">
        <origin xyz="0.019050000000008261714 3.78516662458139308e-14 -0.046015000000003032643" rpy="-1.5707963267947879782 -8.4491074221037422062e-14 1.5707963267945974639" />
        <parent link="hip_roll_assembly_2" />
        <child link="right_roll_to_pitch_assembly" />
        <axis xyz="0 0 1"/>
        <limit effort="1" velocity="20" lower="-0.43633231299858238339" upper="0.43633231299858238339"/>
        <joint_properties friction="0.0"/>
    </joint>
    <joint name="right_hip_yaw" type="revolute">
        <origin xyz="-0.018999999999998431338 -0.03500000000000151601 0.045940938812377415945" rpy="-4.6224992538811313716e-16 -2.2037927038832600325e-14 -1.6653345370219725828e-16" />
        <parent link="trunk_assembly" />
        <child link="hip_roll_assembly_2" />
        <axis xyz="0 0 1"/>
        <limit effort="1" velocity="20" lower="-0.52359877559829881566" upper="0.52359877559829881566"/>
        <joint_properties friction="0.0"/>
    </joint>
    <link name="neck_pitch_assembly">
        <visual>
            <origin xyz="-0.020000000000000003886 -0.025110000000000007314 0.019049999999999980144" rpy="-1.57079632679489678 -5.7226758296263346013e-34 0" />
            <geometry>
                <mesh filename="package:///neck_left_sheet.stl"/>
            </geometry>
            <material name="neck_left_sheet_material">
                <color rgba="0.22352941176470589313 0.21960784313725489891 0.21960784313725489891 1.0"/>
            </material>
        </visual>
        <collision>
            <origin xyz="-0.020000000000000003886 -0.025110000000000007314 0.019049999999999980144" rpy="-1.57079632679489678 -5.7226758296263346013e-34 0" />
            <geometry>
                <mesh filename="package:///neck_left_sheet.stl"/>
            </geometry>
        </collision>
        <visual>
            <origin xyz="-0.019999999999999983069 -0.025110000000000007314 0.019050000000000018308" rpy="-1.57079632679489678 2.9174024805477541804e-17 0" />
            <geometry>
                <mesh filename="package:///neck_right_sheet.stl"/>
            </geometry>
            <material name="neck_right_sheet_material">
                <color rgba="0.22352941176470589313 0.21960784313725489891 0.21960784313725489891 1.0"/>
            </material>
        </visual>
        <collision>
            <origin xyz="-0.019999999999999983069 -0.025110000000000007314 0.019050000000000018308" rpy="-1.57079632679489678 2.9174024805477541804e-17 0" />
            <geometry>
                <mesh filename="package:///neck_right_sheet.stl"/>
            </geometry>
        </collision>
        <visual>
            <origin xyz="-4.6451557877968951971e-15 0.040500000000001076805 0.0094500000000000018013" rpy="-1.570796326794896558 -1.1963610174028695711e-16 -1.570796326794896558" />
            <geometry>
                <mesh filename="package:///wj-wk00-0123middlecase_56.stl"/>
            </geometry>
            <material name="wj-wk00-0123middlecase_56_material">
                <color rgba="0.24705882352941177516 0.24313725490196078094 0.24313725490196078094 1.0"/>
            </material>
        </visual>
        <collision>
            <origin xyz="-4.6451557877968951971e-15 0.040500000000001076805 0.0094500000000000018013" rpy="-1.570796326794896558 -1.1963610174028695711e-16 -1.570796326794896558" />
            <geometry>
                <mesh filename="package:///wj-wk00-0123middlecase_56.stl"/>
            </geometry>
        </collision>
        <visual>
            <origin xyz="-4.6451557877968951971e-15 0.040500000000001076805 0.0094500000000000018013" rpy="-1.570796326794896558 -1.1963610174028695711e-16 -1.570796326794896558" />
            <geometry>
                <mesh filename="package:///drive_palonier.stl"/>
            </geometry>
            <material name="drive_palonier_material">
                <color rgba="0.62352941176470588758 0.66666666666666662966 0.70196078431372543882 1.0"/>
            </material>
        </visual>
        <collision>
            <origin xyz="-4.6451557877968951971e-15 0.040500000000001076805 0.0094500000000000018013" rpy="-1.570796326794896558 -1.1963610174028695711e-16 -1.570796326794896558" />
            <geometry>
                <mesh filename="package:///drive_palonier.stl"/>
            </geometry>
        </collision>
        <visual>
            <origin xyz="-4.6451557877968951971e-15 0.040500000000001076805 0.0094500000000000018013" rpy="-1.570796326794896558 -1.1963610174028695711e-16 -1.570796326794896558" />
            <geometry>
                <mesh filename="package:///wj-wk00-0124bottomcase_45.stl"/>
            </geometry>
            <material name="wj-wk00-0124bottomcase_45_material">
                <color rgba="0.24705882352941177516 0.24313725490196078094 0.24313725490196078094 1.0"/>
            </material>
        </visual>
        <collision>
            <origin xyz="-4.6451557877968951971e-15 0.040500000000001076805 0.0094500000000000018013" rpy="-1.570796326794896558 -1.1963610174028695711e-16 -1.570796326794896558" />
            <geometry>
                <mesh filename="package:///wj-wk00-0124bottomcase_45.stl"/>
            </geometry>
        </collision>
        <visual>
            <origin xyz="-4.6451557877968951971e-15 0.040500000000001076805 0.0094500000000000018013" rpy="-1.570796326794896558 -1.1963610174028695711e-16 -1.570796326794896558" />
            <geometry>
                <mesh filename="package:///wj-wk00-0122topcabinetcase_95.stl"/>
            </geometry>
            <material name="wj-wk00-0122topcabinetcase_95_material">
                <color rgba="0.24705882352941177516 0.24313725490196078094 0.24313725490196078094 1.0"/>
            </material>
        </visual>
        <collision>
            <origin xyz="-4.6451557877968951971e-15 0.040500000000001076805 0.0094500000000000018013" rpy="-1.570796326794896558 -1.1963610174028695711e-16 -1.570796326794896558" />
            <geometry>
                <mesh filename="package:///wj-wk00-0122topcabinetcase_95.stl"/>
            </geometry>
        </collision>
        <visual>
            <origin xyz="-4.6310611595545836394e-15 0.040500000000001187828 0.0065499999999996099537" rpy="-1.570796326794896558 -1.1963610174028695711e-16 -1.570796326794896558" />
            <geometry>
                <mesh filename="package:///passive_palonier.stl"/>
            </geometry>
            <material name="passive_palonier_material">
                <color rgba="0.62352941176470588758 0.66666666666666662966 0.70196078431372543882 1.0"/>
            </material>
        </visual>
        <collision>
            <origin xyz="-4.6310611595545836394e-15 0.040500000000001187828 0.0065499999999996099537" rpy="-1.570796326794896558 -1.1963610174028695711e-16 -1.570796326794896558" />
            <geometry>
                <mesh filename="package:///passive_palonier.stl"/>
            </geometry>
        </collision>
        <inertial>
            <origin xyz="-5.6313726543509343256e-06 0.049296760188245386525 0.018178555579869758868" rpy="0 0 0"/>
            <mass value="0.066180000000000058225" />
            <inertia ixx="3.4945638152178037808e-05" ixy="8.7563261033050618581e-09"  ixz="-2.1559156609796960061e-09" iyy="1.7023145118232429324e-05" iyz="-1.8518807639996545184e-08" izz="2.8004252155145963987e-05" />
        </inertial>
    </link>
    <link name="head_pitch_to_yaw">
        <visual>
            <origin xyz="-0.020000000000000017764 -0.091110000000000052056 0.01905000000000000096" rpy="-1.570796326794896558 7.9294345455100184532e-33 -2.5410719686278673872e-30" />
            <geometry>
                <mesh filename="package:///head_pitch_to_yaw.stl"/>
            </geometry>
            <material name="head_pitch_to_yaw_material">
                <color rgba="0.4000000000000000222 0.4000000000000000222 0.4000000000000000222 1.0"/>
            </material>
        </visual>
        <collision>
            <origin xyz="-0.020000000000000017764 -0.091110000000000052056 0.01905000000000000096" rpy="-1.570796326794896558 7.9294345455100184532e-33 -2.5410719686278673872e-30" />
            <geometry>
                <mesh filename="package:///head_pitch_to_yaw.stl"/>
            </geometry>
        </collision>
        <inertial>
            <origin xyz="-0.0076624665903661749386 0.026014958700652721091 0.018668069848403360395" rpy="0 0 0"/>
            <mass value="0.016937787992335997383" />
            <inertia ixx="9.4303589355219884623e-06" ixy="1.351952788299898561e-06"  ixz="3.0589894259326036064e-08" iyy="4.6476284415361823608e-06" iyz="-8.4280232933014340716e-08" izz="8.0291501280952298655e-06" />
        </inertial>
    </link>
    <link name="neck_yaw_assembly">
        <visual>
            <origin xyz="-0.020000000000000399403 -1.7526128118228179176e-16 -0.1482099999999997586" rpy="-1.6401918885578133178e-14 -4.5219687082974091848e-30 -3.1578605360630712105e-29" />
            <geometry>
                <mesh filename="package:///head_yaw_to_roll.stl"/>
            </geometry>
            <material name="head_yaw_to_roll_material">
                <color rgba="0.64705882352941179736 0.64705882352941179736 0.64705882352941179736 1.0"/>
            </material>
        </visual>
        <collision>
            <origin xyz="-0.020000000000000399403 -1.7526128118228179176e-16 -0.1482099999999997586" rpy="-1.6401918885578133178e-14 -4.5219687082974091848e-30 -3.1578605360630712105e-29" />
            <geometry>
                <mesh filename="package:///head_yaw_to_roll.stl"/>
            </geometry>
        </collision>
        <visual>
            <origin xyz="0.025500000000000022649 7.1828393927164668753e-19 -0.0094499999999999861888" rpy="1.570796326794896558 -1.3665250874134194164e-30 -6.3350563935584114029e-30" />
            <geometry>
                <mesh filename="package:///wj-wk00-0123middlecase_56.stl"/>
            </geometry>
            <material name="wj-wk00-0123middlecase_56_material">
                <color rgba="0.24705882352941177516 0.24313725490196078094 0.24313725490196078094 1.0"/>
            </material>
        </visual>
        <collision>
            <origin xyz="0.025500000000000022649 7.1828393927164668753e-19 -0.0094499999999999861888" rpy="1.570796326794896558 -1.3665250874134194164e-30 -6.3350563935584114029e-30" />
            <geometry>
                <mesh filename="package:///wj-wk00-0123middlecase_56.stl"/>
            </geometry>
        </collision>
        <visual>
            <origin xyz="0.025500000000000022649 7.1828393927164668753e-19 -0.0094499999999999861888" rpy="1.570796326794896558 -1.3665250874134194164e-30 -6.3350563935584114029e-30" />
            <geometry>
                <mesh filename="package:///drive_palonier.stl"/>
            </geometry>
            <material name="drive_palonier_material">
                <color rgba="0.62352941176470588758 0.66666666666666662966 0.70196078431372543882 1.0"/>
            </material>
        </visual>
        <collision>
            <origin xyz="0.025500000000000022649 7.1828393927164668753e-19 -0.0094499999999999861888" rpy="1.570796326794896558 -1.3665250874134194164e-30 -6.3350563935584114029e-30" />
            <geometry>
                <mesh filename="package:///drive_palonier.stl"/>
            </geometry>
        </collision>
        <visual>
            <origin xyz="0.025500000000000022649 7.1828393927164668753e-19 -0.0094499999999999861888" rpy="1.570796326794896558 -1.3665250874134194164e-30 -6.3350563935584114029e-30" />
            <geometry>
                <mesh filename="package:///wj-wk00-0124bottomcase_45.stl"/>
            </geometry>
            <material name="wj-wk00-0124bottomcase_45_material">
                <color rgba="0.24705882352941177516 0.24313725490196078094 0.24313725490196078094 1.0"/>
            </material>
        </visual>
        <collision>
            <origin xyz="0.025500000000000022649 7.1828393927164668753e-19 -0.0094499999999999861888" rpy="1.570796326794896558 -1.3665250874134194164e-30 -6.3350563935584114029e-30" />
            <geometry>
                <mesh filename="package:///wj-wk00-0124bottomcase_45.stl"/>
            </geometry>
        </collision>
        <visual>
            <origin xyz="0.025500000000000022649 7.1828393927164668753e-19 -0.0094499999999999861888" rpy="1.570796326794896558 -1.3665250874134194164e-30 -6.3350563935584114029e-30" />
            <geometry>
                <mesh filename="package:///wj-wk00-0122topcabinetcase_95.stl"/>
            </geometry>
            <material name="wj-wk00-0122topcabinetcase_95_material">
                <color rgba="0.24705882352941177516 0.24313725490196078094 0.24313725490196078094 1.0"/>
            </material>
        </visual>
        <collision>
            <origin xyz="0.025500000000000022649 7.1828393927164668753e-19 -0.0094499999999999861888" rpy="1.570796326794896558 -1.3665250874134194164e-30 -6.3350563935584114029e-30" />
            <geometry>
                <mesh filename="package:///wj-wk00-0122topcabinetcase_95.stl"/>
            </geometry>
        </collision>
        <visual>
            <origin xyz="0.025499999999999817951 1.5802246663976227126e-17 -0.0065500000000004166001" rpy="1.570796326794896558 -1.3665250874134194164e-30 -6.3350563935584114029e-30" />
            <geometry>
                <mesh filename="package:///passive_palonier.stl"/>
            </geometry>
            <material name="passive_palonier_material">
                <color rgba="0.62352941176470588758 0.66666666666666662966 0.70196078431372543882 1.0"/>
            </material>
        </visual>
        <collision>
            <origin xyz="0.025499999999999817951 1.5802246663976227126e-17 -0.0065500000000004166001" rpy="1.570796326794896558 -1.3665250874134194164e-30 -6.3350563935584114029e-30" />
            <geometry>
                <mesh filename="package:///passive_palonier.stl"/>
            </geometry>
        </collision>
        <inertial>
            <origin xyz="0.0041290688015579134207 3.9574458977432641613e-06 -0.022282839840630268985" rpy="0 0 0"/>
            <mass value="0.09180988857925044544" />
            <inertia ixx="3.1170636339689771095e-05" ixy="4.2942915561174826103e-09"  ixz="-4.4125133978803805264e-06" iyy="6.9493543438961454277e-05" iyz="-3.8202750258600759636e-09" izz="7.0402479889611943153e-05" />
        </inertial>
    </link>
    <link name="head_assembly">
        <visual>
            <origin xyz="-0.12905999999999934191 7.8328185951215267835e-16 0.060949999999999997236" rpy="2.2204460492701854731e-16 1.570796326794896336 0" />
            <geometry>
                <mesh filename="package:///head_bot_sheet.stl"/>
            </geometry>
            <material name="head_bot_sheet_material">
                <color rgba="0.41176470588235292158 0.41176470588235292158 0.41176470588235292158 1.0"/>
            </material>
        </visual>
        <collision>
            <origin xyz="-0.12905999999999934191 7.8328185951215267835e-16 0.060949999999999997236" rpy="2.2204460492701854731e-16 1.570796326794896336 0" />
            <geometry>
                <mesh filename="package:///head_bot_sheet.stl"/>
            </geometry>
        </collision>
        <visual>
            <origin xyz="-0.12905999999999934191 7.8578907703602540735e-16 0.060949999999999997236" rpy="2.2204460492704379086e-16 1.570796326794896336 0" />
            <geometry>
                <mesh filename="package:///head.stl"/>
            </geometry>
            <material name="head_material">
                <color rgba="0.91764705882352937127 0.91764705882352937127 0.91764705882352937127 1.0"/>
            </material>
        </visual>
        <collision>
            <origin xyz="-0.12905999999999934191 7.8578907703602540735e-16 0.060949999999999997236" rpy="2.2204460492704379086e-16 1.570796326794896336 0" />
            <geometry>
                <mesh filename="package:///head.stl"/>
            </geometry>
        </collision>
        <visual>
            <origin xyz="-0.12906000000000428241 2.9835888534085475143e-16 0.060949999999999886213" rpy="7.0798265109979077958e-31 1.5707963267948956698 0" />
            <geometry>
                <mesh filename="package:///head_roll_mount.stl"/>
            </geometry>
            <material name="head_roll_mount_material">
                <color rgba="0.50196078431372548323 0.50196078431372548323 0.50196078431372548323 1.0"/>
            </material>
        </visual>
        <collision>
            <origin xyz="-0.12906000000000428241 2.9835888534085475143e-16 0.060949999999999886213" rpy="7.0798265109979077958e-31 1.5707963267948956698 0" />
            <geometry>
                <mesh filename="package:///head_roll_mount.stl"/>
            </geometry>
        </collision>
        <visual>
            <origin xyz="0.032050000000000633538 0.048000000000000771216 0.0059499999999998998135" rpy="1.5707963267948945596 -1.570796326794896336 0" />
            <geometry>
                <mesh filename="package:///raspberrypizerow.stl"/>
            </geometry>
            <material name="raspberrypizerow_material">
                <color rgba="0.2313725490196078538 0.38039215686274507888 0.7058823529411765163 1.0"/>
            </material>
        </visual>
        <collision>
            <origin xyz="0.032050000000000633538 0.048000000000000771216 0.0059499999999998998135" rpy="1.5707963267948945596 -1.570796326794896336 0" />
            <geometry>
                <mesh filename="package:///raspberrypizerow.stl"/>
            </geometry>
        </collision>
        <visual>
            <origin xyz="6.3837823915946501074e-16 -0.034999999999999240052 0.1673250000000001958" rpy="2.7755575616297359729e-16 4.8251187118251247395e-27 -2.2204460492471524603e-16" />
            <geometry>
                <mesh filename="package:///roll_bearing.stl"/>
            </geometry>
            <material name="roll_bearing_material">
                <color rgba="0.5999999999999999778 0.5999999999999999778 0.5999999999999999778 1.0"/>
            </material>
        </visual>
        <collision>
            <origin xyz="6.3837823915946501074e-16 -0.034999999999999240052 0.1673250000000001958" rpy="2.7755575616297359729e-16 4.8251187118251247395e-27 -2.2204460492471524603e-16" />
            <geometry>
                <mesh filename="package:///roll_bearing.stl"/>
            </geometry>
        </collision>
        <visual>
            <origin xyz="-0.0062459440337521432429 0.033140784271761480895 0.10281206307850690451" rpy="-1.1544526422504834648e-15 -1.3045791727887252609 -1.8181502823667208268" />
            <geometry>
                <mesh filename="package:///sg90.stl"/>
            </geometry>
            <material name="sg90_material">
                <color rgba="0.43529411764705883137 0.67058823529411759612 0.97647058823529409022 1.0"/>
            </material>
        </visual>
        <collision>
            <origin xyz="-0.0062459440337521432429 0.033140784271761480895 0.10281206307850690451" rpy="-1.1544526422504834648e-15 -1.3045791727887252609 -1.8181502823667208268" />
            <geometry>
                <mesh filename="package:///sg90.stl"/>
            </geometry>
        </collision>
        <visual>
            <origin xyz="-0.0062459440337521154873 -0.033140784271759933521 0.10281206307850687676" rpy="1.7909863475450052973e-17 -1.3045791727887248168 1.8181502823667212709" />
            <geometry>
                <mesh filename="package:///sg90.stl"/>
            </geometry>
            <material name="sg90_material">
                <color rgba="0.43529411764705883137 0.67058823529411759612 0.97647058823529409022 1.0"/>
            </material>
        </visual>
        <collision>
            <origin xyz="-0.0062459440337521154873 -0.033140784271759933521 0.10281206307850687676" rpy="1.7909863475450052973e-17 -1.3045791727887248168 1.8181502823667212709" />
            <geometry>
                <mesh filename="package:///sg90.stl"/>
            </geometry>
        </collision>
        <visual>
            <origin xyz="0.032050000000000578027 -0.03400001261999926333 -0.0055500126200000027277" rpy="-1.570796326794896558 2.7755575615300298709e-16 -1.570796326794896336" />
            <geometry>
                <mesh filename="package:///board.stl"/>
            </geometry>
            <material name="board_material">
                <color rgba="0 0.50196078431372548323 0 1.0"/>
            </material>
        </visual>
        <collision>
            <origin xyz="0.032050000000000578027 -0.03400001261999926333 -0.0055500126200000027277" rpy="-1.570796326794896558 2.7755575615300298709e-16 -1.570796326794896336" />
            <geometry>
                <mesh filename="package:///board.stl"/>
            </geometry>
        </collision>
        <visual>
            <origin xyz="0.025500000000000050404 7.1828393927164668753e-19 -0.0094500000000000000666" rpy="1.570796326794896558 -0 0" />
            <geometry>
                <mesh filename="package:///wj-wk00-0123middlecase_56.stl"/>
            </geometry>
            <material name="wj-wk00-0123middlecase_56_material">
                <color rgba="0.24705882352941177516 0.24313725490196078094 0.24313725490196078094 1.0"/>
            </material>
        </visual>
        <collision>
            <origin xyz="0.025500000000000050404 7.1828393927164668753e-19 -0.0094500000000000000666" rpy="1.570796326794896558 -0 0" />
            <geometry>
                <mesh filename="package:///wj-wk00-0123middlecase_56.stl"/>
            </geometry>
        </collision>
        <visual>
            <origin xyz="0.025500000000000050404 7.1828393927164668753e-19 -0.0094500000000000000666" rpy="1.570796326794896558 -0 0" />
            <geometry>
                <mesh filename="package:///drive_palonier.stl"/>
            </geometry>
            <material name="drive_palonier_material">
                <color rgba="0.62352941176470588758 0.66666666666666662966 0.70196078431372543882 1.0"/>
            </material>
        </visual>
        <collision>
            <origin xyz="0.025500000000000050404 7.1828393927164668753e-19 -0.0094500000000000000666" rpy="1.570796326794896558 -0 0" />
            <geometry>
                <mesh filename="package:///drive_palonier.stl"/>
            </geometry>
        </collision>
        <visual>
            <origin xyz="0.025500000000000050404 7.1828393927164668753e-19 -0.0094500000000000000666" rpy="1.570796326794896558 -0 0" />
            <geometry>
                <mesh filename="package:///wj-wk00-0124bottomcase_45.stl"/>
            </geometry>
            <material name="wj-wk00-0124bottomcase_45_material">
                <color rgba="0.24705882352941177516 0.24313725490196078094 0.24313725490196078094 1.0"/>
            </material>
        </visual>
        <collision>
            <origin xyz="0.025500000000000050404 7.1828393927164668753e-19 -0.0094500000000000000666" rpy="1.570796326794896558 -0 0" />
            <geometry>
                <mesh filename="package:///wj-wk00-0124bottomcase_45.stl"/>
            </geometry>
        </collision>
        <visual>
            <origin xyz="0.025500000000000050404 7.1828393927164668753e-19 -0.0094500000000000000666" rpy="1.570796326794896558 -0 0" />
            <geometry>
                <mesh filename="package:///wj-wk00-0122topcabinetcase_95.stl"/>
            </geometry>
            <material name="wj-wk00-0122topcabinetcase_95_material">
                <color rgba="0.24705882352941177516 0.24313725490196078094 0.24313725490196078094 1.0"/>
            </material>
        </visual>
        <collision>
            <origin xyz="0.025500000000000050404 7.1828393927164668753e-19 -0.0094500000000000000666" rpy="1.570796326794896558 -0 0" />
            <geometry>
                <mesh filename="package:///wj-wk00-0122topcabinetcase_95.stl"/>
            </geometry>
        </collision>
        <visual>
            <origin xyz="0.02550000000000032796 3.3392071659837929687e-16 -0.0065499999999983141152" rpy="1.570796326794896558 -0 0" />
            <geometry>
                <mesh filename="package:///passive_palonier.stl"/>
            </geometry>
            <material name="passive_palonier_material">
                <color rgba="0.62352941176470588758 0.66666666666666662966 0.70196078431372543882 1.0"/>
            </material>
        </visual>
        <collision>
            <origin xyz="0.02550000000000032796 3.3392071659837929687e-16 -0.0065499999999983141152" rpy="1.570796326794896558 -0 0" />
            <geometry>
                <mesh filename="package:///passive_palonier.stl"/>
            </geometry>
        </collision>
        <inertial>
            <origin xyz="0.0076177852948051101925 0.00018097970253239852381 0.024257508476548270138" rpy="0 0 0"/>
            <mass value="0.35258298534369564292" />
            <inertia ixx="0.002063857377990464554" ixy="-1.3848221046687924304e-06"  ixz="9.1037277340193334765e-05" iyy="0.0014412682765872009485" iyz="-2.914545167224348376e-06" izz="0.00091677314815290927852" />
        </inertial>
    </link>
    <link name="head">
        <inertial>
            <origin xyz="0 0 0" rpy="0 0 0" />
            <mass value="1e-9" />
            <inertia ixx="0" ixy="0" ixz="0" iyy="0" iyz="0" izz="0" />
        </inertial>
    </link>
    <joint name="head_frame" type="fixed">
        <origin xyz="0.04245000000000057061 7.4178402136026999614e-16 0.035949999999999988909" rpy="2.2204460492701854731e-16 1.570796326794896336 0" />
        <parent link="head_assembly" />
        <child link="head" />
        <axis xyz="0 0 0"/>
    </joint>
    <link name="left_antenna_holder">
        <visual>
            <origin xyz="0.07913918595530011757 -0.11097414404234512419 -0.079315037574383365215" rpy="-1.3234423712230722892 -0.26621715400617168568 -3.461928158332506337e-18" />
            <geometry>
                <mesh filename="package:///antenna.stl"/>
            </geometry>
            <material name="antenna_material">
                <color rgba="0.64705882352941179736 0.64705882352941179736 0.64705882352941179736 1.0"/>
            </material>
        </visual>
        <collision>
            <origin xyz="0.07913918595530011757 -0.11097414404234512419 -0.079315037574383365215" rpy="-1.3234423712230722892 -0.26621715400617168568 -3.461928158332506337e-18" />
            <geometry>
                <mesh filename="package:///antenna.stl"/>
            </geometry>
        </collision>
        <visual>
            <origin xyz="0.029698103650376478368 -0.1109618801559370399 0.1019938543975157097" rpy="-1.8181502823667212709 -0.26621715400617168568 -3.4619281583421190386e-18" />
            <geometry>
                <mesh filename="package:///left_antenna_holder.stl"/>
            </geometry>
            <material name="left_antenna_holder_material">
                <color rgba="0.98039215686274505668 0.71372549019607844922 0.0039215686274509803377 1.0"/>
            </material>
        </visual>
        <collision>
            <origin xyz="0.029698103650376478368 -0.1109618801559370399 0.1019938543975157097" rpy="-1.8181502823667212709 -0.26621715400617168568 -3.4619281583421190386e-18" />
            <geometry>
                <mesh filename="package:///left_antenna_holder.stl"/>
            </geometry>
        </collision>
        <inertial>
            <origin xyz="-0.0049398548214985120441 0.0081303220914737319575 -0.0023337426173884881844" rpy="0 0 0"/>
            <mass value="0.0042162890957708797426" />
            <inertia ixx="3.5881972229367808433e-06" ixy="-1.6933723332353453197e-07"  ixz="1.5481705881188097027e-09" iyy="2.5430131672962947247e-07" iyz="3.9979038225547723809e-08" izz="3.8079123149071858251e-06" />
        </inertial>
    </link>
    <joint name="left_antenna" type="revolute">
        <origin xyz="0.00070406945503534434927 0.060662837687359784378 0.11643485329544212004" rpy="-3.1415926535896234739 1.3045791727887248168 1.3234423712232488146" />
        <parent link="head_assembly" />
        <child link="left_antenna_holder" />
        <axis xyz="0 0 1"/>
        <limit effort="1" velocity="20" lower="-1.570796326794896558" upper="1.570796326794896558"/>
        <joint_properties friction="0.0"/>
    </joint>
    <link name="right_antenna_holder">
        <visual>
            <origin xyz="0.029698103650376478368 0.11096188015593702603 0.1019938543975157097" rpy="1.8181502823667210489 -0.26621715400617174119 -2.8114837816279266359e-17" />
            <geometry>
                <mesh filename="package:///right_antenna_holder.stl"/>
            </geometry>
            <material name="right_antenna_holder_material">
                <color rgba="0.98039215686274505668 0.71372549019607844922 0.0039215686274509803377 1.0"/>
            </material>
        </visual>
        <collision>
            <origin xyz="0.029698103650376478368 0.11096188015593702603 0.1019938543975157097" rpy="1.8181502823667210489 -0.26621715400617174119 -2.8114837816279266359e-17" />
            <geometry>
                <mesh filename="package:///right_antenna_holder.stl"/>
            </geometry>
        </collision>
        <visual>
            <origin xyz="0.029698103650376499185 0.10995093695903178366 0.10199385439751569582" rpy="1.8181502823667210489 -0.26621715400617174119 -2.811483781727350227e-17" />
            <geometry>
                <mesh filename="package:///antenna.stl"/>
            </geometry>
            <material name="antenna_material">
                <color rgba="0.64705882352941179736 0.64705882352941179736 0.64705882352941179736 1.0"/>
            </material>
        </visual>
        <collision>
            <origin xyz="0.029698103650376499185 0.10995093695903178366 0.10199385439751569582" rpy="1.8181502823667210489 -0.26621715400617174119 -2.811483781727350227e-17" />
            <geometry>
                <mesh filename="package:///antenna.stl"/>
            </geometry>
        </collision>
        <inertial>
            <origin xyz="-0.0049398571608862355126 -0.0082621254299192429388 -0.002333741121575003824" rpy="0 0 0"/>
            <mass value="0.004216286984950681424" />
            <inertia ixx="3.6498064950645681909e-06" ixy="1.7208228546032648088e-07"  ixz="1.5481440054414281871e-09" iyy="2.5430123930068699704e-07" iyz="-4.0627217574811662444e-08" izz="3.8695215401713850114e-06" />
        </inertial>
    </link>
    <joint name="right_antenna" type="revolute">
        <origin xyz="0.00070406945503534434927 -0.06066283768735826476 0.11643485329544212004" rpy="3.1415926535896230298 1.3045791727887245948 -1.3234423712232490367" />
        <parent link="head_assembly" />
        <child link="right_antenna_holder" />
        <axis xyz="0 0 1"/>
        <limit effort="1" velocity="20" lower="-1.570796326794896558" upper="1.570796326794896558"/>
        <joint_properties friction="0.0"/>
    </joint>
    <joint name="head_roll" type="revolute">
        <origin xyz="0.040950000000000097433 -1.7527483370943786056e-16 -0.019149999999999778311" rpy="-7.3227915058204641542e-14 -1.570796326794896336 0" />
        <parent link="neck_yaw_assembly" />
        <child link="head_assembly" />
        <axis xyz="0 0 1"/>
        <limit effort="1" velocity="20" lower="-0.52359877559829881566" upper="0.52359877559829881566"/>
        <joint_properties friction="0.0"/>
    </joint>
    <joint name="head_yaw" type="revolute">
        <origin xyz="-1.6913553890773869171e-17 0.056999999999999939604 0.019050000000000014838" rpy="-1.570796326794896558 7.3522809646371816617e-14 6.1232339957365034931e-17" />
        <parent link="head_pitch_to_yaw" />
        <child link="neck_yaw_assembly" />
        <axis xyz="0 0 1"/>
        <limit effort="1" velocity="20" lower="-2.7925268031909271649" upper="2.7925268031909271649"/>
        <joint_properties friction="0.0"/>
    </joint>
    <joint name="head_pitch" type="revolute">
        <origin xyz="8.6736173798840354721e-19 0.066000000000000016986 -3.4694469519536141888e-18" rpy="-1.4406834481465239151e-16 -1.1423136877781657605e-16 1.1213426021061680001e-13" />
        <parent link="neck_pitch_assembly" />
        <child link="head_pitch_to_yaw" />
        <axis xyz="0 0 1"/>
        <limit effort="1" velocity="20" lower="-0.785398163397448279" upper="0.785398163397448279"/>
        <joint_properties friction="0.0"/>
    </joint>
    <joint name="neck_pitch" type="revolute">
        <origin xyz="0.00099999999999896352354 0.019150000000000326483 0.090000938812376238274" rpy="1.570796326794896558 8.9928064994637667153e-14 6.1232449686014378908e-17" />
        <parent link="trunk_assembly" />
        <child link="neck_pitch_assembly" />
        <axis xyz="0 0 1"/>
        <limit effort="1" velocity="20" lower="-0.34906585039886589561" upper="1.1344640137963142301"/>
        <joint_properties friction="0.0"/>
    </joint>
</robot>