<robot name="onshape">
    <mujoco>
        <compiler fusestatic="false"/>
    </mujoco>
    <link name="trunk_assembly">
        <visual>
            <origin xyz="-0.019000000000000002998 0 0.06489093881237623096" rpy="0 -0 0" />
            <geometry>
                <mesh filename="package:///body_front.stl"/>
            </geometry>
            <material name="body_front_material">
                <color rgba="0.91764705882352937127 0.91764705882352937127 0.91764705882352937127 1.0"/>
            </material>
        </visual>
        <collision>
            <origin xyz="-0.019000000000000002998 0 0.06489093881237623096" rpy="0 -0 0" />
            <geometry>
                <mesh filename="package:///body_front.stl"/>
            </geometry>
        </collision>
        <visual>
            <origin xyz="-0.12630000000000002336 -0.025700000000000007561 0.057607885438805628286" rpy="1.570796326794896558 -1.570796326794896558 0" />
            <geometry>
                <mesh filename="package:///usb_c_charger.stl"/>
            </geometry>
            <material name="usb_c_charger_material">
                <color rgba="0.61568627450980395466 0.81176470588235294379 0.92941176470588238168 1.0"/>
            </material>
        </visual>
        <collision>
            <origin xyz="-0.12630000000000002336 -0.025700000000000007561 0.057607885438805628286" rpy="1.570796326794896558 -1.570796326794896558 0" />
            <geometry>
                <mesh filename="package:///usb_c_charger.stl"/>
            </geometry>
        </collision>
        <visual>
            <origin xyz="-0.019000000000000030753 3.4694469519536141888e-18 0.064890938812376217082" rpy="0 -0 0" />
            <geometry>
                <mesh filename="package:///body_back.stl"/>
            </geometry>
            <material name="body_back_material">
                <color rgba="0.91764705882352937127 0.91764705882352937127 0.91764705882352937127 1.0"/>
            </material>
        </visual>
        <collision>
            <origin xyz="-0.019000000000000030753 3.4694469519536141888e-18 0.064890938812376217082" rpy="0 -0 0" />
            <geometry>
                <mesh filename="package:///body_back.stl"/>
            </geometry>
        </collision>
        <visual>
            <origin xyz="-0.019000000000000002998 -3.4694469519536141888e-18 0.064890938812376217082" rpy="0 -0 0" />
            <geometry>
                <mesh filename="package:///body_middle_bottom.stl"/>
            </geometry>
            <material name="body_middle_bottom_material">
                <color rgba="0.91764705882352937127 0.91764705882352937127 0.91764705882352937127 1.0"/>
            </material>
        </visual>
        <collision>
            <origin xyz="-0.019000000000000002998 -3.4694469519536141888e-18 0.064890938812376217082" rpy="0 -0 0" />
            <geometry>
                <mesh filename="package:///body_middle_bottom.stl"/>
            </geometry>
        </collision>
        <visual>
            <origin xyz="-0.018999999999999683808 0 0.064890938812376189326" rpy="-3.3848262945888805998e-16 -0 0" />
            <geometry>
                <mesh filename="package:///battery_pack_lid.stl"/>
            </geometry>
            <material name="battery_pack_lid_material">
                <color rgba="0.2313725490196078538 0.38039215686274507888 0.7058823529411765163 1.0"/>
            </material>
        </visual>
        <collision>
            <origin xyz="-0.018999999999999683808 0 0.064890938812376189326" rpy="-3.3848262945888805998e-16 -0 0" />
            <geometry>
                <mesh filename="package:///battery_pack_lid.stl"/>
            </geometry>
        </collision>
        <visual>
            <origin xyz="-0.019000000000000002998 0 0.064890938812376217082" rpy="0 -0 0" />
            <geometry>
                <mesh filename="package:///body_middle_top.stl"/>
            </geometry>
            <material name="body_middle_top_material">
                <color rgba="0.91764705882352937127 0.91764705882352937127 0.91764705882352937127 1.0"/>
            </material>
        </visual>
        <collision>
            <origin xyz="-0.019000000000000002998 0 0.064890938812376217082" rpy="0 -0 0" />
            <geometry>
                <mesh filename="package:///body_middle_top.stl"/>
            </geometry>
        </collision>
        <visual>
            <origin xyz="-0.084609999999999518927 1.249000902703301108e-16 0.041790938812376277056" rpy="-1.4062102177136728734e-16 2.5389959684908792913e-51 7.8060348058444099458e-33" />
            <geometry>
                <mesh filename="package:///bno055.stl"/>
            </geometry>
            <material name="bno055_material">
                <color rgba="0.61568627450980395466 0.81176470588235294379 0.92941176470588238168 1.0"/>
            </material>
        </visual>
        <collision>
            <origin xyz="-0.084609999999999518927 1.249000902703301108e-16 0.041790938812376277056" rpy="-1.4062102177136728734e-16 2.5389959684908792913e-51 7.8060348058444099458e-33" />
            <geometry>
                <mesh filename="package:///bno055.stl"/>
            </geometry>
        </collision>
        <visual>
            <origin xyz="-0.018999999999999999528 -6.9388939039072283776e-18 0.06489093881237623096" rpy="0 -0 0" />
            <geometry>
                <mesh filename="package:///roll_bearing.stl"/>
            </geometry>
            <material name="roll_bearing_material">
                <color rgba="0.5999999999999999778 0.5999999999999999778 0.5999999999999999778 1.0"/>
            </material>
        </visual>
        <collision>
            <origin xyz="-0.018999999999999999528 -6.9388939039072283776e-18 0.06489093881237623096" rpy="0 -0 0" />
            <geometry>
                <mesh filename="package:///roll_bearing.stl"/>
            </geometry>
        </collision>
        <visual>
            <origin xyz="-0.01899999999999998912 9.1072982488782372457e-18 0.06489093881237623096" rpy="-1.4062102177136726269e-16 7.6230808650822444942e-36 1.0842021724854837303e-19" />
            <geometry>
                <mesh filename="package:///trunk_bottom.stl"/>
            </geometry>
            <material name="trunk_bottom_material">
                <color rgba="0.18039215686274509554 0.18039215686274509554 0.18039215686274509554 1.0"/>
            </material>
        </visual>
        <collision>
            <origin xyz="-0.01899999999999998912 9.1072982488782372457e-18 0.06489093881237623096" rpy="-1.4062102177136726269e-16 7.6230808650822444942e-36 1.0842021724854837303e-19" />
            <geometry>
                <mesh filename="package:///trunk_bottom.stl"/>
            </geometry>
        </collision>
        <visual>
            <origin xyz="-0.019000000000000322187 -2.4242760576775879144e-16 0.06489093881237648076" rpy="-4.8355416892852906111e-17 5.5511151231258122844e-17 0" />
            <geometry>
                <mesh filename="package:///trunk_top.stl"/>
            </geometry>
            <material name="trunk_top_material">
                <color rgba="0.18039215686274509554 0.18039215686274509554 0.18039215686274509554 1.0"/>
            </material>
        </visual>
        <collision>
            <origin xyz="-0.019000000000000322187 -2.4242760576775879144e-16 0.06489093881237648076" rpy="-4.8355416892852906111e-17 5.5511151231258122844e-17 0" />
            <geometry>
                <mesh filename="package:///trunk_top.stl"/>
            </geometry>
        </collision>
        <visual>
            <origin xyz="-0.10110999233999992675 0.021059987380000404905 0.060390938152375769898" rpy="2.220446049250285944e-14 -1.406210217713700237e-16 -1.570796326794896558" />
            <geometry>
                <mesh filename="package:///board.stl"/>
            </geometry>
            <material name="board_material">
                <color rgba="0 0.50196078431372548323 0 1.0"/>
            </material>
        </visual>
        <collision>
            <origin xyz="-0.10110999233999992675 0.021059987380000404905 0.060390938152375769898" rpy="2.220446049250285944e-14 -1.406210217713700237e-16 -1.570796326794896558" />
            <geometry>
                <mesh filename="package:///board.stl"/>
            </geometry>
        </collision>
        <visual>
            <origin xyz="-0.018999999999999999528 -0.070000000000000034417 0.06489093881237623096" rpy="0 -0 0" />
            <geometry>
                <mesh filename="package:///roll_bearing.stl"/>
            </geometry>
            <material name="roll_bearing_material">
                <color rgba="0.5999999999999999778 0.5999999999999999778 0.5999999999999999778 1.0"/>
            </material>
        </visual>
        <collision>
            <origin xyz="-0.018999999999999999528 -0.070000000000000034417 0.06489093881237623096" rpy="0 -0 0" />
            <geometry>
                <mesh filename="package:///roll_bearing.stl"/>
            </geometry>
        </collision>
        <visual>
            <origin xyz="-0.13026488058013999116 -0.010499999999999986774 0.064892951865625880803" rpy="-3.141592653589793116 7.1750566777276333942e-17 2.1913059978610238687" />
            <geometry>
                <mesh filename="package:///cell.stl"/>
            </geometry>
            <material name="cell_material">
                <color rgba="0.61568627450980395466 0.81176470588235294379 0.92941176470588238168 1.0"/>
            </material>
        </visual>
        <collision>
            <origin xyz="-0.13026488058013999116 -0.010499999999999986774 0.064892951865625880803" rpy="-3.141592653589793116 7.1750566777276333942e-17 2.1913059978610238687" />
            <geometry>
                <mesh filename="package:///cell.stl"/>
            </geometry>
        </collision>
        <visual>
            <origin xyz="-0.14026488058014013882 -0.063524458557367310951 0.03133447345594035649" rpy="-1.3044563776959597654e-16 1.570796326794896336 0" />
            <geometry>
                <mesh filename="package:///holder.stl"/>
            </geometry>
            <material name="holder_material">
                <color rgba="0.64705882352941179736 0.64705882352941179736 0.64705882352941179736 1.0"/>
            </material>
        </visual>
        <collision>
            <origin xyz="-0.14026488058014013882 -0.063524458557367310951 0.03133447345594035649" rpy="-1.3044563776959597654e-16 1.570796326794896336 0" />
            <geometry>
                <mesh filename="package:///holder.stl"/>
            </geometry>
        </collision>
        <visual>
            <origin xyz="-0.13026488058013999116 0.010500000000000004122 -0.00010704813437409382458" rpy="8.3177805134519239719e-17 2.7557624392889133747e-16 0.75026546877138966529" />
            <geometry>
                <mesh filename="package:///cell.stl"/>
            </geometry>
            <material name="cell_material">
                <color rgba="0.61568627450980395466 0.81176470588235294379 0.92941176470588238168 1.0"/>
            </material>
        </visual>
        <collision>
            <origin xyz="-0.13026488058013999116 0.010500000000000004122 -0.00010704813437409382458" rpy="8.3177805134519239719e-17 2.7557624392889133747e-16 0.75026546877138966529" />
            <geometry>
                <mesh filename="package:///cell.stl"/>
            </geometry>
        </collision>
        <visual>
            <origin xyz="0.00099999999999953077812 0.0097000000000003246819 0.064500938812376201748" rpy="1.0972295724176328418e-22 1.5707963267948743535 0" />
            <geometry>
                <mesh filename="package:///wj-wk00-0123middlecase_56.stl"/>
            </geometry>
            <material name="wj-wk00-0123middlecase_56_material">
                <color rgba="0.24705882352941177516 0.24313725490196078094 0.24313725490196078094 1.0"/>
            </material>
        </visual>
        <collision>
            <origin xyz="0.00099999999999953077812 0.0097000000000003246819 0.064500938812376201748" rpy="1.0972295724176328418e-22 1.5707963267948743535 0" />
            <geometry>
                <mesh filename="package:///wj-wk00-0123middlecase_56.stl"/>
            </geometry>
        </collision>
        <visual>
            <origin xyz="0.00099999999999953077812 0.0097000000000003246819 0.064500938812376201748" rpy="1.0972295724176328418e-22 1.5707963267948743535 0" />
            <geometry>
                <mesh filename="package:///drive_palonier.stl"/>
            </geometry>
            <material name="drive_palonier_material">
                <color rgba="0.62352941176470588758 0.66666666666666662966 0.70196078431372543882 1.0"/>
            </material>
        </visual>
        <collision>
            <origin xyz="0.00099999999999953077812 0.0097000000000003246819 0.064500938812376201748" rpy="1.0972295724176328418e-22 1.5707963267948743535 0" />
            <geometry>
                <mesh filename="package:///drive_palonier.stl"/>
            </geometry>
        </collision>
        <visual>
            <origin xyz="0.00099999999999953077812 0.0097000000000003246819 0.064500938812376201748" rpy="1.0972295724176328418e-22 1.5707963267948743535 0" />
            <geometry>
                <mesh filename="package:///wj-wk00-0124bottomcase_45.stl"/>
            </geometry>
            <material name="wj-wk00-0124bottomcase_45_material">
                <color rgba="0.24705882352941177516 0.24313725490196078094 0.24313725490196078094 1.0"/>
            </material>
        </visual>
        <collision>
            <origin xyz="0.00099999999999953077812 0.0097000000000003246819 0.064500938812376201748" rpy="1.0972295724176328418e-22 1.5707963267948743535 0" />
            <geometry>
                <mesh filename="package:///wj-wk00-0124bottomcase_45.stl"/>
            </geometry>
        </collision>
        <visual>
            <origin xyz="0.00099999999999953077812 0.0097000000000003246819 0.064500938812376201748" rpy="1.0972295724176328418e-22 1.5707963267948743535 0" />
            <geometry>
                <mesh filename="package:///wj-wk00-0122topcabinetcase_95.stl"/>
            </geometry>
            <material name="wj-wk00-0122topcabinetcase_95_material">
                <color rgba="0.24705882352941177516 0.24313725490196078094 0.24313725490196078094 1.0"/>
            </material>
        </visual>
        <collision>
            <origin xyz="0.00099999999999953077812 0.0097000000000003246819 0.064500938812376201748" rpy="1.0972295724176328418e-22 1.5707963267948743535 0" />
            <geometry>
                <mesh filename="package:///wj-wk00-0122topcabinetcase_95.stl"/>
            </geometry>
        </collision>
        <visual>
            <origin xyz="0.00099999999999958585559 0.012600000000000624589 0.064500938812376257259" rpy="1.0972295724176328418e-22 1.5707963267948743535 0" />
            <geometry>
                <mesh filename="package:///passive_palonier.stl"/>
            </geometry>
            <material name="passive_palonier_material">
                <color rgba="0.62352941176470588758 0.66666666666666662966 0.70196078431372543882 1.0"/>
            </material>
        </visual>
        <collision>
            <origin xyz="0.00099999999999958585559 0.012600000000000624589 0.064500938812376257259" rpy="1.0972295724176328418e-22 1.5707963267948743535 0" />
            <geometry>
                <mesh filename="package:///passive_palonier.stl"/>
            </geometry>
        </collision>
        <visual>
            <origin xyz="-0.044499999999999907685 -0.03500000000000113437 0.055390938812376840084" rpy="-1.570796326794896336 2.220446049250285944e-14 -3.141592653589793116" />
            <geometry>
                <mesh filename="package:///wj-wk00-0123middlecase_56.stl"/>
            </geometry>
            <material name="wj-wk00-0123middlecase_56_material">
                <color rgba="0.24705882352941177516 0.24313725490196078094 0.24313725490196078094 1.0"/>
            </material>
        </visual>
        <collision>
            <origin xyz="-0.044499999999999907685 -0.03500000000000113437 0.055390938812376840084" rpy="-1.570796326794896336 2.220446049250285944e-14 -3.141592653589793116" />
            <geometry>
                <mesh filename="package:///wj-wk00-0123middlecase_56.stl"/>
            </geometry>
        </collision>
        <visual>
            <origin xyz="-0.044499999999999907685 -0.03500000000000113437 0.055390938812376840084" rpy="-1.570796326794896336 2.220446049250285944e-14 -3.141592653589793116" />
            <geometry>
                <mesh filename="package:///drive_palonier.stl"/>
            </geometry>
            <material name="drive_palonier_material">
                <color rgba="0.62352941176470588758 0.66666666666666662966 0.70196078431372543882 1.0"/>
            </material>
        </visual>
        <collision>
            <origin xyz="-0.044499999999999907685 -0.03500000000000113437 0.055390938812376840084" rpy="-1.570796326794896336 2.220446049250285944e-14 -3.141592653589793116" />
            <geometry>
                <mesh filename="package:///drive_palonier.stl"/>
            </geometry>
        </collision>
        <visual>
            <origin xyz="-0.044499999999999907685 -0.03500000000000113437 0.055390938812376840084" rpy="-1.570796326794896336 2.220446049250285944e-14 -3.141592653589793116" />
            <geometry>
                <mesh filename="package:///wj-wk00-0124bottomcase_45.stl"/>
            </geometry>
            <material name="wj-wk00-0124bottomcase_45_material">
                <color rgba="0.24705882352941177516 0.24313725490196078094 0.24313725490196078094 1.0"/>
            </material>
        </visual>
        <collision>
            <origin xyz="-0.044499999999999907685 -0.03500000000000113437 0.055390938812376840084" rpy="-1.570796326794896336 2.220446049250285944e-14 -3.141592653589793116" />
            <geometry>
                <mesh filename="package:///wj-wk00-0124bottomcase_45.stl"/>
            </geometry>
        </collision>
        <visual>
            <origin xyz="-0.044499999999999907685 -0.03500000000000113437 0.055390938812376840084" rpy="-1.570796326794896336 2.220446049250285944e-14 -3.141592653589793116" />
            <geometry>
                <mesh filename="package:///wj-wk00-0122topcabinetcase_95.stl"/>
            </geometry>
            <material name="wj-wk00-0122topcabinetcase_95_material">
                <color rgba="0.24705882352941177516 0.24313725490196078094 0.24313725490196078094 1.0"/>
            </material>
        </visual>
        <collision>
            <origin xyz="-0.044499999999999907685 -0.03500000000000113437 0.055390938812376840084" rpy="-1.570796326794896336 2.220446049250285944e-14 -3.141592653589793116" />
            <geometry>
                <mesh filename="package:///wj-wk00-0122topcabinetcase_95.stl"/>
            </geometry>
        </collision>
        <visual>
            <origin xyz="-0.044499999999999824418 -0.035000000000001148248 0.052490938812376819467" rpy="-1.570796326794896336 2.220446049250285944e-14 -3.141592653589793116" />
            <geometry>
                <mesh filename="package:///passive_palonier.stl"/>
            </geometry>
            <material name="passive_palonier_material">
                <color rgba="0.62352941176470588758 0.66666666666666662966 0.70196078431372543882 1.0"/>
            </material>
        </visual>
        <collision>
            <origin xyz="-0.044499999999999824418 -0.035000000000001148248 0.052490938812376819467" rpy="-1.570796326794896336 2.220446049250285944e-14 -3.141592653589793116" />
            <geometry>
                <mesh filename="package:///passive_palonier.stl"/>
            </geometry>
        </collision>
        <visual>
            <origin xyz="-0.044499999999999907685 0.035000000000001363354 0.055390938812376867839" rpy="-1.5707963267948956698 2.2204460492502868907e-14 3.141592653589793116" />
            <geometry>
                <mesh filename="package:///wj-wk00-0123middlecase_56.stl"/>
            </geometry>
            <material name="wj-wk00-0123middlecase_56_material">
                <color rgba="0.24705882352941177516 0.24313725490196078094 0.24313725490196078094 1.0"/>
            </material>
        </visual>
        <collision>
            <origin xyz="-0.044499999999999907685 0.035000000000001363354 0.055390938812376867839" rpy="-1.5707963267948956698 2.2204460492502868907e-14 3.141592653589793116" />
            <geometry>
                <mesh filename="package:///wj-wk00-0123middlecase_56.stl"/>
            </geometry>
        </collision>
        <visual>
            <origin xyz="-0.044499999999999907685 0.035000000000001363354 0.055390938812376867839" rpy="-1.5707963267948956698 2.2204460492502868907e-14 3.141592653589793116" />
            <geometry>
                <mesh filename="package:///drive_palonier.stl"/>
            </geometry>
            <material name="drive_palonier_material">
                <color rgba="0.62352941176470588758 0.66666666666666662966 0.70196078431372543882 1.0"/>
            </material>
        </visual>
        <collision>
            <origin xyz="-0.044499999999999907685 0.035000000000001363354 0.055390938812376867839" rpy="-1.5707963267948956698 2.2204460492502868907e-14 3.141592653589793116" />
            <geometry>
                <mesh filename="package:///drive_palonier.stl"/>
            </geometry>
        </collision>
        <visual>
            <origin xyz="-0.044499999999999907685 0.035000000000001363354 0.055390938812376867839" rpy="-1.5707963267948956698 2.2204460492502868907e-14 3.141592653589793116" />
            <geometry>
                <mesh filename="package:///wj-wk00-0124bottomcase_45.stl"/>
            </geometry>
            <material name="wj-wk00-0124bottomcase_45_material">
                <color rgba="0.24705882352941177516 0.24313725490196078094 0.24313725490196078094 1.0"/>
            </material>
        </visual>
        <collision>
            <origin xyz="-0.044499999999999907685 0.035000000000001363354 0.055390938812376867839" rpy="-1.5707963267948956698 2.2204460492502868907e-14 3.141592653589793116" />
            <geometry>
                <mesh filename="package:///wj-wk00-0124bottomcase_45.stl"/>
            </geometry>
        </collision>
        <visual>
            <origin xyz="-0.044499999999999907685 0.035000000000001363354 0.055390938812376867839" rpy="-1.5707963267948956698 2.2204460492502868907e-14 3.141592653589793116" />
            <geometry>
                <mesh filename="package:///wj-wk00-0122topcabinetcase_95.stl"/>
            </geometry>
            <material name="wj-wk00-0122topcabinetcase_95_material">
                <color rgba="0.24705882352941177516 0.24313725490196078094 0.24313725490196078094 1.0"/>
            </material>
        </visual>
        <collision>
            <origin xyz="-0.044499999999999907685 0.035000000000001363354 0.055390938812376867839" rpy="-1.5707963267948956698 2.2204460492502868907e-14 3.141592653589793116" />
            <geometry>
                <mesh filename="package:///wj-wk00-0122topcabinetcase_95.stl"/>
            </geometry>
        </collision>
        <visual>
            <origin xyz="-0.044499999999999796663 0.035000000000001099676 0.052490938812376507216" rpy="-1.5707963267948956698 2.2204460492502868907e-14 3.141592653589793116" />
            <geometry>
                <mesh filename="package:///passive_palonier.stl"/>
            </geometry>
            <material name="passive_palonier_material">
                <color rgba="0.62352941176470588758 0.66666666666666662966 0.70196078431372543882 1.0"/>
            </material>
        </visual>
        <collision>
            <origin xyz="-0.044499999999999796663 0.035000000000001099676 0.052490938812376507216" rpy="-1.5707963267948956698 2.2204460492502868907e-14 3.141592653589793116" />
            <geometry>
                <mesh filename="package:///passive_palonier.stl"/>
            </geometry>
        </collision>
        <inertial>
            <origin xyz="-0.047716162406376327887 4.4081241495618263902e-06 0.03835859752206989548" rpy="0 0 0"/>
            <mass value="0.69443340465392744409" />
            <inertia ixx="0.0016756623451642425286" ixy="-7.5116301151240406469e-06"  ixz="-2.8148739423304949565e-05" iyy="0.0034372805130111179842" iyz="-5.0580795252412824809e-07" izz="0.0029080002062932580782" />
        </inertial>
    </link>
    <link name="trunk">
        <inertial>
            <origin xyz="0 0 0" rpy="0 0 0" />
            <mass value="1e-9" />
            <inertia ixx="0" ixy="0" ixz="0" iyy="0" iyz="0" izz="0" />
        </inertial>
    </link>
    <joint name="trunk_frame" type="fixed">
        <origin xyz="-0.024000000000000760308 -2.4112656316077618612e-16 0.088190938812376745704" rpy="-1.4062102177136726269e-16 -9.4252837597218562265e-17 7.8061435390716270015e-33" />
        <parent link="trunk_assembly" />
        <child link="trunk" />
        <axis xyz="0 0 0"/>
    </joint>
    <link name="hip_roll_assembly">
        <visual>
            <origin xyz="-3.3306690738754696213e-16 -0.034999999999999101274 0.019049999999999983613" rpy="-8.7699839287071181655e-16 7.0914210924513814834e-16 -6.6960326172704724262e-16" />
            <geometry>
                <mesh filename="package:///roll_motor_bottom.stl"/>
            </geometry>
            <material name="roll_motor_bottom_material">
                <color rgba="0.64705882352941179736 0.64705882352941179736 0.64705882352941179736 1.0"/>
            </material>
        </visual>
        <collision>
            <origin xyz="-3.3306690738754696213e-16 -0.034999999999999101274 0.019049999999999983613" rpy="-8.7699839287071181655e-16 7.0914210924513814834e-16 -6.6960326172704724262e-16" />
            <geometry>
                <mesh filename="package:///roll_motor_bottom.stl"/>
            </geometry>
        </collision>
        <visual>
            <origin xyz="0 -0.034999999999999989453 0.019050000000000011369" rpy="0 -0 -9.4981851882792658846e-34" />
            <geometry>
                <mesh filename="package:///roll_motor_top.stl"/>
            </geometry>
            <material name="roll_motor_top_material">
                <color rgba="0.90196078431372550543 0.90196078431372550543 0.90196078431372550543 1.0"/>
            </material>
        </visual>
        <collision>
            <origin xyz="0 -0.034999999999999989453 0.019050000000000011369" rpy="0 -0 -9.4981851882792658846e-34" />
            <geometry>
                <mesh filename="package:///roll_motor_top.stl"/>
            </geometry>
        </collision>
        <visual>
            <origin xyz="0.0096000000000012308127 4.538036613155327359e-15 -0.020515000000001056696" rpy="-1.5707963267952660402 -1.5707963267947782082 0" />
            <geometry>
                <mesh filename="package:///wj-wk00-0123middlecase_56.stl"/>
            </geometry>
            <material name="wj-wk00-0123middlecase_56_material">
                <color rgba="0.24705882352941177516 0.24313725490196078094 0.24313725490196078094 1.0"/>
            </material>
        </visual>
        <collision>
            <origin xyz="0.0096000000000012308127 4.538036613155327359e-15 -0.020515000000001056696" rpy="-1.5707963267952660402 -1.5707963267947782082 0" />
            <geometry>
                <mesh filename="package:///wj-wk00-0123middlecase_56.stl"/>
            </geometry>
        </collision>
        <visual>
            <origin xyz="0.0096000000000012308127 4.538036613155327359e-15 -0.020515000000001056696" rpy="-1.5707963267952660402 -1.5707963267947782082 0" />
            <geometry>
                <mesh filename="package:///drive_palonier.stl"/>
            </geometry>
            <material name="drive_palonier_material">
                <color rgba="0.62352941176470588758 0.66666666666666662966 0.70196078431372543882 1.0"/>
            </material>
        </visual>
        <collision>
            <origin xyz="0.0096000000000012308127 4.538036613155327359e-15 -0.020515000000001056696" rpy="-1.5707963267952660402 -1.5707963267947782082 0" />
            <geometry>
                <mesh filename="package:///drive_palonier.stl"/>
            </geometry>
        </collision>
        <visual>
            <origin xyz="0.0096000000000012308127 4.538036613155327359e-15 -0.020515000000001056696" rpy="-1.5707963267952660402 -1.5707963267947782082 0" />
            <geometry>
                <mesh filename="package:///wj-wk00-0124bottomcase_45.stl"/>
            </geometry>
            <material name="wj-wk00-0124bottomcase_45_material">
                <color rgba="0.24705882352941177516 0.24313725490196078094 0.24313725490196078094 1.0"/>
            </material>
        </visual>
        <collision>
            <origin xyz="0.0096000000000012308127 4.538036613155327359e-15 -0.020515000000001056696" rpy="-1.5707963267952660402 -1.5707963267947782082 0" />
            <geometry>
                <mesh filename="package:///wj-wk00-0124bottomcase_45.stl"/>
            </geometry>
        </collision>
        <visual>
            <origin xyz="0.0096000000000012308127 4.538036613155327359e-15 -0.020515000000001056696" rpy="-1.5707963267952660402 -1.5707963267947782082 0" />
            <geometry>
                <mesh filename="package:///wj-wk00-0122topcabinetcase_95.stl"/>
            </geometry>
            <material name="wj-wk00-0122topcabinetcase_95_material">
                <color rgba="0.24705882352941177516 0.24313725490196078094 0.24313725490196078094 1.0"/>
            </material>
        </visual>
        <collision>
            <origin xyz="0.0096000000000012308127 4.538036613155327359e-15 -0.020515000000001056696" rpy="-1.5707963267952660402 -1.5707963267947782082 0" />
            <geometry>
                <mesh filename="package:///wj-wk00-0122topcabinetcase_95.stl"/>
            </geometry>
        </collision>
        <visual>
            <origin xyz="0.012500000000001520312 3.1710745140856033686e-15 -0.020515000000001698544" rpy="-1.5707963267952660402 -1.5707963267947782082 0" />
            <geometry>
                <mesh filename="package:///passive_palonier.stl"/>
            </geometry>
            <material name="passive_palonier_material">
                <color rgba="0.62352941176470588758 0.66666666666666662966 0.70196078431372543882 1.0"/>
            </material>
        </visual>
        <collision>
            <origin xyz="0.012500000000001520312 3.1710745140856033686e-15 -0.020515000000001698544" rpy="-1.5707963267952660402 -1.5707963267947782082 0" />
            <geometry>
                <mesh filename="package:///passive_palonier.stl"/>
            </geometry>
        </collision>
        <inertial>
            <origin xyz="0.00079508052674416378712 -5.4654095788103962574e-06 -0.033060020136905336752" rpy="0 0 0"/>
            <mass value="0.066480000000000025184" />
            <inertia ixx="2.4441098454925312531e-05" ixy="2.3565814732732271755e-09"  ixz="-3.8105868119092279331e-07" iyy="2.8181841945863979652e-05" iyz="-7.5003565220589387221e-09" izz="1.4268673550007153456e-05" />
        </inertial>
    </link>
    <link name="left_roll_to_pitch_assembly">
        <visual>
            <origin xyz="-0.03500000000000001027 -0.06500000000000000222 0.019050000000000014838" rpy="1.570796326794896558 1.570796326794896336 0" />
            <geometry>
                <mesh filename="package:///left_roll_to_pitch.stl"/>
            </geometry>
            <material name="left_roll_to_pitch_material">
                <color rgba="0.90980392156862743835 0.57254901960784310155 0.16470588235294117418 1.0"/>
            </material>
        </visual>
        <collision>
            <origin xyz="-0.03500000000000001027 -0.06500000000000000222 0.019050000000000014838" rpy="1.570796326794896558 1.570796326794896336 0" />
            <geometry>
                <mesh filename="package:///left_roll_to_pitch.stl"/>
            </geometry>
        </collision>
        <visual>
            <origin xyz="0.064699999999999174838 3.7608262858090935055e-17 0.009610000000000033446" rpy="1.570796326794896558 1.570796326794896336 0" />
            <geometry>
                <mesh filename="package:///wj-wk00-0123middlecase_56.stl"/>
            </geometry>
            <material name="wj-wk00-0123middlecase_56_material">
                <color rgba="0.24705882352941177516 0.24313725490196078094 0.24313725490196078094 1.0"/>
            </material>
        </visual>
        <collision>
            <origin xyz="0.064699999999999174838 3.7608262858090935055e-17 0.009610000000000033446" rpy="1.570796326794896558 1.570796326794896336 0" />
            <geometry>
                <mesh filename="package:///wj-wk00-0123middlecase_56.stl"/>
            </geometry>
        </collision>
        <visual>
            <origin xyz="0.064699999999999174838 3.7608262858090935055e-17 0.009610000000000033446" rpy="1.570796326794896558 1.570796326794896336 0" />
            <geometry>
                <mesh filename="package:///drive_palonier.stl"/>
            </geometry>
            <material name="drive_palonier_material">
                <color rgba="0.62352941176470588758 0.66666666666666662966 0.70196078431372543882 1.0"/>
            </material>
        </visual>
        <collision>
            <origin xyz="0.064699999999999174838 3.7608262858090935055e-17 0.009610000000000033446" rpy="1.570796326794896558 1.570796326794896336 0" />
            <geometry>
                <mesh filename="package:///drive_palonier.stl"/>
            </geometry>
        </collision>
        <visual>
            <origin xyz="0.064699999999999174838 3.7608262858090935055e-17 0.009610000000000033446" rpy="1.570796326794896558 1.570796326794896336 0" />
            <geometry>
                <mesh filename="package:///wj-wk00-0124bottomcase_45.stl"/>
            </geometry>
            <material name="wj-wk00-0124bottomcase_45_material">
                <color rgba="0.24705882352941177516 0.24313725490196078094 0.24313725490196078094 1.0"/>
            </material>
        </visual>
        <collision>
            <origin xyz="0.064699999999999174838 3.7608262858090935055e-17 0.009610000000000033446" rpy="1.570796326794896558 1.570796326794896336 0" />
            <geometry>
                <mesh filename="package:///wj-wk00-0124bottomcase_45.stl"/>
            </geometry>
        </collision>
        <visual>
            <origin xyz="0.064699999999999174838 3.7608262858090935055e-17 0.009610000000000033446" rpy="1.570796326794896558 1.570796326794896336 0" />
            <geometry>
                <mesh filename="package:///wj-wk00-0122topcabinetcase_95.stl"/>
            </geometry>
            <material name="wj-wk00-0122topcabinetcase_95_material">
                <color rgba="0.24705882352941177516 0.24313725490196078094 0.24313725490196078094 1.0"/>
            </material>
        </visual>
        <collision>
            <origin xyz="0.064699999999999174838 3.7608262858090935055e-17 0.009610000000000033446" rpy="1.570796326794896558 1.570796326794896336 0" />
            <geometry>
                <mesh filename="package:///wj-wk00-0122topcabinetcase_95.stl"/>
            </geometry>
        </collision>
        <visual>
            <origin xyz="0.067600000000001075895 4.1572377051241060641e-16 0.0096099999999998235445" rpy="1.570796326794896558 1.570796326794896336 0" />
            <geometry>
                <mesh filename="package:///passive_palonier.stl"/>
            </geometry>
            <material name="passive_palonier_material">
                <color rgba="0.62352941176470588758 0.66666666666666662966 0.70196078431372543882 1.0"/>
            </material>
        </visual>
        <collision>
            <origin xyz="0.067600000000001075895 4.1572377051241060641e-16 0.0096099999999998235445" rpy="1.570796326794896558 1.570796326794896336 0" />
            <geometry>
                <mesh filename="package:///passive_palonier.stl"/>
            </geometry>
        </collision>
        <inertial>
            <origin xyz="0.05080424543750635541 -0.00041104958524985408695 0.020470437421083717555" rpy="0 0 0"/>
            <mass value="0.075160000000000018461" />
            <inertia ixx="2.523352224027168846e-05" ixy="1.221334614555976386e-07"  ixz="-5.9049889515429003126e-07" iyy="4.138548557727461495e-05" iyz="-1.0754428972189734494e-07" izz="2.8126993683181194188e-05" />
        </inertial>
    </link>
    <link name="knee_and_ankle_assembly">
        <visual>
            <origin xyz="0.016059999999999834824 0.065000000000000113243 0.10914999999999995539" rpy="-1.570796326794896558 1.2490009027779248844e-16 -1.4988010832431876542e-15" />
            <geometry>
                <mesh filename="package:///left_cache.stl"/>
            </geometry>
            <material name="left_cache_material">
                <color rgba="0.91764705882352937127 0.91764705882352937127 0.91764705882352937127 1.0"/>
            </material>
        </visual>
        <collision>
            <origin xyz="0.016059999999999834824 0.065000000000000113243 0.10914999999999995539" rpy="-1.570796326794896558 1.2490009027779248844e-16 -1.4988010832431876542e-15" />
            <geometry>
                <mesh filename="package:///left_cache.stl"/>
            </geometry>
        </collision>
        <visual>
            <origin xyz="0.016059999999999761966 0.14364999999999930602 0.10925000000000001377" rpy="-1.570796326794896558 8.326672687807578623e-17 -4.9960036108065839168e-16" />
            <geometry>
                <mesh filename="package:///leg_spacer.stl"/>
            </geometry>
            <material name="leg_spacer_material">
                <color rgba="0.64705882352941179736 0.64705882352941179736 0.64705882352941179736 1.0"/>
            </material>
        </visual>
        <collision>
            <origin xyz="0.016059999999999761966 0.14364999999999930602 0.10925000000000001377" rpy="-1.570796326794896558 8.326672687807578623e-17 -4.9960036108065839168e-16" />
            <geometry>
                <mesh filename="package:///leg_spacer.stl"/>
            </geometry>
        </collision>
        <visual>
            <origin xyz="0.016059999999999702985 0.14364999999999991664 0.10914999999999973335" rpy="-1.5707963267948972241 -2.7755575615764727009e-17 -7.7715611723681006777e-16" />
            <geometry>
                <mesh filename="package:///left_knee_to_ankle_right_sheet.stl"/>
            </geometry>
            <material name="left_knee_to_ankle_right_sheet_material">
                <color rgba="0.22352941176470589313 0.21960784313725489891 0.21960784313725489891 1.0"/>
            </material>
        </visual>
        <collision>
            <origin xyz="0.016059999999999702985 0.14364999999999991664 0.10914999999999973335" rpy="-1.5707963267948972241 -2.7755575615764727009e-17 -7.7715611723681006777e-16" />
            <geometry>
                <mesh filename="package:///left_knee_to_ankle_right_sheet.stl"/>
            </geometry>
        </collision>
        <visual>
            <origin xyz="0.016060000000000011766 0.14365000000000002767 0.10914999999999992764" rpy="-1.57079632679489678 -1.3540045904053323075e-29 5.6576118046319440419e-30" />
            <geometry>
                <mesh filename="package:///left_knee_to_ankle_left_sheet.stl"/>
            </geometry>
            <material name="left_knee_to_ankle_left_sheet_material">
                <color rgba="0.22352941176470589313 0.21960784313725489891 0.21960784313725489891 1.0"/>
            </material>
        </visual>
        <collision>
            <origin xyz="0.016060000000000011766 0.14365000000000002767 0.10914999999999992764" rpy="-1.57079632679489678 -1.3540045904053323075e-29 5.6576118046319440419e-30" />
            <geometry>
                <mesh filename="package:///left_knee_to_ankle_left_sheet.stl"/>
            </geometry>
        </collision>
        <visual>
            <origin xyz="2.498001805406602216e-16 -0.053149999999999267275 0.009550000000000002931" rpy="-1.570796326794896558 1.8087084087002228275e-16 1.5707963267948983344" />
            <geometry>
                <mesh filename="package:///wj-wk00-0123middlecase_56.stl"/>
            </geometry>
            <material name="wj-wk00-0123middlecase_56_material">
                <color rgba="0.24705882352941177516 0.24313725490196078094 0.24313725490196078094 1.0"/>
            </material>
        </visual>
        <collision>
            <origin xyz="2.498001805406602216e-16 -0.053149999999999267275 0.009550000000000002931" rpy="-1.570796326794896558 1.8087084087002228275e-16 1.5707963267948983344" />
            <geometry>
                <mesh filename="package:///wj-wk00-0123middlecase_56.stl"/>
            </geometry>
        </collision>
        <visual>
            <origin xyz="2.498001805406602216e-16 -0.053149999999999267275 0.009550000000000002931" rpy="-1.570796326794896558 1.8087084087002228275e-16 1.5707963267948983344" />
            <geometry>
                <mesh filename="package:///drive_palonier.stl"/>
            </geometry>
            <material name="drive_palonier_material">
                <color rgba="0.62352941176470588758 0.66666666666666662966 0.70196078431372543882 1.0"/>
            </material>
        </visual>
        <collision>
            <origin xyz="2.498001805406602216e-16 -0.053149999999999267275 0.009550000000000002931" rpy="-1.570796326794896558 1.8087084087002228275e-16 1.5707963267948983344" />
            <geometry>
                <mesh filename="package:///drive_palonier.stl"/>
            </geometry>
        </collision>
        <visual>
            <origin xyz="2.498001805406602216e-16 -0.053149999999999267275 0.009550000000000002931" rpy="-1.570796326794896558 1.8087084087002228275e-16 1.5707963267948983344" />
            <geometry>
                <mesh filename="package:///wj-wk00-0124bottomcase_45.stl"/>
            </geometry>
            <material name="wj-wk00-0124bottomcase_45_material">
                <color rgba="0.24705882352941177516 0.24313725490196078094 0.24313725490196078094 1.0"/>
            </material>
        </visual>
        <collision>
            <origin xyz="2.498001805406602216e-16 -0.053149999999999267275 0.009550000000000002931" rpy="-1.570796326794896558 1.8087084087002228275e-16 1.5707963267948983344" />
            <geometry>
                <mesh filename="package:///wj-wk00-0124bottomcase_45.stl"/>
            </geometry>
        </collision>
        <visual>
            <origin xyz="2.498001805406602216e-16 -0.053149999999999267275 0.009550000000000002931" rpy="-1.570796326794896558 1.8087084087002228275e-16 1.5707963267948983344" />
            <geometry>
                <mesh filename="package:///wj-wk00-0122topcabinetcase_95.stl"/>
            </geometry>
            <material name="wj-wk00-0122topcabinetcase_95_material">
                <color rgba="0.24705882352941177516 0.24313725490196078094 0.24313725490196078094 1.0"/>
            </material>
        </visual>
        <collision>
            <origin xyz="2.498001805406602216e-16 -0.053149999999999267275 0.009550000000000002931" rpy="-1.570796326794896558 1.8087084087002228275e-16 1.5707963267948983344" />
            <geometry>
                <mesh filename="package:///wj-wk00-0122topcabinetcase_95.stl"/>
            </geometry>
        </collision>
        <visual>
            <origin xyz="5.4123372450476381346e-16 -0.053149999999999204825 0.0066499999999974773734" rpy="-1.570796326794896558 1.8087084087002228275e-16 1.5707963267948983344" />
            <geometry>
                <mesh filename="package:///passive_palonier.stl"/>
            </geometry>
            <material name="passive_palonier_material">
                <color rgba="0.62352941176470588758 0.66666666666666662966 0.70196078431372543882 1.0"/>
            </material>
        </visual>
        <collision>
            <origin xyz="5.4123372450476381346e-16 -0.053149999999999204825 0.0066499999999974773734" rpy="-1.570796326794896558 1.8087084087002228275e-16 1.5707963267948983344" />
            <geometry>
                <mesh filename="package:///passive_palonier.stl"/>
            </geometry>
        </collision>
        <inertial>
            <origin xyz="0.0025336932138010693528 -0.039063478721483628486 0.010278596297792179023" rpy="0 0 0"/>
            <mass value="0.12407000000000002748" />
            <inertia ixx="0.00021140693369007881332" ixy="-2.6870524909747258498e-05"  ixz="3.8193904536404858747e-06" iyy="7.8361262144982429052e-05" iyz="2.0798361433231416987e-05" izz="0.00022560384919498218401" />
        </inertial>
    </link>
    <link name="knee_and_ankle_assembly_2">
        <visual>
            <origin xyz="0.016059999999999567677 0.14364999999999961133 0.10924999999999987499" rpy="-1.57079632679489678 2.9490299099070175172e-17 -1.0547118733926107008e-15" />
            <geometry>
                <mesh filename="package:///leg_spacer.stl"/>
            </geometry>
            <material name="leg_spacer_material">
                <color rgba="0.64705882352941179736 0.64705882352941179736 0.64705882352941179736 1.0"/>
            </material>
        </visual>
        <collision>
            <origin xyz="0.016059999999999567677 0.14364999999999961133 0.10924999999999987499" rpy="-1.57079632679489678 2.9490299099070175172e-17 -1.0547118733926107008e-15" />
            <geometry>
                <mesh filename="package:///leg_spacer.stl"/>
            </geometry>
        </collision>
        <visual>
            <origin xyz="0.016059999999999602371 0.14364999999999930602 0.10914999999999992764" rpy="-1.5707963267948970021 -2.151057109898714321e-16 -1.1657341758556004602e-15" />
            <geometry>
                <mesh filename="package:///left_knee_to_ankle_right_sheet.stl"/>
            </geometry>
            <material name="left_knee_to_ankle_right_sheet_material">
                <color rgba="0.22352941176470589313 0.21960784313725489891 0.21960784313725489891 1.0"/>
            </material>
        </visual>
        <collision>
            <origin xyz="0.016059999999999602371 0.14364999999999930602 0.10914999999999992764" rpy="-1.5707963267948970021 -2.151057109898714321e-16 -1.1657341758556004602e-15" />
            <geometry>
                <mesh filename="package:///left_knee_to_ankle_right_sheet.stl"/>
            </geometry>
        </collision>
        <visual>
            <origin xyz="0.016060000000000004827 0.14365000000000002767 0.10914999999999991376" rpy="-1.57079632679489678 -1.5625979630913822685e-29 -3.9443045261050590271e-30" />
            <geometry>
                <mesh filename="package:///left_knee_to_ankle_left_sheet.stl"/>
            </geometry>
            <material name="left_knee_to_ankle_left_sheet_material">
                <color rgba="0.22352941176470589313 0.21960784313725489891 0.21960784313725489891 1.0"/>
            </material>
        </visual>
        <collision>
            <origin xyz="0.016060000000000004827 0.14365000000000002767 0.10914999999999991376" rpy="-1.57079632679489678 -1.5625979630913822685e-29 -3.9443045261050590271e-30" />
            <geometry>
                <mesh filename="package:///left_knee_to_ankle_left_sheet.stl"/>
            </geometry>
        </collision>
        <visual>
            <origin xyz="3.1918911957973250537e-16 -0.053149999999999184008 0.0095499999999999474198" rpy="-1.57079632679489678 3.057709313177538991e-16 1.5707963267948998887" />
            <geometry>
                <mesh filename="package:///wj-wk00-0123middlecase_56.stl"/>
            </geometry>
            <material name="wj-wk00-0123middlecase_56_material">
                <color rgba="0.24705882352941177516 0.24313725490196078094 0.24313725490196078094 1.0"/>
            </material>
        </visual>
        <collision>
            <origin xyz="3.1918911957973250537e-16 -0.053149999999999184008 0.0095499999999999474198" rpy="-1.57079632679489678 3.057709313177538991e-16 1.5707963267948998887" />
            <geometry>
                <mesh filename="package:///wj-wk00-0123middlecase_56.stl"/>
            </geometry>
        </collision>
        <visual>
            <origin xyz="3.1918911957973250537e-16 -0.053149999999999184008 0.0095499999999999474198" rpy="-1.57079632679489678 3.057709313177538991e-16 1.5707963267948998887" />
            <geometry>
                <mesh filename="package:///drive_palonier.stl"/>
            </geometry>
            <material name="drive_palonier_material">
                <color rgba="0.62352941176470588758 0.66666666666666662966 0.70196078431372543882 1.0"/>
            </material>
        </visual>
        <collision>
            <origin xyz="3.1918911957973250537e-16 -0.053149999999999184008 0.0095499999999999474198" rpy="-1.57079632679489678 3.057709313177538991e-16 1.5707963267948998887" />
            <geometry>
                <mesh filename="package:///drive_palonier.stl"/>
            </geometry>
        </collision>
        <visual>
            <origin xyz="3.1918911957973250537e-16 -0.053149999999999184008 0.0095499999999999474198" rpy="-1.57079632679489678 3.057709313177538991e-16 1.5707963267948998887" />
            <geometry>
                <mesh filename="package:///wj-wk00-0124bottomcase_45.stl"/>
            </geometry>
            <material name="wj-wk00-0124bottomcase_45_material">
                <color rgba="0.24705882352941177516 0.24313725490196078094 0.24313725490196078094 1.0"/>
            </material>
        </visual>
        <collision>
            <origin xyz="3.1918911957973250537e-16 -0.053149999999999184008 0.0095499999999999474198" rpy="-1.57079632679489678 3.057709313177538991e-16 1.5707963267948998887" />
            <geometry>
                <mesh filename="package:///wj-wk00-0124bottomcase_45.stl"/>
            </geometry>
        </collision>
        <visual>
            <origin xyz="3.1918911957973250537e-16 -0.053149999999999184008 0.0095499999999999474198" rpy="-1.57079632679489678 3.057709313177538991e-16 1.5707963267948998887" />
            <geometry>
                <mesh filename="package:///wj-wk00-0122topcabinetcase_95.stl"/>
            </geometry>
            <material name="wj-wk00-0122topcabinetcase_95_material">
                <color rgba="0.24705882352941177516 0.24313725490196078094 0.24313725490196078094 1.0"/>
            </material>
        </visual>
        <collision>
            <origin xyz="3.1918911957973250537e-16 -0.053149999999999184008 0.0095499999999999474198" rpy="-1.57079632679489678 3.057709313177538991e-16 1.5707963267948998887" />
            <geometry>
                <mesh filename="package:///wj-wk00-0122topcabinetcase_95.stl"/>
            </geometry>
        </collision>
        <visual>
            <origin xyz="-3.2612801348363973375e-16 -0.053149999999999211764 0.0066499999999980879961" rpy="-1.57079632679489678 3.057709313177538991e-16 1.5707963267948998887" />
            <geometry>
                <mesh filename="package:///passive_palonier.stl"/>
            </geometry>
            <material name="passive_palonier_material">
                <color rgba="0.62352941176470588758 0.66666666666666662966 0.70196078431372543882 1.0"/>
            </material>
        </visual>
        <collision>
            <origin xyz="-3.2612801348363973375e-16 -0.053149999999999211764 0.0066499999999980879961" rpy="-1.57079632679489678 3.057709313177538991e-16 1.5707963267948998887" />
            <geometry>
                <mesh filename="package:///passive_palonier.stl"/>
            </geometry>
        </collision>
        <inertial>
            <origin xyz="5.0186022712414941614e-06 -0.057746250763045847698 0.018115359047914576102" rpy="0 0 0"/>
            <mass value="0.072590000000000029501" />
            <inertia ixx="4.9956626026661073376e-05" ixy="1.0381750097634580758e-08"  ixz="2.2523053252195198891e-09" iyy="1.8710599332134470466e-05" iyz="8.3252326202172763302e-08" izz="4.2378392100879942283e-05" />
        </inertial>
    </link>
    <link name="foot_assembly">
        <visual>
            <origin xyz="0.016060000000000018705 0.22230000000000008087 0.10904999999999998028" rpy="-1.570796326794896558 -2.4440595197579891635e-29 0" />
            <geometry>
                <mesh filename="package:///foot_side.stl"/>
            </geometry>
            <material name="foot_side_material">
                <color rgba="0.98039215686274505668 0.71372549019607844922 0.0039215686274509803377 1.0"/>
            </material>
        </visual>
        <collision>
            <origin xyz="0.016060000000000018705 0.22230000000000008087 0.10904999999999998028" rpy="-1.570796326794896558 -2.4440595197579891635e-29 0" />
            <geometry>
                <mesh filename="package:///foot_side.stl"/>
            </geometry>
        </collision>
        <visual>
            <origin xyz="0.016559999999999974046 0.22280000000000030336 0.10955000000000034155" rpy="-1.570796326794896558 4.8789097761603291317e-18 0" />
            <geometry>
                <mesh filename="package:///foot_bottom_tpu.stl"/>
            </geometry>
            <material name="foot_bottom_tpu_material">
                <color rgba="0.3058823529411764941 0.29803921568627450567 0.27843137254901961786 1.0"/>
            </material>
        </visual>
        <collision>
            <origin xyz="0.016559999999999974046 0.22280000000000030336 0.10955000000000034155" rpy="-1.570796326794896558 4.8789097761603291317e-18 0" />
            <geometry>
                <mesh filename="package:///foot_bottom_tpu.stl"/>
            </geometry>
        </collision>
        <visual>
            <origin xyz="0.016559999999999960169 0.22280000000000038662 0.10955000000000034155" rpy="-1.570796326794896558 4.8789097761603291317e-18 0" />
            <geometry>
                <mesh filename="package:///foot_bottom_pla.stl"/>
            </geometry>
            <material name="foot_bottom_pla_material">
                <color rgba="0.3058823529411764941 0.29803921568627450567 0.27843137254901961786 1.0"/>
            </material>
        </visual>
        <collision>
            <origin xyz="0.016559999999999960169 0.22280000000000038662 0.10955000000000034155" rpy="-1.570796326794896558 4.8789097761603291317e-18 0" />
            <geometry>
                <mesh filename="package:///foot_bottom_pla.stl"/>
            </geometry>
        </collision>
        <visual>
            <origin xyz="0.016060000000000018705 0.22230000000000008087 0.10904999999999998028" rpy="-1.570796326794896558 -2.4440595197579891635e-29 0" />
            <geometry>
                <mesh filename="package:///foot_top.stl"/>
            </geometry>
            <material name="foot_top_material">
                <color rgba="0.98039215686274505668 0.71372549019607844922 0.0039215686274509803377 1.0"/>
            </material>
        </visual>
        <collision>
            <origin xyz="0.016060000000000018705 0.22230000000000008087 0.10904999999999998028" rpy="-1.570796326794896558 -2.4440595197579891635e-29 0" />
            <geometry>
                <mesh filename="package:///foot_top.stl"/>
            </geometry>
        </collision>
        <inertial>
            <origin xyz="0.011071805402718556954 -0.024660828914218842212 0.019062631506296966177" rpy="0 0 0"/>
            <mass value="0.075240000000000001323" />
            <inertia ixx="1.8748234895076202868e-05" ixy="1.5883913400525383184e-06"  ixz="-6.523543144887125668e-09" iyy="6.7442711011305003831e-05" iyz="5.6739085477872305016e-08" izz="6.0609999935800022827e-05" />
        </inertial>
    </link>
    <link name="left_foot">
        <inertial>
            <origin xyz="0 0 0" rpy="0 0 0" />
            <mass value="1e-9" />
            <inertia ixx="0" ixy="0" ixz="0" iyy="0" iyz="0" izz="0" />
        </inertial>
    </link>
    <joint name="left_foot_frame" type="fixed">
        <origin xyz="0.00049999999999996574962 -0.036224999999999646372 0.019550000000000317124" rpy="-1.570796326794896558 4.8789097759078905605e-18 3.7865323450608544239e-29" />
        <parent link="foot_assembly" />
        <child link="left_foot" />
        <axis xyz="0 0 0"/>
    </joint>
    <joint name="left_ankle" type="revolute">
        <origin xyz="3.8857805861880478915e-16 -0.078649999999999067879 9.9999999999947353224e-05" rpy="-3.0577093135086125731e-16 -2.1510571099027823781e-16 -1.1379786005983670304e-15" />
        <parent link="knee_and_ankle_assembly_2" />
        <child link="foot_assembly" />
        <axis xyz="0 0 1"/>
        <limit effort="1" velocity="20" lower="-1.570796326794896558" upper="1.570796326794896558"/>
        <joint_properties friction="0.0"/>
    </joint>
    <joint name="left_knee" type="revolute">
        <origin xyz="6.2450045135165055399e-17 -0.078649999999999636868 9.9999999999988986588e-05" rpy="-1.433738720798104591e-17 9.7838404045009444717e-16 4.9960036108120734026e-16" />
        <parent link="knee_and_ankle_assembly" />
        <child link="knee_and_ankle_assembly_2" />
        <axis xyz="0 0 1"/>
        <limit effort="1" velocity="20" lower="-1.570796326794896558" upper="1.570796326794896558"/>
        <joint_properties friction="0.0"/>
    </joint>
    <joint name="left_hip_pitch" type="revolute">
        <origin xyz="0.074149999999998994493 5.7702594872394152858e-16 0.035109999999999731701" rpy="-3.141592653589793116 1.5707963267948958919 0" />
        <parent link="left_roll_to_pitch_assembly" />
        <child link="knee_and_ankle_assembly" />
        <axis xyz="0 0 1"/>
        <limit effort="1" velocity="20" lower="-1.2217304763960306069" upper="0.52359877559829881566"/>
        <joint_properties friction="0.0"/>
    </joint>
    <joint name="left_hip_roll" type="revolute">
        <origin xyz="0.019050000000002908357 -1.2559397966072083364e-15 -0.046015000000000465252" rpy="-1.57079632679495651 1.0208316397064496209e-13 1.5707963267945266317" />
        <parent link="hip_roll_assembly" />
        <child link="left_roll_to_pitch_assembly" />
        <axis xyz="0 0 1"/>
        <limit effort="1" velocity="20" lower="-0.43633231299858238339" upper="0.43633231299858238339"/>
        <joint_properties friction="0.0"/>
    </joint>
    <joint name="left_hip_yaw" type="revolute">
        <origin xyz="-0.018999999999999715034 0.035000000000001356415 0.045940938812377457579" rpy="-5.4063708435955792693e-16 -2.1649348979904514729e-14 -1.6653345373435771223e-16" />
        <parent link="trunk_assembly" />
        <child link="hip_roll_assembly" />
        <axis xyz="0 0 1"/>
        <limit effort="1" velocity="20" lower="-0.52359877559829881566" upper="0.52359877559829881566"/>
        <joint_properties friction="0.0"/>
    </joint>
    <link name="hip_roll_assembly_2">
        <visual>
            <origin xyz="-3.712308238590367182e-16 -0.034999999999999337197 0.019050000000000018308" rpy="4.4170622972785230236e-18 -5.5503510379564441531e-17 -3.0531133177191765419e-16" />
            <geometry>
                <mesh filename="package:///roll_motor_bottom.stl"/>
            </geometry>
            <material name="roll_motor_bottom_material">
                <color rgba="0.64705882352941179736 0.64705882352941179736 0.64705882352941179736 1.0"/>
            </material>
        </visual>
        <collision>
            <origin xyz="-3.712308238590367182e-16 -0.034999999999999337197 0.019050000000000018308" rpy="4.4170622972785230236e-18 -5.5503510379564441531e-17 -3.0531133177191765419e-16" />
            <geometry>
                <mesh filename="package:///roll_motor_bottom.stl"/>
            </geometry>
        </collision>
        <visual>
            <origin xyz="-3.4694469519536141888e-18 -0.035000000000000003331 0.019050000000000018308" rpy="2.8684392160171886915e-31 -6.1629758185104750018e-31 -7.3929534754180212532e-32" />
            <geometry>
                <mesh filename="package:///roll_motor_top.stl"/>
            </geometry>
            <material name="roll_motor_top_material">
                <color rgba="0.90196078431372550543 0.90196078431372550543 0.90196078431372550543 1.0"/>
            </material>
        </visual>
        <collision>
            <origin xyz="-3.4694469519536141888e-18 -0.035000000000000003331 0.019050000000000018308" rpy="2.8684392160171886915e-31 -6.1629758185104750018e-31 -7.3929534754180212532e-32" />
            <geometry>
                <mesh filename="package:///roll_motor_top.stl"/>
            </geometry>
        </collision>
        <visual>
            <origin xyz="0.0096000000000104612763 3.6366742950377783927e-14 -0.020515000000000928326" rpy="-1.5707963267952425035 -1.5707963267947684383 0" />
            <geometry>
                <mesh filename="package:///wj-wk00-0123middlecase_56.stl"/>
            </geometry>
            <material name="wj-wk00-0123middlecase_56_material">
                <color rgba="0.24705882352941177516 0.24313725490196078094 0.24313725490196078094 1.0"/>
            </material>
        </visual>
        <collision>
            <origin xyz="0.0096000000000104612763 3.6366742950377783927e-14 -0.020515000000000928326" rpy="-1.5707963267952425035 -1.5707963267947684383 0" />
            <geometry>
                <mesh filename="package:///wj-wk00-0123middlecase_56.stl"/>
            </geometry>
        </collision>
        <visual>
            <origin xyz="0.0096000000000104612763 3.6366742950377783927e-14 -0.020515000000000928326" rpy="-1.5707963267952425035 -1.5707963267947684383 0" />
            <geometry>
                <mesh filename="package:///drive_palonier.stl"/>
            </geometry>
            <material name="drive_palonier_material">
                <color rgba="0.62352941176470588758 0.66666666666666662966 0.70196078431372543882 1.0"/>
            </material>
        </visual>
        <collision>
            <origin xyz="0.0096000000000104612763 3.6366742950377783927e-14 -0.020515000000000928326" rpy="-1.5707963267952425035 -1.5707963267947684383 0" />
            <geometry>
                <mesh filename="package:///drive_palonier.stl"/>
            </geometry>
        </collision>
        <visual>
            <origin xyz="0.0096000000000104612763 3.6366742950377783927e-14 -0.020515000000000928326" rpy="-1.5707963267952425035 -1.5707963267947684383 0" />
            <geometry>
                <mesh filename="package:///wj-wk00-0124bottomcase_45.stl"/>
            </geometry>
            <material name="wj-wk00-0124bottomcase_45_material">
                <color rgba="0.24705882352941177516 0.24313725490196078094 0.24313725490196078094 1.0"/>
            </material>
        </visual>
        <collision>
            <origin xyz="0.0096000000000104612763 3.6366742950377783927e-14 -0.020515000000000928326" rpy="-1.5707963267952425035 -1.5707963267947684383 0" />
            <geometry>
                <mesh filename="package:///wj-wk00-0124bottomcase_45.stl"/>
            </geometry>
        </collision>
        <visual>
            <origin xyz="0.0096000000000104612763 3.6366742950377783927e-14 -0.020515000000000928326" rpy="-1.5707963267952425035 -1.5707963267947684383 0" />
            <geometry>
                <mesh filename="package:///wj-wk00-0122topcabinetcase_95.stl"/>
            </geometry>
            <material name="wj-wk00-0122topcabinetcase_95_material">
                <color rgba="0.24705882352941177516 0.24313725490196078094 0.24313725490196078094 1.0"/>
            </material>
        </visual>
        <collision>
            <origin xyz="0.0096000000000104612763 3.6366742950377783927e-14 -0.020515000000000928326" rpy="-1.5707963267952425035 -1.5707963267947684383 0" />
            <geometry>
                <mesh filename="package:///wj-wk00-0122topcabinetcase_95.stl"/>
            </geometry>
        </collision>
        <visual>
            <origin xyz="0.012500000000016031274 3.6977365613921620024e-14 -0.020515000000000980368" rpy="-1.5707963267952425035 -1.5707963267947684383 0" />
            <geometry>
                <mesh filename="package:///passive_palonier.stl"/>
            </geometry>
            <material name="passive_palonier_material">
                <color rgba="0.62352941176470588758 0.66666666666666662966 0.70196078431372543882 1.0"/>
            </material>
        </visual>
        <collision>
            <origin xyz="0.012500000000016031274 3.6977365613921620024e-14 -0.020515000000000980368" rpy="-1.5707963267952425035 -1.5707963267947684383 0" />
            <geometry>
                <mesh filename="package:///passive_palonier.stl"/>
            </geometry>
        </collision>
        <inertial>
            <origin xyz="0.00079508052675019054174 -5.4654095505154927414e-06 -0.033060020136904004484" rpy="0 0 0"/>
            <mass value="0.066480000000000025184" />
            <inertia ixx="2.4441098454924828028e-05" ixy="2.356581473017842606e-09"  ixz="-3.8105868119084841323e-07" iyy="2.8181841945863152948e-05" iyz="-7.5003565179789547231e-09" izz="1.4268673550006804479e-05" />
        </inertial>
    </link>
    <link name="right_roll_to_pitch_assembly">
        <visual>
            <origin xyz="0.035000000000000024147 -0.06500000000000000222 0.019050000000000021777" rpy="1.570796326794896558 1.570796326794896336 0" />
            <geometry>
                <mesh filename="package:///right_roll_to_pitch.stl"/>
            </geometry>
            <material name="right_roll_to_pitch_material">
                <color rgba="0.90980392156862743835 0.57254901960784310155 0.16470588235294117418 1.0"/>
            </material>
        </visual>
        <collision>
            <origin xyz="0.035000000000000024147 -0.06500000000000000222 0.019050000000000021777" rpy="1.570796326794896558 1.570796326794896336 0" />
            <geometry>
                <mesh filename="package:///right_roll_to_pitch.stl"/>
            </geometry>
        </collision>
        <visual>
            <origin xyz="-0.064699999999999924238 3.617169497954764168e-17 0.0096099999999999814043" rpy="-1.570796326794896558 1.570796326794896336 0" />
            <geometry>
                <mesh filename="package:///wj-wk00-0123middlecase_56.stl"/>
            </geometry>
            <material name="wj-wk00-0123middlecase_56_material">
                <color rgba="0.24705882352941177516 0.24313725490196078094 0.24313725490196078094 1.0"/>
            </material>
        </visual>
        <collision>
            <origin xyz="-0.064699999999999924238 3.617169497954764168e-17 0.0096099999999999814043" rpy="-1.570796326794896558 1.570796326794896336 0" />
            <geometry>
                <mesh filename="package:///wj-wk00-0123middlecase_56.stl"/>
            </geometry>
        </collision>
        <visual>
            <origin xyz="-0.064699999999999924238 3.617169497954764168e-17 0.0096099999999999814043" rpy="-1.570796326794896558 1.570796326794896336 0" />
            <geometry>
                <mesh filename="package:///drive_palonier.stl"/>
            </geometry>
            <material name="drive_palonier_material">
                <color rgba="0.62352941176470588758 0.66666666666666662966 0.70196078431372543882 1.0"/>
            </material>
        </visual>
        <collision>
            <origin xyz="-0.064699999999999924238 3.617169497954764168e-17 0.0096099999999999814043" rpy="-1.570796326794896558 1.570796326794896336 0" />
            <geometry>
                <mesh filename="package:///drive_palonier.stl"/>
            </geometry>
        </collision>
        <visual>
            <origin xyz="-0.064699999999999924238 3.617169497954764168e-17 0.0096099999999999814043" rpy="-1.570796326794896558 1.570796326794896336 0" />
            <geometry>
                <mesh filename="package:///wj-wk00-0124bottomcase_45.stl"/>
            </geometry>
            <material name="wj-wk00-0124bottomcase_45_material">
                <color rgba="0.24705882352941177516 0.24313725490196078094 0.24313725490196078094 1.0"/>
            </material>
        </visual>
        <collision>
            <origin xyz="-0.064699999999999924238 3.617169497954764168e-17 0.0096099999999999814043" rpy="-1.570796326794896558 1.570796326794896336 0" />
            <geometry>
                <mesh filename="package:///wj-wk00-0124bottomcase_45.stl"/>
            </geometry>
        </collision>
        <visual>
            <origin xyz="-0.064699999999999924238 3.617169497954764168e-17 0.0096099999999999814043" rpy="-1.570796326794896558 1.570796326794896336 0" />
            <geometry>
                <mesh filename="package:///wj-wk00-0122topcabinetcase_95.stl"/>
            </geometry>
            <material name="wj-wk00-0122topcabinetcase_95_material">
                <color rgba="0.24705882352941177516 0.24313725490196078094 0.24313725490196078094 1.0"/>
            </material>
        </visual>
        <collision>
            <origin xyz="-0.064699999999999924238 3.617169497954764168e-17 0.0096099999999999814043" rpy="-1.570796326794896558 1.570796326794896336 0" />
            <geometry>
                <mesh filename="package:///wj-wk00-0122topcabinetcase_95.stl"/>
            </geometry>
        </collision>
        <visual>
            <origin xyz="-0.067600000000005461276 1.2098340992222622603e-16 0.0096099999999999727307" rpy="-1.570796326794896558 1.570796326794896336 0" />
            <geometry>
                <mesh filename="package:///passive_palonier.stl"/>
            </geometry>
            <material name="passive_palonier_material">
                <color rgba="0.62352941176470588758 0.66666666666666662966 0.70196078431372543882 1.0"/>
            </material>
        </visual>
        <collision>
            <origin xyz="-0.067600000000005461276 1.2098340992222622603e-16 0.0096099999999999727307" rpy="-1.570796326794896558 1.570796326794896336 0" />
            <geometry>
                <mesh filename="package:///passive_palonier.stl"/>
            </geometry>
        </collision>
        <inertial>
            <origin xyz="-0.050804245559722710501 -0.00042074186984665220201 0.020470437477687390693" rpy="0 0 0"/>
            <mass value="0.075160000000000032339" />
            <inertia ixx="2.5232917470049133322e-05" ixy="-1.3052786017327282926e-07"  ixz="5.9049873224145463597e-07" iyy="4.1385487041401177995e-05" iyz="-9.1342675969404232282e-08" izz="2.8126389586193778155e-05" />
        </inertial>
    </link>
    <link name="knee_and_ankle_assembly_3">
        <visual>
            <origin xyz="0.016059999999999848702 -0.064999999999997698508 0.10919999999999696616" rpy="1.5707963267948956698 1.9428902928376199927e-16 -3.8857805861818464587e-16" />
            <geometry>
                <mesh filename="package:///right_cache.stl"/>
            </geometry>
            <material name="right_cache_material">
                <color rgba="0.91764705882352937127 0.91764705882352937127 0.91764705882352937127 1.0"/>
            </material>
        </visual>
        <collision>
            <origin xyz="0.016059999999999848702 -0.064999999999997698508 0.10919999999999696616" rpy="1.5707963267948956698 1.9428902928376199927e-16 -3.8857805861818464587e-16" />
            <geometry>
                <mesh filename="package:///right_cache.stl"/>
            </geometry>
        </collision>
        <visual>
            <origin xyz="0.016060000000000036052 -0.14364999999999555902 -0.07214999999999784086" rpy="1.5707963267948961139 1.9428902928356005088e-16 -3.8857805861818464587e-16" />
            <geometry>
                <mesh filename="package:///leg_spacer.stl"/>
            </geometry>
            <material name="leg_spacer_material">
                <color rgba="0.64705882352941179736 0.64705882352941179736 0.64705882352941179736 1.0"/>
            </material>
        </visual>
        <collision>
            <origin xyz="0.016060000000000036052 -0.14364999999999555902 -0.07214999999999784086" rpy="1.5707963267948961139 1.9428902928356005088e-16 -3.8857805861818464587e-16" />
            <geometry>
                <mesh filename="package:///leg_spacer.stl"/>
            </geometry>
        </collision>
        <visual>
            <origin xyz="0.016060000000000001358 -0.14365000000000002767 -0.072049999999999905786" rpy="1.570796326794896336 -1.0667543517107491842e-29 2.7269350010242323734e-31" />
            <geometry>
                <mesh filename="package:///left_knee_to_ankle_right_sheet.stl"/>
            </geometry>
            <material name="left_knee_to_ankle_right_sheet_material">
                <color rgba="0.22352941176470589313 0.21960784313725489891 0.21960784313725489891 1.0"/>
            </material>
        </visual>
        <collision>
            <origin xyz="0.016060000000000001358 -0.14365000000000002767 -0.072049999999999905786" rpy="1.570796326794896336 -1.0667543517107491842e-29 2.7269350010242323734e-31" />
            <geometry>
                <mesh filename="package:///left_knee_to_ankle_right_sheet.stl"/>
            </geometry>
        </collision>
        <visual>
            <origin xyz="0.016060000000000181769 -0.14364999999999483737 -0.07204999999999768534" rpy="1.5707963267948956698 1.9428902928240094304e-16 -3.6082248299250317924e-16" />
            <geometry>
                <mesh filename="package:///left_knee_to_ankle_left_sheet.stl"/>
            </geometry>
            <material name="left_knee_to_ankle_left_sheet_material">
                <color rgba="0.22352941176470589313 0.21960784313725489891 0.21960784313725489891 1.0"/>
            </material>
        </visual>
        <collision>
            <origin xyz="0.016060000000000181769 -0.14364999999999483737 -0.07204999999999768534" rpy="1.5707963267948956698 1.9428902928240094304e-16 -3.6082248299250317924e-16" />
            <geometry>
                <mesh filename="package:///left_knee_to_ankle_left_sheet.stl"/>
            </geometry>
        </collision>
        <visual>
            <origin xyz="1.3877787807814456755e-17 0.053149999999999808509 0.027549999999999352784" rpy="1.570796326794896558 -1.0412936844949911005e-15 -1.5707963267948952257" />
            <geometry>
                <mesh filename="package:///wj-wk00-0123middlecase_56.stl"/>
            </geometry>
            <material name="wj-wk00-0123middlecase_56_material">
                <color rgba="0.24705882352941177516 0.24313725490196078094 0.24313725490196078094 1.0"/>
            </material>
        </visual>
        <collision>
            <origin xyz="1.3877787807814456755e-17 0.053149999999999808509 0.027549999999999352784" rpy="1.570796326794896558 -1.0412936844949911005e-15 -1.5707963267948952257" />
            <geometry>
                <mesh filename="package:///wj-wk00-0123middlecase_56.stl"/>
            </geometry>
        </collision>
        <visual>
            <origin xyz="1.3877787807814456755e-17 0.053149999999999808509 0.027549999999999352784" rpy="1.570796326794896558 -1.0412936844949911005e-15 -1.5707963267948952257" />
            <geometry>
                <mesh filename="package:///drive_palonier.stl"/>
            </geometry>
            <material name="drive_palonier_material">
                <color rgba="0.62352941176470588758 0.66666666666666662966 0.70196078431372543882 1.0"/>
            </material>
        </visual>
        <collision>
            <origin xyz="1.3877787807814456755e-17 0.053149999999999808509 0.027549999999999352784" rpy="1.570796326794896558 -1.0412936844949911005e-15 -1.5707963267948952257" />
            <geometry>
                <mesh filename="package:///drive_palonier.stl"/>
            </geometry>
        </collision>
        <visual>
            <origin xyz="1.3877787807814456755e-17 0.053149999999999808509 0.027549999999999352784" rpy="1.570796326794896558 -1.0412936844949911005e-15 -1.5707963267948952257" />
            <geometry>
                <mesh filename="package:///wj-wk00-0124bottomcase_45.stl"/>
            </geometry>
            <material name="wj-wk00-0124bottomcase_45_material">
                <color rgba="0.24705882352941177516 0.24313725490196078094 0.24313725490196078094 1.0"/>
            </material>
        </visual>
        <collision>
            <origin xyz="1.3877787807814456755e-17 0.053149999999999808509 0.027549999999999352784" rpy="1.570796326794896558 -1.0412936844949911005e-15 -1.5707963267948952257" />
            <geometry>
                <mesh filename="package:///wj-wk00-0124bottomcase_45.stl"/>
            </geometry>
        </collision>
        <visual>
            <origin xyz="1.3877787807814456755e-17 0.053149999999999808509 0.027549999999999352784" rpy="1.570796326794896558 -1.0412936844949911005e-15 -1.5707963267948952257" />
            <geometry>
                <mesh filename="package:///wj-wk00-0122topcabinetcase_95.stl"/>
            </geometry>
            <material name="wj-wk00-0122topcabinetcase_95_material">
                <color rgba="0.24705882352941177516 0.24313725490196078094 0.24313725490196078094 1.0"/>
            </material>
        </visual>
        <collision>
            <origin xyz="1.3877787807814456755e-17 0.053149999999999808509 0.027549999999999352784" rpy="1.570796326794896558 -1.0412936844949911005e-15 -1.5707963267948952257" />
            <geometry>
                <mesh filename="package:///wj-wk00-0122topcabinetcase_95.stl"/>
            </geometry>
        </collision>
        <visual>
            <origin xyz="-3.1225022567582527699e-16 0.053149999999999246458 0.030449999999998145217" rpy="1.570796326794896558 -1.0412936844949911005e-15 -1.5707963267948952257" />
            <geometry>
                <mesh filename="package:///passive_palonier.stl"/>
            </geometry>
            <material name="passive_palonier_material">
                <color rgba="0.62352941176470588758 0.66666666666666662966 0.70196078431372543882 1.0"/>
            </material>
        </visual>
        <collision>
            <origin xyz="-3.1225022567582527699e-16 0.053149999999999246458 0.030449999999998145217" rpy="1.570796326794896558 -1.0412936844949911005e-15 -1.5707963267948952257" />
            <geometry>
                <mesh filename="package:///passive_palonier.stl"/>
            </geometry>
        </collision>
        <inertial>
            <origin xyz="0.0025336932138007718478 0.039063478721483989309 0.010807935972360698321" rpy="0 0 0"/>
            <mass value="0.12407000000000002748" />
            <inertia ixx="0.00021235928141328868583" ixy="2.6870524909746391136e-05"  ixz="3.9652703536817059799e-06" iyy="7.9313609868190282229e-05" iyz="-2.1742952498332393811e-05" izz="0.00022560384919497372723" />
        </inertial>
    </link>
    <link name="knee_and_ankle_assembly_4">
        <visual>
            <origin xyz="0.01606000000000048708 0.14365000000000105462 0.10925000000000054112" rpy="-1.5707963267948950037 7.2858385972341789055e-17 1.3877787807814705246e-15" />
            <geometry>
                <mesh filename="package:///leg_spacer.stl"/>
            </geometry>
            <material name="leg_spacer_material">
                <color rgba="0.64705882352941179736 0.64705882352941179736 0.64705882352941179736 1.0"/>
            </material>
        </visual>
        <collision>
            <origin xyz="0.01606000000000048708 0.14365000000000105462 0.10925000000000054112" rpy="-1.5707963267948950037 7.2858385972341789055e-17 1.3877787807814705246e-15" />
            <geometry>
                <mesh filename="package:///leg_spacer.stl"/>
            </geometry>
        </collision>
        <visual>
            <origin xyz="0.016060000000000011766 0.1436499999999999444 0.10914999999999996927" rpy="-1.57079632679489678 -5.0731055856417974745e-29 5.5511151231232601961e-17" />
            <geometry>
                <mesh filename="package:///left_knee_to_ankle_right_sheet.stl"/>
            </geometry>
            <material name="left_knee_to_ankle_right_sheet_material">
                <color rgba="0.22352941176470589313 0.21960784313725489891 0.21960784313725489891 1.0"/>
            </material>
        </visual>
        <collision>
            <origin xyz="0.016060000000000011766 0.1436499999999999444 0.10914999999999996927" rpy="-1.57079632679489678 -5.0731055856417974745e-29 5.5511151231232601961e-17" />
            <geometry>
                <mesh filename="package:///left_knee_to_ankle_right_sheet.stl"/>
            </geometry>
        </collision>
        <visual>
            <origin xyz="0.016060000000000008297 0.14365000000000005542 0.10914999999999994151" rpy="-1.57079632679489678 -4.3003071499638919549e-30 0" />
            <geometry>
                <mesh filename="package:///left_knee_to_ankle_left_sheet.stl"/>
            </geometry>
            <material name="left_knee_to_ankle_left_sheet_material">
                <color rgba="0.22352941176470589313 0.21960784313725489891 0.21960784313725489891 1.0"/>
            </material>
        </visual>
        <collision>
            <origin xyz="0.016060000000000008297 0.14365000000000005542 0.10914999999999994151" rpy="-1.57079632679489678 -4.3003071499638919549e-30 0" />
            <geometry>
                <mesh filename="package:///left_knee_to_ankle_left_sheet.stl"/>
            </geometry>
        </collision>
        <visual>
            <origin xyz="-2.0816681711721685133e-17 -0.053150000000000030553 0.0095499999999999890532" rpy="-1.570796326794896558 2.6413756771558975202e-16 1.570796326794896558" />
            <geometry>
                <mesh filename="package:///wj-wk00-0123middlecase_56.stl"/>
            </geometry>
            <material name="wj-wk00-0123middlecase_56_material">
                <color rgba="0.24705882352941177516 0.24313725490196078094 0.24313725490196078094 1.0"/>
            </material>
        </visual>
        <collision>
            <origin xyz="-2.0816681711721685133e-17 -0.053150000000000030553 0.0095499999999999890532" rpy="-1.570796326794896558 2.6413756771558975202e-16 1.570796326794896558" />
            <geometry>
                <mesh filename="package:///wj-wk00-0123middlecase_56.stl"/>
            </geometry>
        </collision>
        <visual>
            <origin xyz="-2.0816681711721685133e-17 -0.053150000000000030553 0.0095499999999999890532" rpy="-1.570796326794896558 2.6413756771558975202e-16 1.570796326794896558" />
            <geometry>
                <mesh filename="package:///drive_palonier.stl"/>
            </geometry>
            <material name="drive_palonier_material">
                <color rgba="0.62352941176470588758 0.66666666666666662966 0.70196078431372543882 1.0"/>
            </material>
        </visual>
        <collision>
            <origin xyz="-2.0816681711721685133e-17 -0.053150000000000030553 0.0095499999999999890532" rpy="-1.570796326794896558 2.6413756771558975202e-16 1.570796326794896558" />
            <geometry>
                <mesh filename="package:///drive_palonier.stl"/>
            </geometry>
        </collision>
        <visual>
            <origin xyz="-2.0816681711721685133e-17 -0.053150000000000030553 0.0095499999999999890532" rpy="-1.570796326794896558 2.6413756771558975202e-16 1.570796326794896558" />
            <geometry>
                <mesh filename="package:///wj-wk00-0124bottomcase_45.stl"/>
            </geometry>
            <material name="wj-wk00-0124bottomcase_45_material">
                <color rgba="0.24705882352941177516 0.24313725490196078094 0.24313725490196078094 1.0"/>
            </material>
        </visual>
        <collision>
            <origin xyz="-2.0816681711721685133e-17 -0.053150000000000030553 0.0095499999999999890532" rpy="-1.570796326794896558 2.6413756771558975202e-16 1.570796326794896558" />
            <geometry>
                <mesh filename="package:///wj-wk00-0124bottomcase_45.stl"/>
            </geometry>
        </collision>
        <visual>
            <origin xyz="-2.0816681711721685133e-17 -0.053150000000000030553 0.0095499999999999890532" rpy="-1.570796326794896558 2.6413756771558975202e-16 1.570796326794896558" />
            <geometry>
                <mesh filename="package:///wj-wk00-0122topcabinetcase_95.stl"/>
            </geometry>
            <material name="wj-wk00-0122topcabinetcase_95_material">
                <color rgba="0.24705882352941177516 0.24313725490196078094 0.24313725490196078094 1.0"/>
            </material>
        </visual>
        <collision>
            <origin xyz="-2.0816681711721685133e-17 -0.053150000000000030553 0.0095499999999999890532" rpy="-1.570796326794896558 2.6413756771558975202e-16 1.570796326794896558" />
            <geometry>
                <mesh filename="package:///wj-wk00-0122topcabinetcase_95.stl"/>
            </geometry>
        </collision>
        <visual>
            <origin xyz="2.2898349882893853646e-16 -0.053150000000000141576 0.0066500000000009884538" rpy="-1.570796326794896558 2.6413756771558975202e-16 1.570796326794896558" />
            <geometry>
                <mesh filename="package:///passive_palonier.stl"/>
            </geometry>
            <material name="passive_palonier_material">
                <color rgba="0.62352941176470588758 0.66666666666666662966 0.70196078431372543882 1.0"/>
            </material>
        </visual>
        <collision>
            <origin xyz="2.2898349882893853646e-16 -0.053150000000000141576 0.0066500000000009884538" rpy="-1.570796326794896558 2.6413756771558975202e-16 1.570796326794896558" />
            <geometry>
                <mesh filename="package:///passive_palonier.stl"/>
            </geometry>
        </collision>
        <inertial>
            <origin xyz="5.0186022709452825046e-06 -0.057746250763046631793 0.018115359047914735696" rpy="0 0 0"/>
            <mass value="0.072590000000000029501" />
            <inertia ixx="4.9956626026662367642e-05" ixy="1.0381750097637863011e-08"  ixz="2.2523053251877706293e-09" iyy="1.8710599332134917699e-05" iyz="8.3252326202542069667e-08" izz="4.2378392100880606357e-05" />
        </inertial>
    </link>
    <link name="foot_assembly_2">
        <visual>
            <origin xyz="0.016060000000000008297 0.22230000000000005311 0.10904999999999999416" rpy="-1.570796326794896558 7.0102415868698340716e-31 0" />
            <geometry>
                <mesh filename="package:///foot_side.stl"/>
            </geometry>
            <material name="foot_side_material">
                <color rgba="0.98039215686274505668 0.71372549019607844922 0.0039215686274509803377 1.0"/>
            </material>
        </visual>
        <collision>
            <origin xyz="0.016060000000000008297 0.22230000000000005311 0.10904999999999999416" rpy="-1.570796326794896558 7.0102415868698340716e-31 0" />
            <geometry>
                <mesh filename="package:///foot_side.stl"/>
            </geometry>
        </collision>
        <visual>
            <origin xyz="0.016560000000000227316 0.22280000000000013682 0.10955000000000066074" rpy="-1.570796326794896558 7.0102415868698340716e-31 0" />
            <geometry>
                <mesh filename="package:///foot_bottom_tpu.stl"/>
            </geometry>
            <material name="foot_bottom_tpu_material">
                <color rgba="0.3058823529411764941 0.29803921568627450567 0.27843137254901961786 1.0"/>
            </material>
        </visual>
        <collision>
            <origin xyz="0.016560000000000227316 0.22280000000000013682 0.10955000000000066074" rpy="-1.570796326794896558 7.0102415868698340716e-31 0" />
            <geometry>
                <mesh filename="package:///foot_bottom_tpu.stl"/>
            </geometry>
        </collision>
        <visual>
            <origin xyz="0.016560000000000227316 0.22280000000000013682 0.10955000000000066074" rpy="-1.570796326794896558 7.0102415868698340716e-31 0" />
            <geometry>
                <mesh filename="package:///foot_bottom_pla.stl"/>
            </geometry>
            <material name="foot_bottom_pla_material">
                <color rgba="0.3058823529411764941 0.29803921568627450567 0.27843137254901961786 1.0"/>
            </material>
        </visual>
        <collision>
            <origin xyz="0.016560000000000227316 0.22280000000000013682 0.10955000000000066074" rpy="-1.570796326794896558 7.0102415868698340716e-31 0" />
            <geometry>
                <mesh filename="package:///foot_bottom_pla.stl"/>
            </geometry>
        </collision>
        <visual>
            <origin xyz="0.016060000000000008297 0.22230000000000005311 0.10904999999999999416" rpy="-1.570796326794896558 7.0102415868698340716e-31 0" />
            <geometry>
                <mesh filename="package:///foot_top.stl"/>
            </geometry>
            <material name="foot_top_material">
                <color rgba="0.98039215686274505668 0.71372549019607844922 0.0039215686274509803377 1.0"/>
            </material>
        </visual>
        <collision>
            <origin xyz="0.016060000000000008297 0.22230000000000005311 0.10904999999999999416" rpy="-1.570796326794896558 7.0102415868698340716e-31 0" />
            <geometry>
                <mesh filename="package:///foot_top.stl"/>
            </geometry>
        </collision>
        <inertial>
            <origin xyz="0.011071805402718683589 -0.024660828914218960173 0.019062631506297132711" rpy="0 0 0"/>
            <mass value="0.075240000000000001323" />
            <inertia ixx="1.8748234895076274018e-05" ixy="1.5883913400525976107e-06"  ixz="-6.5235431448998311622e-09" iyy="6.7442711011305030936e-05" iyz="5.6739085477939855894e-08" izz="6.0609999935800097366e-05" />
        </inertial>
    </link>
    <link name="right_foot">
        <inertial>
            <origin xyz="0 0 0" rpy="0 0 0" />
            <mass value="1e-9" />
            <inertia ixx="0" ixy="0" ixz="0" iyy="0" iyz="0" izz="0" />
        </inertial>
    </link>
    <joint name="right_foot_frame" type="fixed">
        <origin xyz="0.00050000000000024330538 -0.036224999999999923928 0.019550000000000650191" rpy="-1.570796326794896558 -3.0222156344620005664e-28 -2.5243548967072377773e-28" />
        <parent link="foot_assembly_2" />
        <child link="right_foot" />
        <axis xyz="0 0 0"/>
    </joint>
    <joint name="right_ankle" type="revolute">
        <origin xyz="-2.5673907444456744997e-16 -0.078649999999999331557 9.9999999999947353224e-05" rpy="3.1786111035240684541e-16 -6.6613381497353178635e-16 1.026830726893522614e-13" />
        <parent link="knee_and_ankle_assembly_4" />
        <child link="foot_assembly_2" />
        <axis xyz="0 0 1"/>
        <limit effort="1" velocity="20" lower="-1.570796326794896558" upper="1.570796326794896558"/>
        <joint_properties friction="0.0"/>
    </joint>
    <joint name="right_knee" type="revolute">
        <origin xyz="-2.0816681711721685133e-17 0.078649999999999151146 0.036999999999999075295" rpy="3.1415926535897922278 -4.3118451852923719846e-26 2.0787928434596164854e-13" />
        <parent link="knee_and_ankle_assembly_3" />
        <child link="knee_and_ankle_assembly_4" />
        <axis xyz="0 0 1"/>
        <limit effort="1" velocity="20" lower="-1.570796326794896558" upper="1.570796326794896558"/>
        <joint_properties friction="0.0"/>
    </joint>
    <joint name="right_hip_pitch" type="revolute">
        <origin xyz="-0.074149999999999938183 1.3700249702069955404e-16 0.035109999999999981501" rpy="-5.8199867801976243694e-16 1.5707963267947913089 0" />
        <parent link="right_roll_to_pitch_assembly" />
        <child link="knee_and_ankle_assembly_3" />
        <axis xyz="0 0 1"/>
        <limit effort="1" velocity="20" lower="-0.52359877559829881566" upper="1.2217304763960306069"/>
        <joint_properties friction="0.0"/>
    </joint>
    <joint name="right_hip_roll" type="revolute">
        <origin xyz="0.019050000000007772522 3.498590306350024548e-14 -0.046015000000001887726" rpy="-1.5707963267947930852 -7.5380278374294396407e-14 1.5707963267945495023" />
        <parent link="hip_roll_assembly_2" />
        <child link="right_roll_to_pitch_assembly" />
        <axis xyz="0 0 1"/>
        <limit effort="1" velocity="20" lower="-0.43633231299858238339" upper="0.43633231299858238339"/>
        <joint_properties friction="0.0"/>
    </joint>
    <joint name="right_hip_yaw" type="revolute">
        <origin xyz="-0.018999999999999697686 -0.035000000000001127431 0.045940938812377443701" rpy="-1.4614506473940839798e-15 -2.1038726316805495209e-14 -4.9960036110118277749e-16" />
        <parent link="trunk_assembly" />
        <child link="hip_roll_assembly_2" />
        <axis xyz="0 0 1"/>
        <limit effort="1" velocity="20" lower="-0.52359877559829881566" upper="0.52359877559829881566"/>
        <joint_properties friction="0.0"/>
    </joint>
    <link name="neck_pitch_assembly">
        <visual>
            <origin xyz="-0.020000000000000007355 -0.025110000000000021192 0.019049999999999976674" rpy="-1.57079632679489678 2.0569781264721369144e-32 -3.6977854932234928379e-31" />
            <geometry>
                <mesh filename="package:///neck_left_sheet.stl"/>
            </geometry>
            <material name="neck_left_sheet_material">
                <color rgba="0.22352941176470589313 0.21960784313725489891 0.21960784313725489891 1.0"/>
            </material>
        </visual>
        <collision>
            <origin xyz="-0.020000000000000007355 -0.025110000000000021192 0.019049999999999976674" rpy="-1.57079632679489678 2.0569781264721369144e-32 -3.6977854932234928379e-31" />
            <geometry>
                <mesh filename="package:///neck_left_sheet.stl"/>
            </geometry>
        </collision>
        <visual>
            <origin xyz="-0.020000000000000007355 -0.025110000000000021192 0.01905000000000000096" rpy="-1.57079632679489678 -5.2602704289599958849e-17 -3.6977854932234928379e-31" />
            <geometry>
                <mesh filename="package:///neck_right_sheet.stl"/>
            </geometry>
            <material name="neck_right_sheet_material">
                <color rgba="0.22352941176470589313 0.21960784313725489891 0.21960784313725489891 1.0"/>
            </material>
        </visual>
        <collision>
            <origin xyz="-0.020000000000000007355 -0.025110000000000021192 0.01905000000000000096" rpy="-1.57079632679489678 -5.2602704289599958849e-17 -3.6977854932234928379e-31" />
            <geometry>
                <mesh filename="package:///neck_right_sheet.stl"/>
            </geometry>
        </collision>
        <visual>
            <origin xyz="-4.1199682554449168492e-18 0.04049999999999998046 0.0094499999999999931277" rpy="-1.570796326794896558 -1.1963610179149899356e-16 -1.57079632679489678" />
            <geometry>
                <mesh filename="package:///wj-wk00-0123middlecase_56.stl"/>
            </geometry>
            <material name="wj-wk00-0123middlecase_56_material">
                <color rgba="0.24705882352941177516 0.24313725490196078094 0.24313725490196078094 1.0"/>
            </material>
        </visual>
        <collision>
            <origin xyz="-4.1199682554449168492e-18 0.04049999999999998046 0.0094499999999999931277" rpy="-1.570796326794896558 -1.1963610179149899356e-16 -1.57079632679489678" />
            <geometry>
                <mesh filename="package:///wj-wk00-0123middlecase_56.stl"/>
            </geometry>
        </collision>
        <visual>
            <origin xyz="-4.1199682554449168492e-18 0.04049999999999998046 0.0094499999999999931277" rpy="-1.570796326794896558 -1.1963610179149899356e-16 -1.57079632679489678" />
            <geometry>
                <mesh filename="package:///drive_palonier.stl"/>
            </geometry>
            <material name="drive_palonier_material">
                <color rgba="0.62352941176470588758 0.66666666666666662966 0.70196078431372543882 1.0"/>
            </material>
        </visual>
        <collision>
            <origin xyz="-4.1199682554449168492e-18 0.04049999999999998046 0.0094499999999999931277" rpy="-1.570796326794896558 -1.1963610179149899356e-16 -1.57079632679489678" />
            <geometry>
                <mesh filename="package:///drive_palonier.stl"/>
            </geometry>
        </collision>
        <visual>
            <origin xyz="-4.1199682554449168492e-18 0.04049999999999998046 0.0094499999999999931277" rpy="-1.570796326794896558 -1.1963610179149899356e-16 -1.57079632679489678" />
            <geometry>
                <mesh filename="package:///wj-wk00-0124bottomcase_45.stl"/>
            </geometry>
            <material name="wj-wk00-0124bottomcase_45_material">
                <color rgba="0.24705882352941177516 0.24313725490196078094 0.24313725490196078094 1.0"/>
            </material>
        </visual>
        <collision>
            <origin xyz="-4.1199682554449168492e-18 0.04049999999999998046 0.0094499999999999931277" rpy="-1.570796326794896558 -1.1963610179149899356e-16 -1.57079632679489678" />
            <geometry>
                <mesh filename="package:///wj-wk00-0124bottomcase_45.stl"/>
            </geometry>
        </collision>
        <visual>
            <origin xyz="-4.1199682554449168492e-18 0.04049999999999998046 0.0094499999999999931277" rpy="-1.570796326794896558 -1.1963610179149899356e-16 -1.57079632679489678" />
            <geometry>
                <mesh filename="package:///wj-wk00-0122topcabinetcase_95.stl"/>
            </geometry>
            <material name="wj-wk00-0122topcabinetcase_95_material">
                <color rgba="0.24705882352941177516 0.24313725490196078094 0.24313725490196078094 1.0"/>
            </material>
        </visual>
        <collision>
            <origin xyz="-4.1199682554449168492e-18 0.04049999999999998046 0.0094499999999999931277" rpy="-1.570796326794896558 -1.1963610179149899356e-16 -1.57079632679489678" />
            <geometry>
                <mesh filename="package:///wj-wk00-0122topcabinetcase_95.stl"/>
            </geometry>
        </collision>
        <visual>
            <origin xyz="-1.7130394325270970057e-17 0.040500000000000091482 0.0065499999999996012801" rpy="-1.570796326794896558 -1.1963610179149899356e-16 -1.57079632679489678" />
            <geometry>
                <mesh filename="package:///passive_palonier.stl"/>
            </geometry>
            <material name="passive_palonier_material">
                <color rgba="0.62352941176470588758 0.66666666666666662966 0.70196078431372543882 1.0"/>
            </material>
        </visual>
        <collision>
            <origin xyz="-1.7130394325270970057e-17 0.040500000000000091482 0.0065499999999996012801" rpy="-1.570796326794896558 -1.1963610179149899356e-16 -1.57079632679489678" />
            <geometry>
                <mesh filename="package:///passive_palonier.stl"/>
            </geometry>
        </collision>
        <inertial>
            <origin xyz="-5.6313726504995830876e-06 0.049296760188244484469 0.01817855557986974846" rpy="0 0 0"/>
            <mass value="0.066180000000000030469" />
            <inertia ixx="3.4945638152177461826e-05" ixy="8.7563261019916330486e-09"  ixz="-2.1559156609446508451e-09" iyy="1.7023145118232439489e-05" iyz="-1.8518807640006074305e-08" izz="2.8004252155145357511e-05" />
        </inertial>
    </link>
    <link name="head_pitch_to_yaw">
        <visual>
            <origin xyz="-0.020000000000000014294 -0.091110000000000010423 0.01904999999999994198" rpy="-1.570796326794896558 2.7630897179646344447e-33 0" />
            <geometry>
                <mesh filename="package:///head_pitch_to_yaw.stl"/>
            </geometry>
            <material name="head_pitch_to_yaw_material">
                <color rgba="0.4000000000000000222 0.4000000000000000222 0.4000000000000000222 1.0"/>
            </material>
        </visual>
        <collision>
            <origin xyz="-0.020000000000000014294 -0.091110000000000010423 0.01904999999999994198" rpy="-1.570796326794896558 2.7630897179646344447e-33 0" />
            <geometry>
                <mesh filename="package:///head_pitch_to_yaw.stl"/>
            </geometry>
        </collision>
        <inertial>
            <origin xyz="-0.0065771887358402562201 0.02508139646434261183 0.018643483248194946122" rpy="0 0 0"/>
            <mass value="0.015591038955987642986" />
            <inertia ixx="8.9289443945510407432e-06" ixy="1.1495847726043986657e-06"  ixz="2.5224918220957864522e-08" iyy="4.3348012651742814965e-06" iyz="-7.7328847699739944223e-08" izz="7.3766655896716992828e-06" />
        </inertial>
    </link>
    <link name="neck_yaw_assembly">
        <visual>
            <origin xyz="-0.020000000000000638795 4.0115480381963664058e-18 -0.14820999999999998065" rpy="9.9920072216261840385e-16 -3.1554436208840535275e-30 -2.6517164082541871435e-31" />
            <geometry>
                <mesh filename="package:///head_yaw_to_roll.stl"/>
            </geometry>
            <material name="head_yaw_to_roll_material">
                <color rgba="0.64705882352941179736 0.64705882352941179736 0.64705882352941179736 1.0"/>
            </material>
        </visual>
        <collision>
            <origin xyz="-0.020000000000000638795 4.0115480381963664058e-18 -0.14820999999999998065" rpy="9.9920072216261840385e-16 -3.1554436208840535275e-30 -2.6517164082541871435e-31" />
            <geometry>
                <mesh filename="package:///head_yaw_to_roll.stl"/>
            </geometry>
        </collision>
        <visual>
            <origin xyz="0.025500000000000026118 7.047314121155778821e-19 -0.0094499999999999861888" rpy="1.570796326794896558 -0 5.9992953443081224981e-33" />
            <geometry>
                <mesh filename="package:///wj-wk00-0123middlecase_56.stl"/>
            </geometry>
            <material name="wj-wk00-0123middlecase_56_material">
                <color rgba="0.24705882352941177516 0.24313725490196078094 0.24313725490196078094 1.0"/>
            </material>
        </visual>
        <collision>
            <origin xyz="0.025500000000000026118 7.047314121155778821e-19 -0.0094499999999999861888" rpy="1.570796326794896558 -0 5.9992953443081224981e-33" />
            <geometry>
                <mesh filename="package:///wj-wk00-0123middlecase_56.stl"/>
            </geometry>
        </collision>
        <visual>
            <origin xyz="0.025500000000000026118 7.047314121155778821e-19 -0.0094499999999999861888" rpy="1.570796326794896558 -0 5.9992953443081224981e-33" />
            <geometry>
                <mesh filename="package:///drive_palonier.stl"/>
            </geometry>
            <material name="drive_palonier_material">
                <color rgba="0.62352941176470588758 0.66666666666666662966 0.70196078431372543882 1.0"/>
            </material>
        </visual>
        <collision>
            <origin xyz="0.025500000000000026118 7.047314121155778821e-19 -0.0094499999999999861888" rpy="1.570796326794896558 -0 5.9992953443081224981e-33" />
            <geometry>
                <mesh filename="package:///drive_palonier.stl"/>
            </geometry>
        </collision>
        <visual>
            <origin xyz="0.025500000000000026118 7.047314121155778821e-19 -0.0094499999999999861888" rpy="1.570796326794896558 -0 5.9992953443081224981e-33" />
            <geometry>
                <mesh filename="package:///wj-wk00-0124bottomcase_45.stl"/>
            </geometry>
            <material name="wj-wk00-0124bottomcase_45_material">
                <color rgba="0.24705882352941177516 0.24313725490196078094 0.24313725490196078094 1.0"/>
            </material>
        </visual>
        <collision>
            <origin xyz="0.025500000000000026118 7.047314121155778821e-19 -0.0094499999999999861888" rpy="1.570796326794896558 -0 5.9992953443081224981e-33" />
            <geometry>
                <mesh filename="package:///wj-wk00-0124bottomcase_45.stl"/>
            </geometry>
        </collision>
        <visual>
            <origin xyz="0.025500000000000026118 7.047314121155778821e-19 -0.0094499999999999861888" rpy="1.570796326794896558 -0 5.9992953443081224981e-33" />
            <geometry>
                <mesh filename="package:///wj-wk00-0122topcabinetcase_95.stl"/>
            </geometry>
            <material name="wj-wk00-0122topcabinetcase_95_material">
                <color rgba="0.24705882352941177516 0.24313725490196078094 0.24313725490196078094 1.0"/>
            </material>
        </visual>
        <collision>
            <origin xyz="0.025500000000000026118 7.047314121155778821e-19 -0.0094499999999999861888" rpy="1.570796326794896558 -0 5.9992953443081224981e-33" />
            <geometry>
                <mesh filename="package:///wj-wk00-0122topcabinetcase_95.stl"/>
            </geometry>
        </collision>
        <visual>
            <origin xyz="0.025500000000000033057 1.3292318634672284361e-16 -0.0065500000000003888445" rpy="1.570796326794896558 -0 5.9992953443081224981e-33" />
            <geometry>
                <mesh filename="package:///passive_palonier.stl"/>
            </geometry>
            <material name="passive_palonier_material">
                <color rgba="0.62352941176470588758 0.66666666666666662966 0.70196078431372543882 1.0"/>
            </material>
        </visual>
        <collision>
            <origin xyz="0.025500000000000033057 1.3292318634672284361e-16 -0.0065500000000003888445" rpy="1.570796326794896558 -0 5.9992953443081224981e-33" />
            <geometry>
                <mesh filename="package:///passive_palonier.stl"/>
            </geometry>
        </collision>
        <inertial>
            <origin xyz="0.0040173574292659249355 4.0070466829219060663e-06 -0.022234386319938143767" rpy="0 0 0"/>
            <mass value="0.090572249204174976045" />
            <inertia ixx="2.9946810782591205791e-05" ixy="4.2628973930195694608e-09"  ixz="-4.2480319265773111947e-06" iyy="6.6389322419559398253e-05" iyz="-3.8082918999389719317e-09" izz="6.6625959348107281722e-05" />
        </inertial>
    </link>
    <link name="head_assembly">
        <visual>
            <origin xyz="-0.12905999999999784311 -1.2987386773660736239e-16 0.060950000000001641753" rpy="-1.2621774483535835759e-29 1.5707963267948756858 0" />
            <geometry>
                <mesh filename="package:///head_bot_sheet.stl"/>
            </geometry>
            <material name="head_bot_sheet_material">
                <color rgba="0.41176470588235292158 0.41176470588235292158 0.41176470588235292158 1.0"/>
            </material>
        </visual>
        <collision>
            <origin xyz="-0.12905999999999784311 -1.2987386773660736239e-16 0.060950000000001641753" rpy="-1.2621774483535835759e-29 1.5707963267948756858 0" />
            <geometry>
                <mesh filename="package:///head_bot_sheet.stl"/>
            </geometry>
        </collision>
        <visual>
            <origin xyz="-0.12905999999999812067 -2.5591237028804725284e-16 0.060950000000001947065" rpy="5.2385294487330827111e-31 1.5707963267948756858 0" />
            <geometry>
                <mesh filename="package:///head.stl"/>
            </geometry>
            <material name="head_material">
                <color rgba="0.91764705882352937127 0.91764705882352937127 0.91764705882352937127 1.0"/>
            </material>
        </visual>
        <collision>
            <origin xyz="-0.12905999999999812067 -2.5591237028804725284e-16 0.060950000000001947065" rpy="5.2385294487330827111e-31 1.5707963267948756858 0" />
            <geometry>
                <mesh filename="package:///head.stl"/>
            </geometry>
        </collision>
        <visual>
            <origin xyz="0.032050000000000355982 0.045000000000000893452 0.00095000000000007578382" rpy="1.570796326794896558 -1.5707963267948785724 0" />
            <geometry>
                <mesh filename="package:///raspberrypizerow.stl"/>
            </geometry>
            <material name="raspberrypizerow_material">
                <color rgba="0.2313725490196078538 0.38039215686274507888 0.7058823529411765163 1.0"/>
            </material>
        </visual>
        <collision>
            <origin xyz="0.032050000000000355982 0.045000000000000893452 0.00095000000000007578382" rpy="1.570796326794896558 -1.5707963267948785724 0" />
            <geometry>
                <mesh filename="package:///raspberrypizerow.stl"/>
            </geometry>
        </collision>
        <visual>
            <origin xyz="2.0539125955565395998e-15 -0.035000000000002300105 0.16632500000000657869" rpy="-9.9920072216266470998e-15 5.7886752914364020336e-32 1.8488927466173995087e-32" />
            <geometry>
                <mesh filename="package:///roll_bearing.stl"/>
            </geometry>
            <material name="roll_bearing_material">
                <color rgba="0.5999999999999999778 0.5999999999999999778 0.5999999999999999778 1.0"/>
            </material>
        </visual>
        <collision>
            <origin xyz="2.0539125955565395998e-15 -0.035000000000002300105 0.16632500000000657869" rpy="-9.9920072216266470998e-15 5.7886752914364020336e-32 1.8488927466173995087e-32" />
            <geometry>
                <mesh filename="package:///roll_bearing.stl"/>
            </geometry>
        </collision>
        <visual>
            <origin xyz="-0.0062459440337501448415 0.033140784271761397628 0.10281206307851015191" rpy="2.0241194116514311105e-14 -1.3045791727887234845 -1.8181502823666495505" />
            <geometry>
                <mesh filename="package:///sg90.stl"/>
            </geometry>
            <material name="sg90_material">
                <color rgba="0.43529411764705883137 0.67058823529411759612 0.97647058823529409022 1.0"/>
            </material>
        </visual>
        <collision>
            <origin xyz="-0.0062459440337501448415 0.033140784271761397628 0.10281206307851015191" rpy="2.0241194116514311105e-14 -1.3045791727887234845 -1.8181502823666495505" />
            <geometry>
                <mesh filename="package:///sg90.stl"/>
            </geometry>
        </collision>
        <visual>
            <origin xyz="-0.0062459440337509219976 -0.033140784271761730695 0.10281206307851017967" rpy="1.8050255755409940982e-14 -1.3045791727887343647 1.8181502823666293445" />
            <geometry>
                <mesh filename="package:///sg90.stl"/>
            </geometry>
            <material name="sg90_material">
                <color rgba="0.43529411764705883137 0.67058823529411759612 0.97647058823529409022 1.0"/>
            </material>
        </visual>
        <collision>
            <origin xyz="-0.0062459440337509219976 -0.033140784271761730695 0.10281206307851017967" rpy="1.8050255755409940982e-14 -1.3045791727887343647 1.8181502823666293445" />
            <geometry>
                <mesh filename="package:///sg90.stl"/>
            </geometry>
        </collision>
        <visual>
            <origin xyz="0.032049999999999356781 -0.03350000766000000435 -0.02004998738000049463" rpy="-3.141592653589793116 -1.5707963267948872321 0" />
            <geometry>
                <mesh filename="package:///board.stl"/>
            </geometry>
            <material name="board_material">
                <color rgba="0 0.50196078431372548323 0 1.0"/>
            </material>
        </visual>
        <collision>
            <origin xyz="0.032049999999999356781 -0.03350000766000000435 -0.02004998738000049463" rpy="-3.141592653589793116 -1.5707963267948872321 0" />
            <geometry>
                <mesh filename="package:///board.stl"/>
            </geometry>
        </collision>
        <visual>
            <origin xyz="0.025500000000000022649 7.047314121155778821e-19 -0.0094499999999999931277" rpy="1.570796326794896558 1.9295584304788236679e-32 6.162975822058072259e-33" />
            <geometry>
                <mesh filename="package:///wj-wk00-0123middlecase_56.stl"/>
            </geometry>
            <material name="wj-wk00-0123middlecase_56_material">
                <color rgba="0.24705882352941177516 0.24313725490196078094 0.24313725490196078094 1.0"/>
            </material>
        </visual>
        <collision>
            <origin xyz="0.025500000000000022649 7.047314121155778821e-19 -0.0094499999999999931277" rpy="1.570796326794896558 1.9295584304788236679e-32 6.162975822058072259e-33" />
            <geometry>
                <mesh filename="package:///wj-wk00-0123middlecase_56.stl"/>
            </geometry>
        </collision>
        <visual>
            <origin xyz="0.025500000000000022649 7.047314121155778821e-19 -0.0094499999999999931277" rpy="1.570796326794896558 1.9295584304788236679e-32 6.162975822058072259e-33" />
            <geometry>
                <mesh filename="package:///drive_palonier.stl"/>
            </geometry>
            <material name="drive_palonier_material">
                <color rgba="0.62352941176470588758 0.66666666666666662966 0.70196078431372543882 1.0"/>
            </material>
        </visual>
        <collision>
            <origin xyz="0.025500000000000022649 7.047314121155778821e-19 -0.0094499999999999931277" rpy="1.570796326794896558 1.9295584304788236679e-32 6.162975822058072259e-33" />
            <geometry>
                <mesh filename="package:///drive_palonier.stl"/>
            </geometry>
        </collision>
        <visual>
            <origin xyz="0.025500000000000022649 7.047314121155778821e-19 -0.0094499999999999931277" rpy="1.570796326794896558 1.9295584304788236679e-32 6.162975822058072259e-33" />
            <geometry>
                <mesh filename="package:///wj-wk00-0124bottomcase_45.stl"/>
            </geometry>
            <material name="wj-wk00-0124bottomcase_45_material">
                <color rgba="0.24705882352941177516 0.24313725490196078094 0.24313725490196078094 1.0"/>
            </material>
        </visual>
        <collision>
            <origin xyz="0.025500000000000022649 7.047314121155778821e-19 -0.0094499999999999931277" rpy="1.570796326794896558 1.9295584304788236679e-32 6.162975822058072259e-33" />
            <geometry>
                <mesh filename="package:///wj-wk00-0124bottomcase_45.stl"/>
            </geometry>
        </collision>
        <visual>
            <origin xyz="0.025500000000000022649 7.047314121155778821e-19 -0.0094499999999999931277" rpy="1.570796326794896558 1.9295584304788236679e-32 6.162975822058072259e-33" />
            <geometry>
                <mesh filename="package:///wj-wk00-0122topcabinetcase_95.stl"/>
            </geometry>
            <material name="wj-wk00-0122topcabinetcase_95_material">
                <color rgba="0.24705882352941177516 0.24313725490196078094 0.24313725490196078094 1.0"/>
            </material>
        </visual>
        <collision>
            <origin xyz="0.025500000000000022649 7.047314121155778821e-19 -0.0094499999999999931277" rpy="1.570796326794896558 1.9295584304788236679e-32 6.162975822058072259e-33" />
            <geometry>
                <mesh filename="package:///wj-wk00-0122topcabinetcase_95.stl"/>
            </geometry>
        </collision>
        <visual>
            <origin xyz="0.025500000000000272449 1.8032992633865152499e-16 -0.00654999999999878596" rpy="1.570796326794896558 1.9295584304788236679e-32 6.162975822058072259e-33" />
            <geometry>
                <mesh filename="package:///passive_palonier.stl"/>
            </geometry>
            <material name="passive_palonier_material">
                <color rgba="0.62352941176470588758 0.66666666666666662966 0.70196078431372543882 1.0"/>
            </material>
        </visual>
        <collision>
            <origin xyz="0.025500000000000272449 1.8032992633865152499e-16 -0.00654999999999878596" rpy="1.570796326794896558 1.9295584304788236679e-32 6.162975822058072259e-33" />
            <geometry>
                <mesh filename="package:///passive_palonier.stl"/>
            </geometry>
        </collision>
        <inertial>
            <origin xyz="0.0065636512604166918905 0.00018736090796466511833 0.02611319932017273221" rpy="0 0 0"/>
            <mass value="0.33587292587593409188" />
            <inertia ixx="0.0019919122156102056671" ixy="-1.4254502711677873531e-06"  ixz="7.4912351122561775035e-05" iyy="0.0013798614573781989214" iyz="2.1090229113026565649e-06" izz="0.00088718283625004450317" />
        </inertial>
    </link>
    <link name="head">
        <inertial>
            <origin xyz="0 0 0" rpy="0 0 0" />
            <mass value="1e-9" />
            <inertia ixx="0" ixy="0" ixz="0" iyy="0" iyz="0" izz="0" />
        </inertial>
    </link>
    <joint name="head_frame" type="fixed">
        <origin xyz="0.042450000000000626121 -2.563053935755732482e-16 0.03595000000000117546" rpy="-1.2621774483535835759e-29 1.5707963267948756858 0" />
        <parent link="head_assembly" />
        <child link="head" />
        <axis xyz="0 0 0"/>
    </joint>
    <link name="left_antenna_holder">
        <visual>
            <origin xyz="0.07913918595530011757 -0.11097414404234534624 -0.079315037574384711361" rpy="-1.3234423712230736214 -0.26621715400617157465 -2.2550414098412094971e-17" />
            <geometry>
                <mesh filename="package:///antenna.stl"/>
            </geometry>
            <material name="antenna_material">
                <color rgba="0.64705882352941179736 0.64705882352941179736 0.64705882352941179736 1.0"/>
            </material>
        </visual>
        <collision>
            <origin xyz="0.07913918595530011757 -0.11097414404234534624 -0.079315037574384711361" rpy="-1.3234423712230736214 -0.26621715400617157465 -2.2550414098412094971e-17" />
            <geometry>
                <mesh filename="package:///antenna.stl"/>
            </geometry>
        </collision>
        <visual>
            <origin xyz="0.029698103650376481838 -0.11096188015593699827 0.10199385439751569582" rpy="-1.8181502823667210489 -0.26621715400617157465 -2.2550414098407321746e-17" />
            <geometry>
                <mesh filename="package:///left_antenna_holder.stl"/>
            </geometry>
            <material name="left_antenna_holder_material">
                <color rgba="0.98039215686274505668 0.71372549019607844922 0.0039215686274509803377 1.0"/>
            </material>
        </visual>
        <collision>
            <origin xyz="0.029698103650376481838 -0.11096188015593699827 0.10199385439751569582" rpy="-1.8181502823667210489 -0.26621715400617157465 -2.2550414098407321746e-17" />
            <geometry>
                <mesh filename="package:///left_antenna_holder.stl"/>
            </geometry>
        </collision>
        <inertial>
            <origin xyz="-0.004939854821498559749 0.00813032209147374757 -0.0023337426173885011949" rpy="0 0 0"/>
            <mass value="0.00421628909577088061" />
            <inertia ixx="3.5881972229367939723e-06" ixy="-1.6933723332352309702e-07"  ixz="1.5481705881245182829e-09" iyy="2.5430131672962703725e-07" iyz="3.9979038225552031766e-08" izz="3.8079123149072294472e-06" />
        </inertial>
    </link>
    <joint name="left_antenna" type="revolute">
        <origin xyz="0.00070406945503787010665 0.060662837687360374184 0.11643485329544565887" rpy="3.1415926535897309435 1.3045791727887228184 1.3234423712230789505" />
        <parent link="head_assembly" />
        <child link="left_antenna_holder" />
        <axis xyz="0 0 1"/>
        <limit effort="1" velocity="20" lower="-1.570796326794896558" upper="1.570796326794896558"/>
        <joint_properties friction="0.0"/>
    </joint>
    <link name="right_antenna_holder">
        <visual>
            <origin xyz="0.029698103650376474899 0.11096188015593705378 0.10199385439751573745" rpy="1.8181502823667212709 -0.26621715400617168568 -1.1402457340383256411e-17" />
            <geometry>
                <mesh filename="package:///right_antenna_holder.stl"/>
            </geometry>
            <material name="right_antenna_holder_material">
                <color rgba="0.98039215686274505668 0.71372549019607844922 0.0039215686274509803377 1.0"/>
            </material>
        </visual>
        <collision>
            <origin xyz="0.029698103650376474899 0.11096188015593705378 0.10199385439751573745" rpy="1.8181502823667212709 -0.26621715400617168568 -1.1402457340383256411e-17" />
            <geometry>
                <mesh filename="package:///right_antenna_holder.stl"/>
            </geometry>
        </collision>
        <visual>
            <origin xyz="0.029698103650378115947 0.10995093695903201958 0.10199385439751602889" rpy="1.8181502823667219371 -0.26621715400617174119 -1.1402457340385508979e-17" />
            <geometry>
                <mesh filename="package:///antenna.stl"/>
            </geometry>
            <material name="antenna_material">
                <color rgba="0.64705882352941179736 0.64705882352941179736 0.64705882352941179736 1.0"/>
            </material>
        </visual>
        <collision>
            <origin xyz="0.029698103650378115947 0.10995093695903201958 0.10199385439751602889" rpy="1.8181502823667219371 -0.26621715400617174119 -1.1402457340385508979e-17" />
            <geometry>
                <mesh filename="package:///antenna.stl"/>
            </geometry>
        </collision>
        <inertial>
            <origin xyz="-0.004939857160886270207 -0.0082621254299192325304 -0.0023337411215750107629" rpy="0 0 0"/>
            <mass value="0.004216286984950681424" />
            <inertia ixx="3.6498064950645580265e-06" ixy="1.7208228546031893699e-07"  ixz="1.548144005457831799e-09" iyy="2.5430123930068604413e-07" iyz="-4.0627217574810325721e-08" izz="3.8695215401713841644e-06" />
        </inertial>
    </link>
    <joint name="right_antenna" type="revolute">
        <origin xyz="0.00070406945503653783902 -0.060662837687360852967 0.11643485329544586704" rpy="-3.1415926535897518157 1.3045791727887290357 -1.3234423712230898307" />
        <parent link="head_assembly" />
        <child link="right_antenna_holder" />
        <axis xyz="0 0 1"/>
        <limit effort="1" velocity="20" lower="-1.570796326794896558" upper="1.570796326794896558"/>
        <joint_properties friction="0.0"/>
    </joint>
    <joint name="head_roll" type="revolute">
        <origin xyz="0.040950000000000402745 1.1462727468602995629e-16 -0.019150000000000444444" rpy="-2.4980018054066286428e-15 -1.5707963267948730213 0" />
        <parent link="neck_yaw_assembly" />
        <child link="head_assembly" />
        <axis xyz="0 0 1"/>
        <limit effort="1" velocity="20" lower="-0.52359877559829881566" upper="0.52359877559829881566"/>
        <joint_properties friction="0.0"/>
    </joint>
    <joint name="head_yaw" type="revolute">
        <origin xyz="-1.5178830414797062076e-17 0.056999999999999939604 0.019049999999999959327" rpy="-1.570796326794896558 -7.286368982477690022e-17 -5.2678381782433861865e-15" />
        <parent link="head_pitch_to_yaw" />
        <child link="neck_yaw_assembly" />
        <axis xyz="0 0 1"/>
        <limit effort="1" velocity="20" lower="-2.7925268031909271649" upper="2.7925268031909271649"/>
        <joint_properties friction="0.0"/>
    </joint>
    <joint name="head_pitch" type="revolute">
        <origin xyz="-5.6378512969246230568e-18 0.066000000000000003109 -6.9388939039072283776e-18" rpy="5.9571514509304171254e-17 -7.163548953726033378e-17 1.6653345369378257762e-16" />
        <parent link="neck_pitch_assembly" />
        <child link="head_pitch_to_yaw" />
        <axis xyz="0 0 1"/>
        <limit effort="1" velocity="20" lower="-0.785398163397448279" upper="0.785398163397448279"/>
        <joint_properties friction="0.0"/>
    </joint>
    <joint name="neck_pitch" type="revolute">
        <origin xyz="0.00099999999999897046243 0.019150000000000326483 0.090000938812376238274" rpy="1.57079632679489678 -2.2148949341271863515e-14 2.5552148182455563673e-16" />
        <parent link="trunk_assembly" />
        <child link="neck_pitch_assembly" />
        <axis xyz="0 0 1"/>
        <limit effort="1" velocity="20" lower="-0.34906585039886589561" upper="1.1344640137963142301"/>
        <joint_properties friction="0.0"/>
    </joint>
</robot>