<mujoco model="onshape">
  <compiler angle="radian"/>
  <asset>
    <mesh name="body_front" file="body_front.stl"/>
    <mesh name="body_back" file="body_back.stl"/>
    <mesh name="body_middle_bottom" file="body_middle_bottom.stl"/>
    <mesh name="body_middle_top" file="body_middle_top.stl"/>
    <mesh name="roll_bearing" file="roll_bearing.stl"/>
    <mesh name="trunk_bottom" file="trunk_bottom.stl"/>
    <mesh name="trunk_top" file="trunk_top.stl"/>
    <mesh name="wj-wk00-0123middlecase_56" file="wj-wk00-0123middlecase_56.stl"/>
    <mesh name="drive_palonier" file="drive_palonier.stl"/>
    <mesh name="wj-wk00-0124bottomcase_45" file="wj-wk00-0124bottomcase_45.stl"/>
    <mesh name="wj-wk00-0122topcabinetcase_95" file="wj-wk00-0122topcabinetcase_95.stl"/>
    <mesh name="passive_palonier" file="passive_palonier.stl"/>
    <mesh name="roll_motor_bottom" file="roll_motor_bottom.stl"/>
    <mesh name="roll_motor_top" file="roll_motor_top.stl"/>
    <mesh name="left_roll_to_pitch" file="left_roll_to_pitch.stl"/>
    <mesh name="left_cache" file="left_cache.stl"/>
    <mesh name="leg_spacer" file="leg_spacer.stl"/>
    <mesh name="left_knee_to_ankle_right_sheet" file="left_knee_to_ankle_right_sheet.stl"/>
    <mesh name="left_knee_to_ankle_left_sheet" file="left_knee_to_ankle_left_sheet.stl"/>
    <mesh name="foot_side" file="foot_side.stl"/>
    <mesh name="foot_bottom" file="foot_bottom.stl"/>
    <mesh name="foot_top" file="foot_top.stl"/>
    <mesh name="right_roll_to_pitch" file="right_roll_to_pitch.stl"/>
    <mesh name="right_cache" file="right_cache.stl"/>
    <mesh name="neck_left_sheet" file="neck_left_sheet.stl"/>
    <mesh name="neck_right_sheet" file="neck_right_sheet.stl"/>
    <mesh name="head_pitch_to_yaw" file="head_pitch_to_yaw.stl"/>
    <mesh name="head_bot_sheet" file="head_bot_sheet.stl"/>
    <mesh name="head" file="head.stl"/>
  </asset>
  <default>
    <!-- TODO tune damping, frictionloss and kp -->
    <!-- <geom contype="1" conaffinity="1" solref=".004 1" /> -->
    <geom contype="1" conaffinity="1"/>
    <!-- <joint damping="0.095" frictionloss="0.058" armature="0.0018"/>
    <position kp="2.54" kv="0.0" forcerange="-2 2"/> -->
    <joint damping="1.44" frictionloss="0.19" armature="0.012"/>
    <position kp="19.6" kv="0.0" forcerange="-3.69 3.69"/>
  </default>
  <contact>
    <exclude name="exclude1" body1="trunk_assembly" body2="neck_assembly"/>
    <exclude name="exclude2" body1="trunk_assembly" body2="hip_roll_assembly"/>
    <exclude name="exclude3" body1="trunk_assembly" body2="hip_roll_assembly_2"/>
    <exclude name="exclude4" body1="hip_roll_assembly" body2="left_roll_to_pitch_assembly"/>
    <exclude name="exclude5" body1="hip_roll_assembly_2" body2="right_roll_to_pitch_assembly"/>
    <exclude name="exclude6" body1="trunk_assembly" body2="left_roll_to_pitch_assembly"/>
    <exclude name="exclude7" body1="trunk_assembly" body2="right_roll_to_pitch_assembly"/>
  </contact>
  <worldbody>
    <body name="base" pos="0 0 0.22">
    <!-- <body name="base" pos="0 0 0.3"> -->
      <freejoint />
      <body name="trunk_assembly">
        <inertial pos="-0.0647728 -0.00628649 0.0188402" quat="0.392123 0.586953 0.590825 0.390706" mass="0.559221" diaginertia="0.00225663 0.0018353 0.00157712"/>
        <geom pos="-0.0559808 -0.00639723 0.0433406" quat="0.99994 0 0.0109126 0" type="mesh" rgba="0.917647 0.917647 0.917647 1" mesh="body_front"/>
        <geom pos="-0.0559808 -0.00639723 0.0433406" quat="0.99994 0 0.0109126 0" type="mesh" rgba="0.917647 0.917647 0.917647 1" mesh="body_back"/>
        <geom pos="-0.0559808 -0.00639723 0.0433406" quat="0.99994 0 0.0109126 0" type="mesh" rgba="0.917647 0.917647 0.917647 1" mesh="body_middle_bottom"/>
        <geom pos="-0.0559808 -0.00639723 0.0433406" quat="0.99994 0 0.0109126 0" type="mesh" rgba="0.917647 0.917647 0.917647 1" mesh="body_middle_top"/>
        <geom pos="-0.0559808 -0.00639723 0.0433406" quat="0.99994 0 0.0109126 0" type="mesh" rgba="0.6 0.6 0.6 1" mesh="roll_bearing"/>
        <geom pos="-0.0559808 -0.00639723 0.0433406" quat="0.99994 0 0.0109126 0" type="mesh" rgba="0.180392 0.180392 0.180392 1" mesh="trunk_bottom"/>
        <geom pos="-0.0559808 -0.00639723 0.0433406" quat="0.99994 0 0.0109126 0" type="mesh" rgba="0.180392 0.180392 0.180392 1" mesh="trunk_top"/>
        <geom pos="-0.0559808 -0.0763972 0.0433406" quat="0.99994 0 0.0109126 0" type="mesh" rgba="0.6 0.6 0.6 1" mesh="roll_bearing"/>
        <geom pos="-0.035994 0.00330277 0.0425142" quat="0.699348 0 0.714781 0" type="mesh" rgba="0.247059 0.243137 0.243137 1" mesh="wj-wk00-0123middlecase_56"/>
        <geom pos="-0.035994 0.00330277 0.0425142" quat="0.699348 0 0.714781 0" type="mesh" rgba="0.623529 0.666667 0.701961 1" mesh="drive_palonier"/>
        <geom pos="-0.035994 0.00330277 0.0425142" quat="0.699348 0 0.714781 0" type="mesh" rgba="0.247059 0.243137 0.243137 1" mesh="wj-wk00-0124bottomcase_45"/>
        <geom pos="-0.035994 0.00330277 0.0425142" quat="0.699348 0 0.714781 0" type="mesh" rgba="0.247059 0.243137 0.243137 1" mesh="wj-wk00-0122topcabinetcase_95"/>
        <geom pos="-0.035994 0.00620277 0.0425142" quat="0.699348 0 0.714781 0" type="mesh" rgba="0.623529 0.666667 0.701961 1" mesh="passive_palonier"/>
        <geom pos="-0.081682 -0.0413972 0.0343993" quat="-0.00771637 -0.00771637 0.707065 -0.707065" type="mesh" rgba="0.247059 0.243137 0.243137 1" mesh="wj-wk00-0123middlecase_56"/>
        <geom pos="-0.081682 -0.0413972 0.0343993" quat="-0.00771637 -0.00771637 0.707065 -0.707065" type="mesh" rgba="0.623529 0.666667 0.701961 1" mesh="drive_palonier"/>
        <geom pos="-0.081682 -0.0413972 0.0343993" quat="-0.00771637 -0.00771637 0.707065 -0.707065" type="mesh" rgba="0.247059 0.243137 0.243137 1" mesh="wj-wk00-0124bottomcase_45"/>
        <geom pos="-0.081682 -0.0413972 0.0343993" quat="-0.00771637 -0.00771637 0.707065 -0.707065" type="mesh" rgba="0.247059 0.243137 0.243137 1" mesh="wj-wk00-0122topcabinetcase_95"/>
        <geom pos="-0.0817453 -0.0413972 0.0315" quat="-0.00771637 -0.00771637 0.707065 -0.707065" type="mesh" rgba="0.623529 0.666667 0.701961 1" mesh="passive_palonier"/>
        <geom pos="-0.081682 0.0286028 0.0343993" quat="-0.00771637 -0.00771637 0.707065 -0.707065" type="mesh" rgba="0.247059 0.243137 0.243137 1" mesh="wj-wk00-0123middlecase_56"/>
        <geom pos="-0.081682 0.0286028 0.0343993" quat="-0.00771637 -0.00771637 0.707065 -0.707065" type="mesh" rgba="0.623529 0.666667 0.701961 1" mesh="drive_palonier"/>
        <geom pos="-0.081682 0.0286028 0.0343993" quat="-0.00771637 -0.00771637 0.707065 -0.707065" type="mesh" rgba="0.247059 0.243137 0.243137 1" mesh="wj-wk00-0124bottomcase_45"/>
        <geom pos="-0.081682 0.0286028 0.0343993" quat="-0.00771637 -0.00771637 0.707065 -0.707065" type="mesh" rgba="0.247059 0.243137 0.243137 1" mesh="wj-wk00-0122topcabinetcase_95"/>
        <geom pos="-0.0817453 0.0286028 0.0315" quat="-0.00771637 -0.00771637 0.707065 -0.707065" type="mesh" rgba="0.623529 0.666667 0.701961 1" mesh="passive_palonier"/>
        <body name="trunk" pos="-0.0604711 -0.00639723 0.0667441" quat="0.99994 0 0.0109126 0">
          <inertial pos="0 0 0" mass="1e-09" diaginertia="0 0 0"/>
        </body>
        <body name="hip_roll_assembly" pos="-0.0563943 0.0286028 0.0243951" quat="0.99994 0 0.0109126 0">
          <inertial pos="0.000819684 -1.3291e-05 -0.0333601" quat="0.70723 0.0121578 0.0131239 0.706757" mass="0.06648" diaginertia="2.87887e-05 2.49916e-05 1.40679e-05"/>
          <joint name="left_hip_yaw" pos="0 0 0" axis="0 0 1" range="-0.523599 0.523599" />
          <geom pos="0 -0.0351098 0.01905" quat="1 0 0 0" type="mesh" rgba="0.647059 0.647059 0.647059 1" mesh="roll_motor_bottom"/>
          <geom pos="0 -0.035 0.01905" type="mesh" rgba="0.901961 0.901961 0.901961 1" mesh="roll_motor_top"/>
          <geom pos="0.0096 0 -0.020515" quat="0.5 -0.5 -0.5 -0.5" type="mesh" rgba="0.247059 0.243137 0.243137 1" mesh="wj-wk00-0123middlecase_56"/>
          <geom pos="0.0096 0 -0.020515" quat="0.5 -0.5 -0.5 -0.5" type="mesh" rgba="0.623529 0.666667 0.701961 1" mesh="drive_palonier"/>
          <geom pos="0.0096 0 -0.020515" quat="0.5 -0.5 -0.5 -0.5" type="mesh" rgba="0.247059 0.243137 0.243137 1" mesh="wj-wk00-0124bottomcase_45"/>
          <geom pos="0.0096 0 -0.020515" quat="0.5 -0.5 -0.5 -0.5" type="mesh" rgba="0.247059 0.243137 0.243137 1" mesh="wj-wk00-0122topcabinetcase_95"/>
          <geom pos="0.0125 0 -0.020515" quat="0.5 -0.5 -0.5 -0.5" type="mesh" rgba="0.623529 0.666667 0.701961 1" mesh="passive_palonier"/>
          <body name="left_roll_to_pitch_assembly" pos="0.01905 0 -0.046015" quat="0.5 -0.5 -0.5 0.5">
            <inertial pos="0.050854 -0.00041792 0.0205386" quat="0.533258 0.468566 0.469437 0.525082" mass="0.07516" diaginertia="4.13536e-05 2.81572e-05 2.51419e-05"/>
            <joint name="left_hip_roll" pos="0 0 0" axis="0 0 1" range="-0.436332 0.436332" />
            <geom pos="-0.035 -0.065 0.01905" quat="0.5 0.5 0.5 -0.5" type="mesh" rgba="0.909804 0.572549 0.164706 1" mesh="left_roll_to_pitch"/>
            <geom pos="0.0647 0 0.00961" quat="0.5 0.5 0.5 -0.5" type="mesh" rgba="0.247059 0.243137 0.243137 1" mesh="wj-wk00-0123middlecase_56"/>
            <geom pos="0.0647 0 0.00961" quat="0.5 0.5 0.5 -0.5" type="mesh" rgba="0.623529 0.666667 0.701961 1" mesh="drive_palonier"/>
            <geom pos="0.0647 0 0.00961" quat="0.5 0.5 0.5 -0.5" type="mesh" rgba="0.247059 0.243137 0.243137 1" mesh="wj-wk00-0124bottomcase_45"/>
            <geom pos="0.0647 0 0.00961" quat="0.5 0.5 0.5 -0.5" type="mesh" rgba="0.247059 0.243137 0.243137 1" mesh="wj-wk00-0122topcabinetcase_95"/>
            <geom pos="0.0676 0 0.00961" quat="0.5 0.5 0.5 -0.5" type="mesh" rgba="0.623529 0.666667 0.701961 1" mesh="passive_palonier"/>
            <body name="knee_and_ankle_assembly" pos="0.07415 0 0.03511" quat="0 0.707107 0 -0.707107">
              <inertial pos="0.000560479 -0.0396129 0.0109583" quat="0.543489 0.427268 -0.507961 0.513846" mass="0.12407" diaginertia="0.000220017 0.000207378 6.90532e-05"/>
              <joint name="left_hip_pitch" pos="0 0 0" axis="0 0 1" range="-1.5708 0.523599" />
              <geom pos="0.01606 0.065 0.11065" quat="0.707107 -0.707107 0 0" type="mesh" rgba="0.917647 0.917647 0.917647 1" mesh="left_cache"/>
              <geom pos="0.01606 0.14365 0.10925" quat="0.707107 -0.707107 0 0" type="mesh" rgba="0.647059 0.647059 0.647059 1" mesh="leg_spacer"/>
              <geom pos="0.01606 0.14365 0.10915" quat="0.707107 -0.707107 0 0" type="mesh" rgba="0.223529 0.219608 0.219608 1" mesh="left_knee_to_ankle_right_sheet"/>
              <geom pos="0.01606 0.14365 0.10915" quat="0.707107 -0.707107 0 0" type="mesh" rgba="0.223529 0.219608 0.219608 1" mesh="left_knee_to_ankle_left_sheet"/>
              <geom pos="0 -0.05315 0.00955" quat="0.5 -0.5 -0.5 0.5" type="mesh" rgba="0.247059 0.243137 0.243137 1" mesh="wj-wk00-0123middlecase_56"/>
              <geom pos="0 -0.05315 0.00955" quat="0.5 -0.5 -0.5 0.5" type="mesh" rgba="0.623529 0.666667 0.701961 1" mesh="drive_palonier"/>
              <geom pos="0 -0.05315 0.00955" quat="0.5 -0.5 -0.5 0.5" type="mesh" rgba="0.247059 0.243137 0.243137 1" mesh="wj-wk00-0124bottomcase_45"/>
              <geom pos="0 -0.05315 0.00955" quat="0.5 -0.5 -0.5 0.5" type="mesh" rgba="0.247059 0.243137 0.243137 1" mesh="wj-wk00-0122topcabinetcase_95"/>
              <geom pos="0 -0.05315 0.00665" quat="0.5 -0.5 -0.5 0.5" type="mesh" rgba="0.623529 0.666667 0.701961 1" mesh="passive_palonier"/>
              <body name="knee_and_ankle_assembly_2" pos="0 -0.07865 0.0001" quat="1 0 0 0">
                <inertial pos="5.0186e-06 -0.0576779 0.0181154" quat="0.708351 0.705861 1.00924e-05 0.000223072" mass="0.07259" diaginertia="5.02829e-05 4.26981e-05 1.86965e-05"/>
                <joint name="left_knee" pos="0 0 0" axis="0 0 1" range="-1.5708 1.5708" />
                <geom pos="0.01606 0.14365 0.10925" quat="0.707107 -0.707107 0 0" type="mesh" rgba="0.647059 0.647059 0.647059 1" mesh="leg_spacer"/>
                <geom pos="0.01606 0.14365 0.10915" quat="0.707107 -0.707107 0 0" type="mesh" rgba="0.223529 0.219608 0.219608 1" mesh="left_knee_to_ankle_right_sheet"/>
                <geom pos="0.01606 0.14365 0.10915" quat="0.707107 -0.707107 0 0" type="mesh" rgba="0.223529 0.219608 0.219608 1" mesh="left_knee_to_ankle_left_sheet"/>
                <geom pos="0 -0.05315 0.00955" quat="0.5 -0.5 -0.5 0.5" type="mesh" rgba="0.247059 0.243137 0.243137 1" mesh="wj-wk00-0123middlecase_56"/>
                <geom pos="0 -0.05315 0.00955" quat="0.5 -0.5 -0.5 0.5" type="mesh" rgba="0.623529 0.666667 0.701961 1" mesh="drive_palonier"/>
                <geom pos="0 -0.05315 0.00955" quat="0.5 -0.5 -0.5 0.5" type="mesh" rgba="0.247059 0.243137 0.243137 1" mesh="wj-wk00-0124bottomcase_45"/>
                <geom pos="0 -0.05315 0.00955" quat="0.5 -0.5 -0.5 0.5" type="mesh" rgba="0.247059 0.243137 0.243137 1" mesh="wj-wk00-0122topcabinetcase_95"/>
                <geom pos="0 -0.05315 0.00665" quat="0.5 -0.5 -0.5 0.5" type="mesh" rgba="0.623529 0.666667 0.701961 1" mesh="passive_palonier"/>
                <body name="foot_assembly" pos="0 -0.07865 0.0001" quat="1 0 0 0">
                  <inertial pos="0.0107495 -0.0231588 0.0187619" quat="0.511091 0.506972 0.493063 0.488523" mass="0.05624" diaginertia="5.30921e-05 4.67536e-05 1.66117e-05"/>
                  <joint name="left_ankle" pos="0 0 0" axis="0 0 1" range="-1.5708 1.5708" />
                  <geom pos="0.01606 0.2223 0.10905" quat="0.707107 -0.707107 0 0" type="mesh" rgba="0.980392 0.713726 0.00392157 1" mesh="foot_side"/>
                  <geom pos="0.01606 0.2223 0.10905" quat="0.707107 -0.707107 0 0" type="mesh" rgba="0.305882 0.298039 0.278431 1" mesh="foot_bottom"/>
                  <geom pos="0.01606 0.2223 0.10905" quat="0.707107 -0.707107 0 0" type="mesh" rgba="0.980392 0.713726 0.00392157 1" mesh="foot_top"/>
                  <body name="left_foot" pos="0 -0.036725 0.01905" quat="0.707107 -0.707107 0 0">
                    <inertial pos="0 0 0" mass="1e-09" diaginertia="0 0 0"/>
                  </body>
                </body>
              </body>
            </body>
          </body>
        </body>
        <body name="hip_roll_assembly_2" pos="-0.0563943 -0.0413972 0.0243951" quat="0.99994 0 0.0109126 0">
          <inertial pos="0.000819684 -1.3291e-05 -0.0333601" quat="0.70723 0.0121578 0.0131239 0.706757" mass="0.06648" diaginertia="2.87887e-05 2.49916e-05 1.40679e-05"/>
          <joint name="right_hip_yaw" pos="0 0 0" axis="0 0 1" range="-0.523599 0.523599" />
          <geom pos="0 -0.0351098 0.01905" quat="1 0 0 0" type="mesh" rgba="0.647059 0.647059 0.647059 1" mesh="roll_motor_bottom"/>
          <geom pos="0 -0.035 0.01905" type="mesh" rgba="0.901961 0.901961 0.901961 1" mesh="roll_motor_top"/>
          <geom pos="0.0096 0 -0.020515" quat="0.5 -0.5 -0.5 -0.5" type="mesh" rgba="0.247059 0.243137 0.243137 1" mesh="wj-wk00-0123middlecase_56"/>
          <geom pos="0.0096 0 -0.020515" quat="0.5 -0.5 -0.5 -0.5" type="mesh" rgba="0.623529 0.666667 0.701961 1" mesh="drive_palonier"/>
          <geom pos="0.0096 0 -0.020515" quat="0.5 -0.5 -0.5 -0.5" type="mesh" rgba="0.247059 0.243137 0.243137 1" mesh="wj-wk00-0124bottomcase_45"/>
          <geom pos="0.0096 0 -0.020515" quat="0.5 -0.5 -0.5 -0.5" type="mesh" rgba="0.247059 0.243137 0.243137 1" mesh="wj-wk00-0122topcabinetcase_95"/>
          <geom pos="0.0125 0 -0.020515" quat="0.5 -0.5 -0.5 -0.5" type="mesh" rgba="0.623529 0.666667 0.701961 1" mesh="passive_palonier"/>
          <body name="right_roll_to_pitch_assembly" pos="0.01905 0 -0.046015" quat="0.5 -0.5 -0.5 0.5">
            <inertial pos="-0.050854 -0.000427613 0.0205386" quat="0.469 0.52524 0.533108 0.468997" mass="0.07516" diaginertia="4.13534e-05 2.81568e-05 2.51412e-05"/>
            <joint name="right_hip_roll" pos="0 0 0" axis="0 0 1" range="-0.436332 0.436332" />
            <geom pos="0.035 -0.065 0.01905" quat="0.5 0.5 0.5 -0.5" type="mesh" rgba="0.909804 0.572549 0.164706 1" mesh="right_roll_to_pitch"/>
            <geom pos="-0.0647 0 0.00961" quat="0.5 -0.5 0.5 0.5" type="mesh" rgba="0.247059 0.243137 0.243137 1" mesh="wj-wk00-0123middlecase_56"/>
            <geom pos="-0.0647 0 0.00961" quat="0.5 -0.5 0.5 0.5" type="mesh" rgba="0.623529 0.666667 0.701961 1" mesh="drive_palonier"/>
            <geom pos="-0.0647 0 0.00961" quat="0.5 -0.5 0.5 0.5" type="mesh" rgba="0.247059 0.243137 0.243137 1" mesh="wj-wk00-0124bottomcase_45"/>
            <geom pos="-0.0647 0 0.00961" quat="0.5 -0.5 0.5 0.5" type="mesh" rgba="0.247059 0.243137 0.243137 1" mesh="wj-wk00-0122topcabinetcase_95"/>
            <geom pos="-0.0676 0 0.00961" quat="0.5 -0.5 0.5 0.5" type="mesh" rgba="0.623529 0.666667 0.701961 1" mesh="passive_palonier"/>
            <body name="knee_and_ankle_assembly_3" pos="-0.07415 0 0.03511" quat="0.707107 0 0.707107 0">
              <inertial pos="0.000560479 0.0396129 0.0114877" quat="0.423393 0.542655 -0.517855 0.508025" mass="0.12407" diaginertia="0.000220261 0.000208238 6.9693e-05"/>
              <joint name="right_hip_pitch" pos="0 0 0" axis="0 0 1" range="-0.523599 1.5708" />
              <geom pos="0.01606 -0.065 0.1107" quat="0.707107 0.707107 0 0" type="mesh" rgba="0.917647 0.917647 0.917647 1" mesh="right_cache"/>
              <geom pos="0.01606 -0.14365 -0.07215" quat="0.707107 0.707107 0 0" type="mesh" rgba="0.647059 0.647059 0.647059 1" mesh="leg_spacer"/>
              <geom pos="0.01606 -0.14365 -0.07205" quat="0.707107 0.707107 0 0" type="mesh" rgba="0.223529 0.219608 0.219608 1" mesh="left_knee_to_ankle_right_sheet"/>
              <geom pos="0.01606 -0.14365 -0.07205" quat="0.707107 0.707107 0 0" type="mesh" rgba="0.223529 0.219608 0.219608 1" mesh="left_knee_to_ankle_left_sheet"/>
              <geom pos="0 0.05315 0.02755" quat="0.5 0.5 -0.5 -0.5" type="mesh" rgba="0.247059 0.243137 0.243137 1" mesh="wj-wk00-0123middlecase_56"/>
              <geom pos="0 0.05315 0.02755" quat="0.5 0.5 -0.5 -0.5" type="mesh" rgba="0.623529 0.666667 0.701961 1" mesh="drive_palonier"/>
              <geom pos="0 0.05315 0.02755" quat="0.5 0.5 -0.5 -0.5" type="mesh" rgba="0.247059 0.243137 0.243137 1" mesh="wj-wk00-0124bottomcase_45"/>
              <geom pos="0 0.05315 0.02755" quat="0.5 0.5 -0.5 -0.5" type="mesh" rgba="0.247059 0.243137 0.243137 1" mesh="wj-wk00-0122topcabinetcase_95"/>
              <geom pos="0 0.05315 0.03045" quat="0.5 0.5 -0.5 -0.5" type="mesh" rgba="0.623529 0.666667 0.701961 1" mesh="passive_palonier"/>
              <body name="knee_and_ankle_assembly_4" pos="0 0.07865 0.037" quat="0 1 0 0">
                <inertial pos="5.0186e-06 -0.0576779 0.0181154" quat="0.708351 0.705861 1.00924e-05 0.000223072" mass="0.07259" diaginertia="5.02829e-05 4.26981e-05 1.86965e-05"/>
                <joint name="right_knee" pos="0 0 0" axis="0 0 1" range="-1.5708 1.5708" />
                <geom pos="0.01606 0.14365 0.10925" quat="0.707107 -0.707107 0 0" type="mesh" rgba="0.647059 0.647059 0.647059 1" mesh="leg_spacer"/>
                <geom pos="0.01606 0.14365 0.10915" quat="0.707107 -0.707107 0 0" type="mesh" rgba="0.223529 0.219608 0.219608 1" mesh="left_knee_to_ankle_right_sheet"/>
                <geom pos="0.01606 0.14365 0.10915" quat="0.707107 -0.707107 0 0" type="mesh" rgba="0.223529 0.219608 0.219608 1" mesh="left_knee_to_ankle_left_sheet"/>
                <geom pos="0 -0.05315 0.00955" quat="0.5 -0.5 -0.5 0.5" type="mesh" rgba="0.247059 0.243137 0.243137 1" mesh="wj-wk00-0123middlecase_56"/>
                <geom pos="0 -0.05315 0.00955" quat="0.5 -0.5 -0.5 0.5" type="mesh" rgba="0.623529 0.666667 0.701961 1" mesh="drive_palonier"/>
                <geom pos="0 -0.05315 0.00955" quat="0.5 -0.5 -0.5 0.5" type="mesh" rgba="0.247059 0.243137 0.243137 1" mesh="wj-wk00-0124bottomcase_45"/>
                <geom pos="0 -0.05315 0.00955" quat="0.5 -0.5 -0.5 0.5" type="mesh" rgba="0.247059 0.243137 0.243137 1" mesh="wj-wk00-0122topcabinetcase_95"/>
                <geom pos="0 -0.05315 0.00665" quat="0.5 -0.5 -0.5 0.5" type="mesh" rgba="0.623529 0.666667 0.701961 1" mesh="passive_palonier"/>
                <body name="foot_assembly_2" pos="0 -0.07865 0.0001" quat="1 0 0 0">
                  <inertial pos="0.0107495 -0.0231588 0.0187619" quat="0.511091 0.506972 0.493063 0.488523" mass="0.05624" diaginertia="5.30921e-05 4.67536e-05 1.66117e-05"/>
                  <joint name="right_ankle" pos="0 0 0" axis="0 0 1" range="-1.5708 1.5708" />
                  <geom pos="0.01606 0.2223 0.10905" quat="0.707107 -0.707107 0 0" type="mesh" rgba="0.980392 0.713726 0.00392157 1" mesh="foot_side"/>
                  <geom pos="0.01606 0.2223 0.10905" quat="0.707107 -0.707107 0 0" type="mesh" rgba="0.305882 0.298039 0.278431 1" mesh="foot_bottom"/>
                  <geom pos="0.01606 0.2223 0.10905" quat="0.707107 -0.707107 0 0" type="mesh" rgba="0.980392 0.713726 0.00392157 1" mesh="foot_top"/>
                  <body name="right_foot" pos="0 -0.036725 0.01905" quat="0.707107 -0.707107 0 0">
                    <inertial pos="0 0 0" mass="1e-09" diaginertia="0 0 0"/>
                  </body>
                </body>
              </body>
            </body>
          </body>
        </body>
        <body name="neck_assembly" pos="-0.0354375 0.0127528 0.0680081" quat="0.707065 0.707065 0.00771637 -0.00771637">
          <inertial pos="-5.63233e-06 0.0492189 0.0181786" quat="0.706802 0.707411 0.000279897 6.02133e-05" mass="0.06618" diaginertia="3.5272e-05 2.83168e-05 1.70072e-05"/>
          <joint name="neck_pitch" pos="0 0 0" axis="0 0 1" range="-0.349066 1.13446" />
          <geom pos="-0.02 -0.02511 0.01905" quat="0.707107 -0.707107 0 0" type="mesh" rgba="0.223529 0.219608 0.219608 1" mesh="neck_left_sheet"/>
          <geom pos="-0.02 -0.02511 0.01905" quat="0.707107 -0.707107 0 0" type="mesh" rgba="0.223529 0.219608 0.219608 1" mesh="neck_right_sheet"/>
          <geom pos="0 0.0405 0.00945" quat="0.5 -0.5 0.5 -0.5" type="mesh" rgba="0.247059 0.243137 0.243137 1" mesh="wj-wk00-0123middlecase_56"/>
          <geom pos="0 0.0405 0.00945" quat="0.5 -0.5 0.5 -0.5" type="mesh" rgba="0.623529 0.666667 0.701961 1" mesh="drive_palonier"/>
          <geom pos="0 0.0405 0.00945" quat="0.5 -0.5 0.5 -0.5" type="mesh" rgba="0.247059 0.243137 0.243137 1" mesh="wj-wk00-0124bottomcase_45"/>
          <geom pos="0 0.0405 0.00945" quat="0.5 -0.5 0.5 -0.5" type="mesh" rgba="0.247059 0.243137 0.243137 1" mesh="wj-wk00-0122topcabinetcase_95"/>
          <geom pos="0 0.0405 0.00655" quat="0.5 -0.5 0.5 -0.5" type="mesh" rgba="0.623529 0.666667 0.701961 1" mesh="passive_palonier"/>
          <body name="head_pitch_assembly" pos="0 0.066 0">
            <inertial pos="-0.0113112 0.0347198 0.0188396" quat="0.0951082 0.697009 -0.132821 0.698206" mass="0.07185" diaginertia="2.92018e-05 2.58493e-05 2.16918e-05"/>
            <joint name="head_pitch" pos="0 0 0" axis="0 0 1" range="-1.5708 1.5708" />
            <geom pos="-0.02 -0.09111 0.01905" quat="0.707107 -0.707107 0 0" type="mesh" rgba="0.972549 0.529412 0.00392157 1" mesh="head_pitch_to_yaw"/>
            <geom pos="-0.0255 0.04745 0.01905" quat="0 0 1 0" type="mesh" rgba="0.247059 0.243137 0.243137 1" mesh="wj-wk00-0123middlecase_56"/>
            <geom pos="-0.0255 0.04745 0.01905" quat="0 0 1 0" type="mesh" rgba="0.623529 0.666667 0.701961 1" mesh="drive_palonier"/>
            <geom pos="-0.0255 0.04745 0.01905" quat="0 0 1 0" type="mesh" rgba="0.247059 0.243137 0.243137 1" mesh="wj-wk00-0124bottomcase_45"/>
            <geom pos="-0.0255 0.04745 0.01905" quat="0 0 1 0" type="mesh" rgba="0.247059 0.243137 0.243137 1" mesh="wj-wk00-0122topcabinetcase_95"/>
            <geom pos="-0.0255 0.05035 0.01905" quat="0 0 1 0" type="mesh" rgba="0.623529 0.666667 0.701961 1" mesh="passive_palonier"/>
            <body name="head_assembly" pos="0 0.0569 0.01905" quat="0.707107 0.707107 0 0">
              <inertial pos="0.0167926 -7.16408e-05 0.0215261" quat="0.00266419 0.724778 -0.00251154 0.688973" mass="0.22929" diaginertia="0.00157278 0.000979062 0.000790099"/>
              <joint name="head_yaw" pos="0 0 0" axis="0 0 1" range="-2.96706 2.96706" />
              <geom pos="-0.02 0 0.14811" quat="0 -1 0 0" type="mesh" rgba="0.411765 0.411765 0.411765 1" mesh="head_bot_sheet"/>
              <geom pos="-0.02 0 0.14811" quat="0 1 0 0" type="mesh" rgba="0.917647 0.917647 0.917647 1" mesh="head"/>
              <body name="head" pos="0 0 -0.0125" quat="0 -1 0 0">
                <inertial pos="0 0 0" mass="1e-09" diaginertia="0 0 0"/>
              </body>
            </body>
          </body>
        </body>
      </body>
    </body>
  </worldbody>
    <actuator>
    <position name="left_hip_yaw"    joint="left_hip_yaw"    inheritrange="1"/>
    <position name="left_hip_roll"   joint="left_hip_roll"   inheritrange="1"/>
    <position name="left_hip_pitch"  joint="left_hip_pitch"  inheritrange="1"/>
    <position name="left_knee"       joint="left_knee"       inheritrange="1"/>
    <position name="left_ankle"      joint="left_ankle"      inheritrange="1"/>
    <position name="right_hip_yaw"   joint="right_hip_yaw"   inheritrange="1"/>
    <position name="right_hip_roll"  joint="right_hip_roll"  inheritrange="1"/>
    <position name="right_hip_pitch" joint="right_hip_pitch" inheritrange="1"/>
    <position name="right_knee"      joint="right_knee"      inheritrange="1"/>
    <position name="right_ankle"     joint="right_ankle"     inheritrange="1"/>
    <position name="neck_pitch"      joint="neck_pitch"      inheritrange="1"/>
    <position name="head_pitch"      joint="head_pitch"      inheritrange="1"/>
    <position name="head_yaw"        joint="head_yaw"        inheritrange="1"/>
    <!-- <position name="left_antenna"    joint="left_antenna"    inheritrange="1"/>
    <position name="right_antenna"   joint="right_antenna"   inheritrange="1"/> -->
  </actuator>
</mujoco>