<robot name="onshape">
<link name="body_module">
<visual>
<origin xyz="-0.049872899514971674728 -0.1141428912905502191 0.01507892295095538196" rpy="-6.2367202746833250932e-14 -1.5074919608395581653e-14 1.5707963267948974462" />
<geometry>
<mesh filename="package:///cage.stl"/>
</geometry>
<material name="cage_material">
<color rgba="0.64705882352941179736 0.64705882352941179736 0.64705882352941179736 1.0"/>
</material>
</visual>
<collision>
<origin xyz="-0.049872899514971674728 -0.1141428912905502191 0.01507892295095538196" rpy="-6.2367202746833250932e-14 -1.5074919608395581653e-14 1.5707963267948974462" />
<geometry>
<mesh filename="package:///cage.stl"/>
</geometry>
</collision>
<visual>
<origin xyz="0.00012710048502770354695 -0.0066038964305766140184 0.023078922950959934041" rpy="-6.2367202746833276176e-14 -1.5074919608395581653e-14 1.5707963267948974462" />
<geometry>
<mesh filename="package:///body_part.stl"/>
</geometry>
<material name="body_part_material">
<color rgba="0 0 0 1.0"/>
</material>
</visual>
<collision>
<origin xyz="0.00012710048502770354695 -0.0066038964305766140184 0.023078922950959934041" rpy="-6.2367202746833276176e-14 -1.5074919608395581653e-14 1.5707963267948974462" />
<geometry>
<mesh filename="package:///body_part.stl"/>
</geometry>
</collision>
<visual>
<origin xyz="-0.049872899514971653911 -0.11414289129055023297 0.015078922950955361143" rpy="-6.2089646990676974419e-14 -1.5074919608395581653e-14 1.5707963267948974462" />
<geometry>
<mesh filename="package:///front_cover.stl"/>
</geometry>
<material name="front_cover_material">
<color rgba="0.64705882352941179736 0.64705882352941179736 0.64705882352941179736 1.0"/>
</material>
</visual>
<collision>
<origin xyz="-0.049872899514971653911 -0.11414289129055023297 0.015078922950955361143" rpy="-6.2089646990676974419e-14 -1.5074919608395581653e-14 1.5707963267948974462" />
<geometry>
<mesh filename="package:///front_cover.stl"/>
</geometry>
</collision>
<visual>
<origin xyz="0.000127100485029466026 -0.0066038964305761838069 -0.0049210770490394836751" rpy="-6.2367202746833263554e-14 -1.5074919608395581653e-14 1.5707963267948974462" />
<geometry>
<mesh filename="package:///body_part.stl"/>
</geometry>
<material name="body_part_material">
<color rgba="0 0 0 1.0"/>
</material>
</visual>
<collision>
<origin xyz="0.000127100485029466026 -0.0066038964305761838069 -0.0049210770490394836751" rpy="-6.2367202746833263554e-14 -1.5074919608395581653e-14 1.5707963267948974462" />
<geometry>
<mesh filename="package:///body_part.stl"/>
</geometry>
</collision>
<visual>
<origin xyz="0.00012710048502794640823 -0.031603896430576552956 0.019578922950959625621" rpy="-1.5074919608395890887e-14 6.2367202746832013998e-14 -3.1415926535897922278" />
<geometry>
<mesh filename="package:///dc15_a01_case_f_dummy.stl"/>
</geometry>
<material name="dc15_a01_case_f_dummy_material">
<color rgba="0.28235294117647058432 0.25490196078431370807 0.25490196078431370807 1.0"/>
</material>
</visual>
<collision>
<origin xyz="0.00012710048502794640823 -0.031603896430576552956 0.019578922950959625621" rpy="-1.5074919608395890887e-14 6.2367202746832013998e-14 -3.1415926535897922278" />
<geometry>
<mesh filename="package:///dc15_a01_case_f_dummy.stl"/>
</geometry>
</collision>
<visual>
<origin xyz="0.00012710048502794640823 -0.031603896430576552956 0.019578922950959625621" rpy="-1.507491960839588142e-14 6.2367202746832013998e-14 -3.1415926535897922278" />
<geometry>
<mesh filename="package:///dc15_a01_case_m_dummy.stl"/>
</geometry>
<material name="dc15_a01_case_m_dummy_material">
<color rgba="0.28235294117647058432 0.25490196078431370807 0.25490196078431370807 1.0"/>
</material>
</visual>
<collision>
<origin xyz="0.00012710048502794640823 -0.031603896430576552956 0.019578922950959625621" rpy="-1.507491960839588142e-14 6.2367202746832013998e-14 -3.1415926535897922278" />
<geometry>
<mesh filename="package:///dc15_a01_case_m_dummy.stl"/>
</geometry>
</collision>
<visual>
<origin xyz="0.00012710048502916765356 -0.031603896430576261523 7.8922950960035043177e-05" rpy="-1.5074919608395890887e-14 6.2367202746832013998e-14 -3.1415926535897922278" />
<geometry>
<mesh filename="package:///dc15_a01_case_b_dummy.stl"/>
</geometry>
<material name="dc15_a01_case_b_dummy_material">
<color rgba="0.28235294117647058432 0.25490196078431370807 0.25490196078431370807 1.0"/>
</material>
</visual>
<collision>
<origin xyz="0.00012710048502916765356 -0.031603896430576261523 7.8922950960035043177e-05" rpy="-1.5074919608395890887e-14 6.2367202746832013998e-14 -3.1415926535897922278" />
<geometry>
<mesh filename="package:///dc15_a01_case_b_dummy.stl"/>
</geometry>
</collision>
<visual>
<origin xyz="0.00012710048502790477487 0.018396103569423449819 0.01957892295096038196" rpy="1.5074919608395890887e-14 -6.2367202746832013998e-14 9.4368957093184552907e-16" />
<geometry>
<mesh filename="package:///dc15_a01_case_f_dummy.stl"/>
</geometry>
<material name="dc15_a01_case_f_dummy_material">
<color rgba="0.28235294117647058432 0.25490196078431370807 0.25490196078431370807 1.0"/>
</material>
</visual>
<collision>
<origin xyz="0.00012710048502790477487 0.018396103569423449819 0.01957892295096038196" rpy="1.5074919608395890887e-14 -6.2367202746832013998e-14 9.4368957093184552907e-16" />
<geometry>
<mesh filename="package:///dc15_a01_case_f_dummy.stl"/>
</geometry>
</collision>
<visual>
<origin xyz="0.00012710048502790477487 0.018396103569423449819 0.01957892295096038196" rpy="1.5074919608395887731e-14 -6.2367202746832013998e-14 9.2165518404232636261e-16" />
<geometry>
<mesh filename="package:///dc15_a01_case_m_dummy.stl"/>
</geometry>
<material name="dc15_a01_case_m_dummy_material">
<color rgba="0.28235294117647058432 0.25490196078431370807 0.25490196078431370807 1.0"/>
</material>
</visual>
<collision>
<origin xyz="0.00012710048502790477487 0.018396103569423449819 0.01957892295096038196" rpy="1.5074919608395887731e-14 -6.2367202746832013998e-14 9.2165518404232636261e-16" />
<geometry>
<mesh filename="package:///dc15_a01_case_m_dummy.stl"/>
</geometry>
</collision>
<visual>
<origin xyz="0.0001271004850291260202 0.018396103569423727375 7.8922950960787913166e-05" rpy="1.5074919608395890887e-14 -6.2367202746832013998e-14 9.4368957093184552907e-16" />
<geometry>
<mesh filename="package:///dc15_a01_case_b_dummy.stl"/>
</geometry>
<material name="dc15_a01_case_b_dummy_material">
<color rgba="0.28235294117647058432 0.25490196078431370807 0.25490196078431370807 1.0"/>
</material>
</visual>
<collision>
<origin xyz="0.0001271004850291260202 0.018396103569423727375 7.8922950960787913166e-05" rpy="1.5074919608395890887e-14 -6.2367202746832013998e-14 9.4368957093184552907e-16" />
<geometry>
<mesh filename="package:///dc15_a01_case_b_dummy.stl"/>
</geometry>
</collision>
<visual>
<origin xyz="0.030627100485025718357 -0.014603896430577120724 0.055078922950961083094" rpy="1.5707963267948956698 1.5707963267948321651 0" />
<geometry>
<mesh filename="package:///dc15_a01_case_f_dummy.stl"/>
</geometry>
<material name="dc15_a01_case_f_dummy_material">
<color rgba="0.28235294117647058432 0.25490196078431370807 0.25490196078431370807 1.0"/>
</material>
</visual>
<collision>
<origin xyz="0.030627100485025718357 -0.014603896430577120724 0.055078922950961083094" rpy="1.5707963267948956698 1.5707963267948321651 0" />
<geometry>
<mesh filename="package:///dc15_a01_case_f_dummy.stl"/>
</geometry>
</collision>
<visual>
<origin xyz="0.030627100485025718357 -0.014603896430577117255 0.055078922950961083094" rpy="1.5707963267948956698 1.5707963267948323871 0" />
<geometry>
<mesh filename="package:///dc15_a01_case_m_dummy.stl"/>
</geometry>
<material name="dc15_a01_case_m_dummy_material">
<color rgba="0.28235294117647058432 0.25490196078431370807 0.25490196078431370807 1.0"/>
</material>
</visual>
<collision>
<origin xyz="0.030627100485025718357 -0.014603896430577117255 0.055078922950961083094" rpy="1.5707963267948956698 1.5707963267948323871 0" />
<geometry>
<mesh filename="package:///dc15_a01_case_m_dummy.stl"/>
</geometry>
</collision>
<visual>
<origin xyz="0.03062710048502569754 0.0048961035694229321572 0.055078922950961367588" rpy="1.5707963267948956698 1.5707963267948323871 0" />
<geometry>
<mesh filename="package:///dc15_a01_case_b_dummy.stl"/>
</geometry>
<material name="dc15_a01_case_b_dummy_material">
<color rgba="0.28235294117647058432 0.25490196078431370807 0.25490196078431370807 1.0"/>
</material>
</visual>
<collision>
<origin xyz="0.03062710048502569754 0.0048961035694229321572 0.055078922950961367588" rpy="1.5707963267948956698 1.5707963267948323871 0" />
<geometry>
<mesh filename="package:///dc15_a01_case_b_dummy.stl"/>
</geometry>
</collision>
<inertial>
<origin xyz="0.0016680134949268812534 -0.0066173978520780996071 0.018442511129776326811" rpy="0 0 0"/>
<mass value="0.37223434038043856642" />
<inertia ixx="0.00071055936376538764241" ixy="9.7664060790223399901e-08"  ixz="-4.5494010314782572116e-05" iyy="0.0010776825157143754465" iyz="1.8353865662841084127e-07" izz="0.00095043910116850583575" />
</inertial>
</link>

<link name="trunk">
<inertial>
<origin xyz="0 0 0" rpy="0 0 0" />
<mass value="1e-9" />
<inertia ixx="0" ixy="0" ixz="0" iyy="0" iyz="0" izz="0" />
</inertial>
</link>
<joint name="trunk_frame" type="fixed">
<origin xyz="-0.014872899514971796298 -0.0066038964305765012613 0.015078922950959212229" rpy="1.5111348801390842167e-14 -6.2433989600656073464e-14 9.1593399531630240418e-16" />
<parent link="body_module" />
<child link="trunk" />
<axis xyz="0 0 0"/>
</joint>

<link name="double_u_module">
<visual>
<origin xyz="6.9388939039072283776e-18 -4.2012834183813296818e-18 0.02299999999999994757" rpy="1.570796326794896558 9.7144514654699410024e-17 4.996003610813283318e-16" />
<geometry>
<mesh filename="package:///dc15_a01_horn_dummy.stl"/>
</geometry>
<material name="dc15_a01_horn_dummy_material">
<color rgba="0.49803921568627451677 0.49803921568627451677 0.49803921568627451677 1.0"/>
</material>
</visual>
<collision>
<origin xyz="6.9388939039072283776e-18 -4.2012834183813296818e-18 0.02299999999999994757" rpy="1.570796326794896558 9.7144514654699410024e-17 4.996003610813283318e-16" />
<geometry>
<mesh filename="package:///dc15_a01_horn_dummy.stl"/>
</geometry>
</collision>
<visual>
<origin xyz="-0.14608752727508525493 -1.306463617845032843e-17 0.027999999999999990175" rpy="1.57079632679489678 2.0816681711737678055e-17 -3.141592653589793116" />
<geometry>
<mesh filename="package:///double_u.stl"/>
</geometry>
<material name="double_u_material">
<color rgba="0.28235294117647058432 0.25490196078431370807 0.25490196078431370807 1.0"/>
</material>
</visual>
<collision>
<origin xyz="-0.14608752727508525493 -1.306463617845032843e-17 0.027999999999999990175" rpy="1.57079632679489678 2.0816681711737678055e-17 -3.141592653589793116" />
<geometry>
<mesh filename="package:///double_u.stl"/>
</geometry>
</collision>
<visual>
<origin xyz="-0.033999999999999933054 -0.011500225429056537899 0.011499999999999897457" rpy="3.141592653589793116 -8.6736173798778897526e-17 4.4408920985005285402e-16" />
<geometry>
<mesh filename="package:///dc15_a01_horn_dummy.stl"/>
</geometry>
<material name="dc15_a01_horn_dummy_material">
<color rgba="0.49803921568627451677 0.49803921568627451677 0.49803921568627451677 1.0"/>
</material>
</visual>
<collision>
<origin xyz="-0.033999999999999933054 -0.011500225429056537899 0.011499999999999897457" rpy="3.141592653589793116 -8.6736173798778897526e-17 4.4408920985005285402e-16" />
<geometry>
<mesh filename="package:///dc15_a01_horn_dummy.stl"/>
</geometry>
</collision>
<visual>
<origin xyz="0 0 0" rpy="-3.141592653589793116 -3.3480749407005644071e-30 9.2593440517554546076e-32" />
<geometry>
<mesh filename="package:///dc15_a01_horn_idle2_dummy.stl"/>
</geometry>
<material name="dc15_a01_horn_idle2_dummy_material">
<color rgba="0.2313725490196078538 0.38039215686274507888 0.7058823529411765163 1.0"/>
</material>
</visual>
<collision>
<origin xyz="0 0 0" rpy="-3.141592653589793116 -3.3480749407005644071e-30 9.2593440517554546076e-32" />
<geometry>
<mesh filename="package:///dc15_a01_horn_idle2_dummy.stl"/>
</geometry>
</collision>
<visual>
<origin xyz="-0.033999999999999919176 0.011499999999999992867 0.011499999999999893988" rpy="-1.57079632679489678 -1.0755285551053250687e-16 3.885780586187937451e-16" />
<geometry>
<mesh filename="package:///dc15_a01_horn_idle2_dummy.stl"/>
</geometry>
<material name="dc15_a01_horn_idle2_dummy_material">
<color rgba="0.2313725490196078538 0.38039215686274507888 0.7058823529411765163 1.0"/>
</material>
</visual>
<collision>
<origin xyz="-0.033999999999999919176 0.011499999999999992867 0.011499999999999893988" rpy="-1.57079632679489678 -1.0755285551053250687e-16 3.885780586187937451e-16" />
<geometry>
<mesh filename="package:///dc15_a01_horn_idle2_dummy.stl"/>
</geometry>
</collision>
<inertial>
<origin xyz="-0.017000000000030695418 -9.7383147422208432478e-05 0.011597681130580182393" rpy="0 0 0"/>
<mass value="0.0166732881110219118" />
<inertia ixx="3.3991102625818662647e-06" ixy="-2.7690080818134595965e-08"  ixz="-2.7600088606009577101e-08" iyy="4.0856733350887326875e-06" iyz="-1.5860400711786071962e-10" izz="4.0856784024946459741e-06" />
</inertial>
</link>

<link name="right_hip_pitch_roll_module">
<visual>
<origin xyz="-0.067053147256374831531 -0.024500000000000077272 0.0090000000000003375911" rpy="1.1102230246252334544e-16 1.7694179454963317978e-15 6.2103100439966272296e-16" />
<geometry>
<mesh filename="package:///hip_right_roll_to_pitch.stl"/>
</geometry>
<material name="hip_right_roll_to_pitch_material">
<color rgba="0.28235294117647058432 0.25490196078431370807 0.25490196078431370807 1.0"/>
</material>
</visual>
<collision>
<origin xyz="-0.067053147256374831531 -0.024500000000000077272 0.0090000000000003375911" rpy="1.1102230246252334544e-16 1.7694179454963317978e-15 6.2103100439966272296e-16" />
<geometry>
<mesh filename="package:///hip_right_roll_to_pitch.stl"/>
</geometry>
</collision>
<visual>
<origin xyz="-3.4694469519536141888e-18 0 -0.0035000000000000083128" rpy="-2.7941167530352633554e-33 6.9388939039539144602e-18 1.6653345369381982664e-16" />
<geometry>
<mesh filename="package:///dc15_a01_case_f_dummy.stl"/>
</geometry>
<material name="dc15_a01_case_f_dummy_material">
<color rgba="0.28235294117647058432 0.25490196078431370807 0.25490196078431370807 1.0"/>
</material>
</visual>
<collision>
<origin xyz="-3.4694469519536141888e-18 0 -0.0035000000000000083128" rpy="-2.7941167530352633554e-33 6.9388939039539144602e-18 1.6653345369381982664e-16" />
<geometry>
<mesh filename="package:///dc15_a01_case_f_dummy.stl"/>
</geometry>
</collision>
<visual>
<origin xyz="0 1.3877787807814456755e-17 -0.0034999999999999996392" rpy="-2.7941167530352647238e-33 -9.8683866765610190355e-32 -3.5021876616293929274e-30" />
<geometry>
<mesh filename="package:///dc15_a01_case_m_dummy.stl"/>
</geometry>
<material name="dc15_a01_case_m_dummy_material">
<color rgba="0.28235294117647058432 0.25490196078431370807 0.25490196078431370807 1.0"/>
</material>
</visual>
<collision>
<origin xyz="0 1.3877787807814456755e-17 -0.0034999999999999996392" rpy="-2.7941167530352647238e-33 -9.8683866765610190355e-32 -3.5021876616293929274e-30" />
<geometry>
<mesh filename="package:///dc15_a01_case_m_dummy.stl"/>
</geometry>
</collision>
<visual>
<origin xyz="3.4694469519536141888e-18 1.3877787807814456755e-17 -0.022999999999999999611" rpy="1.6653345369377311128e-16 1.752070710736700397e-16 1.6306400674184160985e-16" />
<geometry>
<mesh filename="package:///dc15_a01_case_b_dummy.stl"/>
</geometry>
<material name="dc15_a01_case_b_dummy_material">
<color rgba="0.28235294117647058432 0.25490196078431370807 0.25490196078431370807 1.0"/>
</material>
</visual>
<collision>
<origin xyz="3.4694469519536141888e-18 1.3877787807814456755e-17 -0.022999999999999999611" rpy="1.6653345369377311128e-16 1.752070710736700397e-16 1.6306400674184160985e-16" />
<geometry>
<mesh filename="package:///dc15_a01_case_b_dummy.stl"/>
</geometry>
</collision>
<visual>
<origin xyz="0.025000000000000206085 -0.020999999999999852118 -0.013499999999999810762" rpy="-1.57079632679489678 2.7235158572834500736e-16 -3.141592653589793116" />
<geometry>
<mesh filename="package:///dc15_a01_case_f_dummy.stl"/>
</geometry>
<material name="dc15_a01_case_f_dummy_material">
<color rgba="0.28235294117647058432 0.25490196078431370807 0.25490196078431370807 1.0"/>
</material>
</visual>
<collision>
<origin xyz="0.025000000000000206085 -0.020999999999999852118 -0.013499999999999810762" rpy="-1.57079632679489678 2.7235158572834500736e-16 -3.141592653589793116" />
<geometry>
<mesh filename="package:///dc15_a01_case_f_dummy.stl"/>
</geometry>
</collision>
<visual>
<origin xyz="0.025000000000000209555 -0.020999999999999852118 -0.013499999999999810762" rpy="-1.57079632679489678 2.7235158572834500736e-16 -3.141592653589793116" />
<geometry>
<mesh filename="package:///dc15_a01_case_m_dummy.stl"/>
</geometry>
<material name="dc15_a01_case_m_dummy_material">
<color rgba="0.28235294117647058432 0.25490196078431370807 0.25490196078431370807 1.0"/>
</material>
</visual>
<collision>
<origin xyz="0.025000000000000209555 -0.020999999999999852118 -0.013499999999999810762" rpy="-1.57079632679489678 2.7235158572834500736e-16 -3.141592653589793116" />
<geometry>
<mesh filename="package:///dc15_a01_case_m_dummy.stl"/>
</geometry>
</collision>
<visual>
<origin xyz="0.02500000000000023731 -0.0014999999999998486766 -0.013499999999999788211" rpy="-1.570796326794896558 -1.179611963664556448e-16 -3.141592653589793116" />
<geometry>
<mesh filename="package:///dc15_a01_case_b_dummy.stl"/>
</geometry>
<material name="dc15_a01_case_b_dummy_material">
<color rgba="0.28235294117647058432 0.25490196078431370807 0.25490196078431370807 1.0"/>
</material>
</visual>
<collision>
<origin xyz="0.02500000000000023731 -0.0014999999999998486766 -0.013499999999999788211" rpy="-1.570796326794896558 -1.179611963664556448e-16 -3.141592653589793116" />
<geometry>
<mesh filename="package:///dc15_a01_case_b_dummy.stl"/>
</geometry>
</collision>
<inertial>
<origin xyz="0.011900061122336359765 -0.011878662121091884685 -0.0062345861167470836492" rpy="0 0 0"/>
<mass value="0.051958418033162222238" />
<inertia ixx="1.077718811568965518e-05" ixy="6.9987340329293664605e-07"  ixz="-2.8590642676661358795e-06" iyy="1.6310208765774600255e-05" iyz="3.1556882097165602516e-07" izz="1.3688126867683528926e-05" />
</inertial>
</link>

<link name="leg_module">
<visual>
<origin xyz="-0.042500000000000426326 -0.047130780071020866862 0.023000000000000284106" rpy="-1.5707963267949036634 -7.668011143135150495e-16 -1.5707963267949074382" />
<geometry>
<mesh filename="package:///block_to_axis.stl"/>
</geometry>
<material name="block_to_axis_material">
<color rgba="0.81568627450980391025 0.44313725490196076429 0.0039215686274509803377 1.0"/>
</material>
</visual>
<collision>
<origin xyz="-0.042500000000000426326 -0.047130780071020866862 0.023000000000000284106" rpy="-1.5707963267949036634 -7.668011143135150495e-16 -1.5707963267949074382" />
<geometry>
<mesh filename="package:///block_to_axis.stl"/>
</geometry>
</collision>
<visual>
<origin xyz="-0.042499999999999586719 0.047130780071019708066 0" rpy="1.570796326794896336 -2.347312697404189473e-16 1.57079632679489678" />
<geometry>
<mesh filename="package:///block_to_axis.stl"/>
</geometry>
<material name="block_to_axis_material">
<color rgba="0.81568627450980391025 0.44313725490196076429 0.0039215686274509803377 1.0"/>
</material>
</visual>
<collision>
<origin xyz="-0.042499999999999586719 0.047130780071019708066 0" rpy="1.570796326794896336 -2.347312697404189473e-16 1.57079632679489678" />
<geometry>
<mesh filename="package:///block_to_axis.stl"/>
</geometry>
</collision>
<visual>
<origin xyz="-0.042499999999999128752 0.04713078007102119299 1.249000902703301108e-16" rpy="1.570796326794911435 3.3306690738541151566e-16 1.5707963267948739094" />
<geometry>
<mesh filename="package:///renfort.stl"/>
</geometry>
<material name="renfort_material">
<color rgba="0.28235294117647058432 0.25490196078431370807 0.25490196078431370807 1.0"/>
</material>
</visual>
<collision>
<origin xyz="-0.042499999999999128752 0.04713078007102119299 1.249000902703301108e-16" rpy="1.570796326794911435 3.3306690738541151566e-16 1.5707963267948739094" />
<geometry>
<mesh filename="package:///renfort.stl"/>
</geometry>
</collision>
<visual>
<origin xyz="0 0 0" rpy="-3.141592653589793116 -2.4128106645613580507e-30 6.1992489098871171809e-32" />
<geometry>
<mesh filename="package:///dc15_a01_horn_idle2_dummy.stl"/>
</geometry>
<material name="dc15_a01_horn_idle2_dummy_material">
<color rgba="0.2313725490196078538 0.38039215686274507888 0.7058823529411765163 1.0"/>
</material>
</visual>
<collision>
<origin xyz="0 0 0" rpy="-3.141592653589793116 -2.4128106645613580507e-30 6.1992489098871171809e-32" />
<geometry>
<mesh filename="package:///dc15_a01_horn_idle2_dummy.stl"/>
</geometry>
</collision>
<visual>
<origin xyz="9.1940344226770776004e-16 -1.3791051634015616401e-16 0.022999999999999951039" rpy="1.5707963267948958919 3.5091998893900845269e-16 1.5707963267948983344" />
<geometry>
<mesh filename="package:///dc15_a01_horn_dummy.stl"/>
</geometry>
<material name="dc15_a01_horn_dummy_material">
<color rgba="0.49803921568627451677 0.49803921568627451677 0.49803921568627451677 1.0"/>
</material>
</visual>
<collision>
<origin xyz="9.1940344226770776004e-16 -1.3791051634015616401e-16 0.022999999999999951039" rpy="1.5707963267948958919 3.5091998893900845269e-16 1.5707963267948983344" />
<geometry>
<mesh filename="package:///dc15_a01_horn_dummy.stl"/>
</geometry>
</collision>
<visual>
<origin xyz="-0.065000000000000737743 -1.2012960071139389129e-16 0.0035000000000003361755" rpy="3.1415926535897789051 -7.1128996308130812421e-16 -1.5707963267948954478" />
<geometry>
<mesh filename="package:///dc15_a01_case_f_dummy.stl"/>
</geometry>
<material name="dc15_a01_case_f_dummy_material">
<color rgba="0.28235294117647058432 0.25490196078431370807 0.25490196078431370807 1.0"/>
</material>
</visual>
<collision>
<origin xyz="-0.065000000000000737743 -1.2012960071139389129e-16 0.0035000000000003361755" rpy="3.1415926535897789051 -7.1128996308130812421e-16 -1.5707963267948954478" />
<geometry>
<mesh filename="package:///dc15_a01_case_f_dummy.stl"/>
</geometry>
</collision>
<visual>
<origin xyz="-0.065000000000000612843 -2.0599841277224584246e-16 0.0035000000000002806644" rpy="3.1415926535897860106 -5.1745344263165272867e-16 -1.5707963267949078823" />
<geometry>
<mesh filename="package:///dc15_a01_case_m_dummy.stl"/>
</geometry>
<material name="dc15_a01_case_m_dummy_material">
<color rgba="0.28235294117647058432 0.25490196078431370807 0.25490196078431370807 1.0"/>
</material>
</visual>
<collision>
<origin xyz="-0.065000000000000612843 -2.0599841277224584246e-16 0.0035000000000002806644" rpy="3.1415926535897860106 -5.1745344263165272867e-16 -1.5707963267949078823" />
<geometry>
<mesh filename="package:///dc15_a01_case_m_dummy.stl"/>
</geometry>
</collision>
<visual>
<origin xyz="-0.065000000000000293654 -1.9125326322644298216e-16 0.02300000000000057554" rpy="3.1415926535897868987 -8.5052035001921181953e-16 -1.5707963267949078823" />
<geometry>
<mesh filename="package:///dc15_a01_case_b_dummy.stl"/>
</geometry>
<material name="dc15_a01_case_b_dummy_material">
<color rgba="0.28235294117647058432 0.25490196078431370807 0.25490196078431370807 1.0"/>
</material>
</visual>
<collision>
<origin xyz="-0.065000000000000293654 -1.9125326322644298216e-16 0.02300000000000057554" rpy="3.1415926535897868987 -8.5052035001921181953e-16 -1.5707963267949078823" />
<geometry>
<mesh filename="package:///dc15_a01_case_b_dummy.stl"/>
</geometry>
</collision>
<inertial>
<origin xyz="-0.04066214439160994315 -8.0826559980548288368e-06 0.01139680825905472171" rpy="0 0 0"/>
<mass value="0.032944425271424632173" />
<inertia ixx="4.3758701766587681462e-06" ixy="-2.7174645457765444655e-09"  ixz="-1.4631730985499493298e-07" iyy="1.9179805403556646291e-05" iyz="-5.5721405946673152118e-10" izz="1.687420348374110235e-05" />
</inertial>
</link>

<link name="leg_module_2">
<visual>
<origin xyz="-0.042500000000001286748 -0.047130780071021338706 0.023000000000000048184" rpy="-1.5707963267949038855 -3.8857805861781536036e-16 -1.5707963267948961139" />
<geometry>
<mesh filename="package:///block_to_axis.stl"/>
</geometry>
<material name="block_to_axis_material">
<color rgba="0.81568627450980391025 0.44313725490196076429 0.0039215686274509803377 1.0"/>
</material>
</visual>
<collision>
<origin xyz="-0.042500000000001286748 -0.047130780071021338706 0.023000000000000048184" rpy="-1.5707963267949038855 -3.8857805861781536036e-16 -1.5707963267948961139" />
<geometry>
<mesh filename="package:///block_to_axis.stl"/>
</geometry>
</collision>
<visual>
<origin xyz="-0.042500000000001425526 0.04713078007102081135 -2.6367796834847467835e-16" rpy="1.5707963267948894526 -4.4408920984796049907e-16 1.570796326794896558" />
<geometry>
<mesh filename="package:///block_to_axis.stl"/>
</geometry>
<material name="block_to_axis_material">
<color rgba="0.81568627450980391025 0.44313725490196076429 0.0039215686274509803377 1.0"/>
</material>
</visual>
<collision>
<origin xyz="-0.042500000000001425526 0.04713078007102081135 -2.6367796834847467835e-16" rpy="1.5707963267948894526 -4.4408920984796049907e-16 1.570796326794896558" />
<geometry>
<mesh filename="package:///block_to_axis.stl"/>
</geometry>
</collision>
<visual>
<origin xyz="-0.042500000000001328382 0.04713078007102031175 -8.3266726846886740532e-17" rpy="1.5707963267949041075 1.6653345369273925976e-16 1.5707963267948970021" />
<geometry>
<mesh filename="package:///renfort.stl"/>
</geometry>
<material name="renfort_material">
<color rgba="0.28235294117647058432 0.25490196078431370807 0.25490196078431370807 1.0"/>
</material>
</visual>
<collision>
<origin xyz="-0.042500000000001328382 0.04713078007102031175 -8.3266726846886740532e-17" rpy="1.5707963267949041075 1.6653345369273925976e-16 1.5707963267948970021" />
<geometry>
<mesh filename="package:///renfort.stl"/>
</geometry>
</collision>
<visual>
<origin xyz="0 0 0" rpy="-3.141592653589793116 -5.1408416446361323273e-30 2.5248363881734739591e-30" />
<geometry>
<mesh filename="package:///dc15_a01_horn_idle2_dummy.stl"/>
</geometry>
<material name="dc15_a01_horn_idle2_dummy_material">
<color rgba="0.2313725490196078538 0.38039215686274507888 0.7058823529411765163 1.0"/>
</material>
</visual>
<collision>
<origin xyz="0 0 0" rpy="-3.141592653589793116 -5.1408416446361323273e-30 2.5248363881734739591e-30" />
<geometry>
<mesh filename="package:///dc15_a01_horn_idle2_dummy.stl"/>
</geometry>
</collision>
<visual>
<origin xyz="-3.8857805861880478915e-16 1.2359904766334750548e-17 0.022999999999999728995" rpy="1.570796326794896558 -1.6653345369373734137e-16 1.5707963267949089925" />
<geometry>
<mesh filename="package:///dc15_a01_horn_dummy.stl"/>
</geometry>
<material name="dc15_a01_horn_dummy_material">
<color rgba="0.49803921568627451677 0.49803921568627451677 0.49803921568627451677 1.0"/>
</material>
</visual>
<collision>
<origin xyz="-3.8857805861880478915e-16 1.2359904766334750548e-17 0.022999999999999728995" rpy="1.570796326794896558 -1.6653345369373734137e-16 1.5707963267949089925" />
<geometry>
<mesh filename="package:///dc15_a01_horn_dummy.stl"/>
</geometry>
</collision>
<visual>
<origin xyz="-0.065000000000002347567 -7.8713077722447621909e-16 0.0035000000000003361755" rpy="3.1415926535897709115 -2.2204460492230199726e-16 -1.5707963267948847896" />
<geometry>
<mesh filename="package:///dc15_a01_case_f_dummy.stl"/>
</geometry>
<material name="dc15_a01_case_f_dummy_material">
<color rgba="0.28235294117647058432 0.25490196078431370807 0.25490196078431370807 1.0"/>
</material>
</visual>
<collision>
<origin xyz="-0.065000000000002347567 -7.8713077722447621909e-16 0.0035000000000003361755" rpy="3.1415926535897709115 -2.2204460492230199726e-16 -1.5707963267948847896" />
<geometry>
<mesh filename="package:///dc15_a01_case_f_dummy.stl"/>
</geometry>
</collision>
<visual>
<origin xyz="-0.065000000000002070011 -8.8622685578965132436e-16 0.0035000000000001973977" rpy="3.1415926535897860106 -5.5511151230959662251e-17 -1.5707963267949085484" />
<geometry>
<mesh filename="package:///dc15_a01_case_m_dummy.stl"/>
</geometry>
<material name="dc15_a01_case_m_dummy_material">
<color rgba="0.28235294117647058432 0.25490196078431370807 0.25490196078431370807 1.0"/>
</material>
</visual>
<collision>
<origin xyz="-0.065000000000002070011 -8.8622685578965132436e-16 0.0035000000000001973977" rpy="3.1415926535897860106 -5.5511151230959662251e-17 -1.5707963267949085484" />
<geometry>
<mesh filename="package:///dc15_a01_case_m_dummy.stl"/>
</geometry>
</collision>
<visual>
<origin xyz="-0.065000000000001764699 -7.5156894596695167365e-16 0.02300000000000070044" rpy="3.1415926535897860106 -2.7755575615529798068e-16 -1.5707963267948961139" />
<geometry>
<mesh filename="package:///dc15_a01_case_b_dummy.stl"/>
</geometry>
<material name="dc15_a01_case_b_dummy_material">
<color rgba="0.28235294117647058432 0.25490196078431370807 0.25490196078431370807 1.0"/>
</material>
</visual>
<collision>
<origin xyz="-0.065000000000001764699 -7.5156894596695167365e-16 0.02300000000000070044" rpy="3.1415926535897860106 -2.7755575615529798068e-16 -1.5707963267948961139" />
<geometry>
<mesh filename="package:///dc15_a01_case_b_dummy.stl"/>
</geometry>
</collision>
<inertial>
<origin xyz="-0.040662144391611192151 -8.0826559984370490662e-06 0.011396808259054628035" rpy="0 0 0"/>
<mass value="0.032944425271424632173" />
<inertia ixx="4.3758701766587986394e-06" ixy="-2.7174645459111470171e-09"  ixz="-1.463173098548990065e-07" iyy="1.9179805403556910565e-05" iyz="-5.5721405949400418296e-10" izz="1.6874203483741264981e-05" />
</inertial>
</link>

<link name="foot_module">
<visual>
<origin xyz="-2.7755575615628913511e-17 0 1.3877787807814456755e-17" rpy="3.141592653589793116 -2.539658231031556068e-30 -1.2252563520693843038e-32" />
<geometry>
<mesh filename="package:///dc15_a01_horn_idle2_dummy.stl"/>
</geometry>
<material name="dc15_a01_horn_idle2_dummy_material">
<color rgba="0.2313725490196078538 0.38039215686274507888 0.7058823529411765163 1.0"/>
</material>
</visual>
<collision>
<origin xyz="-2.7755575615628913511e-17 0 1.3877787807814456755e-17" rpy="3.141592653589793116 -2.539658231031556068e-30 -1.2252563520693843038e-32" />
<geometry>
<mesh filename="package:///dc15_a01_horn_idle2_dummy.stl"/>
</geometry>
</collision>
<visual>
<origin xyz="2.7755575615628913511e-17 -5.2475385148298414606e-17 -0.0051999999999999824141" rpy="-3.141592653589793116 -1.570796326794896558 0" />
<geometry>
<mesh filename="package:///foot.stl"/>
</geometry>
<material name="foot_material">
<color rgba="0.81568627450980391025 0.44313725490196076429 0.0039215686274509803377 1.0"/>
</material>
</visual>
<collision>
<origin xyz="2.7755575615628913511e-17 -5.2475385148298414606e-17 -0.0051999999999999824141" rpy="-3.141592653589793116 -1.570796326794896558 0" />
<geometry>
<mesh filename="package:///foot.stl"/>
</geometry>
</collision>
<visual>
<origin xyz="2.7755575615628913511e-17 -5.2475385148298414606e-17 -0.0051999999999999824141" rpy="-3.141592653589793116 -1.570796326794896558 0" />
<geometry>
<mesh filename="package:///foot_contact.stl"/>
</geometry>
<material name="foot_contact_material">
<color rgba="0 0 0 1.0"/>
</material>
</visual>
<collision>
<origin xyz="2.7755575615628913511e-17 -5.2475385148298414606e-17 -0.0051999999999999824141" rpy="-3.141592653589793116 -1.570796326794896558 0" />
<geometry>
<mesh filename="package:///foot_contact.stl"/>
</geometry>
</collision>
<visual>
<origin xyz="-1.1102230246251565404e-16 -6.8955258170078082003e-17 0.022999999999999840017" rpy="1.5707963267948958919 -1.7486012637846363423e-15 1.5707963267948981123" />
<geometry>
<mesh filename="package:///dc15_a01_horn_dummy.stl"/>
</geometry>
<material name="dc15_a01_horn_dummy_material">
<color rgba="0.49803921568627451677 0.49803921568627451677 0.49803921568627451677 1.0"/>
</material>
</visual>
<collision>
<origin xyz="-1.1102230246251565404e-16 -6.8955258170078082003e-17 0.022999999999999840017" rpy="1.5707963267948958919 -1.7486012637846363423e-15 1.5707963267948981123" />
<geometry>
<mesh filename="package:///dc15_a01_horn_dummy.stl"/>
</geometry>
</collision>
<inertial>
<origin xyz="-0.025588734355348044525 0.0068409488045857889602 0.011531458344445711175" rpy="0 0 0"/>
<mass value="0.051710092735949994558" />
<inertia ixx="2.0693214459049846587e-05" ixy="1.9521464615031936806e-06"  ixz="-4.1574104828601224754e-08" iyy="8.736770204808135348e-06" iyz="1.1141804136043349835e-08" izz="2.1617151776014340139e-05" />
</inertial>
</link>

<link name="right_foot_tip">
<inertial>
<origin xyz="0 0 0" rpy="0 0 0" />
<mass value="1e-9" />
<inertia ixx="0" ixy="0" ixz="0" iyy="0" iyz="0" izz="0" />
</inertial>
</link>
<joint name="right_foot_tip_frame" type="fixed">
<origin xyz="-0.037499999999999200639 4.9120863626628263887e-15 0.011500000000000301648" rpy="1.5707963267948952257 -1.0214051826550951078e-14 1.57079632679489678" />
<parent link="foot_module" />
<child link="right_foot_tip" />
<axis xyz="0 0 0"/>
</joint>

<joint name="right_ankle" type="revolute">
<origin xyz="-0.065000000000002153278 -8.8752789839663392968e-16 1.8041124150158793782e-16" rpy="-1.0269562977782461341e-14 1.7185939463948808782e-15 1.0613769886213497671e-13" />
<parent link="leg_module_2" />
<child link="foot_module" />
<axis xyz="0 0 1"/>
<limit effort="1" velocity="20" lower="-1.570796326794896558" upper="1.570796326794896558"/>
<joint_properties friction="0.0"/>
</joint>

<joint name="right_knee" type="revolute">
<origin xyz="-0.065000000000000626721 -2.0578157233774874157e-16 2.498001805406602216e-16" rpy="-8.5052035001972290279e-16 1.421728862755529065e-14 -1.0522870376072329388e-13" />
<parent link="leg_module" />
<child link="leg_module_2" />
<axis xyz="0 0 1"/>
<limit effort="1" velocity="20" lower="-2.0943951023931952626" upper="2.0943951023931952626"/>
<joint_properties friction="0.0"/>
</joint>

<joint name="right_hip_pitch" type="revolute">
<origin xyz="0.025000000000000216493 -0.024499999999999855227 -0.013499999999999812497" rpy="1.570796326794896558 2.7235158572835087452e-16 -3.141592653589793116" />
<parent link="right_hip_pitch_roll_module" />
<child link="leg_module" />
<axis xyz="0 0 1"/>
<limit effort="1" velocity="20" lower="-0.52359877559829881566" upper="1.570796326794896558"/>
<joint_properties friction="0.0"/>
</joint>

<joint name="right_hip_roll" type="revolute">
<origin xyz="-0.033999999999999877542 0.011500000000001705039 0.011500000000000806452" rpy="-1.570796326794896336 -1.5707963267948286123 0" />
<parent link="double_u_module" />
<child link="right_hip_pitch_roll_module" />
<axis xyz="0 0 1"/>
<limit effort="1" velocity="20" lower="-1.570796326794896558" upper="0.34906585039886589561"/>
<joint_properties friction="0.0"/>
</joint>

<joint name="right_hip_yaw" type="revolute">
<origin xyz="0.00012710048502772764334 -0.031603896430576608467 0.023078922950959552401" rpy="3.1415926535897304994 -1.5078389055347532112e-14 1.5707963267948974462" />
<parent link="body_module" />
<child link="double_u_module" />
<axis xyz="0 0 1"/>
<limit effort="1" velocity="20" lower="-0.69813170079773179122" upper="0.69813170079773179122"/>
<joint_properties friction="0.0"/>
</joint>

<link name="double_u_module_2">
<visual>
<origin xyz="0.034000000000001168177 0.011500000000000549713 0.01150000000000000501" rpy="3.1051550219981292186e-16 -4.1406029711123635988e-29 1.6653345369381314598e-16" />
<geometry>
<mesh filename="package:///dc15_a01_horn_dummy.stl"/>
</geometry>
<material name="dc15_a01_horn_dummy_material">
<color rgba="0.49803921568627451677 0.49803921568627451677 0.49803921568627451677 1.0"/>
</material>
</visual>
<collision>
<origin xyz="0.034000000000001168177 0.011500000000000549713 0.01150000000000000501" rpy="3.1051550219981292186e-16 -4.1406029711123635988e-29 1.6653345369381314598e-16" />
<geometry>
<mesh filename="package:///dc15_a01_horn_dummy.stl"/>
</geometry>
</collision>
<visual>
<origin xyz="-0.11208752727508929092 0.016500000000000694667 0.011499999999999999806" rpy="3.1415926535897926719 3.989863994768643966e-17 -3.1415926535897926719" />
<geometry>
<mesh filename="package:///double_u.stl"/>
</geometry>
<material name="double_u_material">
<color rgba="0.28235294117647058432 0.25490196078431370807 0.25490196078431370807 1.0"/>
</material>
</visual>
<collision>
<origin xyz="-0.11208752727508929092 0.016500000000000694667 0.011499999999999999806" rpy="3.1415926535897926719 3.989863994768643966e-17 -3.1415926535897926719" />
<geometry>
<mesh filename="package:///double_u.stl"/>
</geometry>
</collision>
<visual>
<origin xyz="3.4694469519536141888e-18 9.2157184661267876891e-17 0.02300022542905653597" rpy="1.570796326794896558 -1.7347234759806010223e-17 2.2204460492504915606e-16" />
<geometry>
<mesh filename="package:///dc15_a01_horn_dummy.stl"/>
</geometry>
<material name="dc15_a01_horn_dummy_material">
<color rgba="0.49803921568627451677 0.49803921568627451677 0.49803921568627451677 1.0"/>
</material>
</visual>
<collision>
<origin xyz="3.4694469519536141888e-18 9.2157184661267876891e-17 0.02300022542905653597" rpy="1.570796326794896558 -1.7347234759806010223e-17 2.2204460492504915606e-16" />
<geometry>
<mesh filename="package:///dc15_a01_horn_dummy.stl"/>
</geometry>
</collision>
<visual>
<origin xyz="0.034000000000001182054 -0.0115000000000000345 0.011499999999999996336" rpy="1.5707963267948970021 6.9388939039125947888e-18 2.2204460492508805677e-16" />
<geometry>
<mesh filename="package:///dc15_a01_horn_idle2_dummy.stl"/>
</geometry>
<material name="dc15_a01_horn_idle2_dummy_material">
<color rgba="0.2313725490196078538 0.38039215686274507888 0.7058823529411765163 1.0"/>
</material>
</visual>
<collision>
<origin xyz="0.034000000000001182054 -0.0115000000000000345 0.011499999999999996336" rpy="1.5707963267948970021 6.9388939039125947888e-18 2.2204460492508805677e-16" />
<geometry>
<mesh filename="package:///dc15_a01_horn_idle2_dummy.stl"/>
</geometry>
</collision>
<visual>
<origin xyz="0 0 0" rpy="-3.141592653589793116 -3.8526263963279615011e-31 6.4358684515981144592e-32" />
<geometry>
<mesh filename="package:///dc15_a01_horn_idle2_dummy.stl"/>
</geometry>
<material name="dc15_a01_horn_idle2_dummy_material">
<color rgba="0.2313725490196078538 0.38039215686274507888 0.7058823529411765163 1.0"/>
</material>
</visual>
<collision>
<origin xyz="0 0 0" rpy="-3.141592653589793116 -3.8526263963279615011e-31 6.4358684515981144592e-32" />
<geometry>
<mesh filename="package:///dc15_a01_horn_idle2_dummy.stl"/>
</geometry>
</collision>
<inertial>
<origin xyz="0.016999999999969886422 9.7681130580394738691e-05 0.01159738314742220916" rpy="0 0 0"/>
<mass value="0.0166732881110219118" />
<inertia ixx="3.3991102625820924225e-06" ixy="-2.7600088606013713004e-08"  ixz="2.7690080818135840045e-08" iyy="4.0856784024949144835e-06" iyz="1.5860400711647177998e-10" izz="4.0856733350887996031e-06" />
</inertial>
</link>

<link name="left_hip_pitch_roll_module">
<visual>
<origin xyz="-0.067053147256375594809 -0.024500000000000049516 -0.032000000000000465572" rpy="3.141592653589793116 1.6028126974030637996e-15 -3.141592653589793116" />
<geometry>
<mesh filename="package:///hip_left_roll_to_pitch.stl"/>
</geometry>
<material name="hip_left_roll_to_pitch_material">
<color rgba="0.28235294117647058432 0.25490196078431370807 0.25490196078431370807 1.0"/>
</material>
</visual>
<collision>
<origin xyz="-0.067053147256375594809 -0.024500000000000049516 -0.032000000000000465572" rpy="3.141592653589793116 1.6028126974030637996e-15 -3.141592653589793116" />
<geometry>
<mesh filename="package:///hip_left_roll_to_pitch.stl"/>
</geometry>
</collision>
<visual>
<origin xyz="0.025000000000000480171 -0.0050000000000000113798 -0.0095000000000003380352" rpy="1.570796326794896558 -1.6826817716976283598e-16 3.141592653589793116" />
<geometry>
<mesh filename="package:///dc15_a01_case_f_dummy.stl"/>
</geometry>
<material name="dc15_a01_case_f_dummy_material">
<color rgba="0.28235294117647058432 0.25490196078431370807 0.25490196078431370807 1.0"/>
</material>
</visual>
<collision>
<origin xyz="0.025000000000000480171 -0.0050000000000000113798 -0.0095000000000003380352" rpy="1.570796326794896558 -1.6826817716976283598e-16 3.141592653589793116" />
<geometry>
<mesh filename="package:///dc15_a01_case_f_dummy.stl"/>
</geometry>
</collision>
<visual>
<origin xyz="0.025000000000000476702 -0.0050000000000000044409 -0.0095000000000003380352" rpy="1.570796326794896558 -1.6826817716976283598e-16 3.141592653589793116" />
<geometry>
<mesh filename="package:///dc15_a01_case_m_dummy.stl"/>
</geometry>
<material name="dc15_a01_case_m_dummy_material">
<color rgba="0.28235294117647058432 0.25490196078431370807 0.25490196078431370807 1.0"/>
</material>
</visual>
<collision>
<origin xyz="0.025000000000000476702 -0.0050000000000000044409 -0.0095000000000003380352" rpy="1.570796326794896558 -1.6826817716976283598e-16 3.141592653589793116" />
<geometry>
<mesh filename="package:///dc15_a01_case_m_dummy.stl"/>
</geometry>
</collision>
<visual>
<origin xyz="0.025000000000000480171 -0.024500000000000007883 -0.0095000000000003363004" rpy="1.5707963267948970021 -1.6653345369377957008e-16 3.141592653589793116" />
<geometry>
<mesh filename="package:///dc15_a01_case_b_dummy.stl"/>
</geometry>
<material name="dc15_a01_case_b_dummy_material">
<color rgba="0.28235294117647058432 0.25490196078431370807 0.25490196078431370807 1.0"/>
</material>
</visual>
<collision>
<origin xyz="0.025000000000000480171 -0.024500000000000007883 -0.0095000000000003363004" rpy="1.5707963267948970021 -1.6653345369377957008e-16 3.141592653589793116" />
<geometry>
<mesh filename="package:///dc15_a01_case_b_dummy.stl"/>
</geometry>
</collision>
<visual>
<origin xyz="-6.9388939039072283776e-18 6.9388939039072283776e-18 -0.0035000000000000031086" rpy="-1.2165742382660529434e-30 1.7347234760260427231e-18 1.0135044610367681794e-28" />
<geometry>
<mesh filename="package:///dc15_a01_case_f_dummy.stl"/>
</geometry>
<material name="dc15_a01_case_f_dummy_material">
<color rgba="0.28235294117647058432 0.25490196078431370807 0.25490196078431370807 1.0"/>
</material>
</visual>
<collision>
<origin xyz="-6.9388939039072283776e-18 6.9388939039072283776e-18 -0.0035000000000000031086" rpy="-1.2165742382660529434e-30 1.7347234760260427231e-18 1.0135044610367681794e-28" />
<geometry>
<mesh filename="package:///dc15_a01_case_f_dummy.stl"/>
</geometry>
</collision>
<visual>
<origin xyz="0 0 -0.0035000000000000013739" rpy="8.21038787536631811e-32 -4.43527532880738304e-30 2.5910682678029832497e-30" />
<geometry>
<mesh filename="package:///dc15_a01_case_m_dummy.stl"/>
</geometry>
<material name="dc15_a01_case_m_dummy_material">
<color rgba="0.28235294117647058432 0.25490196078431370807 0.25490196078431370807 1.0"/>
</material>
</visual>
<collision>
<origin xyz="0 0 -0.0035000000000000013739" rpy="8.21038787536631811e-32 -4.43527532880738304e-30 2.5910682678029832497e-30" />
<geometry>
<mesh filename="package:///dc15_a01_case_m_dummy.stl"/>
</geometry>
</collision>
<visual>
<origin xyz="-2.4286128663675299322e-17 -6.9388939039072283776e-18 -0.023000000000000003081" rpy="-3.3306690738754597605e-16 5.0133508455734103207e-16 -5.5511151231208184251e-17" />
<geometry>
<mesh filename="package:///dc15_a01_case_b_dummy.stl"/>
</geometry>
<material name="dc15_a01_case_b_dummy_material">
<color rgba="0.28235294117647058432 0.25490196078431370807 0.25490196078431370807 1.0"/>
</material>
</visual>
<collision>
<origin xyz="-2.4286128663675299322e-17 -6.9388939039072283776e-18 -0.023000000000000003081" rpy="-3.3306690738754597605e-16 5.0133508455734103207e-16 -5.5511151231208184251e-17" />
<geometry>
<mesh filename="package:///dc15_a01_case_b_dummy.stl"/>
</geometry>
</collision>
<inertial>
<origin xyz="0.011900061122336507216 -0.01168521155361623709 -0.016571963315777264031" rpy="0 0 0"/>
<mass value="0.051958418033162222238" />
<inertia ixx="1.0856606633787742525e-05" ixy="5.6937025181468092711e-07"  ixz="2.9775069853284710192e-06" iyy="1.6414113728581997961e-05" iyz="-3.3769744827910039372e-07" izz="1.3663640422974467593e-05" />
</inertial>
</link>

<link name="leg_module_3">
<visual>
<origin xyz="-0.042499999999998823441 -0.047130780071017917832 0.02299999999999988165" rpy="-1.570796326794896336 -4.9665721191828684637e-16 -1.5707963267948910069" />
<geometry>
<mesh filename="package:///block_to_axis.stl"/>
</geometry>
<material name="block_to_axis_material">
<color rgba="0.81568627450980391025 0.44313725490196076429 0.0039215686274509803377 1.0"/>
</material>
</visual>
<collision>
<origin xyz="-0.042499999999998823441 -0.047130780071017917832 0.02299999999999988165" rpy="-1.570796326794896336 -4.9665721191828684637e-16 -1.5707963267948910069" />
<geometry>
<mesh filename="package:///block_to_axis.stl"/>
</geometry>
</collision>
<visual>
<origin xyz="-0.042499999999999427125 0.047130780071019423572 -6.9388939039072283776e-18" rpy="1.570796326794896336 -5.5322230588507740558e-16 1.570796326794896558" />
<geometry>
<mesh filename="package:///block_to_axis.stl"/>
</geometry>
<material name="block_to_axis_material">
<color rgba="0.81568627450980391025 0.44313725490196076429 0.0039215686274509803377 1.0"/>
</material>
</visual>
<collision>
<origin xyz="-0.042499999999999427125 0.047130780071019423572 -6.9388939039072283776e-18" rpy="1.570796326794896336 -5.5322230588507740558e-16 1.570796326794896558" />
<geometry>
<mesh filename="package:///block_to_axis.stl"/>
</geometry>
</collision>
<visual>
<origin xyz="-0.042499999999999260591 0.047130780071017966404 -4.1633363423443370266e-17" rpy="1.5707963267948961139 1.7574844076072912051e-16 1.5707963267949018871" />
<geometry>
<mesh filename="package:///renfort.stl"/>
</geometry>
<material name="renfort_material">
<color rgba="0.28235294117647058432 0.25490196078431370807 0.25490196078431370807 1.0"/>
</material>
</visual>
<collision>
<origin xyz="-0.042499999999999260591 0.047130780071017966404 -4.1633363423443370266e-17" rpy="1.5707963267948961139 1.7574844076072912051e-16 1.5707963267949018871" />
<geometry>
<mesh filename="package:///renfort.stl"/>
</geometry>
</collision>
<visual>
<origin xyz="0 0 6.9388939039072283776e-18" rpy="-3.141592653589793116 6.0380872525306508896e-31 2.6172886996596942861e-24" />
<geometry>
<mesh filename="package:///dc15_a01_horn_idle2_dummy.stl"/>
</geometry>
<material name="dc15_a01_horn_idle2_dummy_material">
<color rgba="0.2313725490196078538 0.38039215686274507888 0.7058823529411765163 1.0"/>
</material>
</visual>
<collision>
<origin xyz="0 0 6.9388939039072283776e-18" rpy="-3.141592653589793116 6.0380872525306508896e-31 2.6172886996596942861e-24" />
<geometry>
<mesh filename="package:///dc15_a01_horn_idle2_dummy.stl"/>
</geometry>
</collision>
<visual>
<origin xyz="-1.0443035325380378708e-15 2.003605614753212194e-16 0.022999999999999853895" rpy="1.57079632679489678 -9.4417175807085359404e-17 1.5707963267948974462" />
<geometry>
<mesh filename="package:///dc15_a01_horn_dummy.stl"/>
</geometry>
<material name="dc15_a01_horn_dummy_material">
<color rgba="0.49803921568627451677 0.49803921568627451677 0.49803921568627451677 1.0"/>
</material>
</visual>
<collision>
<origin xyz="-1.0443035325380378708e-15 2.003605614753212194e-16 0.022999999999999853895" rpy="1.57079632679489678 -9.4417175807085359404e-17 1.5707963267948974462" />
<geometry>
<mesh filename="package:///dc15_a01_horn_dummy.stl"/>
</geometry>
</collision>
<visual>
<origin xyz="-0.064999999999998780975 -1.4441572937506919061e-16 0.0034999999999999822919" rpy="3.1415926535897922278 5.3850638565685795826e-16 -1.5707963267948883423" />
<geometry>
<mesh filename="package:///dc15_a01_case_f_dummy.stl"/>
</geometry>
<material name="dc15_a01_case_f_dummy_material">
<color rgba="0.28235294117647058432 0.25490196078431370807 0.25490196078431370807 1.0"/>
</material>
</visual>
<collision>
<origin xyz="-0.064999999999998780975 -1.4441572937506919061e-16 0.0034999999999999822919" rpy="3.1415926535897922278 5.3850638565685795826e-16 -1.5707963267948883423" />
<geometry>
<mesh filename="package:///dc15_a01_case_f_dummy.stl"/>
</geometry>
</collision>
<visual>
<origin xyz="-0.064999999999998628319 -8.7603535536828758268e-17 0.0034999999999999822919" rpy="3.1415926535897922278 4.2748408319437617593e-16 -1.5707963267948930053" />
<geometry>
<mesh filename="package:///dc15_a01_case_m_dummy.stl"/>
</geometry>
<material name="dc15_a01_case_m_dummy_material">
<color rgba="0.28235294117647058432 0.25490196078431370807 0.25490196078431370807 1.0"/>
</material>
</visual>
<collision>
<origin xyz="-0.064999999999998628319 -8.7603535536828758268e-17 0.0034999999999999822919" rpy="3.1415926535897922278 4.2748408319437617593e-16 -1.5707963267948930053" />
<geometry>
<mesh filename="package:///dc15_a01_case_m_dummy.stl"/>
</geometry>
</collision>
<visual>
<origin xyz="-0.064999999999998600564 -9.2590865530262078664e-17 0.022999999999999867772" rpy="-3.141592653589793116 -1.6605126655692372104e-17 -1.5707963267948930053" />
<geometry>
<mesh filename="package:///dc15_a01_case_b_dummy.stl"/>
</geometry>
<material name="dc15_a01_case_b_dummy_material">
<color rgba="0.28235294117647058432 0.25490196078431370807 0.25490196078431370807 1.0"/>
</material>
</visual>
<collision>
<origin xyz="-0.064999999999998600564 -9.2590865530262078664e-17 0.022999999999999867772" rpy="-3.141592653589793116 -1.6605126655692372104e-17 -1.5707963267948930053" />
<geometry>
<mesh filename="package:///dc15_a01_case_b_dummy.stl"/>
</geometry>
</collision>
<inertial>
<origin xyz="-0.040662144391609172933 -8.0826559979070046469e-06 0.01139680825905447191" rpy="0 0 0"/>
<mass value="0.032944425271424632173" />
<inertia ixx="4.3758701766585843401e-06" ixy="-2.7174645458487800804e-09"  ixz="-1.4631730985500170925e-07" iyy="1.9179805403555155513e-05" iyz="-5.5721405950243966745e-10" izz="1.6874203483739899564e-05" />
</inertial>
</link>

<link name="leg_module_4">
<visual>
<origin xyz="-0.042499999999999912847 -0.047130780071021026456 0.023000000000000540845" rpy="-1.5707963267949101027 -1.3877787807783265195e-15 -1.5707963267948956698" />
<geometry>
<mesh filename="package:///block_to_axis.stl"/>
</geometry>
<material name="block_to_axis_material">
<color rgba="0.81568627450980391025 0.44313725490196076429 0.0039215686274509803377 1.0"/>
</material>
</visual>
<collision>
<origin xyz="-0.042499999999999912847 -0.047130780071021026456 0.023000000000000540845" rpy="-1.5707963267949101027 -1.3877787807783265195e-15 -1.5707963267948956698" />
<geometry>
<mesh filename="package:///block_to_axis.stl"/>
</geometry>
</collision>
<visual>
<origin xyz="-0.042499999999999607536 0.04713078007102119299 4.9266146717741321481e-16" rpy="1.5707963267949105468 1.609823385706450754e-15 1.57079632679489678" />
<geometry>
<mesh filename="package:///block_to_axis.stl"/>
</geometry>
<material name="block_to_axis_material">
<color rgba="0.81568627450980391025 0.44313725490196076429 0.0039215686274509803377 1.0"/>
</material>
</visual>
<collision>
<origin xyz="-0.042499999999999607536 0.04713078007102119299 4.9266146717741321481e-16" rpy="1.5707963267949105468 1.609823385706450754e-15 1.57079632679489678" />
<geometry>
<mesh filename="package:///block_to_axis.stl"/>
</geometry>
</collision>
<visual>
<origin xyz="-0.042499999999999579781 0.04713078007102119299 5.1347814888913489995e-16" rpy="1.5707963267949101027 1.221245327087657995e-15 1.570796326794896558" />
<geometry>
<mesh filename="package:///renfort.stl"/>
</geometry>
<material name="renfort_material">
<color rgba="0.28235294117647058432 0.25490196078431370807 0.25490196078431370807 1.0"/>
</material>
</visual>
<collision>
<origin xyz="-0.042499999999999579781 0.04713078007102119299 5.1347814888913489995e-16" rpy="1.5707963267949101027 1.221245327087657995e-15 1.570796326794896558" />
<geometry>
<mesh filename="package:///renfort.stl"/>
</geometry>
</collision>
<visual>
<origin xyz="0 0 6.9388939039072283776e-18" rpy="3.141592653589793116 6.4496432703652328653e-32 -4.9573940081464673447e-30" />
<geometry>
<mesh filename="package:///dc15_a01_horn_idle2_dummy.stl"/>
</geometry>
<material name="dc15_a01_horn_idle2_dummy_material">
<color rgba="0.2313725490196078538 0.38039215686274507888 0.7058823529411765163 1.0"/>
</material>
</visual>
<collision>
<origin xyz="0 0 6.9388939039072283776e-18" rpy="3.141592653589793116 6.4496432703652328653e-32 -4.9573940081464673447e-30" />
<geometry>
<mesh filename="package:///dc15_a01_horn_idle2_dummy.stl"/>
</geometry>
</collision>
<visual>
<origin xyz="1.4294121442048890458e-15 -7.7195194680967915701e-17 0.022999999999999888589" rpy="1.5707963267949101027 9.9920072216262905347e-16 1.570796326794896558" />
<geometry>
<mesh filename="package:///dc15_a01_horn_dummy.stl"/>
</geometry>
<material name="dc15_a01_horn_dummy_material">
<color rgba="0.49803921568627451677 0.49803921568627451677 0.49803921568627451677 1.0"/>
</material>
</visual>
<collision>
<origin xyz="1.4294121442048890458e-15 -7.7195194680967915701e-17 0.022999999999999888589" rpy="1.5707963267949101027 9.9920072216262905347e-16 1.570796326794896558" />
<geometry>
<mesh filename="package:///dc15_a01_horn_dummy.stl"/>
</geometry>
</collision>
<visual>
<origin xyz="-0.064999999999999766298 1.6137265135274247996e-15 0.0035000000000008565926" rpy="3.1415926535897797933 -1.1102230246251936169e-15 -1.5707963267948961139" />
<geometry>
<mesh filename="package:///dc15_a01_case_f_dummy.stl"/>
</geometry>
<material name="dc15_a01_case_f_dummy_material">
<color rgba="0.28235294117647058432 0.25490196078431370807 0.25490196078431370807 1.0"/>
</material>
</visual>
<collision>
<origin xyz="-0.064999999999999766298 1.6137265135274247996e-15 0.0035000000000008565926" rpy="3.1415926535897797933 -1.1102230246251936169e-15 -1.5707963267948961139" />
<geometry>
<mesh filename="package:///dc15_a01_case_f_dummy.stl"/>
</geometry>
</collision>
<visual>
<origin xyz="-0.064999999999999766298 1.614810715699910304e-15 0.0035000000000008565926" rpy="3.1415926535897797933 -1.1102230246251936169e-15 -1.5707963267948961139" />
<geometry>
<mesh filename="package:///dc15_a01_case_m_dummy.stl"/>
</geometry>
<material name="dc15_a01_case_m_dummy_material">
<color rgba="0.28235294117647058432 0.25490196078431370807 0.25490196078431370807 1.0"/>
</material>
</visual>
<collision>
<origin xyz="-0.064999999999999766298 1.614810715699910304e-15 0.0035000000000008565926" rpy="3.1415926535897797933 -1.1102230246251936169e-15 -1.5707963267948961139" />
<geometry>
<mesh filename="package:///dc15_a01_case_m_dummy.stl"/>
</geometry>
</collision>
<visual>
<origin xyz="-0.064999999999999766298 1.628254822638730559e-15 0.02300000000000076289" rpy="3.1415926535897797933 -1.1102230246251936169e-15 -1.5707963267948961139" />
<geometry>
<mesh filename="package:///dc15_a01_case_b_dummy.stl"/>
</geometry>
<material name="dc15_a01_case_b_dummy_material">
<color rgba="0.28235294117647058432 0.25490196078431370807 0.25490196078431370807 1.0"/>
</material>
</visual>
<collision>
<origin xyz="-0.064999999999999766298 1.628254822638730559e-15 0.02300000000000076289" rpy="3.1415926535897797933 -1.1102230246251936169e-15 -1.5707963267948961139" />
<geometry>
<mesh filename="package:///dc15_a01_case_b_dummy.stl"/>
</geometry>
</collision>
<inertial>
<origin xyz="-0.040662144391609575389 -8.0826559968842038927e-06 0.011396808259055035695" rpy="0 0 0"/>
<mass value="0.032944425271424632173" />
<inertia ixx="4.3758701766586546438e-06" ixy="-2.7174645455093874615e-09"  ixz="-1.4631730985495332249e-07" iyy="1.9179805403556348135e-05" iyz="-5.5721405946266820322e-10" izz="1.6874203483740770314e-05" />
</inertial>
</link>

<link name="foot_module_2">
<visual>
<origin xyz="0 0 -6.9388939039072283776e-18" rpy="3.141592653589793116 -8.3174355641118837966e-31 5.0037344593012466516e-30" />
<geometry>
<mesh filename="package:///dc15_a01_horn_idle2_dummy.stl"/>
</geometry>
<material name="dc15_a01_horn_idle2_dummy_material">
<color rgba="0.2313725490196078538 0.38039215686274507888 0.7058823529411765163 1.0"/>
</material>
</visual>
<collision>
<origin xyz="0 0 -6.9388939039072283776e-18" rpy="3.141592653589793116 -8.3174355641118837966e-31 5.0037344593012466516e-30" />
<geometry>
<mesh filename="package:///dc15_a01_horn_idle2_dummy.stl"/>
</geometry>
</collision>
<visual>
<origin xyz="0 -5.4426949058772322587e-17 -0.0051999999999999824141" rpy="-3.141592653589793116 -1.570796326794896558 0" />
<geometry>
<mesh filename="package:///foot.stl"/>
</geometry>
<material name="foot_material">
<color rgba="0.81568627450980391025 0.44313725490196076429 0.0039215686274509803377 1.0"/>
</material>
</visual>
<collision>
<origin xyz="0 -5.4426949058772322587e-17 -0.0051999999999999824141" rpy="-3.141592653589793116 -1.570796326794896558 0" />
<geometry>
<mesh filename="package:///foot.stl"/>
</geometry>
</collision>
<visual>
<origin xyz="0 -5.4426949058772322587e-17 -0.0051999999999999824141" rpy="-3.141592653589793116 -1.570796326794896558 0" />
<geometry>
<mesh filename="package:///foot_contact.stl"/>
</geometry>
<material name="foot_contact_material">
<color rgba="0 0 0 1.0"/>
</material>
</visual>
<collision>
<origin xyz="0 -5.4426949058772322587e-17 -0.0051999999999999824141" rpy="-3.141592653589793116 -1.570796326794896558 0" />
<geometry>
<mesh filename="package:///foot_contact.stl"/>
</geometry>
</collision>
<visual>
<origin xyz="-8.3266726846886740532e-17 -3.6212352561015848096e-17 0.022999999999999798383" rpy="1.5707963267948958919 -1.7486012637846365395e-15 1.5707963267948981123" />
<geometry>
<mesh filename="package:///dc15_a01_horn_dummy.stl"/>
</geometry>
<material name="dc15_a01_horn_dummy_material">
<color rgba="0.49803921568627451677 0.49803921568627451677 0.49803921568627451677 1.0"/>
</material>
</visual>
<collision>
<origin xyz="-8.3266726846886740532e-17 -3.6212352561015848096e-17 0.022999999999999798383" rpy="1.5707963267948958919 -1.7486012637846365395e-15 1.5707963267948981123" />
<geometry>
<mesh filename="package:///dc15_a01_horn_dummy.stl"/>
</geometry>
</collision>
<inertial>
<origin xyz="-0.025588734355348068811 0.0068409488045857880928 0.011531458344445711175" rpy="0 0 0"/>
<mass value="0.051710092735949994558" />
<inertia ixx="2.0693214459049843199e-05" ixy="1.9521464615031936806e-06"  ixz="-4.1574104828600271842e-08" iyy="8.736770204808137042e-06" iyz="1.11418041360427675e-08" izz="2.1617151776014340139e-05" />
</inertial>
</link>

<link name="left_foot_tip">
<inertial>
<origin xyz="0 0 0" rpy="0 0 0" />
<mass value="1e-9" />
<inertia ixx="0" ixy="0" ixz="0" iyy="0" iyz="0" izz="0" />
</inertial>
</link>
<joint name="left_foot_tip_frame" type="fixed">
<origin xyz="-0.037499999999999367173 0.0050000000000021832536 0.01150000000000148126" rpy="1.5707963267948952257 -1.0428536596756394336e-14 1.5707963267948961139" />
<parent link="foot_module_2" />
<child link="left_foot_tip" />
<axis xyz="0 0 0"/>
</joint>

<joint name="left_ankle" type="revolute">
<origin xyz="-0.064999999999999738542 1.6044023748440494614e-15 8.6736173798840354721e-16" rpy="-1.1268763699943687011e-14 1.530147876329310037e-14 -3.7007434154172122983e-16" />
<parent link="leg_module_4" />
<child link="foot_module_2" />
<axis xyz="0 0 1"/>
<limit effort="1" velocity="20" lower="-1.570796326794896558" upper="1.570796326794896558"/>
<joint_properties friction="0.0"/>
</joint>

<joint name="left_knee" type="revolute">
<origin xyz="-0.064999999999998614442 -1.7347234759768070944e-18 -9.9920072216264088638e-16" rpy="4.9960035007571566733e-16 -1.5046174721125420955e-14 -7.8207331051164856179e-08" />
<parent link="leg_module_3" />
<child link="leg_module_4" />
<axis xyz="0 0 1"/>
<limit effort="1" velocity="20" lower="-2.0943951023931952626" upper="2.0943951023931952626"/>
<joint_properties friction="0.0"/>
</joint>

<joint name="left_hip_pitch" type="revolute">
<origin xyz="0.025000000000000473233 -0.0015000000000000013323 -0.0095000000000003380352" rpy="-1.5707963267948956698 7.8207331051164842944e-08 3.141592653589793116" />
<parent link="left_hip_pitch_roll_module" />
<child link="leg_module_3" />
<axis xyz="0 0 1"/>
<limit effort="1" velocity="20" lower="-0.52359877559829881566" upper="1.570796326794896558"/>
<joint_properties friction="0.0"/>
</joint>

<joint name="left_hip_roll" type="revolute">
<origin xyz="0.034000000000000807354 -0.0115000000000000345 0.011500000000000017153" rpy="1.570796326794896558 -1.570796326794881681 0" />
<parent link="double_u_module_2" />
<child link="left_hip_pitch_roll_module" />
<axis xyz="0 0 1"/>
<limit effort="1" velocity="20" lower="-1.570796326794896558" upper="0.34906585039886589561"/>
<joint_properties friction="0.0"/>
</joint>

<joint name="left_hip_yaw" type="revolute">
<origin xyz="0.00012710048502768600998 0.018396103569423397778 0.023078922950960308741" rpy="3.1415926535897309435 -1.5078389055347532112e-14 1.5707963267948974462" />
<parent link="body_module" />
<child link="double_u_module_2" />
<axis xyz="0 0 1"/>
<limit effort="1" velocity="20" lower="-0.69813170079773179122" upper="0.69813170079773179122"/>
<joint_properties friction="0.0"/>
</joint>

<link name="head_link">
<visual>
<origin xyz="6.9388939039072283776e-17 -1.1796119636642288242e-16 0.022999999999999878181" rpy="-1.570796326794896558 -2.2021623822161954679e-28 -3.141592653589793116" />
<geometry>
<mesh filename="package:///axis_to_axis.stl"/>
</geometry>
<material name="axis_to_axis_material">
<color rgba="0.28235294117647058432 0.25490196078431370807 0.25490196078431370807 1.0"/>
</material>
</visual>
<collision>
<origin xyz="6.9388939039072283776e-17 -1.1796119636642288242e-16 0.022999999999999878181" rpy="-1.570796326794896558 -2.2021623822161954679e-28 -3.141592653589793116" />
<geometry>
<mesh filename="package:///axis_to_axis.stl"/>
</geometry>
</collision>
<visual>
<origin xyz="7.9797279894933126343e-17 -0.064999999999999100164 0.02299999999999988165" rpy="1.570796326794896558 2.0543045052719165412e-28 -1.1102230246246678164e-16" />
<geometry>
<mesh filename="package:///dc15_a01_horn_dummy.stl"/>
</geometry>
<material name="dc15_a01_horn_dummy_material">
<color rgba="0.49803921568627451677 0.49803921568627451677 0.49803921568627451677 1.0"/>
</material>
</visual>
<collision>
<origin xyz="7.9797279894933126343e-17 -0.064999999999999100164 0.02299999999999988165" rpy="1.570796326794896558 2.0543045052719165412e-28 -1.1102230246246678164e-16" />
<geometry>
<mesh filename="package:///dc15_a01_horn_dummy.stl"/>
</geometry>
</collision>
<visual>
<origin xyz="0.047130780071019132138 -0.022499999999999811817 -6.9388939039072283776e-18" rpy="1.570796326794896558 7.0019013381165752161e-28 5.5511151230842528732e-17" />
<geometry>
<mesh filename="package:///renfort.stl"/>
</geometry>
<material name="renfort_material">
<color rgba="0.28235294117647058432 0.25490196078431370807 0.25490196078431370807 1.0"/>
</material>
</visual>
<collision>
<origin xyz="0.047130780071019132138 -0.022499999999999811817 -6.9388939039072283776e-18" rpy="1.570796326794896558 7.0019013381165752161e-28 5.5511151230842528732e-17" />
<geometry>
<mesh filename="package:///renfort.stl"/>
</geometry>
</collision>
<visual>
<origin xyz="7.6327832942979512154e-17 -1.1796119636642288242e-16 0.022999999999999878181" rpy="1.570796326794896558 2.0543045052719165412e-28 -1.1102230246246678164e-16" />
<geometry>
<mesh filename="package:///dc15_a01_horn_dummy.stl"/>
</geometry>
<material name="dc15_a01_horn_dummy_material">
<color rgba="0.49803921568627451677 0.49803921568627451677 0.49803921568627451677 1.0"/>
</material>
</visual>
<collision>
<origin xyz="7.6327832942979512154e-17 -1.1796119636642288242e-16 0.022999999999999878181" rpy="1.570796326794896558 2.0543045052719165412e-28 -1.1102230246246678164e-16" />
<geometry>
<mesh filename="package:///dc15_a01_horn_dummy.stl"/>
</geometry>
</collision>
<visual>
<origin xyz="-6.9388939039072283776e-18 -0.06499999999999912792 3.4694469519536141888e-18" rpy="-3.141592653589793116 -2.9383826821945038949e-16 -2.2204460492499677077e-16" />
<geometry>
<mesh filename="package:///dc15_a01_horn_idle2_dummy.stl"/>
</geometry>
<material name="dc15_a01_horn_idle2_dummy_material">
<color rgba="0.2313725490196078538 0.38039215686274507888 0.7058823529411765163 1.0"/>
</material>
</visual>
<collision>
<origin xyz="-6.9388939039072283776e-18 -0.06499999999999912792 3.4694469519536141888e-18" rpy="-3.141592653589793116 -2.9383826821945038949e-16 -2.2204460492499677077e-16" />
<geometry>
<mesh filename="package:///dc15_a01_horn_idle2_dummy.stl"/>
</geometry>
</collision>
<visual>
<origin xyz="0 0 0" rpy="3.141592653589793116 2.8115191019968956248e-32 0" />
<geometry>
<mesh filename="package:///dc15_a01_horn_idle2_dummy.stl"/>
</geometry>
<material name="dc15_a01_horn_idle2_dummy_material">
<color rgba="0.2313725490196078538 0.38039215686274507888 0.7058823529411765163 1.0"/>
</material>
</visual>
<collision>
<origin xyz="0 0 0" rpy="3.141592653589793116 2.8115191019968956248e-32 0" />
<geometry>
<mesh filename="package:///dc15_a01_horn_idle2_dummy.stl"/>
</geometry>
</collision>
<visual>
<origin xyz="-3.4694469519536141888e-18 -9.7144514654701197287e-17 -3.4694469519536141888e-18" rpy="1.570796326794896558 2.1124562256396357684e-28 1.2621774483536382266e-29" />
<geometry>
<mesh filename="package:///axis_to_axis.stl"/>
</geometry>
<material name="axis_to_axis_material">
<color rgba="0.28235294117647058432 0.25490196078431370807 0.25490196078431370807 1.0"/>
</material>
</visual>
<collision>
<origin xyz="-3.4694469519536141888e-18 -9.7144514654701197287e-17 -3.4694469519536141888e-18" rpy="1.570796326794896558 2.1124562256396357684e-28 1.2621774483536382266e-29" />
<geometry>
<mesh filename="package:///axis_to_axis.stl"/>
</geometry>
</collision>
<inertial>
<origin xyz="-2.3254920341635024232e-14 -0.032499766606981929373 0.011647932076650640426" rpy="0 0 0"/>
<mass value="0.021984415624223832553" />
<inertia ixx="1.415765603439667777e-05" ixy="2.0746630350688615709e-21"  ixz="6.3654234639713728911e-18" iyy="4.6484934107514758433e-06" iyz="-5.9518761701327196045e-11" izz="1.0918388527634613106e-05" />
</inertial>
</link>

<link name="head_pitch_yaw">
<visual>
<origin xyz="0.034499999999999572675 2.7755575615628913511e-17 -0.011500000000000006745" rpy="3.9443045259401822497e-31 1.570796326794896558 0" />
<geometry>
<mesh filename="package:///dc15_a01_case_f_dummy.stl"/>
</geometry>
<material name="dc15_a01_case_f_dummy_material">
<color rgba="0.28235294117647058432 0.25490196078431370807 0.25490196078431370807 1.0"/>
</material>
</visual>
<collision>
<origin xyz="0.034499999999999572675 2.7755575615628913511e-17 -0.011500000000000006745" rpy="3.9443045259401822497e-31 1.570796326794896558 0" />
<geometry>
<mesh filename="package:///dc15_a01_case_f_dummy.stl"/>
</geometry>
</collision>
<visual>
<origin xyz="0.034499999999999572675 2.7755575615628913511e-17 -0.011500000000000006745" rpy="-1.2227344030942170662e-29 1.5707963267948961139 0" />
<geometry>
<mesh filename="package:///dc15_a01_case_m_dummy.stl"/>
</geometry>
<material name="dc15_a01_case_m_dummy_material">
<color rgba="0.28235294117647058432 0.25490196078431370807 0.25490196078431370807 1.0"/>
</material>
</visual>
<collision>
<origin xyz="0.034499999999999572675 2.7755575615628913511e-17 -0.011500000000000006745" rpy="-1.2227344030942170662e-29 1.5707963267948961139 0" />
<geometry>
<mesh filename="package:///dc15_a01_case_m_dummy.stl"/>
</geometry>
</collision>
<visual>
<origin xyz="0.014999999999999805156 3.1225022567582527699e-17 -0.011499999999999996336" rpy="3.9443045259401822497e-31 1.570796326794896558 0" />
<geometry>
<mesh filename="package:///dc15_a01_case_b_dummy.stl"/>
</geometry>
<material name="dc15_a01_case_b_dummy_material">
<color rgba="0.28235294117647058432 0.25490196078431370807 0.25490196078431370807 1.0"/>
</material>
</visual>
<collision>
<origin xyz="0.014999999999999805156 3.1225022567582527699e-17 -0.011499999999999996336" rpy="3.9443045259401822497e-31 1.570796326794896558 0" />
<geometry>
<mesh filename="package:///dc15_a01_case_b_dummy.stl"/>
</geometry>
</collision>
<visual>
<origin xyz="-1.3877787807814456755e-17 -3.4694469519536141888e-18 -0.0035000000000000083128" rpy="3.8285686989269040753e-16 -1.8369701987210025704e-16 1.2227344030942170662e-29" />
<geometry>
<mesh filename="package:///dc15_a01_case_f_dummy.stl"/>
</geometry>
<material name="dc15_a01_case_f_dummy_material">
<color rgba="0.28235294117647058432 0.25490196078431370807 0.25490196078431370807 1.0"/>
</material>
</visual>
<collision>
<origin xyz="-1.3877787807814456755e-17 -3.4694469519536141888e-18 -0.0035000000000000083128" rpy="3.8285686989269040753e-16 -1.8369701987210025704e-16 1.2227344030942170662e-29" />
<geometry>
<mesh filename="package:///dc15_a01_case_f_dummy.stl"/>
</geometry>
</collision>
<visual>
<origin xyz="-1.3877787807814456755e-17 -3.4694469519536141888e-18 -0.0034999999999999996392" rpy="7.8523839887012719256e-32 -7.0229937281399423577e-31 -3.9443045259401822497e-31" />
<geometry>
<mesh filename="package:///dc15_a01_case_m_dummy.stl"/>
</geometry>
<material name="dc15_a01_case_m_dummy_material">
<color rgba="0.28235294117647058432 0.25490196078431370807 0.25490196078431370807 1.0"/>
</material>
</visual>
<collision>
<origin xyz="-1.3877787807814456755e-17 -3.4694469519536141888e-18 -0.0034999999999999996392" rpy="7.8523839887012719256e-32 -7.0229937281399423577e-31 -3.9443045259401822497e-31" />
<geometry>
<mesh filename="package:///dc15_a01_case_m_dummy.stl"/>
</geometry>
</collision>
<visual>
<origin xyz="6.9388939039072283776e-17 0 -0.023000000000000003081" rpy="3.8285686989269040753e-16 -1.8369701987210025704e-16 1.2227344030942170662e-29" />
<geometry>
<mesh filename="package:///dc15_a01_case_b_dummy.stl"/>
</geometry>
<material name="dc15_a01_case_b_dummy_material">
<color rgba="0.28235294117647058432 0.25490196078431370807 0.25490196078431370807 1.0"/>
</material>
</visual>
<collision>
<origin xyz="6.9388939039072283776e-17 0 -0.023000000000000003081" rpy="3.8285686989269040753e-16 -1.8369701987210025704e-16 1.2227344030942170662e-29" />
<geometry>
<mesh filename="package:///dc15_a01_case_b_dummy.stl"/>
</geometry>
</collision>
<inertial>
<origin xyz="0.013398938364341871771 -0.0075371012414029167972 -0.011366050030856254122" rpy="0 0 0"/>
<mass value="0.035531283067773151985" />
<inertia ixx="4.7367513495907636887e-06" ixy="5.9649128769736445849e-09"  ixz="7.0827477552616218816e-08" iyy="8.9529308450967763205e-06" iyz="2.4524841156376425376e-09" izz="1.1100686057209022326e-05" />
</inertial>
</link>

<link name="head_assembly">
<visual>
<origin xyz="-7.2858385991025897965e-17 0 -0.0050000000000000321965" rpy="1.0788703875010418567e-27 2.4849118514469898508e-29 2.4271100185061689909e-28" />
<geometry>
<mesh filename="package:///part_1.stl"/>
</geometry>
<material name="part_1_material">
<color rgba="0.91764705882352937127 0.91764705882352937127 0.91764705882352937127 1.0"/>
</material>
</visual>
<collision>
<origin xyz="-7.2858385991025897965e-17 0 -0.0050000000000000321965" rpy="1.0788703875010418567e-27 2.4849118514469898508e-29 2.4271100185061689909e-28" />
<geometry>
<mesh filename="package:///part_1.stl"/>
</geometry>
</collision>
<visual>
<origin xyz="0 0 0" rpy="3.141592653589793116 -3.9443045261110005325e-31 -6.0941731135059409671e-32" />
<geometry>
<mesh filename="package:///dc15_a01_horn_idle2_dummy.stl"/>
</geometry>
<material name="dc15_a01_horn_idle2_dummy_material">
<color rgba="0.2313725490196078538 0.38039215686274507888 0.7058823529411765163 1.0"/>
</material>
</visual>
<collision>
<origin xyz="0 0 0" rpy="3.141592653589793116 -3.9443045261110005325e-31 -6.0941731135059409671e-32" />
<geometry>
<mesh filename="package:///dc15_a01_horn_idle2_dummy.stl"/>
</geometry>
</collision>
<inertial>
<origin xyz="0.0076797565947340730094 -7.5471600186113898504e-05 0.0068537011969674131034" rpy="0 0 0"/>
<mass value="0.16975667017560497341" />
<inertia ixx="0.00024450121571474760099" ixy="8.3046448323145042537e-07"  ixz="4.4911601866688117917e-06" iyy="0.00040969075937649694847" iyz="7.2339293580165411033e-08" izz="0.00061408451315825643164" />
</inertial>
</link>

<link name="head_front">
<inertial>
<origin xyz="0 0 0" rpy="0 0 0" />
<mass value="1e-9" />
<inertia ixx="0" ixy="0" ixz="0" iyy="0" iyz="0" izz="0" />
</inertial>
</link>
<joint name="head_front_frame" type="fixed">
<origin xyz="0.07750000000000084599 1.1622647289044607533e-16 0.012500000000000205391" rpy="-3.141592653589793116 2.4849118514469898508e-29 -6.483073905965054422e-28" />
<parent link="head_assembly" />
<child link="head_front" />
<axis xyz="0 0 0"/>
</joint>

<joint name="head_yaw" type="revolute">
<origin xyz="0.037999999999999575784 2.7755575615628913511e-17 -0.01150000000000000501" rpy="1.57079632679489678 2.7183456742966672707e-16 -1.570796326794896558" />
<parent link="head_pitch_yaw" />
<child link="head_assembly" />
<axis xyz="0 0 1"/>
<limit effort="1" velocity="20" lower="-2.0943951023931952626" upper="2.0943951023931952626"/>
<joint_properties friction="0.0"/>
</joint>

<joint name="head_pitch2" type="revolute">
<origin xyz="-3.4694469519536141888e-18 -0.06499999999999912792 3.4694469519536141888e-18" rpy="-3.141592653589793116 1.1051075666822306675e-27 -1.570796326794896336" />
<parent link="head_link" />
<child link="head_pitch_yaw" />
<axis xyz="0 0 1"/>
<limit effort="1" velocity="20" lower="-1.3089969389957472057" upper="0.69813170079773179122"/>
<joint_properties friction="0.0"/>
</joint>

<joint name="head_pitch1" type="revolute">
<origin xyz="0.030627100485025721827 -0.018103896430577130772 0.055078922950961027583" rpy="-1.570796326794881459 -6.2505556286397272481e-14 1.0547118733946938852e-15" />
<parent link="body_module" />
<child link="head_link" />
<axis xyz="0 0 1"/>
<limit effort="1" velocity="20" lower="-1.3089969389957472057" upper="0.1745329251994329478"/>
<joint_properties friction="0.0"/>
</joint>


</robot>
