<robot name="BDX">
    <mujoco>
        <compiler fusestatic="false"/>
    </mujoco>
    <link name="body_module">
        <visual>
            <origin xyz="-0.049872899514971674728 -0.1141428912905502191 0.01507892295095538196" rpy="-6.2367202746833250932e-14 -1.5074919608395581653e-14 1.5707963267948974462" />
            <geometry>
                <mesh filename="package:///cage_bottom.stl"/>
            </geometry>
            <material name="cage_bottom_material">
                <color rgba="0.64705882352941179736 0.64705882352941179736 0.64705882352941179736 1.0"/>
            </material>
        </visual>
        <collision>
            <origin xyz="-0.049872899514971674728 -0.1141428912905502191 0.01507892295095538196" rpy="-6.2367202746833250932e-14 -1.5074919608395581653e-14 1.5707963267948974462" />
            <geometry>
                <mesh filename="package:///cage_bottom.stl"/>
            </geometry>
        </collision>
        <visual>
            <origin xyz="-0.0423728995149717097 0.028396103569423458701 0.013578922950958013938" rpy="-1.570796326794881459 -6.250077645448205144e-14 8.881784197007373884e-16" />
            <geometry>
                <mesh filename="package:///power_switch.stl"/>
            </geometry>
            <material name="power_switch_material">
                <color rgba="0.90196078431372550543 0.90196078431372550543 0.90196078431372550543 1.0"/>
            </material>
        </visual>
        <collision>
            <origin xyz="-0.0423728995149717097 0.028396103569423458701 0.013578922950958013938" rpy="-1.570796326794881459 -6.250077645448205144e-14 8.881784197007373884e-16" />
            <geometry>
                <mesh filename="package:///power_switch.stl"/>
            </geometry>
        </collision>
        <visual>
            <origin xyz="-0.026822899514971677154 -0.11414289129055016359 0.015078922950957383831" rpy="-6.3477211383748394106e-14 -1.5130430759629774043e-14 1.5707963267948974462" />
            <geometry>
                <mesh filename="package:///rasp_spacer.stl"/>
            </geometry>
            <material name="rasp_spacer_material">
                <color rgba="0.76862745098039220171 0.88627450980392152857 0.95294117647058818044 1.0"/>
            </material>
        </visual>
        <collision>
            <origin xyz="-0.026822899514971677154 -0.11414289129055016359 0.015078922950957383831" rpy="-6.3477211383748394106e-14 -1.5130430759629774043e-14 1.5707963267948974462" />
            <geometry>
                <mesh filename="package:///rasp_spacer.stl"/>
            </geometry>
        </collision>
        <visual>
            <origin xyz="-0.049872899514971702484 -0.1141428912905502191 0.01507892295095519114" rpy="-6.3144144476363674421e-14 -1.5463497667014358043e-14 1.5707963267948976682" />
            <geometry>
                <mesh filename="package:///rasp_spacer.stl"/>
            </geometry>
            <material name="rasp_spacer_material">
                <color rgba="0.76862745098039220171 0.88627450980392152857 0.95294117647058818044 1.0"/>
            </material>
        </visual>
        <collision>
            <origin xyz="-0.049872899514971702484 -0.1141428912905502191 0.01507892295095519114" rpy="-6.3144144476363674421e-14 -1.5463497667014358043e-14 1.5707963267948976682" />
            <geometry>
                <mesh filename="package:///rasp_spacer.stl"/>
            </geometry>
        </collision>
        <visual>
            <origin xyz="-0.049872899514971757995 -0.11414289129055026073 0.015078922950955218896" rpy="-6.2367202746832013998e-14 -1.5074919608395587964e-14 1.5707963267948974462" />
            <geometry>
                <mesh filename="package:///cage_top.stl"/>
            </geometry>
            <material name="cage_top_material">
                <color rgba="0.64705882352941179736 0.64705882352941179736 0.64705882352941179736 1.0"/>
            </material>
        </visual>
        <collision>
            <origin xyz="-0.049872899514971757995 -0.11414289129055026073 0.015078922950955218896" rpy="-6.2367202746832013998e-14 -1.5074919608395587964e-14 1.5707963267948974462" />
            <geometry>
                <mesh filename="package:///cage_top.stl"/>
            </geometry>
        </collision>
        <visual>
            <origin xyz="0.040377100485030542609 -0.034103896430575909859 -0.020971077049037202544" rpy="-1.570796326794881681 -6.1207776584054055418e-14 1.6001680655052159878e-15" />
            <geometry>
                <mesh filename="package:///usb_c_charger.stl"/>
            </geometry>
            <material name="usb_c_charger_material">
                <color rgba="0.61568627450980395466 0.81176470588235294379 0.92941176470588238168 1.0"/>
            </material>
        </visual>
        <collision>
            <origin xyz="0.040377100485030542609 -0.034103896430575909859 -0.020971077049037202544" rpy="-1.570796326794881681 -6.1207776584054055418e-14 1.6001680655052159878e-15" />
            <geometry>
                <mesh filename="package:///usb_c_charger.stl"/>
            </geometry>
        </collision>
        <visual>
            <origin xyz="-0.034372899514973721813 -0.0056038964305771717112 0.030078922950957640015" rpy="3.1415926535897775729 6.3144144476363674421e-14 -3.1415926535897922278" />
            <geometry>
                <mesh filename="package:///bno055.stl"/>
            </geometry>
            <material name="bno055_material">
                <color rgba="0.61568627450980395466 0.81176470588235294379 0.92941176470588238168 1.0"/>
            </material>
        </visual>
        <collision>
            <origin xyz="-0.034372899514973721813 -0.0056038964305771717112 0.030078922950957640015" rpy="3.1415926535897775729 6.3144144476363674421e-14 -3.1415926535897922278" />
            <geometry>
                <mesh filename="package:///bno055.stl"/>
            </geometry>
        </collision>
        <visual>
            <origin xyz="-0.049872899514971653911 -0.11414289129055023297 0.015078922950955361143" rpy="-6.2089646990676974419e-14 -1.5074919608395581653e-14 1.5707963267948974462" />
            <geometry>
                <mesh filename="package:///front_cover.stl"/>
            </geometry>
            <material name="front_cover_material">
                <color rgba="0.64705882352941179736 0.64705882352941179736 0.64705882352941179736 1.0"/>
            </material>
        </visual>
        <collision>
            <origin xyz="-0.049872899514971653911 -0.11414289129055023297 0.015078922950955361143" rpy="-6.2089646990676974419e-14 -1.5074919608395581653e-14 1.5707963267948974462" />
            <geometry>
                <mesh filename="package:///front_cover.stl"/>
            </geometry>
        </collision>
        <visual>
            <origin xyz="0.00012710048502939663706 -0.0066038964305761768681 -0.0049210770490394940835" rpy="-6.2367202746833263554e-14 -1.5074919608395581653e-14 1.5707963267948974462" />
            <geometry>
                <mesh filename="package:///body_part.stl"/>
            </geometry>
            <material name="body_part_material">
                <color rgba="0.30196078431372547213 0.29019607843137257275 0.26274509803921569651 1.0"/>
            </material>
        </visual>
        <collision>
            <origin xyz="0.00012710048502939663706 -0.0066038964305761768681 -0.0049210770490394940835" rpy="-6.2367202746833263554e-14 -1.5074919608395581653e-14 1.5707963267948974462" />
            <geometry>
                <mesh filename="package:///body_part.stl"/>
            </geometry>
        </collision>
        <visual>
            <origin xyz="-0.049872899514971640034 -0.11414289129055014971 0.015078922950956266669" rpy="-6.159026101730031571e-14 -1.5074919608395572187e-14 1.5707963267948974462" />
            <geometry>
                <mesh filename="package:///cage_bottom_battery_hold.stl"/>
            </geometry>
            <material name="cage_bottom_battery_hold_material">
                <color rgba="0.64705882352941179736 0.64705882352941179736 0.64705882352941179736 1.0"/>
            </material>
        </visual>
        <collision>
            <origin xyz="-0.049872899514971640034 -0.11414289129055014971 0.015078922950956266669" rpy="-6.159026101730031571e-14 -1.5074919608395572187e-14 1.5707963267948974462" />
            <geometry>
                <mesh filename="package:///cage_bottom_battery_hold.stl"/>
            </geometry>
        </collision>
        <visual>
            <origin xyz="0.00012710048502939663706 -0.0066038964305761777354 -0.0049210770490394958182" rpy="-6.2367202746833364528e-14 -1.5074919608395578498e-14 1.5707963267948976682" />
            <geometry>
                <mesh filename="package:///spacer.stl"/>
            </geometry>
            <material name="spacer_material">
                <color rgba="0.91764705882352937127 0.91764705882352937127 0.91764705882352937127 1.0"/>
            </material>
        </visual>
        <collision>
            <origin xyz="0.00012710048502939663706 -0.0066038964305761777354 -0.0049210770490394958182" rpy="-6.2367202746833364528e-14 -1.5074919608395578498e-14 1.5707963267948976682" />
            <geometry>
                <mesh filename="package:///spacer.stl"/>
            </geometry>
        </collision>
        <visual>
            <origin xyz="0.0073591609532240691294 -0.034103896430576687016 0.031251164398389409682" rpy="1.5707963267948821251 6.2939567726915221061e-14 -3.1415926535897926719" />
            <geometry>
                <mesh filename="package:///bms.stl"/>
            </geometry>
            <material name="bms_material">
                <color rgba="0.2313725490196078538 0.38039215686274507888 0.7058823529411765163 1.0"/>
            </material>
        </visual>
        <collision>
            <origin xyz="0.0073591609532240691294 -0.034103896430576687016 0.031251164398389409682" rpy="1.5707963267948821251 6.2939567726915221061e-14 -3.1415926535897926719" />
            <geometry>
                <mesh filename="package:///bms.stl"/>
            </geometry>
        </collision>
        <visual>
            <origin xyz="-0.049872899514971674728 -0.1141428912905502191 0.015078922950955399307" rpy="-6.2367202746833263554e-14 -1.5074919608395581653e-14 1.5707963267948974462" />
            <geometry>
                <mesh filename="package:///cage_back.stl"/>
            </geometry>
            <material name="cage_back_material">
                <color rgba="0.64705882352941179736 0.64705882352941179736 0.64705882352941179736 1.0"/>
            </material>
        </visual>
        <collision>
            <origin xyz="-0.049872899514971674728 -0.1141428912905502191 0.015078922950955399307" rpy="-6.2367202746833263554e-14 -1.5074919608395581653e-14 1.5707963267948974462" />
            <geometry>
                <mesh filename="package:///cage_back.stl"/>
            </geometry>
        </collision>
        <visual>
            <origin xyz="0.00012710048502949378157 -0.006603896430576145643 -0.0059210770490396615051" rpy="-6.3144144476364621054e-14 -1.5463497667014348577e-14 1.5707963267948978903" />
            <geometry>
                <mesh filename="package:///holder_u2d2_power_hub.stl"/>
            </geometry>
            <material name="holder_u2d2_power_hub_material">
                <color rgba="0.30196078431372547213 0.30196078431372547213 0.30196078431372547213 1.0"/>
            </material>
        </visual>
        <collision>
            <origin xyz="0.00012710048502949378157 -0.006603896430576145643 -0.0059210770490396615051" rpy="-6.3144144476364621054e-14 -1.5463497667014348577e-14 1.5707963267948978903" />
            <geometry>
                <mesh filename="package:///holder_u2d2_power_hub.stl"/>
            </geometry>
        </collision>
        <visual>
            <origin xyz="-0.049872899514968108137 -0.11414289129054938643 -0.042971077049042571971" rpy="-6.2922314259144567025e-14 -1.5519008818240349435e-14 1.5707963267948978903" />
            <geometry>
                <mesh filename="package:///rasp_spacer.stl"/>
            </geometry>
            <material name="rasp_spacer_material">
                <color rgba="0.76862745098039220171 0.88627450980392152857 0.95294117647058818044 1.0"/>
            </material>
        </visual>
        <collision>
            <origin xyz="-0.049872899514968108137 -0.11414289129054938643 -0.042971077049042571971" rpy="-6.2922314259144567025e-14 -1.5519008818240349435e-14 1.5707963267948978903" />
            <geometry>
                <mesh filename="package:///rasp_spacer.stl"/>
            </geometry>
        </collision>
        <visual>
            <origin xyz="0.00012710048502787528457 -0.031603896430576552956 0.019578922950959622151" rpy="-1.5074919608395890887e-14 6.2367202746832013998e-14 -3.1415926535897922278" />
            <geometry>
                <mesh filename="package:///dc15_a01_case_f_dummy.stl"/>
            </geometry>
            <material name="dc15_a01_case_f_dummy_material">
                <color rgba="0.28235294117647058432 0.25490196078431370807 0.25490196078431370807 1.0"/>
            </material>
        </visual>
        <collision>
            <origin xyz="0.00012710048502787528457 -0.031603896430576552956 0.019578922950959622151" rpy="-1.5074919608395890887e-14 6.2367202746832013998e-14 -3.1415926535897922278" />
            <geometry>
                <mesh filename="package:///dc15_a01_case_f_dummy.stl"/>
            </geometry>
        </collision>
        <visual>
            <origin xyz="0.00012710048502787181512 -0.031603896430576552956 0.019578922950959622151" rpy="-1.507491960839588142e-14 6.2367202746832013998e-14 -3.1415926535897922278" />
            <geometry>
                <mesh filename="package:///dc15_a01_case_m_dummy.stl"/>
            </geometry>
            <material name="dc15_a01_case_m_dummy_material">
                <color rgba="0.28235294117647058432 0.25490196078431370807 0.25490196078431370807 1.0"/>
            </material>
        </visual>
        <collision>
            <origin xyz="0.00012710048502787181512 -0.031603896430576552956 0.019578922950959622151" rpy="-1.507491960839588142e-14 6.2367202746832013998e-14 -3.1415926535897922278" />
            <geometry>
                <mesh filename="package:///dc15_a01_case_m_dummy.stl"/>
            </geometry>
        </collision>
        <visual>
            <origin xyz="0.000127100485029089591 -0.031603896430576247645 7.8922950960027236922e-05" rpy="-1.5074919608395890887e-14 6.2367202746832013998e-14 -3.1415926535897922278" />
            <geometry>
                <mesh filename="package:///dc15_a01_case_b_dummy.stl"/>
            </geometry>
            <material name="dc15_a01_case_b_dummy_material">
                <color rgba="0.28235294117647058432 0.25490196078431370807 0.25490196078431370807 1.0"/>
            </material>
        </visual>
        <collision>
            <origin xyz="0.000127100485029089591 -0.031603896430576247645 7.8922950960027236922e-05" rpy="-1.5074919608395890887e-14 6.2367202746832013998e-14 -3.1415926535897922278" />
            <geometry>
                <mesh filename="package:///dc15_a01_case_b_dummy.stl"/>
            </geometry>
        </collision>
        <visual>
            <origin xyz="0.00012710048502783018176 0.018396103569423449819 0.019578922950960368082" rpy="1.5074919608395890887e-14 -6.2367202746832013998e-14 9.4368957093184552907e-16" />
            <geometry>
                <mesh filename="package:///dc15_a01_case_f_dummy.stl"/>
            </geometry>
            <material name="dc15_a01_case_f_dummy_material">
                <color rgba="0.28235294117647058432 0.25490196078431370807 0.25490196078431370807 1.0"/>
            </material>
        </visual>
        <collision>
            <origin xyz="0.00012710048502783018176 0.018396103569423449819 0.019578922950960368082" rpy="1.5074919608395890887e-14 -6.2367202746832013998e-14 9.4368957093184552907e-16" />
            <geometry>
                <mesh filename="package:///dc15_a01_case_f_dummy.stl"/>
            </geometry>
        </collision>
        <visual>
            <origin xyz="0.00012710048502782844704 0.018396103569423449819 0.019578922950960364613" rpy="1.5074919608395887731e-14 -6.2367202746832013998e-14 9.2165518404232636261e-16" />
            <geometry>
                <mesh filename="package:///dc15_a01_case_m_dummy.stl"/>
            </geometry>
            <material name="dc15_a01_case_m_dummy_material">
                <color rgba="0.28235294117647058432 0.25490196078431370807 0.25490196078431370807 1.0"/>
            </material>
        </visual>
        <collision>
            <origin xyz="0.00012710048502782844704 0.018396103569423449819 0.019578922950960364613" rpy="1.5074919608395887731e-14 -6.2367202746832013998e-14 9.2165518404232636261e-16" />
            <geometry>
                <mesh filename="package:///dc15_a01_case_m_dummy.stl"/>
            </geometry>
        </collision>
        <visual>
            <origin xyz="0.00012710048502904622292 0.018396103569423741253 7.8922950960772300655e-05" rpy="1.5074919608395890887e-14 -6.2367202746832013998e-14 9.4368957093184552907e-16" />
            <geometry>
                <mesh filename="package:///dc15_a01_case_b_dummy.stl"/>
            </geometry>
            <material name="dc15_a01_case_b_dummy_material">
                <color rgba="0.28235294117647058432 0.25490196078431370807 0.25490196078431370807 1.0"/>
            </material>
        </visual>
        <collision>
            <origin xyz="0.00012710048502904622292 0.018396103569423741253 7.8922950960772300655e-05" rpy="1.5074919608395890887e-14 -6.2367202746832013998e-14 9.4368957093184552907e-16" />
            <geometry>
                <mesh filename="package:///dc15_a01_case_b_dummy.stl"/>
            </geometry>
        </collision>
        <visual>
            <origin xyz="0.030627100485025753052 -0.014603896430577117255 0.055078922950960867988" rpy="1.5707963267948956698 1.5707963267948321651 0" />
            <geometry>
                <mesh filename="package:///dc15_a01_case_f_dummy.stl"/>
            </geometry>
            <material name="dc15_a01_case_f_dummy_material">
                <color rgba="0.28235294117647058432 0.25490196078431370807 0.25490196078431370807 1.0"/>
            </material>
        </visual>
        <collision>
            <origin xyz="0.030627100485025753052 -0.014603896430577117255 0.055078922950960867988" rpy="1.5707963267948956698 1.5707963267948321651 0" />
            <geometry>
                <mesh filename="package:///dc15_a01_case_f_dummy.stl"/>
            </geometry>
        </collision>
        <visual>
            <origin xyz="0.030627100485025753052 -0.014603896430577117255 0.055078922950960861049" rpy="1.5707963267948956698 1.5707963267948323871 0" />
            <geometry>
                <mesh filename="package:///dc15_a01_case_m_dummy.stl"/>
            </geometry>
            <material name="dc15_a01_case_m_dummy_material">
                <color rgba="0.28235294117647058432 0.25490196078431370807 0.25490196078431370807 1.0"/>
            </material>
        </visual>
        <collision>
            <origin xyz="0.030627100485025753052 -0.014603896430577117255 0.055078922950960861049" rpy="1.5707963267948956698 1.5707963267948323871 0" />
            <geometry>
                <mesh filename="package:///dc15_a01_case_m_dummy.stl"/>
            </geometry>
        </collision>
        <visual>
            <origin xyz="0.030627100485025739174 0.0048961035694229330245 0.055078922950961152483" rpy="1.5707963267948956698 1.5707963267948323871 0" />
            <geometry>
                <mesh filename="package:///dc15_a01_case_b_dummy.stl"/>
            </geometry>
            <material name="dc15_a01_case_b_dummy_material">
                <color rgba="0.28235294117647058432 0.25490196078431370807 0.25490196078431370807 1.0"/>
            </material>
        </visual>
        <collision>
            <origin xyz="0.030627100485025739174 0.0048961035694229330245 0.055078922950961152483" rpy="1.5707963267948956698 1.5707963267948323871 0" />
            <geometry>
                <mesh filename="package:///dc15_a01_case_b_dummy.stl"/>
            </geometry>
        </collision>
        <visual>
            <origin xyz="-0.034872899514969260548 -0.017103896430575932924 -0.02492107704904125004" rpy="1.5707963267948190644 0.62050967106611187862 1.5707963267948525932" />
            <geometry>
                <mesh filename="package:///cell.stl"/>
            </geometry>
            <material name="cell_material">
                <color rgba="0.61568627450980395466 0.81176470588235294379 0.92941176470588238168 1.0"/>
            </material>
        </visual>
        <collision>
            <origin xyz="-0.034872899514969260548 -0.017103896430575932924 -0.02492107704904125004" rpy="1.5707963267948190644 0.62050967106611187862 1.5707963267948525932" />
            <geometry>
                <mesh filename="package:///cell.stl"/>
            </geometry>
        </collision>
        <visual>
            <origin xyz="-0.0013144211052831464293 -0.070128354987943064547 -0.034921077049039919715" rpy="1.4843623144945517932e-14 -6.2367202746866143276e-14 8.8817841970261507457e-16" />
            <geometry>
                <mesh filename="package:///holder.stl"/>
            </geometry>
            <material name="holder_material">
                <color rgba="0.64705882352941179736 0.64705882352941179736 0.64705882352941179736 1.0"/>
            </material>
        </visual>
        <collision>
            <origin xyz="-0.0013144211052831464293 -0.070128354987943064547 -0.034921077049039919715" rpy="1.4843623144945517932e-14 -6.2367202746866143276e-14 8.8817841970261507457e-16" />
            <geometry>
                <mesh filename="package:///holder.stl"/>
            </geometry>
        </collision>
        <visual>
            <origin xyz="0.030127100485030720856 0.003896103569424154249 -0.024921077049036836903" rpy="-1.5707963267949891506 -0.82053085802352232481 1.5707963267949656139" />
            <geometry>
                <mesh filename="package:///cell.stl"/>
            </geometry>
            <material name="cell_material">
                <color rgba="0.61568627450980395466 0.81176470588235294379 0.92941176470588238168 1.0"/>
            </material>
        </visual>
        <collision>
            <origin xyz="0.030127100485030720856 0.003896103569424154249 -0.024921077049036836903" rpy="-1.5707963267949891506 -0.82053085802352232481 1.5707963267949656139" />
            <geometry>
                <mesh filename="package:///cell.stl"/>
            </geometry>
        </collision>
        <visual>
            <origin xyz="-0.036872899514972523605 -0.039603896430576671084 0.027578922950957693305" rpy="2.2204460491569067728e-16 -1.5707963267948328312 0" />
            <geometry>
                <mesh filename="package:///raspberrypizerow.stl"/>
            </geometry>
            <material name="raspberrypizerow_material">
                <color rgba="0.64705882352941179736 0.64705882352941179736 0.64705882352941179736 1.0"/>
            </material>
        </visual>
        <collision>
            <origin xyz="-0.036872899514972523605 -0.039603896430576671084 0.027578922950957693305" rpy="2.2204460491569067728e-16 -1.5707963267948328312 0" />
            <geometry>
                <mesh filename="package:///raspberrypizerow.stl"/>
            </geometry>
        </collision>
        <visual>
            <origin xyz="-0.036872899514972523605 -0.039603896430576671084 0.027578922950957693305" rpy="2.2204460491569067728e-16 -1.5707963267948328312 0" />
            <geometry>
                <mesh filename="package:///raspberrypizerow.stl"/>
            </geometry>
            <material name="raspberrypizerow_material">
                <color rgba="0.2313725490196078538 0.38039215686274507888 0.7058823529411765163 1.0"/>
            </material>
        </visual>
        <collision>
            <origin xyz="-0.036872899514972523605 -0.039603896430576671084 0.027578922950957693305" rpy="2.2204460491569067728e-16 -1.5707963267948328312 0" />
            <geometry>
                <mesh filename="package:///raspberrypizerow.stl"/>
            </geometry>
        </collision>
        <visual>
            <origin xyz="-0.028872899514992861336 -0.012353896430585816629 0.046778922950959013483" rpy="1.5707963267950224573 -6.4032322896069201773e-14 1.1257661469699141594e-13" />
            <geometry>
                <mesh filename="package:///jst-b3b-eh-a.prt.1.stl"/>
            </geometry>
            <material name="jst-b3b-eh-a.prt.1_material">
                <color rgba="0.75294117647058822484 0.75294117647058822484 0.75294117647058822484 1.0"/>
            </material>
        </visual>
        <collision>
            <origin xyz="-0.028872899514992861336 -0.012353896430585816629 0.046778922950959013483" rpy="1.5707963267950224573 -6.4032322896069201773e-14 1.1257661469699141594e-13" />
            <geometry>
                <mesh filename="package:///jst-b3b-eh-a.prt.1.stl"/>
            </geometry>
        </collision>
        <visual>
            <origin xyz="-0.016922899514992786191 -0.012353896430584484362 0.046778922950959776761" rpy="1.5707963267950224573 -6.4032322896069201773e-14 1.1257661469699141594e-13" />
            <geometry>
                <mesh filename="package:///jst-b4b-eh-a.prt.1.stl"/>
            </geometry>
            <material name="jst-b4b-eh-a.prt.1_material">
                <color rgba="0.75294117647058822484 0.75294117647058822484 0.75294117647058822484 1.0"/>
            </material>
        </visual>
        <collision>
            <origin xyz="-0.016922899514992786191 -0.012353896430584484362 0.046778922950959776761" rpy="1.5707963267950224573 -6.4032322896069201773e-14 1.1257661469699141594e-13" />
            <geometry>
                <mesh filename="package:///jst-b4b-eh-a.prt.1.stl"/>
            </geometry>
        </collision>
        <visual>
            <origin xyz="0.051560600485445980123 -0.18184389304755696481 0.051797851409400325062" rpy="-6.3171900051979404309e-14 -1.5102675184011226344e-14 1.5707963267948974462" />
            <geometry>
                <mesh filename="package:///board.stl"/>
            </geometry>
            <material name="board_material">
                <color rgba="0 0 0 1.0"/>
            </material>
        </visual>
        <collision>
            <origin xyz="0.051560600485445980123 -0.18184389304755696481 0.051797851409400325062" rpy="-6.3171900051979404309e-14 -1.5102675184011226344e-14 1.5707963267948974462" />
            <geometry>
                <mesh filename="package:///board.stl"/>
            </geometry>
        </collision>
        <visual>
            <origin xyz="-0.01692289951499417397 -0.00045389643058443493451 0.046778922950959957172" rpy="1.5707963267950224573 -6.4032322896069201773e-14 1.1257661469699141594e-13" />
            <geometry>
                <mesh filename="package:///jst-b4b-eh-a.prt.1.stl"/>
            </geometry>
            <material name="jst-b4b-eh-a.prt.1_material">
                <color rgba="0.75294117647058822484 0.75294117647058822484 0.75294117647058822484 1.0"/>
            </material>
        </visual>
        <collision>
            <origin xyz="-0.01692289951499417397 -0.00045389643058443493451 0.046778922950959957172" rpy="1.5707963267950224573 -6.4032322896069201773e-14 1.1257661469699141594e-13" />
            <geometry>
                <mesh filename="package:///jst-b4b-eh-a.prt.1.stl"/>
            </geometry>
        </collision>
        <visual>
            <origin xyz="-0.028872899514994193604 -0.00045389643058578107992 0.046778922950959193894" rpy="1.5707963267950224573 -6.4032322896069201773e-14 1.1257661469699141594e-13" />
            <geometry>
                <mesh filename="package:///jst-b3b-eh-a.prt.1.stl"/>
            </geometry>
            <material name="jst-b3b-eh-a.prt.1_material">
                <color rgba="0.75294117647058822484 0.75294117647058822484 0.75294117647058822484 1.0"/>
            </material>
        </visual>
        <collision>
            <origin xyz="-0.028872899514994193604 -0.00045389643058578107992 0.046778922950959193894" rpy="1.5707963267950224573 -6.4032322896069201773e-14 1.1257661469699141594e-13" />
            <geometry>
                <mesh filename="package:///jst-b3b-eh-a.prt.1.stl"/>
            </geometry>
        </collision>
        <visual>
            <origin xyz="-0.016922899514993507836 -0.0063538964305844790326 0.046778922950959866967" rpy="1.5707963267950224573 -6.4032322896069201773e-14 1.1257661469699141594e-13" />
            <geometry>
                <mesh filename="package:///jst-b4b-eh-a.prt.1.stl"/>
            </geometry>
            <material name="jst-b4b-eh-a.prt.1_material">
                <color rgba="0.75294117647058822484 0.75294117647058822484 0.75294117647058822484 1.0"/>
            </material>
        </visual>
        <collision>
            <origin xyz="-0.016922899514993507836 -0.0063538964305844790326 0.046778922950959866967" rpy="1.5707963267950224573 -6.4032322896069201773e-14 1.1257661469699141594e-13" />
            <geometry>
                <mesh filename="package:///jst-b4b-eh-a.prt.1.stl"/>
            </geometry>
        </collision>
        <visual>
            <origin xyz="-0.02887289951499352747 -0.006353896430585825178 0.046778922950959096749" rpy="1.5707963267950224573 -6.4032322896069201773e-14 1.1257661469699141594e-13" />
            <geometry>
                <mesh filename="package:///jst-b3b-eh-a.prt.1.stl"/>
            </geometry>
            <material name="jst-b3b-eh-a.prt.1_material">
                <color rgba="0.75294117647058822484 0.75294117647058822484 0.75294117647058822484 1.0"/>
            </material>
        </visual>
        <collision>
            <origin xyz="-0.02887289951499352747 -0.006353896430585825178 0.046778922950959096749" rpy="1.5707963267950224573 -6.4032322896069201773e-14 1.1257661469699141594e-13" />
            <geometry>
                <mesh filename="package:///jst-b3b-eh-a.prt.1.stl"/>
            </geometry>
        </collision>
        <visual>
            <origin xyz="-0.057837899514994489669 0.0028436473125530749295 0.04677892295095739672" rpy="1.5707963267950224573 -6.4032322896069201773e-14 1.1257661469699141594e-13" />
            <geometry>
                <mesh filename="package:///u2d2_casing.prt.stl"/>
            </geometry>
            <material name="u2d2_casing.prt_material">
                <color rgba="0.79607843137254896693 0.82352941176470584317 0.9372549019607843146 1.0"/>
            </material>
        </visual>
        <collision>
            <origin xyz="-0.057837899514994489669 0.0028436473125530749295 0.04677892295095739672" rpy="1.5707963267950224573 -6.4032322896069201773e-14 1.1257661469699141594e-13" />
            <geometry>
                <mesh filename="package:///u2d2_casing.prt.stl"/>
            </geometry>
        </collision>
        <visual>
            <origin xyz="-0.019937899514996120648 0.013643647312557228429 0.05477892295095819486" rpy="1.5707963267950224573 -6.4032322896069201773e-14 1.1257661469699141594e-13" />
            <geometry>
                <mesh filename="package:///jst-b3b-eh-a.prt.stl"/>
            </geometry>
            <material name="jst-b3b-eh-a.prt_material">
                <color rgba="0.75294117647058822484 0.75294117647058822484 0.75294117647058822484 1.0"/>
            </material>
        </visual>
        <collision>
            <origin xyz="-0.019937899514996120648 0.013643647312557228429 0.05477892295095819486" rpy="1.5707963267950224573 -6.4032322896069201773e-14 1.1257661469699141594e-13" />
            <geometry>
                <mesh filename="package:///jst-b3b-eh-a.prt.stl"/>
            </geometry>
        </collision>
        <visual>
            <origin xyz="-0.010037899514994882977 0.0049436473125585335409 0.054778922950958701399" rpy="1.5707963267947711028 6.3573688731349088676e-14 -3.141592653589673656" />
            <geometry>
                <mesh filename="package:///jst-b4b-ph-k-s.prt.stl"/>
            </geometry>
            <material name="jst-b4b-ph-k-s.prt_material">
                <color rgba="0.75294117647058822484 0.75294117647058822484 0.75294117647058822484 1.0"/>
            </material>
        </visual>
        <collision>
            <origin xyz="-0.010037899514994882977 0.0049436473125585335409 0.054778922950958701399" rpy="1.5707963267947711028 6.3573688731349088676e-14 -3.141592653589673656" />
            <geometry>
                <mesh filename="package:///jst-b4b-ph-k-s.prt.stl"/>
            </geometry>
        </collision>
        <visual>
            <origin xyz="-0.021187899514996593603 0.017493647312557109724 0.05477892295095819486" rpy="1.5707963267950224573 -6.4032322896069201773e-14 1.1257661469699141594e-13" />
            <geometry>
                <mesh filename="package:///jst-b4b-eh-a.prt.stl"/>
            </geometry>
            <material name="jst-b4b-eh-a.prt_material">
                <color rgba="0.75294117647058822484 0.75294117647058822484 0.75294117647058822484 1.0"/>
            </material>
        </visual>
        <collision>
            <origin xyz="-0.021187899514996593603 0.017493647312557109724 0.05477892295095819486" rpy="1.5707963267950224573 -6.4032322896069201773e-14 1.1257661469699141594e-13" />
            <geometry>
                <mesh filename="package:///jst-b4b-eh-a.prt.stl"/>
            </geometry>
        </collision>
        <visual>
            <origin xyz="-0.04604147405186335279 0.050591474436928254854 0.054778922950957119331" rpy="3.141592653589778017 6.4032322896068520197e-14 -3.1415926535896807614" />
            <geometry>
                <mesh filename="package:///pcb_u2d2.prt.stl"/>
            </geometry>
            <material name="pcb_u2d2.prt_material">
                <color rgba="0 0.29411764705882353921 0.65490196078431373028 1.0"/>
            </material>
        </visual>
        <collision>
            <origin xyz="-0.04604147405186335279 0.050591474436928254854 0.054778922950957119331" rpy="3.141592653589778017 6.4032322896068520197e-14 -3.1415926535896807614" />
            <geometry>
                <mesh filename="package:///pcb_u2d2.prt.stl"/>
            </geometry>
        </collision>
        <visual>
            <origin xyz="-0.055737814613989480894 0.011843647312554005796 0.056940372525141912108" rpy="1.5707963267950224573 -6.4032322896069201773e-14 1.1257661469699141594e-13" />
            <geometry>
                <mesh filename="package:///micro_usb_2_0_connector__ab_rec.prt.stl"/>
            </geometry>
            <material name="micro_usb_2_0_connector__ab_rec.prt_material">
                <color rgba="0.5999999999999999778 0.5999999999999999778 0.5999999999999999778 1.0"/>
            </material>
        </visual>
        <collision>
            <origin xyz="-0.055737814613989480894 0.011843647312554005796 0.056940372525141912108" rpy="1.5707963267950224573 -6.4032322896069201773e-14 1.1257661469699141594e-13" />
            <geometry>
                <mesh filename="package:///micro_usb_2_0_connector__ab_rec.prt.stl"/>
            </geometry>
        </collision>
        <visual>
            <origin xyz="-0.051389399514572123295 -0.0011438930475683416199 0.046578922950957800386" rpy="1.5707963267947220309 -4.9949124345402063664e-14 1.5707963267949700548" />
            <geometry>
                <mesh filename="package:///39281023.prt.stl"/>
            </geometry>
            <material name="39281023.prt_material">
                <color rgba="0.5999999999999999778 0.5999999999999999778 0.5999999999999999778 1.0"/>
            </material>
        </visual>
        <collision>
            <origin xyz="-0.051389399514572123295 -0.0011438930475683416199 0.046578922950957800386" rpy="1.5707963267947220309 -4.9949124345402063664e-14 1.5707963267949700548" />
            <geometry>
                <mesh filename="package:///39281023.prt.stl"/>
            </geometry>
        </collision>
        <inertial>
            <origin xyz="-0.0067567951196927092047 -0.0066374665469452216043 0.0078705246973564662455" rpy="0 0 0"/>
            <mass value="0.50186117579999178773" />
            <inertia ixx="0.00087118338360908176635" ixy="3.1210124188948608771e-06"  ixz="5.3711012493390343156e-05" iyy="0.0013603649241426013939" iyz="-6.3015861188393611407e-06" izz="0.0010253665580462864755" />
        </inertial>
    </link>
    <link name="trunk">
        <inertial>
            <origin xyz="0 0 0" rpy="0 0 0" />
            <mass value="1e-9" />
            <inertia ixx="0" ixy="0" ixz="0" iyy="0" iyz="0" izz="0" />
        </inertial>
    </link>
    <joint name="trunk_frame" type="fixed">
        <origin xyz="0.032527100485028291599 -0.0066038964305764145252 0.012578922950962011587" rpy="1.5111348801390835856e-14 -6.2433989600656048221e-14 9.1593399531630240418e-16" />
        <parent link="body_module" />
        <child link="trunk" />
        <axis xyz="0 0 0"/>
    </joint>
    <link name="double_u_module">
        <visual>
            <origin xyz="2.0816681711721685133e-17 -4.2012834183813296818e-18 0.022999999999999951039" rpy="1.570796326794896558 9.7144514654699410024e-17 4.996003610813283318e-16" />
            <geometry>
                <mesh filename="package:///dc15_a01_horn_dummy.stl"/>
            </geometry>
            <material name="dc15_a01_horn_dummy_material">
                <color rgba="0.49803921568627451677 0.49803921568627451677 0.49803921568627451677 1.0"/>
            </material>
        </visual>
        <collision>
            <origin xyz="2.0816681711721685133e-17 -4.2012834183813296818e-18 0.022999999999999951039" rpy="1.570796326794896558 9.7144514654699410024e-17 4.996003610813283318e-16" />
            <geometry>
                <mesh filename="package:///dc15_a01_horn_dummy.stl"/>
            </geometry>
        </collision>
        <visual>
            <origin xyz="-0.14608752727508525493 -1.306463617845032843e-17 0.027999999999999993644" rpy="1.57079632679489678 2.0816681711737678055e-17 -3.141592653589793116" />
            <geometry>
                <mesh filename="package:///double_u.stl"/>
            </geometry>
            <material name="double_u_material">
                <color rgba="0.28235294117647058432 0.25490196078431370807 0.25490196078431370807 1.0"/>
            </material>
        </visual>
        <collision>
            <origin xyz="-0.14608752727508525493 -1.306463617845032843e-17 0.027999999999999993644" rpy="1.57079632679489678 2.0816681711737678055e-17 -3.141592653589793116" />
            <geometry>
                <mesh filename="package:///double_u.stl"/>
            </geometry>
        </collision>
        <visual>
            <origin xyz="-0.033999999999999919176 -0.011500225429056536164 0.011499999999999900926" rpy="3.141592653589793116 -8.6736173798778897526e-17 4.4408920985005285402e-16" />
            <geometry>
                <mesh filename="package:///dc15_a01_horn_dummy.stl"/>
            </geometry>
            <material name="dc15_a01_horn_dummy_material">
                <color rgba="0.49803921568627451677 0.49803921568627451677 0.49803921568627451677 1.0"/>
            </material>
        </visual>
        <collision>
            <origin xyz="-0.033999999999999919176 -0.011500225429056536164 0.011499999999999900926" rpy="3.141592653589793116 -8.6736173798778897526e-17 4.4408920985005285402e-16" />
            <geometry>
                <mesh filename="package:///dc15_a01_horn_dummy.stl"/>
            </geometry>
        </collision>
        <visual>
            <origin xyz="0 0 0" rpy="-3.141592653589793116 -3.3480749407005644071e-30 9.2593440517554546076e-32" />
            <geometry>
                <mesh filename="package:///dc15_a01_horn_idle2_dummy.stl"/>
            </geometry>
            <material name="dc15_a01_horn_idle2_dummy_material">
                <color rgba="0.2313725490196078538 0.38039215686274507888 0.7058823529411765163 1.0"/>
            </material>
        </visual>
        <collision>
            <origin xyz="0 0 0" rpy="-3.141592653589793116 -3.3480749407005644071e-30 9.2593440517554546076e-32" />
            <geometry>
                <mesh filename="package:///dc15_a01_horn_idle2_dummy.stl"/>
            </geometry>
        </collision>
        <visual>
            <origin xyz="-0.033999999999999905298 0.011499999999999989397 0.011499999999999895722" rpy="-1.57079632679489678 -4.1633363423422181955e-17 4.996003610813140337e-16" />
            <geometry>
                <mesh filename="package:///dc15_a01_horn_idle2_dummy.stl"/>
            </geometry>
            <material name="dc15_a01_horn_idle2_dummy_material">
                <color rgba="0.2313725490196078538 0.38039215686274507888 0.7058823529411765163 1.0"/>
            </material>
        </visual>
        <collision>
            <origin xyz="-0.033999999999999905298 0.011499999999999989397 0.011499999999999895722" rpy="-1.57079632679489678 -4.1633363423422181955e-17 4.996003610813140337e-16" />
            <geometry>
                <mesh filename="package:///dc15_a01_horn_idle2_dummy.stl"/>
            </geometry>
        </collision>
        <inertial>
            <origin xyz="-0.017000000000027194746 -8.4248510725114106865e-05 0.011584512528129448095" rpy="0 0 0"/>
            <mass value="0.018818301231819770797" />
            <inertia ixx="4.1671223638675305127e-06" ixy="-2.7039262661630013798e-08"  ixz="-2.6949270449491627695e-08" iyy="4.616500202208012939e-06" iyz="-1.3398675452280207827e-10" izz="4.6165051389299900596e-06" />
        </inertial>
    </link>
    <link name="right_hip_pitch_roll_module">
        <visual>
            <origin xyz="-0.067053147256377121366 -0.024500000000000993206 0.0090000000000002959577" rpy="-8.6112219883604645945e-16 1.6243577932283069901e-15 6.1062266354327107561e-16" />
            <geometry>
                <mesh filename="package:///hip_right_roll_to_pitch.stl"/>
            </geometry>
            <material name="hip_right_roll_to_pitch_material">
                <color rgba="0.28235294117647058432 0.25490196078431370807 0.25490196078431370807 1.0"/>
            </material>
        </visual>
        <collision>
            <origin xyz="-0.067053147256377121366 -0.024500000000000993206 0.0090000000000002959577" rpy="-8.6112219883604645945e-16 1.6243577932283069901e-15 6.1062266354327107561e-16" />
            <geometry>
                <mesh filename="package:///hip_right_roll_to_pitch.stl"/>
            </geometry>
        </collision>
        <visual>
            <origin xyz="-2.9837243786801082024e-16 -2.7755575615628913511e-16 -0.0035000000000000204559" rpy="2.4577307349438227031e-30 4.2931254331535647929e-16 1.6653345369332757744e-16" />
            <geometry>
                <mesh filename="package:///dc15_a01_case_f_dummy.stl"/>
            </geometry>
            <material name="dc15_a01_case_f_dummy_material">
                <color rgba="0.28235294117647058432 0.25490196078431370807 0.25490196078431370807 1.0"/>
            </material>
        </visual>
        <collision>
            <origin xyz="-2.9837243786801082024e-16 -2.7755575615628913511e-16 -0.0035000000000000204559" rpy="2.4577307349438227031e-30 4.2931254331535647929e-16 1.6653345369332757744e-16" />
            <geometry>
                <mesh filename="package:///dc15_a01_case_f_dummy.stl"/>
            </geometry>
        </collision>
        <visual>
            <origin xyz="-1.7347234759768070944e-18 0 -0.0034999999999999996392" rpy="-1.2966173603205519582e-33 -3.8396316524368764545e-30 3.6977854936784594168e-31" />
            <geometry>
                <mesh filename="package:///dc15_a01_case_m_dummy.stl"/>
            </geometry>
            <material name="dc15_a01_case_m_dummy_material">
                <color rgba="0.28235294117647058432 0.25490196078431370807 0.25490196078431370807 1.0"/>
            </material>
        </visual>
        <collision>
            <origin xyz="-1.7347234759768070944e-18 0 -0.0034999999999999996392" rpy="-1.2966173603205519582e-33 -3.8396316524368764545e-30 3.6977854936784594168e-31" />
            <geometry>
                <mesh filename="package:///dc15_a01_case_m_dummy.stl"/>
            </geometry>
        </collision>
        <visual>
            <origin xyz="-1.7173762412170390235e-16 -2.498001805406602216e-16 -0.022999999999999999611" rpy="-8.7266099301611075154e-16 -3.6913114184781534669e-16 -4.3892713804560277112e-28" />
            <geometry>
                <mesh filename="package:///dc15_a01_case_b_dummy.stl"/>
            </geometry>
            <material name="dc15_a01_case_b_dummy_material">
                <color rgba="0.28235294117647058432 0.25490196078431370807 0.25490196078431370807 1.0"/>
            </material>
        </visual>
        <collision>
            <origin xyz="-1.7173762412170390235e-16 -2.498001805406602216e-16 -0.022999999999999999611" rpy="-8.7266099301611075154e-16 -3.6913114184781534669e-16 -4.3892713804560277112e-28" />
            <geometry>
                <mesh filename="package:///dc15_a01_case_b_dummy.stl"/>
            </geometry>
        </collision>
        <visual>
            <origin xyz="0.025000000000000646705 -0.02100000000000065703 -0.013499999999999789946" rpy="-1.5707963267948956698 3.4371750726708999825e-16 -3.141592653589793116" />
            <geometry>
                <mesh filename="package:///dc15_a01_case_f_dummy.stl"/>
            </geometry>
            <material name="dc15_a01_case_f_dummy_material">
                <color rgba="0.28235294117647058432 0.25490196078431370807 0.25490196078431370807 1.0"/>
            </material>
        </visual>
        <collision>
            <origin xyz="0.025000000000000646705 -0.02100000000000065703 -0.013499999999999789946" rpy="-1.5707963267948956698 3.4371750726708999825e-16 -3.141592653589793116" />
            <geometry>
                <mesh filename="package:///dc15_a01_case_f_dummy.stl"/>
            </geometry>
        </collision>
        <visual>
            <origin xyz="0.025000000000000646705 -0.02100000000000065703 -0.013499999999999786476" rpy="-1.5707963267948956698 3.4371750726708999825e-16 -3.141592653589793116" />
            <geometry>
                <mesh filename="package:///dc15_a01_case_m_dummy.stl"/>
            </geometry>
            <material name="dc15_a01_case_m_dummy_material">
                <color rgba="0.28235294117647058432 0.25490196078431370807 0.25490196078431370807 1.0"/>
            </material>
        </visual>
        <collision>
            <origin xyz="0.025000000000000646705 -0.02100000000000065703 -0.013499999999999786476" rpy="-1.5707963267948956698 3.4371750726708999825e-16 -3.141592653589793116" />
            <geometry>
                <mesh filename="package:///dc15_a01_case_m_dummy.stl"/>
            </geometry>
        </collision>
        <visual>
            <origin xyz="0.02500000000000067446 -0.0015000000000001401101 -0.013499999999999783007" rpy="-1.5707963267948956698 -4.6595274827713735404e-17 -3.141592653589793116" />
            <geometry>
                <mesh filename="package:///dc15_a01_case_b_dummy.stl"/>
            </geometry>
            <material name="dc15_a01_case_b_dummy_material">
                <color rgba="0.28235294117647058432 0.25490196078431370807 0.25490196078431370807 1.0"/>
            </material>
        </visual>
        <collision>
            <origin xyz="0.02500000000000067446 -0.0015000000000001401101 -0.013499999999999783007" rpy="-1.5707963267948956698 -4.6595274827713735404e-17 -3.141592653589793116" />
            <geometry>
                <mesh filename="package:///dc15_a01_case_b_dummy.stl"/>
            </geometry>
        </collision>
        <inertial>
            <origin xyz="0.011912825164996051694 -0.011752076745460894591 -0.0064503420228230788983" rpy="0 0 0"/>
            <mass value="0.050685765935093662904" />
            <inertia ixx="1.0194327396575008973e-05" ixy="7.6194526548775486306e-07"  ixz="-2.68210655887894066e-06" iyy="1.5570665764189378524e-05" iyz="3.3009359542112554209e-07" izz="1.3178069063709724025e-05" />
        </inertial>
    </link>
    <link name="leg_module">
        <visual>
            <origin xyz="-0.042500000000000662248 -0.047130780071020859923 0.023000000000000159206" rpy="-1.5707963267949038855 -5.5511151230215458268e-17 -1.5707963267949074382" />
            <geometry>
                <mesh filename="package:///block_to_axis.stl"/>
            </geometry>
            <material name="block_to_axis_material">
                <color rgba="0.81568627450980391025 0.44313725490196076429 0.0039215686274509803377 1.0"/>
            </material>
        </visual>
        <collision>
            <origin xyz="-0.042500000000000662248 -0.047130780071020859923 0.023000000000000159206" rpy="-1.5707963267949038855 -5.5511151230215458268e-17 -1.5707963267949074382" />
            <geometry>
                <mesh filename="package:///block_to_axis.stl"/>
            </geometry>
        </collision>
        <visual>
            <origin xyz="-0.042499999999999565903 0.047130780071019701127 -1.3877787807814456755e-17" rpy="1.570796326794896558 -2.3473126974043363983e-16 1.57079632679489678" />
            <geometry>
                <mesh filename="package:///block_to_axis.stl"/>
            </geometry>
            <material name="block_to_axis_material">
                <color rgba="0.81568627450980391025 0.44313725490196076429 0.0039215686274509803377 1.0"/>
            </material>
        </visual>
        <collision>
            <origin xyz="-0.042499999999999565903 0.047130780071019701127 -1.3877787807814456755e-17" rpy="1.570796326794896558 -2.3473126974043363983e-16 1.57079632679489678" />
            <geometry>
                <mesh filename="package:///block_to_axis.stl"/>
            </geometry>
        </collision>
        <visual>
            <origin xyz="-0.042499999999999579781 0.04713078007102119299 2.7755575615628913511e-16" rpy="1.5707963267949118791 3.3306690738537049489e-16 1.5707963267948736874" />
            <geometry>
                <mesh filename="package:///renfort_leg.stl"/>
            </geometry>
            <material name="renfort_leg_material">
                <color rgba="0.28235294117647058432 0.25490196078431370807 0.25490196078431370807 1.0"/>
            </material>
        </visual>
        <collision>
            <origin xyz="-0.042499999999999579781 0.04713078007102119299 2.7755575615628913511e-16" rpy="1.5707963267949118791 3.3306690738537049489e-16 1.5707963267948736874" />
            <geometry>
                <mesh filename="package:///renfort_leg.stl"/>
            </geometry>
        </collision>
        <visual>
            <origin xyz="-1.7347234759768070944e-18 0 -1.3877787807814456755e-17" rpy="-3.141592653589793116 -9.2444637330599932633e-31 2.2255358868987422752e-30" />
            <geometry>
                <mesh filename="package:///dc15_a01_horn_idle2_dummy.stl"/>
            </geometry>
            <material name="dc15_a01_horn_idle2_dummy_material">
                <color rgba="0.2313725490196078538 0.38039215686274507888 0.7058823529411765163 1.0"/>
            </material>
        </visual>
        <collision>
            <origin xyz="-1.7347234759768070944e-18 0 -1.3877787807814456755e-17" rpy="-3.141592653589793116 -9.2444637330599932633e-31 2.2255358868987422752e-30" />
            <geometry>
                <mesh filename="package:///dc15_a01_horn_idle2_dummy.stl"/>
            </geometry>
        </collision>
        <visual>
            <origin xyz="6.6266436782314031007e-16 -1.3791051634015616401e-16 0.022999999999999853895" rpy="1.5707963267948970021 -5.5511151231634039717e-17 1.5707963267948983344" />
            <geometry>
                <mesh filename="package:///dc15_a01_horn_dummy.stl"/>
            </geometry>
            <material name="dc15_a01_horn_dummy_material">
                <color rgba="0.49803921568627451677 0.49803921568627451677 0.49803921568627451677 1.0"/>
            </material>
        </visual>
        <collision>
            <origin xyz="6.6266436782314031007e-16 -1.3791051634015616401e-16 0.022999999999999853895" rpy="1.5707963267948970021 -5.5511151231634039717e-17 1.5707963267948983344" />
            <geometry>
                <mesh filename="package:///dc15_a01_horn_dummy.stl"/>
            </geometry>
        </collision>
        <visual>
            <origin xyz="-0.06500000000000094591 -9.9312918999672206155e-17 0.00350000000000030842" rpy="3.1415926535897784611 2.3091742877810055989e-27 -1.5707963267948954478" />
            <geometry>
                <mesh filename="package:///dc15_a01_case_f_dummy.stl"/>
            </geometry>
            <material name="dc15_a01_case_f_dummy_material">
                <color rgba="0.28235294117647058432 0.25490196078431370807 0.25490196078431370807 1.0"/>
            </material>
        </visual>
        <collision>
            <origin xyz="-0.06500000000000094591 -9.9312918999672206155e-17 0.00350000000000030842" rpy="3.1415926535897784611 2.3091742877810055989e-27 -1.5707963267948954478" />
            <geometry>
                <mesh filename="package:///dc15_a01_case_f_dummy.stl"/>
            </geometry>
        </collision>
        <visual>
            <origin xyz="-0.065000000000000834888 -1.8366384801904445112e-16 0.0035000000000002529088" rpy="3.1415926535897860106 3.3306690738918626439e-16 -1.5707963267949078823" />
            <geometry>
                <mesh filename="package:///dc15_a01_case_m_dummy.stl"/>
            </geometry>
            <material name="dc15_a01_case_m_dummy_material">
                <color rgba="0.28235294117647058432 0.25490196078431370807 0.25490196078431370807 1.0"/>
            </material>
        </visual>
        <collision>
            <origin xyz="-0.065000000000000834888 -1.8366384801904445112e-16 0.0035000000000002529088" rpy="3.1415926535897860106 3.3306690738918626439e-16 -1.5707963267949078823" />
            <geometry>
                <mesh filename="package:///dc15_a01_case_m_dummy.stl"/>
            </geometry>
        </collision>
        <visual>
            <origin xyz="-0.065000000000000501821 -1.8453120975703285467e-16 0.023000000000000561662" rpy="3.1415926535897860106 1.1420607414823103591e-27 -1.5707963267949076602" />
            <geometry>
                <mesh filename="package:///dc15_a01_case_b_dummy.stl"/>
            </geometry>
            <material name="dc15_a01_case_b_dummy_material">
                <color rgba="0.28235294117647058432 0.25490196078431370807 0.25490196078431370807 1.0"/>
            </material>
        </visual>
        <collision>
            <origin xyz="-0.065000000000000501821 -1.8453120975703285467e-16 0.023000000000000561662" rpy="3.1415926535897860106 1.1420607414823103591e-27 -1.5707963267949076602" />
            <geometry>
                <mesh filename="package:///dc15_a01_case_b_dummy.stl"/>
            </geometry>
        </collision>
        <inertial>
            <origin xyz="-0.0399016283517398887 -7.7113301695331147378e-06 0.011400440323216619667" rpy="0 0 0"/>
            <mass value="0.034530807353386039349" />
            <inertia ixx="5.0157740917572851916e-06" ixy="-2.9199735830158616593e-09"  ixz="-1.4737518371929003897e-07" iyy="2.0653502860211055532e-05" iyz="-5.5818119990468832047e-10" izz="1.7774415153791314948e-05" />
        </inertial>
    </link>
    <link name="leg_module_2">
        <visual>
            <origin xyz="-0.042500000000001203482 -0.047130780071021352584 0.022999999999999895528" rpy="-1.5707963267949038855 -3.8857805861780845782e-16 -1.5707963267948961139" />
            <geometry>
                <mesh filename="package:///block_to_axis.stl"/>
            </geometry>
            <material name="block_to_axis_material">
                <color rgba="0.81568627450980391025 0.44313725490196076429 0.0039215686274509803377 1.0"/>
            </material>
        </visual>
        <collision>
            <origin xyz="-0.042500000000001203482 -0.047130780071021352584 0.022999999999999895528" rpy="-1.5707963267949038855 -3.8857805861780845782e-16 -1.5707963267948961139" />
            <geometry>
                <mesh filename="package:///block_to_axis.stl"/>
            </geometry>
        </collision>
        <visual>
            <origin xyz="-0.042500000000001453282 0.04713078007102081135 -2.6367796834847467835e-16" rpy="1.5707963267948894526 -4.4408920984797962895e-16 1.57079632679489678" />
            <geometry>
                <mesh filename="package:///block_to_axis.stl"/>
            </geometry>
            <material name="block_to_axis_material">
                <color rgba="0.81568627450980391025 0.44313725490196076429 0.0039215686274509803377 1.0"/>
            </material>
        </visual>
        <collision>
            <origin xyz="-0.042500000000001453282 0.04713078007102081135 -2.6367796834847467835e-16" rpy="1.5707963267948894526 -4.4408920984797962895e-16 1.57079632679489678" />
            <geometry>
                <mesh filename="package:///block_to_axis.stl"/>
            </geometry>
        </collision>
        <visual>
            <origin xyz="-0.042500000000001258993 0.047130780071020290933 -8.3266726846886740532e-17" rpy="1.5707963267949041075 1.6653345369281405364e-16 1.5707963267948972241" />
            <geometry>
                <mesh filename="package:///renfort_leg.stl"/>
            </geometry>
            <material name="renfort_leg_material">
                <color rgba="0.28235294117647058432 0.25490196078431370807 0.25490196078431370807 1.0"/>
            </material>
        </visual>
        <collision>
            <origin xyz="-0.042500000000001258993 0.047130780071020290933 -8.3266726846886740532e-17" rpy="1.5707963267949041075 1.6653345369281405364e-16 1.5707963267948972241" />
            <geometry>
                <mesh filename="package:///renfort_leg.stl"/>
            </geometry>
        </collision>
        <visual>
            <origin xyz="0 0 0" rpy="3.141592653589793116 -2.7301982891614793661e-30 1.5434930030403632722e-29" />
            <geometry>
                <mesh filename="package:///dc15_a01_horn_idle2_dummy.stl"/>
            </geometry>
            <material name="dc15_a01_horn_idle2_dummy_material">
                <color rgba="0.2313725490196078538 0.38039215686274507888 0.7058823529411765163 1.0"/>
            </material>
        </visual>
        <collision>
            <origin xyz="0 0 0" rpy="3.141592653589793116 -2.7301982891614793661e-30 1.5434930030403632722e-29" />
            <geometry>
                <mesh filename="package:///dc15_a01_horn_idle2_dummy.stl"/>
            </geometry>
        </collision>
        <visual>
            <origin xyz="-2.7755575615628913511e-16 1.0625181290357943453e-17 0.022999999999999576339" rpy="1.57079632679489678 -1.6653345369398920987e-16 1.5707963267949092145" />
            <geometry>
                <mesh filename="package:///dc15_a01_horn_dummy.stl"/>
            </geometry>
            <material name="dc15_a01_horn_dummy_material">
                <color rgba="0.49803921568627451677 0.49803921568627451677 0.49803921568627451677 1.0"/>
            </material>
        </visual>
        <collision>
            <origin xyz="-2.7755575615628913511e-16 1.0625181290357943453e-17 0.022999999999999576339" rpy="1.57079632679489678 -1.6653345369398920987e-16 1.5707963267949092145" />
            <geometry>
                <mesh filename="package:///dc15_a01_horn_dummy.stl"/>
            </geometry>
        </collision>
        <visual>
            <origin xyz="-0.065000000000002181033 -8.0968218241217471132e-16 0.0035000000000002667866" rpy="3.1415926535897713556 -2.2204460492243435333e-16 -1.5707963267948847896" />
            <geometry>
                <mesh filename="package:///dc15_a01_case_f_dummy.stl"/>
            </geometry>
            <material name="dc15_a01_case_f_dummy_material">
                <color rgba="0.28235294117647058432 0.25490196078431370807 0.25490196078431370807 1.0"/>
            </material>
        </visual>
        <collision>
            <origin xyz="-0.065000000000002181033 -8.0968218241217471132e-16 0.0035000000000002667866" rpy="3.1415926535897713556 -2.2204460492243435333e-16 -1.5707963267948847896" />
            <geometry>
                <mesh filename="package:///dc15_a01_case_f_dummy.stl"/>
            </geometry>
        </collision>
        <visual>
            <origin xyz="-0.065000000000001958989 -9.053088140253962024e-16 0.0035000000000001557643" rpy="3.1415926535897860106 1.1102230246306415889e-16 -1.5707963267949085484" />
            <geometry>
                <mesh filename="package:///dc15_a01_case_m_dummy.stl"/>
            </geometry>
            <material name="dc15_a01_case_m_dummy_material">
                <color rgba="0.28235294117647058432 0.25490196078431370807 0.25490196078431370807 1.0"/>
            </material>
        </visual>
        <collision>
            <origin xyz="-0.065000000000001958989 -9.053088140253962024e-16 0.0035000000000001557643" rpy="3.1415926535897860106 1.1102230246306415889e-16 -1.5707963267949085484" />
            <geometry>
                <mesh filename="package:///dc15_a01_case_m_dummy.stl"/>
            </geometry>
        </collision>
        <visual>
            <origin xyz="-0.065000000000001625922 -7.7412035115465016588e-16 0.023000000000000658806" rpy="3.1415926535897860106 -1.1102230246204062419e-16 -1.5707963267948961139" />
            <geometry>
                <mesh filename="package:///dc15_a01_case_b_dummy.stl"/>
            </geometry>
            <material name="dc15_a01_case_b_dummy_material">
                <color rgba="0.28235294117647058432 0.25490196078431370807 0.25490196078431370807 1.0"/>
            </material>
        </visual>
        <collision>
            <origin xyz="-0.065000000000001625922 -7.7412035115465016588e-16 0.023000000000000658806" rpy="3.1415926535897860106 -1.1102230246204062419e-16 -1.5707963267948961139" />
            <geometry>
                <mesh filename="package:///dc15_a01_case_b_dummy.stl"/>
            </geometry>
        </collision>
        <inertial>
            <origin xyz="-0.039901628351740880962 -7.711330169927184958e-06 0.011400440323216496502" rpy="0 0 0"/>
            <mass value="0.034530807353386039349" />
            <inertia ixx="5.0157740917573080615e-06" ixy="-2.9199735831719986174e-09"  ixz="-1.4737518371922460567e-07" iyy="2.0653502860211218163e-05" iyz="-5.5818119993349230036e-10" izz="1.7774415153791362382e-05" />
        </inertial>
    </link>
    <link name="foot_module">
        <visual>
            <origin xyz="2.7755575615628913511e-17 0 0" rpy="-3.141592653589793116 8.5049066343719525342e-31 -2.9347788975850197686e-31" />
            <geometry>
                <mesh filename="package:///dc15_a01_horn_idle2_dummy.stl"/>
            </geometry>
            <material name="dc15_a01_horn_idle2_dummy_material">
                <color rgba="0.2313725490196078538 0.38039215686274507888 0.7058823529411765163 1.0"/>
            </material>
        </visual>
        <collision>
            <origin xyz="2.7755575615628913511e-17 0 0" rpy="-3.141592653589793116 8.5049066343719525342e-31 -2.9347788975850197686e-31" />
            <geometry>
                <mesh filename="package:///dc15_a01_horn_idle2_dummy.stl"/>
            </geometry>
        </collision>
        <visual>
            <origin xyz="2.498001805406602216e-16 -5.2041704279304212832e-17 -0.0051999999999998713918" rpy="-3.141592653589793116 -1.570796326794896558 0" />
            <geometry>
                <mesh filename="package:///foot.stl"/>
            </geometry>
            <material name="foot_material">
                <color rgba="0.81568627450980391025 0.44313725490196076429 0.0039215686274509803377 1.0"/>
            </material>
        </visual>
        <collision>
            <origin xyz="2.498001805406602216e-16 -5.2041704279304212832e-17 -0.0051999999999998713918" rpy="-3.141592653589793116 -1.570796326794896558 0" />
            <geometry>
                <mesh filename="package:///foot.stl"/>
            </geometry>
        </collision>
        <visual>
            <origin xyz="2.498001805406602216e-16 -5.2041704279304212832e-17 -0.0051999999999998713918" rpy="-3.141592653589793116 -1.570796326794896558 0" />
            <geometry>
                <mesh filename="package:///foot_contact.stl"/>
            </geometry>
            <material name="foot_contact_material">
                <color rgba="0 0 0 1.0"/>
            </material>
        </visual>
        <collision>
            <origin xyz="2.498001805406602216e-16 -5.2041704279304212832e-17 -0.0051999999999998713918" rpy="-3.141592653589793116 -1.570796326794896558 0" />
            <geometry>
                <mesh filename="package:///foot_contact.stl"/>
            </geometry>
        </collision>
        <visual>
            <origin xyz="5.5511151231257827021e-17 -7.0689981646054889097e-17 0.02299999999999988165" rpy="1.5707963267948961139 -1.7486012637846353562e-15 1.5707963267948981123" />
            <geometry>
                <mesh filename="package:///dc15_a01_horn_dummy.stl"/>
            </geometry>
            <material name="dc15_a01_horn_dummy_material">
                <color rgba="0.49803921568627451677 0.49803921568627451677 0.49803921568627451677 1.0"/>
            </material>
        </visual>
        <collision>
            <origin xyz="5.5511151231257827021e-17 -7.0689981646054889097e-17 0.02299999999999988165" rpy="1.5707963267948961139 -1.7486012637846353562e-15 1.5707963267948981123" />
            <geometry>
                <mesh filename="package:///dc15_a01_horn_dummy.stl"/>
            </geometry>
        </collision>
        <inertial>
            <origin xyz="-0.026873167661377896781 0.0076028406460558750624 0.01155624085010228258" rpy="0 0 0"/>
            <mass value="0.028234070013912770242" />
            <inertia ixx="1.1973322148719445722e-05" ixy="1.2285719604382020249e-06"  ixz="-4.2627541791625139548e-08" iyy="5.3787427295815348643e-06" iyz="1.2080361154658381561e-08" izz="1.3185549498032306674e-05" />
        </inertial>
    </link>
    <link name="right_foot">
        <inertial>
            <origin xyz="0 0 0" rpy="0 0 0" />
            <mass value="1e-9" />
            <inertia ixx="0" ixy="0" ixz="0" iyy="0" iyz="0" izz="0" />
        </inertial>
    </link>
    <joint name="right_foot_frame" type="fixed">
        <origin xyz="-0.037499999999998978595 -3.5605199344423965613e-16 0.011499999999999552247" rpy="1.5707963267948954478 -9.9920072216264293742e-15 1.57079632679489678" />
        <parent link="foot_module" />
        <child link="right_foot" />
        <axis xyz="0 0 0"/>
    </joint>
    <joint name="right_ankle" type="revolute">
        <origin xyz="-0.0650000000000020145 -9.0595933532888750506e-16 1.3877787807814456755e-16" rpy="-1.0269562978010203906e-14 7.7715611723723191114e-16 2.0455945828244817402e-14" />
        <parent link="leg_module_2" />
        <child link="foot_module" />
        <axis xyz="0 0 1"/>
        <limit effort="1" velocity="20" lower="-1.570796326794896558" upper="1.570796326794896558"/>
        <joint_properties friction="0.0"/>
    </joint>
    <joint name="right_knee" type="revolute">
        <origin xyz="-0.065000000000000890399 -1.8409752888803865289e-16 2.3592239273284576484e-16" rpy="1.1102230529243367767e-16 2.2204460492507932999e-16 -1.1500818382616808057e-13" />
        <parent link="leg_module" />
        <child link="leg_module_2" />
        <axis xyz="0 0 1"/>
        <limit effort="1" velocity="20" lower="-2.0943951023931952626" upper="2.0943951023931952626"/>
        <joint_properties friction="0.0"/>
    </joint>
    <joint name="right_hip_pitch" type="revolute">
        <origin xyz="0.025000000000000646705 -0.024500000000000743405 -0.013499999999999783007" rpy="1.5707963267948972241 -9.4876329561990965088e-14 -3.141592653589793116" />
        <parent link="right_hip_pitch_roll_module" />
        <child link="leg_module" />
        <axis xyz="0 0 1"/>
        <limit effort="1" velocity="20" lower="-0.52359877559829881566" upper="1.570796326794896558"/>
        <joint_properties friction="0.0"/>
    </joint>
    <joint name="right_hip_roll" type="revolute">
        <origin xyz="-0.033999999999999905298 0.011499999999999989397 0.011499999999999895722" rpy="-1.5707963267948958919 -1.570796326794896336 0" />
        <parent link="double_u_module" />
        <child link="right_hip_pitch_roll_module" />
        <axis xyz="0 0 1"/>
        <limit effort="1" velocity="20" lower="-1.570796326794896558" upper="0.43633231299858238339"/>
        <joint_properties friction="0.0"/>
    </joint>
    <joint name="right_hip_yaw" type="revolute">
        <origin xyz="0.00012710048502765305023 -0.031603896430576608467 0.023078922950959548932" rpy="3.1415926535897304994 -1.5078389055347532112e-14 1.5707963267948974462" />
        <parent link="body_module" />
        <child link="double_u_module" />
        <axis xyz="0 0 1"/>
        <limit effort="1" velocity="20" lower="-0.69813170079773179122" upper="0.69813170079773179122"/>
        <joint_properties friction="0.0"/>
    </joint>
    <link name="double_u_module_2">
        <visual>
            <origin xyz="0.034000000000001154299 0.011500000000000549713 0.011500000000000006745" rpy="3.1051550219981292186e-16 -4.1406029711123635988e-29 1.6653345369381314598e-16" />
            <geometry>
                <mesh filename="package:///dc15_a01_horn_dummy.stl"/>
            </geometry>
            <material name="dc15_a01_horn_dummy_material">
                <color rgba="0.49803921568627451677 0.49803921568627451677 0.49803921568627451677 1.0"/>
            </material>
        </visual>
        <collision>
            <origin xyz="0.034000000000001154299 0.011500000000000549713 0.011500000000000006745" rpy="3.1051550219981292186e-16 -4.1406029711123635988e-29 1.6653345369381314598e-16" />
            <geometry>
                <mesh filename="package:///dc15_a01_horn_dummy.stl"/>
            </geometry>
        </collision>
        <visual>
            <origin xyz="-0.1120875272750893048 0.016500000000000694667 0.011499999999999999806" rpy="3.1415926535897926719 3.989863994768643966e-17 -3.1415926535897926719" />
            <geometry>
                <mesh filename="package:///double_u.stl"/>
            </geometry>
            <material name="double_u_material">
                <color rgba="0.28235294117647058432 0.25490196078431370807 0.25490196078431370807 1.0"/>
            </material>
        </visual>
        <collision>
            <origin xyz="-0.1120875272750893048 0.016500000000000694667 0.011499999999999999806" rpy="3.1415926535897926719 3.989863994768643966e-17 -3.1415926535897926719" />
            <geometry>
                <mesh filename="package:///double_u.stl"/>
            </geometry>
        </collision>
        <visual>
            <origin xyz="-3.4694469519536141888e-18 9.2157184661267876891e-17 0.0230002254290565325" rpy="1.570796326794896558 -1.7347234759806010223e-17 2.2204460492504915606e-16" />
            <geometry>
                <mesh filename="package:///dc15_a01_horn_dummy.stl"/>
            </geometry>
            <material name="dc15_a01_horn_dummy_material">
                <color rgba="0.49803921568627451677 0.49803921568627451677 0.49803921568627451677 1.0"/>
            </material>
        </visual>
        <collision>
            <origin xyz="-3.4694469519536141888e-18 9.2157184661267876891e-17 0.0230002254290565325" rpy="1.570796326794896558 -1.7347234759806010223e-17 2.2204460492504915606e-16" />
            <geometry>
                <mesh filename="package:///dc15_a01_horn_dummy.stl"/>
            </geometry>
        </collision>
        <visual>
            <origin xyz="0.034000000000001168177 -0.0115000000000000345 0.011499999999999996336" rpy="1.5707963267948970021 6.9388939039125947888e-18 2.2204460492508805677e-16" />
            <geometry>
                <mesh filename="package:///dc15_a01_horn_idle2_dummy.stl"/>
            </geometry>
            <material name="dc15_a01_horn_idle2_dummy_material">
                <color rgba="0.2313725490196078538 0.38039215686274507888 0.7058823529411765163 1.0"/>
            </material>
        </visual>
        <collision>
            <origin xyz="0.034000000000001168177 -0.0115000000000000345 0.011499999999999996336" rpy="1.5707963267948970021 6.9388939039125947888e-18 2.2204460492508805677e-16" />
            <geometry>
                <mesh filename="package:///dc15_a01_horn_idle2_dummy.stl"/>
            </geometry>
        </collision>
        <visual>
            <origin xyz="0 0 0" rpy="-3.141592653589793116 -3.8526263963279615011e-31 6.4358684515981144592e-32" />
            <geometry>
                <mesh filename="package:///dc15_a01_horn_idle2_dummy.stl"/>
            </geometry>
            <material name="dc15_a01_horn_idle2_dummy_material">
                <color rgba="0.2313725490196078538 0.38039215686274507888 0.7058823529411765163 1.0"/>
            </material>
        </visual>
        <collision>
            <origin xyz="0 0 0" rpy="-3.141592653589793116 -3.8526263963279615011e-31 6.4358684515981144592e-32" />
            <geometry>
                <mesh filename="package:///dc15_a01_horn_idle2_dummy.stl"/>
            </geometry>
        </collision>
        <inertial>
            <origin xyz="0.016999999999973376685 8.4512528129653772266e-05 0.011584248510725115092" rpy="0 0 0"/>
            <mass value="0.018818301231819770797" />
            <inertia ixx="4.1671223638678125747e-06" ixy="-2.6949270449495528679e-08"  ixz="2.7039262661631284347e-08" iyy="4.6165051389302932974e-06" iyz="1.3398675452128389165e-10" izz="4.6165002022080807017e-06" />
        </inertial>
    </link>
    <link name="left_hip_pitch_roll_module">
        <visual>
            <origin xyz="-0.067053147256375608687 -0.024500000000000042577 -0.032000000000000465572" rpy="3.141592653589793116 1.6028126974030637996e-15 -3.141592653589793116" />
            <geometry>
                <mesh filename="package:///hip_left_roll_to_pitch.stl"/>
            </geometry>
            <material name="hip_left_roll_to_pitch_material">
                <color rgba="0.28235294117647058432 0.25490196078431370807 0.25490196078431370807 1.0"/>
            </material>
        </visual>
        <collision>
            <origin xyz="-0.067053147256375608687 -0.024500000000000042577 -0.032000000000000465572" rpy="3.141592653589793116 1.6028126974030637996e-15 -3.141592653589793116" />
            <geometry>
                <mesh filename="package:///hip_left_roll_to_pitch.stl"/>
            </geometry>
        </collision>
        <visual>
            <origin xyz="0.025000000000000466294 -0.0050000000000000113798 -0.0095000000000003397699" rpy="1.570796326794896558 -1.6826817716976283598e-16 3.141592653589793116" />
            <geometry>
                <mesh filename="package:///dc15_a01_case_f_dummy.stl"/>
            </geometry>
            <material name="dc15_a01_case_f_dummy_material">
                <color rgba="0.28235294117647058432 0.25490196078431370807 0.25490196078431370807 1.0"/>
            </material>
        </visual>
        <collision>
            <origin xyz="0.025000000000000466294 -0.0050000000000000113798 -0.0095000000000003397699" rpy="1.570796326794896558 -1.6826817716976283598e-16 3.141592653589793116" />
            <geometry>
                <mesh filename="package:///dc15_a01_case_f_dummy.stl"/>
            </geometry>
        </collision>
        <visual>
            <origin xyz="0.025000000000000462824 -0.0050000000000000044409 -0.0095000000000003380352" rpy="1.570796326794896558 -1.6826817716976283598e-16 3.141592653589793116" />
            <geometry>
                <mesh filename="package:///dc15_a01_case_m_dummy.stl"/>
            </geometry>
            <material name="dc15_a01_case_m_dummy_material">
                <color rgba="0.28235294117647058432 0.25490196078431370807 0.25490196078431370807 1.0"/>
            </material>
        </visual>
        <collision>
            <origin xyz="0.025000000000000462824 -0.0050000000000000044409 -0.0095000000000003380352" rpy="1.570796326794896558 -1.6826817716976283598e-16 3.141592653589793116" />
            <geometry>
                <mesh filename="package:///dc15_a01_case_m_dummy.stl"/>
            </geometry>
        </collision>
        <visual>
            <origin xyz="0.025000000000000466294 -0.024500000000000000944 -0.0095000000000003363004" rpy="1.5707963267948970021 -1.6653345369377957008e-16 3.141592653589793116" />
            <geometry>
                <mesh filename="package:///dc15_a01_case_b_dummy.stl"/>
            </geometry>
            <material name="dc15_a01_case_b_dummy_material">
                <color rgba="0.28235294117647058432 0.25490196078431370807 0.25490196078431370807 1.0"/>
            </material>
        </visual>
        <collision>
            <origin xyz="0.025000000000000466294 -0.024500000000000000944 -0.0095000000000003363004" rpy="1.5707963267948970021 -1.6653345369377957008e-16 3.141592653589793116" />
            <geometry>
                <mesh filename="package:///dc15_a01_case_b_dummy.stl"/>
            </geometry>
        </collision>
        <visual>
            <origin xyz="-5.2041704279304212832e-18 0 -0.0035000000000000013739" rpy="-1.1857032050430350995e-30 1.7347234760260427231e-18 1.0116605681612819211e-28" />
            <geometry>
                <mesh filename="package:///dc15_a01_case_f_dummy.stl"/>
            </geometry>
            <material name="dc15_a01_case_f_dummy_material">
                <color rgba="0.28235294117647058432 0.25490196078431370807 0.25490196078431370807 1.0"/>
            </material>
        </visual>
        <collision>
            <origin xyz="-5.2041704279304212832e-18 0 -0.0035000000000000013739" rpy="-1.1857032050430350995e-30 1.7347234760260427231e-18 1.0116605681612819211e-28" />
            <geometry>
                <mesh filename="package:///dc15_a01_case_f_dummy.stl"/>
            </geometry>
        </collision>
        <visual>
            <origin xyz="1.7347234759768070944e-18 0 -0.0035000000000000013739" rpy="1.1297491197668111264e-31 -4.43527532880738304e-30 1.2899303886838966395e-30" />
            <geometry>
                <mesh filename="package:///dc15_a01_case_m_dummy.stl"/>
            </geometry>
            <material name="dc15_a01_case_m_dummy_material">
                <color rgba="0.28235294117647058432 0.25490196078431370807 0.25490196078431370807 1.0"/>
            </material>
        </visual>
        <collision>
            <origin xyz="1.7347234759768070944e-18 0 -0.0035000000000000013739" rpy="1.1297491197668111264e-31 -4.43527532880738304e-30 1.2899303886838966395e-30" />
            <geometry>
                <mesh filename="package:///dc15_a01_case_m_dummy.stl"/>
            </geometry>
        </collision>
        <visual>
            <origin xyz="-2.2551405187698492227e-17 6.9388939039072283776e-18 -0.023000000000000003081" rpy="-3.3306690738754597605e-16 5.0133508455734103207e-16 -5.5511151231207611094e-17" />
            <geometry>
                <mesh filename="package:///dc15_a01_case_b_dummy.stl"/>
            </geometry>
            <material name="dc15_a01_case_b_dummy_material">
                <color rgba="0.28235294117647058432 0.25490196078431370807 0.25490196078431370807 1.0"/>
            </material>
        </visual>
        <collision>
            <origin xyz="-2.2551405187698492227e-17 6.9388939039072283776e-18 -0.023000000000000003081" rpy="-3.3306690738754597605e-16 5.0133508455734103207e-16 -5.5511151231207611094e-17" />
            <geometry>
                <mesh filename="package:///dc15_a01_case_b_dummy.stl"/>
            </geometry>
        </collision>
        <inertial>
            <origin xyz="0.01192302684260557015 -0.011606470860263534695 -0.016315085728328009018" rpy="0 0 0"/>
            <mass value="0.050936078435093665173" />
            <inertia ixx="1.0342471330591228627e-05" ixy="6.3706533517169182306e-07"  ixz="2.7969122185403285852e-06" iyy="1.5716551187432694573e-05" iyz="-3.3298884875073728796e-07" izz="1.3182726926082259243e-05" />
        </inertial>
    </link>
    <link name="leg_module_3">
        <visual>
            <origin xyz="-0.042499999999998483435 -0.047130780071017910893 0.022999999999999860834" rpy="-1.570796326794896336 -4.966572119182832965e-16 -1.5707963267948912289" />
            <geometry>
                <mesh filename="package:///block_to_axis.stl"/>
            </geometry>
            <material name="block_to_axis_material">
                <color rgba="0.81568627450980391025 0.44313725490196076429 0.0039215686274509803377 1.0"/>
            </material>
        </visual>
        <collision>
            <origin xyz="-0.042499999999998483435 -0.047130780071017910893 0.022999999999999860834" rpy="-1.570796326794896336 -4.966572119182832965e-16 -1.5707963267948912289" />
            <geometry>
                <mesh filename="package:///block_to_axis.stl"/>
            </geometry>
        </collision>
        <visual>
            <origin xyz="-0.042499999999999413247 0.047130780071019444388 0" rpy="1.570796326794896336 -5.5322230588507908191e-16 1.570796326794896558" />
            <geometry>
                <mesh filename="package:///block_to_axis.stl"/>
            </geometry>
            <material name="block_to_axis_material">
                <color rgba="0.81568627450980391025 0.44313725490196076429 0.0039215686274509803377 1.0"/>
            </material>
        </visual>
        <collision>
            <origin xyz="-0.042499999999999413247 0.047130780071019444388 0" rpy="1.570796326794896336 -5.5322230588507908191e-16 1.570796326794896558" />
            <geometry>
                <mesh filename="package:///block_to_axis.stl"/>
            </geometry>
        </collision>
        <visual>
            <origin xyz="-0.042499999999998844258 0.047130780071017980282 -3.4694469519536141888e-17" rpy="1.5707963267948961139 1.75748440760723845e-16 1.5707963267949018871" />
            <geometry>
                <mesh filename="package:///renfort_leg.stl"/>
            </geometry>
            <material name="renfort_leg_material">
                <color rgba="0.28235294117647058432 0.25490196078431370807 0.25490196078431370807 1.0"/>
            </material>
        </visual>
        <collision>
            <origin xyz="-0.042499999999998844258 0.047130780071017980282 -3.4694469519536141888e-17" rpy="1.5707963267948961139 1.75748440760723845e-16 1.5707963267949018871" />
            <geometry>
                <mesh filename="package:///renfort_leg.stl"/>
            </geometry>
        </collision>
        <visual>
            <origin xyz="1.7347234759768070944e-18 0 0" rpy="-3.141592653589793116 -2.0668332250037141152e-30 -6.4869956006508584081e-24" />
            <geometry>
                <mesh filename="package:///dc15_a01_horn_idle2_dummy.stl"/>
            </geometry>
            <material name="dc15_a01_horn_idle2_dummy_material">
                <color rgba="0.2313725490196078538 0.38039215686274507888 0.7058823529411765163 1.0"/>
            </material>
        </visual>
        <collision>
            <origin xyz="1.7347234759768070944e-18 0 0" rpy="-3.141592653589793116 -2.0668332250037141152e-30 -6.4869956006508584081e-24" />
            <geometry>
                <mesh filename="package:///dc15_a01_horn_idle2_dummy.stl"/>
            </geometry>
        </collision>
        <visual>
            <origin xyz="-6.9909356081865325905e-16 2.1792463666958639124e-16 0.022999999999999833078" rpy="1.57079632679489678 -9.441717580708686317e-17 1.5707963267948974462" />
            <geometry>
                <mesh filename="package:///dc15_a01_horn_dummy.stl"/>
            </geometry>
            <material name="dc15_a01_horn_dummy_material">
                <color rgba="0.49803921568627451677 0.49803921568627451677 0.49803921568627451677 1.0"/>
            </material>
        </visual>
        <collision>
            <origin xyz="-6.9909356081865325905e-16 2.1792463666958639124e-16 0.022999999999999833078" rpy="1.57079632679489678 -9.441717580708686317e-17 1.5707963267948974462" />
            <geometry>
                <mesh filename="package:///dc15_a01_horn_dummy.stl"/>
            </geometry>
        </collision>
        <visual>
            <origin xyz="-0.064999999999998420153 -1.1882855810441128597e-16 0.0034999999999999822919" rpy="3.1415926535897922278 5.3850638565700636271e-16 -1.5707963267948883423" />
            <geometry>
                <mesh filename="package:///dc15_a01_case_f_dummy.stl"/>
            </geometry>
            <material name="dc15_a01_case_f_dummy_material">
                <color rgba="0.28235294117647058432 0.25490196078431370807 0.25490196078431370807 1.0"/>
            </material>
        </visual>
        <collision>
            <origin xyz="-0.064999999999998420153 -1.1882855810441128597e-16 0.0034999999999999822919" rpy="3.1415926535897922278 5.3850638565700636271e-16 -1.5707963267948883423" />
            <geometry>
                <mesh filename="package:///dc15_a01_case_f_dummy.stl"/>
            </geometry>
        </collision>
        <visual>
            <origin xyz="-0.064999999999998267497 -5.9847959921199844757e-17 0.0034999999999999822919" rpy="3.1415926535897922278 4.2748408319437760574e-16 -1.5707963267948930053" />
            <geometry>
                <mesh filename="package:///dc15_a01_case_m_dummy.stl"/>
            </geometry>
            <material name="dc15_a01_case_m_dummy_material">
                <color rgba="0.28235294117647058432 0.25490196078431370807 0.25490196078431370807 1.0"/>
            </material>
        </visual>
        <collision>
            <origin xyz="-0.064999999999998267497 -5.9847959921199844757e-17 0.0034999999999999822919" rpy="3.1415926535897922278 4.2748408319437760574e-16 -1.5707963267948930053" />
            <geometry>
                <mesh filename="package:///dc15_a01_case_m_dummy.stl"/>
            </geometry>
        </collision>
        <visual>
            <origin xyz="-0.064999999999998239741 -6.7220534694101274908e-17 0.022999999999999874711" rpy="-3.141592653589793116 -1.6605126655691724991e-17 -1.5707963267948930053" />
            <geometry>
                <mesh filename="package:///dc15_a01_case_b_dummy.stl"/>
            </geometry>
            <material name="dc15_a01_case_b_dummy_material">
                <color rgba="0.28235294117647058432 0.25490196078431370807 0.25490196078431370807 1.0"/>
            </material>
        </visual>
        <collision>
            <origin xyz="-0.064999999999998239741 -6.7220534694101274908e-17 0.022999999999999874711" rpy="-3.141592653589793116 -1.6605126655691724991e-17 -1.5707963267948930053" />
            <geometry>
                <mesh filename="package:///dc15_a01_case_b_dummy.stl"/>
            </geometry>
        </collision>
        <inertial>
            <origin xyz="-0.039901628351738716027 -7.7113301693715872488e-06 0.011400440323216406296" rpy="0 0 0"/>
            <mass value="0.034530807353386039349" />
            <inertia ixx="5.0157740917570971503e-06" ixy="-2.9199735831043629538e-09"  ixz="-1.4737518371936669545e-07" iyy="2.0653502860209324197e-05" iyz="-5.5818119994614930111e-10" izz="1.7774415153789908874e-05" />
        </inertial>
    </link>
    <link name="leg_module_4">
        <visual>
            <origin xyz="-0.042500000000000315303 -0.047130780071021033395 0.02300000000000051309" rpy="-1.5707963267949101027 -1.3877787807783265195e-15 -1.5707963267948956698" />
            <geometry>
                <mesh filename="package:///block_to_axis.stl"/>
            </geometry>
            <material name="block_to_axis_material">
                <color rgba="0.81568627450980391025 0.44313725490196076429 0.0039215686274509803377 1.0"/>
            </material>
        </visual>
        <collision>
            <origin xyz="-0.042500000000000315303 -0.047130780071021033395 0.02300000000000051309" rpy="-1.5707963267949101027 -1.3877787807783265195e-15 -1.5707963267948956698" />
            <geometry>
                <mesh filename="package:///block_to_axis.stl"/>
            </geometry>
        </collision>
        <visual>
            <origin xyz="-0.042499999999999593658 0.047130780071021199928 4.9960036108132044319e-16" rpy="1.5707963267949105468 1.6098233857064517401e-15 1.5707963267948970021" />
            <geometry>
                <mesh filename="package:///block_to_axis.stl"/>
            </geometry>
            <material name="block_to_axis_material">
                <color rgba="0.81568627450980391025 0.44313725490196076429 0.0039215686274509803377 1.0"/>
            </material>
        </visual>
        <collision>
            <origin xyz="-0.042499999999999593658 0.047130780071021199928 4.9960036108132044319e-16" rpy="1.5707963267949105468 1.6098233857064517401e-15 1.5707963267948970021" />
            <geometry>
                <mesh filename="package:///block_to_axis.stl"/>
            </geometry>
        </collision>
        <visual>
            <origin xyz="-0.042499999999999579781 0.047130780071021179112 5.0653925498522767157e-16" rpy="1.5707963267949101027 1.2212453270876577978e-15 1.570796326794896558" />
            <geometry>
                <mesh filename="package:///renfort_leg.stl"/>
            </geometry>
            <material name="renfort_leg_material">
                <color rgba="0.28235294117647058432 0.25490196078431370807 0.25490196078431370807 1.0"/>
            </material>
        </visual>
        <collision>
            <origin xyz="-0.042499999999999579781 0.047130780071021179112 5.0653925498522767157e-16" rpy="1.5707963267949101027 1.2212453270876577978e-15 1.570796326794896558" />
            <geometry>
                <mesh filename="package:///renfort_leg.stl"/>
            </geometry>
        </collision>
        <visual>
            <origin xyz="1.3877787807814456755e-17 0 6.9388939039072283776e-18" rpy="3.141592653589793116 -1.1355857537972441971e-32 2.3665827156018266993e-30" />
            <geometry>
                <mesh filename="package:///dc15_a01_horn_idle2_dummy.stl"/>
            </geometry>
            <material name="dc15_a01_horn_idle2_dummy_material">
                <color rgba="0.2313725490196078538 0.38039215686274507888 0.7058823529411765163 1.0"/>
            </material>
        </visual>
        <collision>
            <origin xyz="1.3877787807814456755e-17 0 6.9388939039072283776e-18" rpy="3.141592653589793116 -1.1355857537972441971e-32 2.3665827156018266993e-30" />
            <geometry>
                <mesh filename="package:///dc15_a01_horn_idle2_dummy.stl"/>
            </geometry>
        </collision>
        <visual>
            <origin xyz="1.0408340855860842566e-15 -9.2374025095764977777e-17 0.022999999999999874711" rpy="1.5707963267949101027 9.9920072216262885625e-16 1.570796326794896558" />
            <geometry>
                <mesh filename="package:///dc15_a01_horn_dummy.stl"/>
            </geometry>
            <material name="dc15_a01_horn_dummy_material">
                <color rgba="0.49803921568627451677 0.49803921568627451677 0.49803921568627451677 1.0"/>
            </material>
        </visual>
        <collision>
            <origin xyz="1.0408340855860842566e-15 -9.2374025095764977777e-17 0.022999999999999874711" rpy="1.5707963267949101027 9.9920072216262885625e-16 1.570796326794896558" />
            <geometry>
                <mesh filename="package:///dc15_a01_horn_dummy.stl"/>
            </geometry>
        </collision>
        <visual>
            <origin xyz="-0.065000000000000085487 1.6154612370034016067e-15 0.0035000000000008565926" rpy="3.1415926535897797933 -1.1102230246251936169e-15 -1.5707963267948961139" />
            <geometry>
                <mesh filename="package:///dc15_a01_case_f_dummy.stl"/>
            </geometry>
            <material name="dc15_a01_case_f_dummy_material">
                <color rgba="0.28235294117647058432 0.25490196078431370807 0.25490196078431370807 1.0"/>
            </material>
        </visual>
        <collision>
            <origin xyz="-0.065000000000000085487 1.6154612370034016067e-15 0.0035000000000008565926" rpy="3.1415926535897797933 -1.1102230246251936169e-15 -1.5707963267948961139" />
            <geometry>
                <mesh filename="package:///dc15_a01_case_f_dummy.stl"/>
            </geometry>
        </collision>
        <visual>
            <origin xyz="-0.065000000000000140998 1.6137265135274247996e-15 0.0035000000000008565926" rpy="3.1415926535897797933 -1.1102230246251936169e-15 -1.5707963267948961139" />
            <geometry>
                <mesh filename="package:///dc15_a01_case_m_dummy.stl"/>
            </geometry>
            <material name="dc15_a01_case_m_dummy_material">
                <color rgba="0.28235294117647058432 0.25490196078431370807 0.25490196078431370807 1.0"/>
            </material>
        </visual>
        <collision>
            <origin xyz="-0.065000000000000140998 1.6137265135274247996e-15 0.0035000000000008565926" rpy="3.1415926535897797933 -1.1102230246251936169e-15 -1.5707963267948961139" />
            <geometry>
                <mesh filename="package:///dc15_a01_case_m_dummy.stl"/>
            </geometry>
        </collision>
        <visual>
            <origin xyz="-0.065000000000000168754 1.6239180139487885413e-15 0.023000000000000735134" rpy="3.1415926535897797933 -1.1102230246251936169e-15 -1.5707963267948961139" />
            <geometry>
                <mesh filename="package:///dc15_a01_case_b_dummy.stl"/>
            </geometry>
            <material name="dc15_a01_case_b_dummy_material">
                <color rgba="0.28235294117647058432 0.25490196078431370807 0.25490196078431370807 1.0"/>
            </material>
        </visual>
        <collision>
            <origin xyz="-0.065000000000000168754 1.6239180139487885413e-15 0.023000000000000735134" rpy="3.1415926535897797933 -1.1102230246251936169e-15 -1.5707963267948961139" />
            <geometry>
                <mesh filename="package:///dc15_a01_case_b_dummy.stl"/>
            </geometry>
        </collision>
        <inertial>
            <origin xyz="-0.039901628351739659717 -7.7113301683934827292e-06 0.011400440323216957939" rpy="0 0 0"/>
            <mass value="0.034530807353386039349" />
            <inertia ixx="5.0157740917571691481e-06" ixy="-2.9199735827629884102e-09"  ixz="-1.4737518371923699353e-07" iyy="2.0653502860210814975e-05" iyz="-5.581811998963287298e-10" izz="1.777441515379100324e-05" />
        </inertial>
    </link>
    <link name="foot_module_2">
        <visual>
            <origin xyz="0 0 0" rpy="3.141592653589793116 -4.8276505048317026277e-31 5.0037344593007477894e-30" />
            <geometry>
                <mesh filename="package:///dc15_a01_horn_idle2_dummy.stl"/>
            </geometry>
            <material name="dc15_a01_horn_idle2_dummy_material">
                <color rgba="0.2313725490196078538 0.38039215686274507888 0.7058823529411765163 1.0"/>
            </material>
        </visual>
        <collision>
            <origin xyz="0 0 0" rpy="3.141592653589793116 -4.8276505048317026277e-31 5.0037344593007477894e-30" />
            <geometry>
                <mesh filename="package:///dc15_a01_horn_idle2_dummy.stl"/>
            </geometry>
        </collision>
        <visual>
            <origin xyz="0 -4.9439619065339002191e-17 -0.0051999999999999754752" rpy="-3.141592653589793116 -1.570796326794896558 0" />
            <geometry>
                <mesh filename="package:///foot.stl"/>
            </geometry>
            <material name="foot_material">
                <color rgba="0.81568627450980391025 0.44313725490196076429 0.0039215686274509803377 1.0"/>
            </material>
        </visual>
        <collision>
            <origin xyz="0 -4.9439619065339002191e-17 -0.0051999999999999754752" rpy="-3.141592653589793116 -1.570796326794896558 0" />
            <geometry>
                <mesh filename="package:///foot.stl"/>
            </geometry>
        </collision>
        <visual>
            <origin xyz="0 -4.9439619065339002191e-17 -0.0051999999999999754752" rpy="-3.141592653589793116 -1.570796326794896558 0" />
            <geometry>
                <mesh filename="package:///foot_contact.stl"/>
            </geometry>
            <material name="foot_contact_material">
                <color rgba="0 0 0 1.0"/>
            </material>
        </visual>
        <collision>
            <origin xyz="0 -4.9439619065339002191e-17 -0.0051999999999999754752" rpy="-3.141592653589793116 -1.570796326794896558 0" />
            <geometry>
                <mesh filename="package:///foot_contact.stl"/>
            </geometry>
        </collision>
        <visual>
            <origin xyz="-8.3266726846886740532e-17 -3.1441863002079628586e-17 0.0229999999999998192" rpy="1.5707963267948958919 -1.7486012637846381172e-15 1.5707963267948981123" />
            <geometry>
                <mesh filename="package:///dc15_a01_horn_dummy.stl"/>
            </geometry>
            <material name="dc15_a01_horn_dummy_material">
                <color rgba="0.49803921568627451677 0.49803921568627451677 0.49803921568627451677 1.0"/>
            </material>
        </visual>
        <collision>
            <origin xyz="-8.3266726846886740532e-17 -3.1441863002079628586e-17 0.0229999999999998192" rpy="1.5707963267948958919 -1.7486012637846381172e-15 1.5707963267948981123" />
            <geometry>
                <mesh filename="package:///dc15_a01_horn_dummy.stl"/>
            </geometry>
        </collision>
        <inertial>
            <origin xyz="-0.02687316766137815352 0.0076028406460558793992 0.011556240850102183701" rpy="0 0 0"/>
            <mass value="0.028234070013912770242" />
            <inertia ixx="1.1973322148719459275e-05" ixy="1.228571960438203719e-06"  ixz="-4.2627541791625192487e-08" iyy="5.3787427295815475698e-06" iyz="1.2080361154658910956e-08" izz="1.3185549498032327003e-05" />
        </inertial>
    </link>
    <link name="left_foot">
        <inertial>
            <origin xyz="0 0 0" rpy="0 0 0" />
            <mass value="1e-9" />
            <inertia ixx="0" ixy="0" ixz="0" iyy="0" iyz="0" izz="0" />
        </inertial>
    </link>
    <joint name="left_foot_frame" type="fixed">
        <origin xyz="-0.037499999999999339417 0.0050000000000035302664 0.011500000000004333145" rpy="1.5707963267948952257 -1.1420177484200466381e-14 1.5707963267948961139" />
        <parent link="foot_module_2" />
        <child link="left_foot" />
        <axis xyz="0 0 0"/>
    </joint>
    <joint name="left_ankle" type="revolute">
        <origin xyz="-0.065000000000000140998 1.6111244283134595889e-15 8.7430063189231077558e-16" rpy="-1.1368826724137153788e-14 1.6596211705633574847e-14 -2.1322488822902390562e-14" />
        <parent link="leg_module_4" />
        <child link="foot_module_2" />
        <axis xyz="0 0 1"/>
        <limit effort="1" velocity="20" lower="-1.570796326794896558" upper="1.570796326794896558"/>
        <joint_properties friction="0.0"/>
    </joint>
    <joint name="left_knee" type="revolute">
        <origin xyz="-0.064999999999998281375 -5.8763757748714340323e-17 0" rpy="5.970893051203023059e-16 -1.4853578868213746426e-14 -7.8207310266750229308e-08" />
        <parent link="leg_module_3" />
        <child link="leg_module_4" />
        <axis xyz="0 0 1"/>
        <limit effort="1" velocity="20" lower="-2.0943951023931952626" upper="2.0943951023931952626"/>
        <joint_properties friction="0.0"/>
    </joint>
    <joint name="left_hip_pitch" type="revolute">
        <origin xyz="0.025000000000000459355 -0.0015000000000000013323 -0.0095000000000003380352" rpy="-1.57079632679489678 7.8207331219164669488e-08 -3.141592653589793116" />
        <parent link="left_hip_pitch_roll_module" />
        <child link="leg_module_3" />
        <axis xyz="0 0 1"/>
        <limit effort="1" velocity="20" lower="-0.52359877559829881566" upper="1.570796326794896558"/>
        <joint_properties friction="0.0"/>
    </joint>
    <joint name="left_hip_roll" type="revolute">
        <origin xyz="0.034000000000001168177 -0.0115000000000000345 0.011499999999999996336" rpy="1.570796326794896558 -1.570796326794896558 0" />
        <parent link="double_u_module_2" />
        <child link="left_hip_pitch_roll_module" />
        <axis xyz="0 0 1"/>
        <limit effort="1" velocity="20" lower="-1.570796326794896558" upper="0.43633231299858238339"/>
        <joint_properties friction="0.0"/>
    </joint>
    <joint name="left_hip_yaw" type="revolute">
        <origin xyz="0.00012710048502760968214 0.018396103569423397778 0.023078922950960291394" rpy="3.1415926535897309435 -1.5078389055347532112e-14 1.5707963267948974462" />
        <parent link="body_module" />
        <child link="double_u_module_2" />
        <axis xyz="0 0 1"/>
        <limit effort="1" velocity="20" lower="-0.69813170079773179122" upper="0.69813170079773179122"/>
        <joint_properties friction="0.0"/>
    </joint>
    <link name="head_link">
        <visual>
            <origin xyz="-2.2551405187698492227e-16 -1.0408340855860842566e-16 0.022999999999999996142" rpy="-1.570796326794896558 -2.2021623822161954679e-28 -3.141592653589793116" />
            <geometry>
                <mesh filename="package:///axis_to_axis.stl"/>
            </geometry>
            <material name="axis_to_axis_material">
                <color rgba="0.28235294117647058432 0.25490196078431370807 0.25490196078431370807 1.0"/>
            </material>
        </visual>
        <collision>
            <origin xyz="-2.2551405187698492227e-16 -1.0408340855860842566e-16 0.022999999999999996142" rpy="-1.570796326794896558 -2.2021623822161954679e-28 -3.141592653589793116" />
            <geometry>
                <mesh filename="package:///axis_to_axis.stl"/>
            </geometry>
        </collision>
        <visual>
            <origin xyz="-2.3245294578089215065e-16 -0.064999999999999100164 0.022999999999999999611" rpy="1.570796326794896558 2.0543045052719165412e-28 -1.1102230246246678164e-16" />
            <geometry>
                <mesh filename="package:///dc15_a01_horn_dummy.stl"/>
            </geometry>
            <material name="dc15_a01_horn_dummy_material">
                <color rgba="0.49803921568627451677 0.49803921568627451677 0.49803921568627451677 1.0"/>
            </material>
        </visual>
        <collision>
            <origin xyz="-2.3245294578089215065e-16 -0.064999999999999100164 0.022999999999999999611" rpy="1.570796326794896558 2.0543045052719165412e-28 -1.1102230246246678164e-16" />
            <geometry>
                <mesh filename="package:///dc15_a01_horn_dummy.stl"/>
            </geometry>
        </collision>
        <visual>
            <origin xyz="-1.0755285551056203985e-16 4.0939474033052647428e-16 0" rpy="1.570796326794896558 3.3807740382092691183e-30 0" />
            <geometry>
                <mesh filename="package:///renfort_head_link.stl"/>
            </geometry>
            <material name="renfort_head_link_material">
                <color rgba="0.28235294117647058432 0.25490196078431370807 0.25490196078431370807 1.0"/>
            </material>
        </visual>
        <collision>
            <origin xyz="-1.0755285551056203985e-16 4.0939474033052647428e-16 0" rpy="1.570796326794896558 3.3807740382092691183e-30 0" />
            <geometry>
                <mesh filename="package:///renfort_head_link.stl"/>
            </geometry>
        </collision>
        <visual>
            <origin xyz="-2.2551405187698492227e-16 -9.7144514654701197287e-17 0.022999999999999996142" rpy="1.570796326794896558 2.0543045052719165412e-28 -1.1102230246246678164e-16" />
            <geometry>
                <mesh filename="package:///dc15_a01_horn_dummy.stl"/>
            </geometry>
            <material name="dc15_a01_horn_dummy_material">
                <color rgba="0.49803921568627451677 0.49803921568627451677 0.49803921568627451677 1.0"/>
            </material>
        </visual>
        <collision>
            <origin xyz="-2.2551405187698492227e-16 -9.7144514654701197287e-17 0.022999999999999996142" rpy="1.570796326794896558 2.0543045052719165412e-28 -1.1102230246246678164e-16" />
            <geometry>
                <mesh filename="package:///dc15_a01_horn_dummy.stl"/>
            </geometry>
        </collision>
        <visual>
            <origin xyz="3.4694469519536141888e-18 -0.064999999999999114042 3.4694469519536141888e-18" rpy="-3.141592653589793116 -2.9383826821945038949e-16 -2.2204460492499677077e-16" />
            <geometry>
                <mesh filename="package:///dc15_a01_horn_idle2_dummy.stl"/>
            </geometry>
            <material name="dc15_a01_horn_idle2_dummy_material">
                <color rgba="0.2313725490196078538 0.38039215686274507888 0.7058823529411765163 1.0"/>
            </material>
        </visual>
        <collision>
            <origin xyz="3.4694469519536141888e-18 -0.064999999999999114042 3.4694469519536141888e-18" rpy="-3.141592653589793116 -2.9383826821945038949e-16 -2.2204460492499677077e-16" />
            <geometry>
                <mesh filename="package:///dc15_a01_horn_idle2_dummy.stl"/>
            </geometry>
        </collision>
        <visual>
            <origin xyz="0 0 0" rpy="3.141592653589793116 2.8115191019968956248e-32 0" />
            <geometry>
                <mesh filename="package:///dc15_a01_horn_idle2_dummy.stl"/>
            </geometry>
            <material name="dc15_a01_horn_idle2_dummy_material">
                <color rgba="0.2313725490196078538 0.38039215686274507888 0.7058823529411765163 1.0"/>
            </material>
        </visual>
        <collision>
            <origin xyz="0 0 0" rpy="3.141592653589793116 2.8115191019968956248e-32 0" />
            <geometry>
                <mesh filename="package:///dc15_a01_horn_idle2_dummy.stl"/>
            </geometry>
        </collision>
        <visual>
            <origin xyz="0 -9.0205620750793968909e-17 0" rpy="1.570796326794896558 2.1124562256396357684e-28 1.2621774483536382266e-29" />
            <geometry>
                <mesh filename="package:///axis_to_axis.stl"/>
            </geometry>
            <material name="axis_to_axis_material">
                <color rgba="0.28235294117647058432 0.25490196078431370807 0.25490196078431370807 1.0"/>
            </material>
        </visual>
        <collision>
            <origin xyz="0 -9.0205620750793968909e-17 0" rpy="1.570796326794896558 2.1124562256396357684e-28 1.2621774483536382266e-29" />
            <geometry>
                <mesh filename="package:///axis_to_axis.stl"/>
            </geometry>
        </collision>
        <inertial>
            <origin xyz="-2.465311096247913048e-14 -0.032499754096266771086 0.011652192306627142532" rpy="0 0 0"/>
            <mass value="0.020865926048949740013" />
            <inertia ixx="1.42994772506051681e-05" ixy="2.01559662912318982e-21"  ixz="6.4038749772340021189e-18" iyy="4.8005448764253559949e-06" iyz="-5.9496902423419134302e-11" izz="1.0668759971070639146e-05" />
        </inertial>
    </link>
    <link name="head_pitch_yaw">
        <visual>
            <origin xyz="0.043000000000002480682 0.0001000000000004851175 -0.011500000000000454303" rpy="1.5707963267948972241 1.7877175507189012539e-16 -1.570796326794896558" />
            <geometry>
                <mesh filename="package:///head_roll_pitch.stl"/>
            </geometry>
            <material name="head_roll_pitch_material">
                <color rgba="0.64705882352941179736 0.64705882352941179736 0.64705882352941179736 1.0"/>
            </material>
        </visual>
        <collision>
            <origin xyz="0.043000000000002480682 0.0001000000000004851175 -0.011500000000000454303" rpy="1.5707963267948972241 1.7877175507189012539e-16 -1.570796326794896558" />
            <geometry>
                <mesh filename="package:///head_roll_pitch.stl"/>
            </geometry>
        </collision>
        <visual>
            <origin xyz="0.034499999999999420019 3.4694469519536141888e-17 -0.011500000000000006745" rpy="-1.0384614260316070598e-30 1.570796326794896558 0" />
            <geometry>
                <mesh filename="package:///dc15_a01_case_f_dummy.stl"/>
            </geometry>
            <material name="dc15_a01_case_f_dummy_material">
                <color rgba="0.28235294117647058432 0.25490196078431370807 0.25490196078431370807 1.0"/>
            </material>
        </visual>
        <collision>
            <origin xyz="0.034499999999999420019 3.4694469519536141888e-17 -0.011500000000000006745" rpy="-1.0384614260316070598e-30 1.570796326794896558 0" />
            <geometry>
                <mesh filename="package:///dc15_a01_case_f_dummy.stl"/>
            </geometry>
        </collision>
        <visual>
            <origin xyz="0.034499999999999420019 3.4694469519536141888e-17 -0.011500000000000006745" rpy="-1.0384614260316070598e-30 1.5707963267948961139 0" />
            <geometry>
                <mesh filename="package:///dc15_a01_case_m_dummy.stl"/>
            </geometry>
            <material name="dc15_a01_case_m_dummy_material">
                <color rgba="0.28235294117647058432 0.25490196078431370807 0.25490196078431370807 1.0"/>
            </material>
        </visual>
        <collision>
            <origin xyz="0.034499999999999420019 3.4694469519536141888e-17 -0.011500000000000006745" rpy="-1.0384614260316070598e-30 1.5707963267948961139 0" />
            <geometry>
                <mesh filename="package:///dc15_a01_case_m_dummy.stl"/>
            </geometry>
        </collision>
        <visual>
            <origin xyz="0.014999999999999735767 7.2858385991025897965e-17 -0.011500000000000003275" rpy="-1.0384614260316070598e-30 1.570796326794896558 0" />
            <geometry>
                <mesh filename="package:///dc15_a01_case_b_dummy.stl"/>
            </geometry>
            <material name="dc15_a01_case_b_dummy_material">
                <color rgba="0.28235294117647058432 0.25490196078431370807 0.25490196078431370807 1.0"/>
            </material>
        </visual>
        <collision>
            <origin xyz="0.014999999999999735767 7.2858385991025897965e-17 -0.011500000000000003275" rpy="-1.0384614260316070598e-30 1.570796326794896558 0" />
            <geometry>
                <mesh filename="package:///dc15_a01_case_b_dummy.stl"/>
            </geometry>
        </collision>
        <visual>
            <origin xyz="-1.3877787807814456755e-17 3.4694469519536141888e-18 -0.0035000000000000083128" rpy="3.8285686989269395741e-16 -1.8369701987209951748e-16 1.0384614260316070598e-30" />
            <geometry>
                <mesh filename="package:///dc15_a01_case_f_dummy.stl"/>
            </geometry>
            <material name="dc15_a01_case_f_dummy_material">
                <color rgba="0.28235294117647058432 0.25490196078431370807 0.25490196078431370807 1.0"/>
            </material>
        </visual>
        <collision>
            <origin xyz="-1.3877787807814456755e-17 3.4694469519536141888e-18 -0.0035000000000000083128" rpy="3.8285686989269395741e-16 -1.8369701987209951748e-16 1.0384614260316070598e-30" />
            <geometry>
                <mesh filename="package:///dc15_a01_case_f_dummy.stl"/>
            </geometry>
        </collision>
        <visual>
            <origin xyz="-1.3877787807814456755e-17 3.4694469519536141888e-18 -0.0034999999999999996392" rpy="1.4442762621570761677e-32 1.6187678482638252831e-30 1.0384614260316070598e-30" />
            <geometry>
                <mesh filename="package:///dc15_a01_case_m_dummy.stl"/>
            </geometry>
            <material name="dc15_a01_case_m_dummy_material">
                <color rgba="0.28235294117647058432 0.25490196078431370807 0.25490196078431370807 1.0"/>
            </material>
        </visual>
        <collision>
            <origin xyz="-1.3877787807814456755e-17 3.4694469519536141888e-18 -0.0034999999999999996392" rpy="1.4442762621570761677e-32 1.6187678482638252831e-30 1.0384614260316070598e-30" />
            <geometry>
                <mesh filename="package:///dc15_a01_case_m_dummy.stl"/>
            </geometry>
        </collision>
        <visual>
            <origin xyz="5.5511151231257827021e-17 1.0408340855860842566e-17 -0.023000000000000003081" rpy="3.8285686989269395741e-16 -1.8369701987209951748e-16 1.0384614260316070598e-30" />
            <geometry>
                <mesh filename="package:///dc15_a01_case_b_dummy.stl"/>
            </geometry>
            <material name="dc15_a01_case_b_dummy_material">
                <color rgba="0.28235294117647058432 0.25490196078431370807 0.25490196078431370807 1.0"/>
            </material>
        </visual>
        <collision>
            <origin xyz="5.5511151231257827021e-17 1.0408340855860842566e-17 -0.023000000000000003081" rpy="3.8285686989269395741e-16 -1.8369701987209951748e-16 1.0384614260316070598e-30" />
            <geometry>
                <mesh filename="package:///dc15_a01_case_b_dummy.stl"/>
            </geometry>
        </collision>
        <inertial>
            <origin xyz="0.0098462389769370297493 -0.0074913907846173907051 -0.011414627018494627811" rpy="0 0 0"/>
            <mass value="0.055748483731440375" />
            <inertia ixx="1.1084353108581466798e-05" ixy="4.6430898558405518791e-08"  ixz="5.391870938911324893e-08" iyy="1.4996460664233086466e-05" iyz="2.6700391159770292421e-09" izz="2.0540187796855563908e-05" />
        </inertial>
    </link>
    <link name="head_assembly">
        <visual>
            <origin xyz="-0.030306635053896472526 -0.030306635053896073539 -0.0052000000000000379252" rpy="-1.1974744221538794912e-16 -5.3543852478563561428e-17 -1.570796326794896558" />
            <geometry>
                <mesh filename="package:///antenna_motor_holder.stl"/>
            </geometry>
            <material name="antenna_motor_holder_material">
                <color rgba="0.49803921568627451677 0.49803921568627451677 0.49803921568627451677 1.0"/>
            </material>
        </visual>
        <collision>
            <origin xyz="-0.030306635053896472526 -0.030306635053896073539 -0.0052000000000000379252" rpy="-1.1974744221538794912e-16 -5.3543852478563561428e-17 -1.570796326794896558" />
            <geometry>
                <mesh filename="package:///antenna_motor_holder.stl"/>
            </geometry>
        </collision>
        <visual>
            <origin xyz="-5.2041704279304212832e-17 -8.6736173798840354721e-19 -0.0052000000000000656808" rpy="-5.3543852478562932805e-17 1.1974744221538797377e-16 5.5511151224368747877e-17" />
            <geometry>
                <mesh filename="package:///head.stl"/>
            </geometry>
            <material name="head_material">
                <color rgba="0.91764705882352937127 0.91764705882352937127 0.91764705882352937127 1.0"/>
            </material>
        </visual>
        <collision>
            <origin xyz="-5.2041704279304212832e-17 -8.6736173798840354721e-19 -0.0052000000000000656808" rpy="-5.3543852478562932805e-17 1.1974744221538797377e-16 5.5511151224368747877e-17" />
            <geometry>
                <mesh filename="package:///head.stl"/>
            </geometry>
        </collision>
        <visual>
            <origin xyz="-5.2041704279304212832e-17 -2.6020852139652106416e-18 -0.0052000000000000656808" rpy="-5.3543852478561342757e-17 1.1974744221538794912e-16 5.5511151224368735551e-17" />
            <geometry>
                <mesh filename="package:///antenna_motor_holder.stl"/>
            </geometry>
            <material name="antenna_motor_holder_material">
                <color rgba="0.49803921568627451677 0.49803921568627451677 0.49803921568627451677 1.0"/>
            </material>
        </visual>
        <collision>
            <origin xyz="-5.2041704279304212832e-17 -2.6020852139652106416e-18 -0.0052000000000000656808" rpy="-5.3543852478561342757e-17 1.1974744221538794912e-16 5.5511151224368735551e-17" />
            <geometry>
                <mesh filename="package:///antenna_motor_holder.stl"/>
            </geometry>
        </collision>
        <visual>
            <origin xyz="-0.046325000000000629563 -0.0045183649461039507994 0.0098000000000001696865" rpy="-1.570796326794896558 -1.1974744221542581444e-16 -3.141592653589793116" />
            <geometry>
                <mesh filename="package:///sg90.stl"/>
            </geometry>
            <material name="sg90_material">
                <color rgba="0.43529411764705883137 0.67058823529411759612 0.97647058823529409022 1.0"/>
            </material>
        </visual>
        <collision>
            <origin xyz="-0.046325000000000629563 -0.0045183649461039507994 0.0098000000000001696865" rpy="-1.570796326794896558 -1.1974744221542581444e-16 -3.141592653589793116" />
            <geometry>
                <mesh filename="package:///sg90.stl"/>
            </geometry>
        </collision>
        <visual>
            <origin xyz="-0.046325000000000629563 0.0045183649461039655446 0.0098000000000001141753" rpy="1.57079632679489678 -1.1974744221538794912e-16 -3.141592653589793116" />
            <geometry>
                <mesh filename="package:///sg90.stl"/>
            </geometry>
            <material name="sg90_material">
                <color rgba="0.43529411764705883137 0.67058823529411759612 0.97647058823529409022 1.0"/>
            </material>
        </visual>
        <collision>
            <origin xyz="-0.046325000000000629563 0.0045183649461039655446 0.0098000000000001141753" rpy="1.57079632679489678 -1.1974744221538794912e-16 -3.141592653589793116" />
            <geometry>
                <mesh filename="package:///sg90.stl"/>
            </geometry>
        </collision>
        <visual>
            <origin xyz="0 0 -2.7755575615628913511e-17" rpy="3.141592653589793116 2.9520654187567551156e-30 -6.0461138453829856947e-32" />
            <geometry>
                <mesh filename="package:///dc15_a01_horn_idle2_dummy.stl"/>
            </geometry>
            <material name="dc15_a01_horn_idle2_dummy_material">
                <color rgba="0.2313725490196078538 0.38039215686274507888 0.7058823529411765163 1.0"/>
            </material>
        </visual>
        <collision>
            <origin xyz="0 0 -2.7755575615628913511e-17" rpy="3.141592653589793116 2.9520654187567551156e-30 -6.0461138453829856947e-32" />
            <geometry>
                <mesh filename="package:///dc15_a01_horn_idle2_dummy.stl"/>
            </geometry>
        </collision>
        <inertial>
            <origin xyz="-0.0049904936490059422297 -5.7224768728719324705e-05 0.0071270976823235611397" rpy="0 0 0"/>
            <mass value="0.11182196316230802458" />
            <inertia ixx="0.00013102969105839397585" ixy="4.9604823205080920893e-07"  ixz="4.4525709954214999752e-06" iyy="0.00026409238986169387715" iyz="3.3092977772311406299e-08" izz="0.00037353425693635865538" />
        </inertial>
    </link>
    <link name="head">
        <inertial>
            <origin xyz="0 0 0" rpy="0 0 0" />
            <mass value="1e-9" />
            <inertia ixx="0" ixy="0" ixz="0" iyy="0" iyz="0" izz="0" />
        </inertial>
    </link>
    <joint name="head_frame" type="fixed">
        <origin xyz="-7.9797279894933126343e-17 8.6736173798840354721e-19 -0.0076000000000000789147" rpy="-3.141592653589793116 1.3183898417348306489e-16 -2.0261749666996487726e-26" />
        <parent link="head_assembly" />
        <child link="head" />
        <axis xyz="0 0 0"/>
    </joint>
    <link name="left_antenna_assembly">
        <visual>
            <origin xyz="0.047829704883305929064 0.0099105372641234146247 -0.080676288527250283877" rpy="1.570796326794896558 -2.1420200727859114585e-31 1.3723147159839140706e-30" />
            <geometry>
                <mesh filename="package:///antenna_tip.stl"/>
            </geometry>
            <material name="antenna_tip_material">
                <color rgba="0.30196078431372547213 0.30196078431372547213 0.30196078431372547213 1.0"/>
            </material>
        </visual>
        <collision>
            <origin xyz="0.047829704883305929064 0.0099105372641234146247 -0.080676288527250283877" rpy="1.570796326794896558 -2.1420200727859114585e-31 1.3723147159839140706e-30" />
            <geometry>
                <mesh filename="package:///antenna_tip.stl"/>
            </geometry>
        </collision>
        <visual>
            <origin xyz="0.05020544527131384771 -0.016818394108500916984 0.027300000000000001349" rpy="1.570796326794896558 -2.1420200727859114585e-31 1.3723147159839140706e-30" />
            <geometry>
                <mesh filename="package:///antenna_holder_left.stl"/>
            </geometry>
            <material name="antenna_holder_left_material">
                <color rgba="0.80000000000000004441 0.80000000000000004441 0.80000000000000004441 1.0"/>
            </material>
        </visual>
        <collision>
            <origin xyz="0.05020544527131384771 -0.016818394108500916984 0.027300000000000001349" rpy="1.570796326794896558 -2.1420200727859114585e-31 1.3723147159839140706e-30" />
            <geometry>
                <mesh filename="package:///antenna_holder_left.stl"/>
            </geometry>
        </collision>
        <visual>
            <origin xyz="0.047829704883305929064 0.0099105372641234146247 -0.080676288527250283877" rpy="1.570796326794896558 -2.1420200727859114585e-31 1.3723147159839140706e-30" />
            <geometry>
                <mesh filename="package:///antenna.stl"/>
            </geometry>
            <material name="antenna_material">
                <color rgba="0.5999999999999999778 0.5999999999999999778 0.5999999999999999778 1.0"/>
            </material>
        </visual>
        <collision>
            <origin xyz="0.047829704883305929064 0.0099105372641234146247 -0.080676288527250283877" rpy="1.570796326794896558 -2.1420200727859114585e-31 1.3723147159839140706e-30" />
            <geometry>
                <mesh filename="package:///antenna.stl"/>
            </geometry>
        </collision>
        <inertial>
            <origin xyz="-0.0012514881850664695637 0.013520387889189860661 -0.013569433206048704676" rpy="0 0 0"/>
            <mass value="0.0021739976315290265516" />
            <inertia ixx="2.1408428456245531742e-06" ixy="-4.4453169495119661366e-08"  ixz="-1.0549835403068911851e-08" iyy="1.1869600811837781296e-07" iyz="1.3610759600233906213e-07" izz="2.0890342232372873653e-06" />
        </inertial>
    </link>
    <joint name="left_antenna" type="revolute">
        <origin xyz="-0.052000000000000864975 -0.03151836494610388284 0.0098000000000001419309" rpy="-1.57079632679489678 1.1974744221533701829e-16 1.1102230247078030323e-16" />
        <parent link="head_assembly" />
        <child link="left_antenna_assembly" />
        <axis xyz="0 0 1"/>
        <limit effort="1" velocity="20" lower="-1.1344640137963142301" upper="2.0943951023931952626"/>
        <joint_properties friction="0.0"/>
    </joint>
    <link name="right_antenna_assembly">
        <visual>
            <origin xyz="0.050205445271313833833 0.016818394108500916984 -0.020699999999999996181" rpy="-1.570796326794896558 1.0007936238654886908e-31 4.9997598966897878144e-30" />
            <geometry>
                <mesh filename="package:///antenna_holder_right.stl"/>
            </geometry>
            <material name="antenna_holder_right_material">
                <color rgba="0.80000000000000004441 0.80000000000000004441 0.80000000000000004441 1.0"/>
            </material>
        </visual>
        <collision>
            <origin xyz="0.050205445271313833833 0.016818394108500916984 -0.020699999999999996181" rpy="-1.570796326794896558 1.0007936238654886908e-31 4.9997598966897878144e-30" />
            <geometry>
                <mesh filename="package:///antenna_holder_right.stl"/>
            </geometry>
        </collision>
        <visual>
            <origin xyz="0.047829704883307760932 -0.010215450772524892198 0.044276288527250289018" rpy="-1.570796326794896558 1.0007936235382055815e-31 4.9997598966917671484e-30" />
            <geometry>
                <mesh filename="package:///antenna_tip.stl"/>
            </geometry>
            <material name="antenna_tip_material">
                <color rgba="0.30196078431372547213 0.30196078431372547213 0.30196078431372547213 1.0"/>
            </material>
        </visual>
        <collision>
            <origin xyz="0.047829704883307760932 -0.010215450772524892198 0.044276288527250289018" rpy="-1.570796326794896558 1.0007936235382055815e-31 4.9997598966917671484e-30" />
            <geometry>
                <mesh filename="package:///antenna_tip.stl"/>
            </geometry>
        </collision>
        <visual>
            <origin xyz="0.047829704883306373153 -0.010215450772527223666 0.044276288527250289018" rpy="-1.570796326794896558 -2.9435109023205088977e-31 1.7621534380226343841e-29" />
            <geometry>
                <mesh filename="package:///antenna.stl"/>
            </geometry>
            <material name="antenna_material">
                <color rgba="0.5999999999999999778 0.5999999999999999778 0.5999999999999999778 1.0"/>
            </material>
        </visual>
        <collision>
            <origin xyz="0.047829704883306373153 -0.010215450772527223666 0.044276288527250289018" rpy="-1.570796326794896558 -2.9435109023205088977e-31 1.7621534380226343841e-29" />
            <geometry>
                <mesh filename="package:///antenna.stl"/>
            </geometry>
        </collision>
        <inertial>
            <origin xyz="-0.001251488547137640352 -0.013579477794938066282 -0.013569434366070356329" rpy="0 0 0"/>
            <mass value="0.0021739987496008352993" />
            <inertia ixx="2.1553254538026376613e-06" ixy="4.4647482566072890398e-08"  ixz="-1.0549835959950504648e-08" iyy="1.1869601838029969329e-07" iyz="-1.3670248108268182406e-07" izz="2.1035168234757093684e-06" />
        </inertial>
    </link>
    <joint name="right_antenna" type="revolute">
        <origin xyz="-0.052000000000000719258 0.031518364946103966107 0.0098000000000001141753" rpy="1.570796326794896558 1.1974744221538782586e-16 5.5511151224369080677e-17" />
        <parent link="head_assembly" />
        <child link="right_antenna_assembly" />
        <axis xyz="0 0 1"/>
        <limit effort="1" velocity="20" lower="-2.0943951023931952626" upper="1.1344640137963142301"/>
        <joint_properties friction="0.0"/>
    </joint>
    <joint name="head_yaw" type="revolute">
        <origin xyz="0.037999999999999423128 3.4694469519536141888e-17 -0.011500000000000006745" rpy="1.570796326794896558 1.5530065672147715551e-15 -1.570796326794896558" />
        <parent link="head_pitch_yaw" />
        <child link="head_assembly" />
        <axis xyz="0 0 1"/>
        <limit effort="1" velocity="20" lower="-2.0943951023931952626" upper="2.0943951023931952626"/>
        <joint_properties friction="0.0"/>
    </joint>
    <joint name="head_pitch" type="revolute">
        <origin xyz="3.4694469519536141888e-18 -0.064999999999999114042 3.4694469519536141888e-18" rpy="3.1415926535897926719 -1.6569800610870191142e-15 -1.570796326794896336" />
        <parent link="head_link" />
        <child link="head_pitch_yaw" />
        <axis xyz="0 0 1"/>
        <limit effort="1" velocity="20" lower="-0.69813170079773179122" upper="0.69813170079773179122"/>
        <joint_properties friction="0.0"/>
    </joint>
    <joint name="neck_pitch" type="revolute">
        <origin xyz="0.030627100485025756521 -0.018103896430577130772 0.055078922950960805538" rpy="-1.570796326794881459 -6.2505556286397272481e-14 1.0547118733946938852e-15" />
        <parent link="body_module" />
        <child link="head_link" />
        <axis xyz="0 0 1"/>
        <limit effort="1" velocity="20" lower="-1.3089969389957472057" upper="0.1745329251994329478"/>
        <joint_properties friction="0.0"/>
    </joint>
</robot>