<robot name="onshape">
<link name="body_module">
<visual>
<origin xyz="-0.049872899514971674728 -0.1141428912905502191 0.01507892295095538196" rpy="-6.2367202746833250932e-14 -1.5074919608395581653e-14 1.5707963267948974462" />
<geometry>
<mesh filename="package:///cage_bottom.stl"/>
</geometry>
<material name="cage_bottom_material">
<color rgba="0.64705882352941179736 0.64705882352941179736 0.64705882352941179736 1.0"/>
</material>
</visual>
<collision>
<origin xyz="-0.049872899514971674728 -0.1141428912905502191 0.01507892295095538196" rpy="-6.2367202746833250932e-14 -1.5074919608395581653e-14 1.5707963267948974462" />
<geometry>
<mesh filename="package:///cage_bottom.stl"/>
</geometry>
</collision>
<visual>
<origin xyz="-0.026822899514971725726 -0.1141428912905502191 0.015078922950957383831" rpy="-6.3477211383748394106e-14 -1.5130430759629774043e-14 1.5707963267948974462" />
<geometry>
<mesh filename="package:///rasp_spacer.stl"/>
</geometry>
<material name="rasp_spacer_material">
<color rgba="0.76862745098039220171 0.88627450980392152857 0.95294117647058818044 1.0"/>
</material>
</visual>
<collision>
<origin xyz="-0.026822899514971725726 -0.1141428912905502191 0.015078922950957383831" rpy="-6.3477211383748394106e-14 -1.5130430759629774043e-14 1.5707963267948974462" />
<geometry>
<mesh filename="package:///rasp_spacer.stl"/>
</geometry>
</collision>
<visual>
<origin xyz="-0.049872899514971702484 -0.1141428912905502191 0.01507892295095519114" rpy="-6.3144144476363674421e-14 -1.5463497667014358043e-14 1.5707963267948976682" />
<geometry>
<mesh filename="package:///rasp_spacer.stl"/>
</geometry>
<material name="rasp_spacer_material">
<color rgba="0.76862745098039220171 0.88627450980392152857 0.95294117647058818044 1.0"/>
</material>
</visual>
<collision>
<origin xyz="-0.049872899514971702484 -0.1141428912905502191 0.01507892295095519114" rpy="-6.3144144476363674421e-14 -1.5463497667014358043e-14 1.5707963267948976682" />
<geometry>
<mesh filename="package:///rasp_spacer.stl"/>
</geometry>
</collision>
<visual>
<origin xyz="-0.049872899514971757995 -0.11414289129055026073 0.015078922950955218896" rpy="-6.2367202746832013998e-14 -1.5074919608395587964e-14 1.5707963267948974462" />
<geometry>
<mesh filename="package:///cage_top.stl"/>
</geometry>
<material name="cage_top_material">
<color rgba="0.64705882352941179736 0.64705882352941179736 0.64705882352941179736 1.0"/>
</material>
</visual>
<collision>
<origin xyz="-0.049872899514971757995 -0.11414289129055026073 0.015078922950955218896" rpy="-6.2367202746832013998e-14 -1.5074919608395587964e-14 1.5707963267948974462" />
<geometry>
<mesh filename="package:///cage_top.stl"/>
</geometry>
</collision>
<visual>
<origin xyz="-0.043372899514973070612 -0.0066038964305769089214 0.028078922950957100474" rpy="3.1415926535897775729 6.3144144476363674421e-14 -3.1415926535897922278" />
<geometry>
<mesh filename="package:///bno055.stl"/>
</geometry>
<material name="bno055_material">
<color rgba="0.61568627450980395466 0.81176470588235294379 0.92941176470588238168 1.0"/>
</material>
</visual>
<collision>
<origin xyz="-0.043372899514973070612 -0.0066038964305769089214 0.028078922950957100474" rpy="3.1415926535897775729 6.3144144476363674421e-14 -3.1415926535897922278" />
<geometry>
<mesh filename="package:///bno055.stl"/>
</geometry>
</collision>
<visual>
<origin xyz="-0.049872899514971653911 -0.11414289129055023297 0.015078922950955361143" rpy="-6.2089646990676974419e-14 -1.5074919608395581653e-14 1.5707963267948974462" />
<geometry>
<mesh filename="package:///front_cover.stl"/>
</geometry>
<material name="front_cover_material">
<color rgba="0.64705882352941179736 0.64705882352941179736 0.64705882352941179736 1.0"/>
</material>
</visual>
<collision>
<origin xyz="-0.049872899514971653911 -0.11414289129055023297 0.015078922950955361143" rpy="-6.2089646990676974419e-14 -1.5074919608395581653e-14 1.5707963267948974462" />
<geometry>
<mesh filename="package:///front_cover.stl"/>
</geometry>
</collision>
<visual>
<origin xyz="0.00012710048502940357595 -0.0066038964305761855417 -0.0049210770490394949508" rpy="-6.2367202746833263554e-14 -1.5074919608395581653e-14 1.5707963267948974462" />
<geometry>
<mesh filename="package:///body_part.stl"/>
</geometry>
<material name="body_part_material">
<color rgba="0.30196078431372547213 0.29019607843137257275 0.26274509803921569651 1.0"/>
</material>
</visual>
<collision>
<origin xyz="0.00012710048502940357595 -0.0066038964305761855417 -0.0049210770490394949508" rpy="-6.2367202746833263554e-14 -1.5074919608395581653e-14 1.5707963267948974462" />
<geometry>
<mesh filename="package:///body_part.stl"/>
</geometry>
</collision>
<visual>
<origin xyz="-0.049872899514971640034 -0.11414289129055014971 0.015078922950956266669" rpy="-6.159026101730031571e-14 -1.5074919608395572187e-14 1.5707963267948974462" />
<geometry>
<mesh filename="package:///cage_bottom_battery_hold.stl"/>
</geometry>
<material name="cage_bottom_battery_hold_material">
<color rgba="0.64705882352941179736 0.64705882352941179736 0.64705882352941179736 1.0"/>
</material>
</visual>
<collision>
<origin xyz="-0.049872899514971640034 -0.11414289129055014971 0.015078922950956266669" rpy="-6.159026101730031571e-14 -1.5074919608395572187e-14 1.5707963267948974462" />
<geometry>
<mesh filename="package:///cage_bottom_battery_hold.stl"/>
</geometry>
</collision>
<visual>
<origin xyz="0.00012710048502940357595 -0.0066038964305761846743 -0.0049210770490394958182" rpy="-6.2367202746833364528e-14 -1.5074919608395578498e-14 1.5707963267948976682" />
<geometry>
<mesh filename="package:///spacer.stl"/>
</geometry>
<material name="spacer_material">
<color rgba="0.91764705882352937127 0.91764705882352937127 0.91764705882352937127 1.0"/>
</material>
</visual>
<collision>
<origin xyz="0.00012710048502940357595 -0.0066038964305761846743 -0.0049210770490394958182" rpy="-6.2367202746833364528e-14 -1.5074919608395578498e-14 1.5707963267948976682" />
<geometry>
<mesh filename="package:///spacer.stl"/>
</geometry>
</collision>
<visual>
<origin xyz="-0.049872899514971674728 -0.1141428912905502191 0.015078922950955399307" rpy="-6.2367202746833263554e-14 -1.5074919608395581653e-14 1.5707963267948974462" />
<geometry>
<mesh filename="package:///cage_back.stl"/>
</geometry>
<material name="cage_back_material">
<color rgba="0.64705882352941179736 0.64705882352941179736 0.64705882352941179736 1.0"/>
</material>
</visual>
<collision>
<origin xyz="-0.049872899514971674728 -0.1141428912905502191 0.015078922950955399307" rpy="-6.2367202746833263554e-14 -1.5074919608395581653e-14 1.5707963267948974462" />
<geometry>
<mesh filename="package:///cage_back.stl"/>
</geometry>
</collision>
<visual>
<origin xyz="0.00012710048502936888148 -0.0066038964305762185014 -0.0049210770490402538924" rpy="-6.3144144476364621054e-14 -1.5463497667014348577e-14 1.5707963267948978903" />
<geometry>
<mesh filename="package:///holder_u2d2_power_hub.stl"/>
</geometry>
<material name="holder_u2d2_power_hub_material">
<color rgba="0.30196078431372547213 0.30196078431372547213 0.30196078431372547213 1.0"/>
</material>
</visual>
<collision>
<origin xyz="0.00012710048502936888148 -0.0066038964305762185014 -0.0049210770490402538924" rpy="-6.3144144476364621054e-14 -1.5463497667014348577e-14 1.5707963267948978903" />
<geometry>
<mesh filename="package:///holder_u2d2_power_hub.stl"/>
</geometry>
</collision>
<visual>
<origin xyz="-0.049872899514968108137 -0.11414289129054938643 -0.042971077049042571971" rpy="-6.2922314259144567025e-14 -1.5519008818240349435e-14 1.5707963267948978903" />
<geometry>
<mesh filename="package:///rasp_spacer.stl"/>
</geometry>
<material name="rasp_spacer_material">
<color rgba="0.76862745098039220171 0.88627450980392152857 0.95294117647058818044 1.0"/>
</material>
</visual>
<collision>
<origin xyz="-0.049872899514968108137 -0.11414289129054938643 -0.042971077049042571971" rpy="-6.2922314259144567025e-14 -1.5519008818240349435e-14 1.5707963267948978903" />
<geometry>
<mesh filename="package:///rasp_spacer.stl"/>
</geometry>
</collision>
<visual>
<origin xyz="0.00012710048502788222347 -0.031603896430576559895 0.019578922950959615212" rpy="-1.5074919608395890887e-14 6.2367202746832013998e-14 -3.1415926535897922278" />
<geometry>
<mesh filename="package:///dc15_a01_case_f_dummy.stl"/>
</geometry>
<material name="dc15_a01_case_f_dummy_material">
<color rgba="0.28235294117647058432 0.25490196078431370807 0.25490196078431370807 1.0"/>
</material>
</visual>
<collision>
<origin xyz="0.00012710048502788222347 -0.031603896430576559895 0.019578922950959615212" rpy="-1.5074919608395890887e-14 6.2367202746832013998e-14 -3.1415926535897922278" />
<geometry>
<mesh filename="package:///dc15_a01_case_f_dummy.stl"/>
</geometry>
</collision>
<visual>
<origin xyz="0.00012710048502787875402 -0.031603896430576566834 0.019578922950959618682" rpy="-1.507491960839588142e-14 6.2367202746832013998e-14 -3.1415926535897922278" />
<geometry>
<mesh filename="package:///dc15_a01_case_m_dummy.stl"/>
</geometry>
<material name="dc15_a01_case_m_dummy_material">
<color rgba="0.28235294117647058432 0.25490196078431370807 0.25490196078431370807 1.0"/>
</material>
</visual>
<collision>
<origin xyz="0.00012710048502787875402 -0.031603896430576566834 0.019578922950959618682" rpy="-1.507491960839588142e-14 6.2367202746832013998e-14 -3.1415926535897922278" />
<geometry>
<mesh filename="package:///dc15_a01_case_m_dummy.stl"/>
</geometry>
</collision>
<visual>
<origin xyz="0.0001271004850290965299 -0.0316038964305762754 7.8922950960025502198e-05" rpy="-1.5074919608395890887e-14 6.2367202746832013998e-14 -3.1415926535897922278" />
<geometry>
<mesh filename="package:///dc15_a01_case_b_dummy.stl"/>
</geometry>
<material name="dc15_a01_case_b_dummy_material">
<color rgba="0.28235294117647058432 0.25490196078431370807 0.25490196078431370807 1.0"/>
</material>
</visual>
<collision>
<origin xyz="0.0001271004850290965299 -0.0316038964305762754 7.8922950960025502198e-05" rpy="-1.5074919608395890887e-14 6.2367202746832013998e-14 -3.1415926535897922278" />
<geometry>
<mesh filename="package:///dc15_a01_case_b_dummy.stl"/>
</geometry>
</collision>
<visual>
<origin xyz="0.02862710048503054952 -0.0391038964305759143 -0.021921077049037701601" rpy="1.5707963267948776842 0.62050967106619059344 3.141592653589783346" />
<geometry>
<mesh filename="package:///cell.stl"/>
</geometry>
<material name="cell_material">
<color rgba="0.61568627450980395466 0.81176470588235294379 0.92941176470588238168 1.0"/>
</material>
</visual>
<collision>
<origin xyz="0.02862710048503054952 -0.0391038964305759143 -0.021921077049037701601" rpy="1.5707963267948776842 0.62050967106619059344 3.141592653589783346" />
<geometry>
<mesh filename="package:///cell.stl"/>
</geometry>
</collision>
<visual>
<origin xyz="0.081651559042398458299 -0.0055454180208900569204 -0.031921077049033880213" rpy="-6.2367202746831988755e-14 -1.5463497667014342266e-14 1.5707963267948978903" />
<geometry>
<mesh filename="package:///holder.stl"/>
</geometry>
<material name="holder_material">
<color rgba="0.64705882352941179736 0.64705882352941179736 0.64705882352941179736 1.0"/>
</material>
</visual>
<collision>
<origin xyz="0.081651559042398458299 -0.0055454180208900569204 -0.031921077049033880213" rpy="-6.2367202746831988755e-14 -1.5463497667014342266e-14 1.5707963267948978903" />
<geometry>
<mesh filename="package:///holder.stl"/>
</geometry>
</collision>
<visual>
<origin xyz="0.0076271004850304554082 0.025896103569424053226 -0.021921077049038006912" rpy="-1.5707963267949192065 -0.82053085802344360999 -3.1415926535897753524" />
<geometry>
<mesh filename="package:///cell.stl"/>
</geometry>
<material name="cell_material">
<color rgba="0.61568627450980395466 0.81176470588235294379 0.92941176470588238168 1.0"/>
</material>
</visual>
<collision>
<origin xyz="0.0076271004850304554082 0.025896103569424053226 -0.021921077049038006912" rpy="-1.5707963267949192065 -0.82053085802344360999 -3.1415926535897753524" />
<geometry>
<mesh filename="package:///cell.stl"/>
</geometry>
</collision>
<visual>
<origin xyz="0.00012710048502783712066 0.018396103569423442881 0.019578922950960368082" rpy="1.5074919608395890887e-14 -6.2367202746832013998e-14 9.4368957093184552907e-16" />
<geometry>
<mesh filename="package:///dc15_a01_case_f_dummy.stl"/>
</geometry>
<material name="dc15_a01_case_f_dummy_material">
<color rgba="0.28235294117647058432 0.25490196078431370807 0.25490196078431370807 1.0"/>
</material>
</visual>
<collision>
<origin xyz="0.00012710048502783712066 0.018396103569423442881 0.019578922950960368082" rpy="1.5074919608395890887e-14 -6.2367202746832013998e-14 9.4368957093184552907e-16" />
<geometry>
<mesh filename="package:///dc15_a01_case_f_dummy.stl"/>
</geometry>
</collision>
<visual>
<origin xyz="0.00012710048502783538593 0.018396103569423435942 0.019578922950960368082" rpy="1.5074919608395887731e-14 -6.2367202746832013998e-14 9.2165518404232636261e-16" />
<geometry>
<mesh filename="package:///dc15_a01_case_m_dummy.stl"/>
</geometry>
<material name="dc15_a01_case_m_dummy_material">
<color rgba="0.28235294117647058432 0.25490196078431370807 0.25490196078431370807 1.0"/>
</material>
</visual>
<collision>
<origin xyz="0.00012710048502783538593 0.018396103569423435942 0.019578922950960368082" rpy="1.5074919608395887731e-14 -6.2367202746832013998e-14 9.2165518404232636261e-16" />
<geometry>
<mesh filename="package:///dc15_a01_case_m_dummy.stl"/>
</geometry>
</collision>
<visual>
<origin xyz="0.00012710048502905316181 0.018396103569423734314 7.8922950960772300655e-05" rpy="1.5074919608395890887e-14 -6.2367202746832013998e-14 9.4368957093184552907e-16" />
<geometry>
<mesh filename="package:///dc15_a01_case_b_dummy.stl"/>
</geometry>
<material name="dc15_a01_case_b_dummy_material">
<color rgba="0.28235294117647058432 0.25490196078431370807 0.25490196078431370807 1.0"/>
</material>
</visual>
<collision>
<origin xyz="0.00012710048502905316181 0.018396103569423734314 7.8922950960772300655e-05" rpy="1.5074919608395890887e-14 -6.2367202746832013998e-14 9.4368957093184552907e-16" />
<geometry>
<mesh filename="package:///dc15_a01_case_b_dummy.stl"/>
</geometry>
</collision>
<visual>
<origin xyz="0.030627100485025759991 -0.014603896430577125928 0.055078922950960867988" rpy="1.5707963267948956698 1.5707963267948321651 0" />
<geometry>
<mesh filename="package:///dc15_a01_case_f_dummy.stl"/>
</geometry>
<material name="dc15_a01_case_f_dummy_material">
<color rgba="0.28235294117647058432 0.25490196078431370807 0.25490196078431370807 1.0"/>
</material>
</visual>
<collision>
<origin xyz="0.030627100485025759991 -0.014603896430577125928 0.055078922950960867988" rpy="1.5707963267948956698 1.5707963267948321651 0" />
<geometry>
<mesh filename="package:///dc15_a01_case_f_dummy.stl"/>
</geometry>
</collision>
<visual>
<origin xyz="0.030627100485025759991 -0.014603896430577125928 0.055078922950960861049" rpy="1.5707963267948956698 1.5707963267948323871 0" />
<geometry>
<mesh filename="package:///dc15_a01_case_m_dummy.stl"/>
</geometry>
<material name="dc15_a01_case_m_dummy_material">
<color rgba="0.28235294117647058432 0.25490196078431370807 0.25490196078431370807 1.0"/>
</material>
</visual>
<collision>
<origin xyz="0.030627100485025759991 -0.014603896430577125928 0.055078922950960861049" rpy="1.5707963267948956698 1.5707963267948323871 0" />
<geometry>
<mesh filename="package:///dc15_a01_case_m_dummy.stl"/>
</geometry>
</collision>
<visual>
<origin xyz="0.030627100485025739174 0.0048961035694229226162 0.055078922950961152483" rpy="1.5707963267948956698 1.5707963267948323871 0" />
<geometry>
<mesh filename="package:///dc15_a01_case_b_dummy.stl"/>
</geometry>
<material name="dc15_a01_case_b_dummy_material">
<color rgba="0.28235294117647058432 0.25490196078431370807 0.25490196078431370807 1.0"/>
</material>
</visual>
<collision>
<origin xyz="0.030627100485025739174 0.0048961035694229226162 0.055078922950961152483" rpy="1.5707963267948956698 1.5707963267948323871 0" />
<geometry>
<mesh filename="package:///dc15_a01_case_b_dummy.stl"/>
</geometry>
</collision>
<visual>
<origin xyz="-0.012372899514969446996 -0.039103896430575969811 -0.021921077049040255114" rpy="1.5707963267948776842 0.62050967106619059344 3.141592653589783346" />
<geometry>
<mesh filename="package:///cell.stl"/>
</geometry>
<material name="cell_material">
<color rgba="0.61568627450980395466 0.81176470588235294379 0.92941176470588238168 1.0"/>
</material>
</visual>
<collision>
<origin xyz="-0.012372899514969446996 -0.039103896430575969811 -0.021921077049040255114" rpy="1.5707963267948776842 0.62050967106619059344 3.141592653589783346" />
<geometry>
<mesh filename="package:///cell.stl"/>
</geometry>
</collision>
<visual>
<origin xyz="0.040651559042398456578 -0.0055454180208901124316 -0.031921077049036433726" rpy="-6.2367202746832001376e-14 -1.54634976670143328e-14 1.5707963267948978903" />
<geometry>
<mesh filename="package:///holder.stl"/>
</geometry>
<material name="holder_material">
<color rgba="0.64705882352941179736 0.64705882352941179736 0.64705882352941179736 1.0"/>
</material>
</visual>
<collision>
<origin xyz="0.040651559042398456578 -0.0055454180208901124316 -0.031921077049036433726" rpy="-6.2367202746832001376e-14 -1.54634976670143328e-14 1.5707963267948978903" />
<geometry>
<mesh filename="package:///holder.stl"/>
</geometry>
</collision>
<visual>
<origin xyz="-0.033372899514969536772 0.025896103569424004653 -0.021921077049040560425" rpy="-1.5707963267949192065 -0.82053085802344372102 -3.1415926535897749083" />
<geometry>
<mesh filename="package:///cell.stl"/>
</geometry>
<material name="cell_material">
<color rgba="0.61568627450980395466 0.81176470588235294379 0.92941176470588238168 1.0"/>
</material>
</visual>
<collision>
<origin xyz="-0.033372899514969536772 0.025896103569424004653 -0.021921077049040560425" rpy="-1.5707963267949192065 -0.82053085802344372102 -3.1415926535897749083" />
<geometry>
<mesh filename="package:///cell.stl"/>
</geometry>
</collision>
<visual>
<origin xyz="-0.036872899514972599933 -0.037603896430576731758 0.027578922950957717591" rpy="2.2204460491569067728e-16 -1.5707963267948328312 0" />
<geometry>
<mesh filename="package:///raspberrypizerow.stl"/>
</geometry>
<material name="raspberrypizerow_material">
<color rgba="0.64705882352941179736 0.64705882352941179736 0.64705882352941179736 1.0"/>
</material>
</visual>
<collision>
<origin xyz="-0.036872899514972599933 -0.037603896430576731758 0.027578922950957717591" rpy="2.2204460491569067728e-16 -1.5707963267948328312 0" />
<geometry>
<mesh filename="package:///raspberrypizerow.stl"/>
</geometry>
</collision>
<visual>
<origin xyz="-0.036872899514972599933 -0.037603896430576731758 0.027578922950957717591" rpy="2.2204460491569067728e-16 -1.5707963267948328312 0" />
<geometry>
<mesh filename="package:///raspberrypizerow.stl"/>
</geometry>
<material name="raspberrypizerow_material">
<color rgba="0.2313725490196078538 0.38039215686274507888 0.7058823529411765163 1.0"/>
</material>
</visual>
<collision>
<origin xyz="-0.036872899514972599933 -0.037603896430576731758 0.027578922950957717591" rpy="2.2204460491569067728e-16 -1.5707963267948328312 0" />
<geometry>
<mesh filename="package:///raspberrypizerow.stl"/>
</geometry>
</collision>
<visual>
<origin xyz="-0.049622899514982221625 -0.011603896430557869568 0.039778922950957647242" rpy="1.5707963267950695307 1.4259599574675832697e-14 -1.5707963267947839814" />
<geometry>
<mesh filename="package:///jst-b3b-eh-a.prt.1.stl"/>
</geometry>
<material name="jst-b3b-eh-a.prt.1_material">
<color rgba="0.75294117647058822484 0.75294117647058822484 0.75294117647058822484 1.0"/>
</material>
</visual>
<collision>
<origin xyz="-0.049622899514982221625 -0.011603896430557869568 0.039778922950957647242" rpy="1.5707963267950695307 1.4259599574675832697e-14 -1.5707963267947839814" />
<geometry>
<mesh filename="package:///jst-b3b-eh-a.prt.1.stl"/>
</geometry>
</collision>
<visual>
<origin xyz="-0.049622899514980889357 -0.023553896430557941244 0.03977892295095747377" rpy="1.5707963267950695307 1.4259599574675832697e-14 -1.5707963267947839814" />
<geometry>
<mesh filename="package:///jst-b4b-eh-a.prt.1.stl"/>
</geometry>
<material name="jst-b4b-eh-a.prt.1_material">
<color rgba="0.75294117647058822484 0.75294117647058822484 0.75294117647058822484 1.0"/>
</material>
</visual>
<collision>
<origin xyz="-0.049622899514980889357 -0.023553896430557941244 0.03977892295095747377" rpy="1.5707963267950695307 1.4259599574675832697e-14 -1.5707963267947839814" />
<geometry>
<mesh filename="package:///jst-b4b-eh-a.prt.1.stl"/>
</geometry>
</collision>
<visual>
<origin xyz="-0.21911289613195361614 -0.092037396430997120422 0.0447978514093846647" rpy="1.5120022418770918684e-14 -6.2270734256202625226e-14 8.7430063189277797845e-16" />
<geometry>
<mesh filename="package:///board.stl"/>
</geometry>
<material name="board_material">
<color rgba="0 0 0 1.0"/>
</material>
</visual>
<collision>
<origin xyz="-0.21911289613195361614 -0.092037396430997120422 0.0447978514093846647" rpy="1.5120022418770918684e-14 -6.2270734256202625226e-14 8.7430063189277797845e-16" />
<geometry>
<mesh filename="package:///board.stl"/>
</geometry>
</collision>
<visual>
<origin xyz="-0.03772289951498083993 -0.023553896430556553465 0.039778922950958216231" rpy="1.5707963267950695307 1.4259599574675832697e-14 -1.5707963267947839814" />
<geometry>
<mesh filename="package:///jst-b4b-eh-a.prt.1.stl"/>
</geometry>
<material name="jst-b4b-eh-a.prt.1_material">
<color rgba="0.75294117647058822484 0.75294117647058822484 0.75294117647058822484 1.0"/>
</material>
</visual>
<collision>
<origin xyz="-0.03772289951498083993 -0.023553896430556553465 0.039778922950958216231" rpy="1.5707963267950695307 1.4259599574675832697e-14 -1.5707963267947839814" />
<geometry>
<mesh filename="package:///jst-b4b-eh-a.prt.1.stl"/>
</geometry>
</collision>
<visual>
<origin xyz="-0.037722899514982186076 -0.0116038964305565373 0.039778922950958389704" rpy="1.5707963267950695307 1.4259599574675832697e-14 -1.5707963267947839814" />
<geometry>
<mesh filename="package:///jst-b3b-eh-a.prt.1.stl"/>
</geometry>
<material name="jst-b3b-eh-a.prt.1_material">
<color rgba="0.75294117647058822484 0.75294117647058822484 0.75294117647058822484 1.0"/>
</material>
</visual>
<collision>
<origin xyz="-0.037722899514982186076 -0.0116038964305565373 0.039778922950958389704" rpy="1.5707963267950695307 1.4259599574675832697e-14 -1.5707963267947839814" />
<geometry>
<mesh filename="package:///jst-b3b-eh-a.prt.1.stl"/>
</geometry>
</collision>
<visual>
<origin xyz="-0.043622899514980884028 -0.023553896430557219599 0.03977892295095784847" rpy="1.5707963267950695307 1.4259599574675832697e-14 -1.5707963267947839814" />
<geometry>
<mesh filename="package:///jst-b4b-eh-a.prt.1.stl"/>
</geometry>
<material name="jst-b4b-eh-a.prt.1_material">
<color rgba="0.75294117647058822484 0.75294117647058822484 0.75294117647058822484 1.0"/>
</material>
</visual>
<collision>
<origin xyz="-0.043622899514980884028 -0.023553896430557219599 0.03977892295095784847" rpy="1.5707963267950695307 1.4259599574675832697e-14 -1.5707963267947839814" />
<geometry>
<mesh filename="package:///jst-b4b-eh-a.prt.1.stl"/>
</geometry>
</collision>
<visual>
<origin xyz="-0.043622899514982230174 -0.011603896430557203434 0.039778922950958015003" rpy="1.5707963267950695307 1.4259599574675832697e-14 -1.5707963267947839814" />
<geometry>
<mesh filename="package:///jst-b3b-eh-a.prt.1.stl"/>
</geometry>
<material name="jst-b3b-eh-a.prt.1_material">
<color rgba="0.75294117647058822484 0.75294117647058822484 0.75294117647058822484 1.0"/>
</material>
</visual>
<collision>
<origin xyz="-0.043622899514982230174 -0.011603896430557203434 0.039778922950958015003" rpy="1.5707963267950695307 1.4259599574675832697e-14 -1.5707963267947839814" />
<geometry>
<mesh filename="package:///jst-b3b-eh-a.prt.1.stl"/>
</geometry>
</collision>
<visual>
<origin xyz="-0.034425355771843330066 0.017361103569443758765 0.039778922950959014204" rpy="1.5707963267950695307 1.4259599574675832697e-14 -1.5707963267947839814" />
<geometry>
<mesh filename="package:///u2d2_casing.prt.stl"/>
</geometry>
<material name="u2d2_casing.prt_material">
<color rgba="0.79607843137254896693 0.82352941176470584317 0.9372549019607843146 1.0"/>
</material>
</visual>
<collision>
<origin xyz="-0.034425355771843330066 0.017361103569443758765 0.039778922950959014204" rpy="1.5707963267950695307 1.4259599574675832697e-14 -1.5707963267947839814" />
<geometry>
<mesh filename="package:///u2d2_casing.prt.stl"/>
</geometry>
</collision>
<visual>
<origin xyz="-0.023625355771839551267 -0.020538896430555231287 0.047778922950957355975" rpy="1.5707963267950695307 1.4259599574675832697e-14 -1.5707963267947839814" />
<geometry>
<mesh filename="package:///jst-b3b-eh-a.prt.stl"/>
</geometry>
<material name="jst-b3b-eh-a.prt_material">
<color rgba="0.75294117647058822484 0.75294117647058822484 0.75294117647058822484 1.0"/>
</material>
</visual>
<collision>
<origin xyz="-0.023625355771839551267 -0.020538896430555231287 0.047778922950957355975" rpy="1.5707963267950695307 1.4259599574675832697e-14 -1.5707963267947839814" />
<geometry>
<mesh filename="package:///jst-b3b-eh-a.prt.stl"/>
</geometry>
</collision>
<visual>
<origin xyz="-0.032325355771838246155 -0.030438896430556472428 0.047778922950956675963" rpy="1.5707963267947240293 -1.4718233739395608161e-14 1.5707963267950164621" />
<geometry>
<mesh filename="package:///jst-b4b-ph-k-s.prt.stl"/>
</geometry>
<material name="jst-b4b-ph-k-s.prt_material">
<color rgba="0.75294117647058822484 0.75294117647058822484 0.75294117647058822484 1.0"/>
</material>
</visual>
<collision>
<origin xyz="-0.032325355771838246155 -0.030438896430556472428 0.047778922950956675963" rpy="1.5707963267947240293 -1.4718233739395608161e-14 1.5707963267950164621" />
<geometry>
<mesh filename="package:///jst-b4b-ph-k-s.prt.stl"/>
</geometry>
</collision>
<visual>
<origin xyz="-0.019775355771839669972 -0.019288896430554758332 0.047778922950957633531" rpy="1.5707963267950695307 1.4259599574675832697e-14 -1.5707963267947839814" />
<geometry>
<mesh filename="package:///jst-b4b-eh-a.prt.stl"/>
</geometry>
<material name="jst-b4b-eh-a.prt_material">
<color rgba="0.75294117647058822484 0.75294117647058822484 0.75294117647058822484 1.0"/>
</material>
</visual>
<collision>
<origin xyz="-0.019775355771839669972 -0.019288896430554758332 0.047778922950957633531" rpy="1.5707963267950695307 1.4259599574675832697e-14 -1.5707963267947839814" />
<geometry>
<mesh filename="package:///jst-b4b-eh-a.prt.stl"/>
</geometry>
</collision>
<visual>
<origin xyz="0.013322471352531478628 0.0055646781063120043243 0.047778922950960062144" rpy="3.1415926535897309435 -1.4259599574676526894e-14 1.5707963267950093567" />
<geometry>
<mesh filename="package:///pcb_u2d2.prt.stl"/>
</geometry>
<material name="pcb_u2d2.prt_material">
<color rgba="0 0.29411764705882353921 0.65490196078431373028 1.0"/>
</material>
</visual>
<collision>
<origin xyz="0.013322471352531478628 0.0055646781063120043243 0.047778922950960062144" rpy="3.1415926535897309435 -1.4259599574676526894e-14 1.5707963267950093567" />
<geometry>
<mesh filename="package:///pcb_u2d2.prt.stl"/>
</geometry>
</collision>
<visual>
<origin xyz="-0.025425355771842877983 0.015261018668437958956 0.049940372525143786331" rpy="1.5707963267950695307 1.4259599574675832697e-14 -1.5707963267947839814" />
<geometry>
<mesh filename="package:///micro_usb_2_0_connector__ab_rec.prt.stl"/>
</geometry>
<material name="micro_usb_2_0_connector__ab_rec.prt_material">
<color rgba="0.5999999999999999778 0.5999999999999999778 0.5999999999999999778 1.0"/>
</material>
</visual>
<collision>
<origin xyz="-0.025425355771842877983 0.015261018668437958956 0.049940372525143786331" rpy="1.5707963267950695307 1.4259599574675832697e-14 -1.5707963267947839814" />
<geometry>
<mesh filename="package:///micro_usb_2_0_connector__ab_rec.prt.stl"/>
</geometry>
</collision>
<visual>
<origin xyz="-0.038412896131964732738 0.010912603569021406269 0.039578922950958723981" rpy="1.5707963267948004127 -9.7117183417599148656e-14 7.3482886442377510654e-14" />
<geometry>
<mesh filename="package:///39281023.prt.stl"/>
</geometry>
<material name="39281023.prt_material">
<color rgba="0.5999999999999999778 0.5999999999999999778 0.5999999999999999778 1.0"/>
</material>
</visual>
<collision>
<origin xyz="-0.038412896131964732738 0.010912603569021406269 0.039578922950958723981" rpy="1.5707963267948004127 -9.7117183417599148656e-14 7.3482886442377510654e-14" />
<geometry>
<mesh filename="package:///39281023.prt.stl"/>
</geometry>
</collision>
<inertial>
<origin xyz="-0.0091020358685774266361 -0.0066475911057015894118 0.0055457166598827612944" rpy="0 0 0"/>
<mass value="1.0982675034326250252" />
<inertia ixx="0.0020954979368059747924" ixy="6.7648236711987283398e-07"  ixz="9.4169471740292566651e-05" iyy="0.0033650086466817667914" iyz="2.0873785569622512895e-06" izz="0.002738055060477650321" />
</inertial>
</link>

<link name="trunk">
<inertial>
<origin xyz="0 0 0" rpy="0 0 0" />
<mass value="1e-9" />
<inertia ixx="0" ixy="0" ixz="0" iyy="0" iyz="0" izz="0" />
</inertial>
</link>
<joint name="trunk_frame" type="fixed">
<origin xyz="0.03252710048502828466 -0.0066038964305764136578 0.012578922950962063629" rpy="1.5074919608395890887e-14 -6.236720274683202662e-14 9.4368957093184533185e-16" />
<parent link="body_module" />
<child link="trunk" />
<axis xyz="0 0 0"/>
</joint>

<link name="double_u_module">
<visual>
<origin xyz="2.0816681711721685133e-17 -4.2012834183813296818e-18 0.022999999999999951039" rpy="1.570796326794896558 9.7144514654699410024e-17 4.996003610813283318e-16" />
<geometry>
<mesh filename="package:///dc15_a01_horn_dummy.stl"/>
</geometry>
<material name="dc15_a01_horn_dummy_material">
<color rgba="0.49803921568627451677 0.49803921568627451677 0.49803921568627451677 1.0"/>
</material>
</visual>
<collision>
<origin xyz="2.0816681711721685133e-17 -4.2012834183813296818e-18 0.022999999999999951039" rpy="1.570796326794896558 9.7144514654699410024e-17 4.996003610813283318e-16" />
<geometry>
<mesh filename="package:///dc15_a01_horn_dummy.stl"/>
</geometry>
</collision>
<visual>
<origin xyz="-0.14608752727508522717 -1.306463617845032843e-17 0.027999999999999993644" rpy="1.57079632679489678 2.0816681711737678055e-17 -3.141592653589793116" />
<geometry>
<mesh filename="package:///double_u.stl"/>
</geometry>
<material name="double_u_material">
<color rgba="0.28235294117647058432 0.25490196078431370807 0.25490196078431370807 1.0"/>
</material>
</visual>
<collision>
<origin xyz="-0.14608752727508522717 -1.306463617845032843e-17 0.027999999999999993644" rpy="1.57079632679489678 2.0816681711737678055e-17 -3.141592653589793116" />
<geometry>
<mesh filename="package:///double_u.stl"/>
</geometry>
</collision>
<visual>
<origin xyz="-0.033999999999999933054 -0.011500225429056536164 0.011499999999999904396" rpy="3.141592653589793116 -8.6736173798778897526e-17 4.4408920985005285402e-16" />
<geometry>
<mesh filename="package:///dc15_a01_horn_dummy.stl"/>
</geometry>
<material name="dc15_a01_horn_dummy_material">
<color rgba="0.49803921568627451677 0.49803921568627451677 0.49803921568627451677 1.0"/>
</material>
</visual>
<collision>
<origin xyz="-0.033999999999999933054 -0.011500225429056536164 0.011499999999999904396" rpy="3.141592653589793116 -8.6736173798778897526e-17 4.4408920985005285402e-16" />
<geometry>
<mesh filename="package:///dc15_a01_horn_dummy.stl"/>
</geometry>
</collision>
<visual>
<origin xyz="0 0 0" rpy="-3.141592653589793116 -3.3480749407005644071e-30 9.2593440517554546076e-32" />
<geometry>
<mesh filename="package:///dc15_a01_horn_idle2_dummy.stl"/>
</geometry>
<material name="dc15_a01_horn_idle2_dummy_material">
<color rgba="0.2313725490196078538 0.38039215686274507888 0.7058823529411765163 1.0"/>
</material>
</visual>
<collision>
<origin xyz="0 0 0" rpy="-3.141592653589793116 -3.3480749407005644071e-30 9.2593440517554546076e-32" />
<geometry>
<mesh filename="package:///dc15_a01_horn_idle2_dummy.stl"/>
</geometry>
</collision>
<visual>
<origin xyz="-0.033999999999999919176 0.011499999999999989397 0.011499999999999899192" rpy="-1.57079632679489678 -4.1633363423422181955e-17 4.996003610813140337e-16" />
<geometry>
<mesh filename="package:///dc15_a01_horn_idle2_dummy.stl"/>
</geometry>
<material name="dc15_a01_horn_idle2_dummy_material">
<color rgba="0.2313725490196078538 0.38039215686274507888 0.7058823529411765163 1.0"/>
</material>
</visual>
<collision>
<origin xyz="-0.033999999999999919176 0.011499999999999989397 0.011499999999999899192" rpy="-1.57079632679489678 -4.1633363423422181955e-17 4.996003610813140337e-16" />
<geometry>
<mesh filename="package:///dc15_a01_horn_idle2_dummy.stl"/>
</geometry>
</collision>
<inertial>
<origin xyz="-0.01700000000002717046 -8.4248510725113835815e-05 0.01158451252812944636" rpy="0 0 0"/>
<mass value="0.018818301231819770797" />
<inertia ixx="4.1671223638675296657e-06" ixy="-2.7039262661630040268e-08"  ixz="-2.6949270449491521816e-08" iyy="4.616500202208012939e-06" iyz="-1.339867545227964948e-10" izz="4.6165051389299917536e-06" />
</inertial>
</link>

<link name="right_hip_pitch_roll_module">
<visual>
<origin xyz="-0.067053147256374859286 -0.024500000000000077272 0.0090000000000003306522" rpy="1.1102230246252383847e-16 1.7694179454963298257e-15 6.2103100439973766474e-16" />
<geometry>
<mesh filename="package:///hip_right_roll_to_pitch.stl"/>
</geometry>
<material name="hip_right_roll_to_pitch_material">
<color rgba="0.28235294117647058432 0.25490196078431370807 0.25490196078431370807 1.0"/>
</material>
</visual>
<collision>
<origin xyz="-0.067053147256374859286 -0.024500000000000077272 0.0090000000000003306522" rpy="1.1102230246252383847e-16 1.7694179454963298257e-15 6.2103100439973766474e-16" />
<geometry>
<mesh filename="package:///hip_right_roll_to_pitch.stl"/>
</geometry>
</collision>
<visual>
<origin xyz="-3.4694469519536141888e-18 1.3877787807814456755e-17 -0.0035000000000000100475" rpy="-1.1981356986760278264e-32 6.9388939039515940998e-18 1.665334536938607488e-16" />
<geometry>
<mesh filename="package:///dc15_a01_case_f_dummy.stl"/>
</geometry>
<material name="dc15_a01_case_f_dummy_material">
<color rgba="0.28235294117647058432 0.25490196078431370807 0.25490196078431370807 1.0"/>
</material>
</visual>
<collision>
<origin xyz="-3.4694469519536141888e-18 1.3877787807814456755e-17 -0.0035000000000000100475" rpy="-1.1981356986760278264e-32 6.9388939039515940998e-18 1.665334536938607488e-16" />
<geometry>
<mesh filename="package:///dc15_a01_case_f_dummy.stl"/>
</geometry>
</collision>
<visual>
<origin xyz="0 1.3877787807814456755e-17 -0.0034999999999999996392" rpy="-1.1981356986760283738e-32 2.6017346130336287431e-30 -3.5391655165615788103e-30" />
<geometry>
<mesh filename="package:///dc15_a01_case_m_dummy.stl"/>
</geometry>
<material name="dc15_a01_case_m_dummy_material">
<color rgba="0.28235294117647058432 0.25490196078431370807 0.25490196078431370807 1.0"/>
</material>
</visual>
<collision>
<origin xyz="0 1.3877787807814456755e-17 -0.0034999999999999996392" rpy="-1.1981356986760283738e-32 2.6017346130336287431e-30 -3.5391655165615788103e-30" />
<geometry>
<mesh filename="package:///dc15_a01_case_m_dummy.stl"/>
</geometry>
</collision>
<visual>
<origin xyz="3.4694469519536141888e-18 2.7755575615628913511e-17 -0.022999999999999999611" rpy="1.6653345369377357967e-16 1.7520707107367275141e-16 1.6306400674184156055e-16" />
<geometry>
<mesh filename="package:///dc15_a01_case_b_dummy.stl"/>
</geometry>
<material name="dc15_a01_case_b_dummy_material">
<color rgba="0.28235294117647058432 0.25490196078431370807 0.25490196078431370807 1.0"/>
</material>
</visual>
<collision>
<origin xyz="3.4694469519536141888e-18 2.7755575615628913511e-17 -0.022999999999999999611" rpy="1.6653345369377357967e-16 1.7520707107367275141e-16 1.6306400674184156055e-16" />
<geometry>
<mesh filename="package:///dc15_a01_case_b_dummy.stl"/>
</geometry>
</collision>
<visual>
<origin xyz="0.025000000000000216493 -0.020999999999999852118 -0.013499999999999810762" rpy="-1.57079632679489678 2.7235158572834485945e-16 -3.141592653589793116" />
<geometry>
<mesh filename="package:///dc15_a01_case_f_dummy.stl"/>
</geometry>
<material name="dc15_a01_case_f_dummy_material">
<color rgba="0.28235294117647058432 0.25490196078431370807 0.25490196078431370807 1.0"/>
</material>
</visual>
<collision>
<origin xyz="0.025000000000000216493 -0.020999999999999852118 -0.013499999999999810762" rpy="-1.57079632679489678 2.7235158572834485945e-16 -3.141592653589793116" />
<geometry>
<mesh filename="package:///dc15_a01_case_f_dummy.stl"/>
</geometry>
</collision>
<visual>
<origin xyz="0.025000000000000216493 -0.020999999999999852118 -0.013499999999999812497" rpy="-1.57079632679489678 2.7235158572834485945e-16 -3.141592653589793116" />
<geometry>
<mesh filename="package:///dc15_a01_case_m_dummy.stl"/>
</geometry>
<material name="dc15_a01_case_m_dummy_material">
<color rgba="0.28235294117647058432 0.25490196078431370807 0.25490196078431370807 1.0"/>
</material>
</visual>
<collision>
<origin xyz="0.025000000000000216493 -0.020999999999999852118 -0.013499999999999812497" rpy="-1.57079632679489678 2.7235158572834485945e-16 -3.141592653589793116" />
<geometry>
<mesh filename="package:///dc15_a01_case_m_dummy.stl"/>
</geometry>
</collision>
<visual>
<origin xyz="0.025000000000000247719 -0.001499999999999820921 -0.013499999999999786476" rpy="-1.570796326794896558 -1.1796119636645594062e-16 -3.141592653589793116" />
<geometry>
<mesh filename="package:///dc15_a01_case_b_dummy.stl"/>
</geometry>
<material name="dc15_a01_case_b_dummy_material">
<color rgba="0.28235294117647058432 0.25490196078431370807 0.25490196078431370807 1.0"/>
</material>
</visual>
<collision>
<origin xyz="0.025000000000000247719 -0.001499999999999820921 -0.013499999999999786476" rpy="-1.570796326794896558 -1.1796119636645594062e-16 -3.141592653589793116" />
<geometry>
<mesh filename="package:///dc15_a01_case_b_dummy.stl"/>
</geometry>
</collision>
<inertial>
<origin xyz="0.011912825164995914651 -0.011752076745460426216 -0.0064503420228230745614" rpy="0 0 0"/>
<mass value="0.050685765935093662904" />
<inertia ixx="1.0194327396574534635e-05" ixy="7.6194526548767037153e-07"  ixz="-2.6821065588788817912e-06" iyy="1.5570665764188714451e-05" iyz="3.3009359542110071343e-07" izz="1.3178069063709420787e-05" />
</inertial>
</link>

<link name="leg_module">
<visual>
<origin xyz="-0.042500000000000703881 -0.047130780071020839106 0.023000000000000186962" rpy="-1.5707963267949038855 -5.5511151230202645442e-17 -1.5707963267949076602" />
<geometry>
<mesh filename="package:///block_to_axis.stl"/>
</geometry>
<material name="block_to_axis_material">
<color rgba="0.81568627450980391025 0.44313725490196076429 0.0039215686274509803377 1.0"/>
</material>
</visual>
<collision>
<origin xyz="-0.042500000000000703881 -0.047130780071020839106 0.023000000000000186962" rpy="-1.5707963267949038855 -5.5511151230202645442e-17 -1.5707963267949076602" />
<geometry>
<mesh filename="package:///block_to_axis.stl"/>
</geometry>
</collision>
<visual>
<origin xyz="-0.042499999999999593658 0.047130780071019715005 1.3877787807814456755e-17" rpy="1.570796326794896336 -2.3473126974043206211e-16 1.57079632679489678" />
<geometry>
<mesh filename="package:///block_to_axis.stl"/>
</geometry>
<material name="block_to_axis_material">
<color rgba="0.81568627450980391025 0.44313725490196076429 0.0039215686274509803377 1.0"/>
</material>
</visual>
<collision>
<origin xyz="-0.042499999999999593658 0.047130780071019715005 1.3877787807814456755e-17" rpy="1.570796326794896336 -2.3473126974043206211e-16 1.57079632679489678" />
<geometry>
<mesh filename="package:///block_to_axis.stl"/>
</geometry>
</collision>
<visual>
<origin xyz="-0.042499999999999600597 0.047130780071021199928 3.0531133177191804862e-16" rpy="1.570796326794911435 3.3306690738540786717e-16 1.5707963267948736874" />
<geometry>
<mesh filename="package:///renfort_leg.stl"/>
</geometry>
<material name="renfort_leg_material">
<color rgba="0.28235294117647058432 0.25490196078431370807 0.25490196078431370807 1.0"/>
</material>
</visual>
<collision>
<origin xyz="-0.042499999999999600597 0.047130780071021199928 3.0531133177191804862e-16" rpy="1.570796326794911435 3.3306690738540786717e-16 1.5707963267948736874" />
<geometry>
<mesh filename="package:///renfort_leg.stl"/>
</geometry>
</collision>
<visual>
<origin xyz="1.7347234759768070944e-18 0 0" rpy="3.141592653589793116 -3.2050474192293779552e-30 1.972152263085852391e-31" />
<geometry>
<mesh filename="package:///dc15_a01_horn_idle2_dummy.stl"/>
</geometry>
<material name="dc15_a01_horn_idle2_dummy_material">
<color rgba="0.2313725490196078538 0.38039215686274507888 0.7058823529411765163 1.0"/>
</material>
</visual>
<collision>
<origin xyz="1.7347234759768070944e-18 0 0" rpy="3.141592653589793116 -3.2050474192293779552e-30 1.972152263085852391e-31" />
<geometry>
<mesh filename="package:///dc15_a01_horn_idle2_dummy.stl"/>
</geometry>
</collision>
<visual>
<origin xyz="6.4358240958739543203e-16 -1.4159680372660687908e-16 0.022999999999999895528" rpy="1.57079632679489678 -5.5511151231298539639e-17 1.5707963267948983344" />
<geometry>
<mesh filename="package:///dc15_a01_horn_dummy.stl"/>
</geometry>
<material name="dc15_a01_horn_dummy_material">
<color rgba="0.49803921568627451677 0.49803921568627451677 0.49803921568627451677 1.0"/>
</material>
</visual>
<collision>
<origin xyz="6.4358240958739543203e-16 -1.4159680372660687908e-16 0.022999999999999895528" rpy="1.57079632679489678 -5.5511151231298539639e-17 1.5707963267948983344" />
<geometry>
<mesh filename="package:///dc15_a01_horn_dummy.stl"/>
</geometry>
</collision>
<visual>
<origin xyz="-0.065000000000000959788 -9.0422461185291069796e-17 0.0035000000000003222977" rpy="3.1415926535897784611 2.1747962150136168199e-27 -1.5707963267948954478" />
<geometry>
<mesh filename="package:///dc15_a01_case_f_dummy.stl"/>
</geometry>
<material name="dc15_a01_case_f_dummy_material">
<color rgba="0.28235294117647058432 0.25490196078431370807 0.25490196078431370807 1.0"/>
</material>
</visual>
<collision>
<origin xyz="-0.065000000000000959788 -9.0422461185291069796e-17 0.0035000000000003222977" rpy="3.1415926535897784611 2.1747962150136168199e-27 -1.5707963267948954478" />
<geometry>
<mesh filename="package:///dc15_a01_case_f_dummy.stl"/>
</geometry>
</collision>
<visual>
<origin xyz="-0.065000000000000862643 -1.7564075194265171831e-16 0.0035000000000002806644" rpy="3.1415926535897860106 3.3306690738864993758e-16 -1.5707963267949078823" />
<geometry>
<mesh filename="package:///dc15_a01_case_m_dummy.stl"/>
</geometry>
<material name="dc15_a01_case_m_dummy_material">
<color rgba="0.28235294117647058432 0.25490196078431370807 0.25490196078431370807 1.0"/>
</material>
</visual>
<collision>
<origin xyz="-0.065000000000000862643 -1.7564075194265171831e-16 0.0035000000000002806644" rpy="3.1415926535897860106 3.3306690738864993758e-16 -1.5707963267949078823" />
<geometry>
<mesh filename="package:///dc15_a01_case_m_dummy.stl"/>
</geometry>
</collision>
<visual>
<origin xyz="-0.065000000000000543454 -1.8930169931596907418e-16 0.023000000000000117573" rpy="3.1415926535897860106 1.1284922822451816742e-27 -1.5707963267949076602" />
<geometry>
<mesh filename="package:///dc15_a01_case_b_dummy.stl"/>
</geometry>
<material name="dc15_a01_case_b_dummy_material">
<color rgba="0.28235294117647058432 0.25490196078431370807 0.25490196078431370807 1.0"/>
</material>
</visual>
<collision>
<origin xyz="-0.065000000000000543454 -1.8930169931596907418e-16 0.023000000000000117573" rpy="3.1415926535897860106 1.1284922822451816742e-27 -1.5707963267949076602" />
<geometry>
<mesh filename="package:///dc15_a01_case_b_dummy.stl"/>
</geometry>
</collision>
<inertial>
<origin xyz="-0.039901628351739902578 -7.7113301695231790413e-06 0.011400440323216604055" rpy="0 0 0"/>
<mass value="0.034530807353386039349" />
<inertia ixx="5.0157740917572597806e-06" ixy="-2.9199735830177451496e-09"  ixz="-1.4737518371931587347e-07" iyy="2.0653502860211031815e-05" iyz="-5.581811999049217922e-10" izz="1.7774415153791318337e-05" />
</inertial>
</link>

<link name="leg_module_2">
<visual>
<origin xyz="-0.042500000000001189604 -0.047130780071021338706 0.02299999999999988165" rpy="-1.5707963267949038855 -3.8857805861781358542e-16 -1.5707963267948961139" />
<geometry>
<mesh filename="package:///block_to_axis.stl"/>
</geometry>
<material name="block_to_axis_material">
<color rgba="0.81568627450980391025 0.44313725490196076429 0.0039215686274509803377 1.0"/>
</material>
</visual>
<collision>
<origin xyz="-0.042500000000001189604 -0.047130780071021338706 0.02299999999999988165" rpy="-1.5707963267949038855 -3.8857805861781358542e-16 -1.5707963267948961139" />
<geometry>
<mesh filename="package:///block_to_axis.stl"/>
</geometry>
</collision>
<visual>
<origin xyz="-0.042500000000001411649 0.04713078007102081135 -2.7755575615628913511e-16" rpy="1.5707963267948894526 -4.4408920984796128793e-16 1.57079632679489678" />
<geometry>
<mesh filename="package:///block_to_axis.stl"/>
</geometry>
<material name="block_to_axis_material">
<color rgba="0.81568627450980391025 0.44313725490196076429 0.0039215686274509803377 1.0"/>
</material>
</visual>
<collision>
<origin xyz="-0.042500000000001411649 0.04713078007102081135 -2.7755575615628913511e-16" rpy="1.5707963267948894526 -4.4408920984796128793e-16 1.57079632679489678" />
<geometry>
<mesh filename="package:///block_to_axis.stl"/>
</geometry>
</collision>
<visual>
<origin xyz="-0.042500000000001231237 0.047130780071020304811 -8.3266726846886740532e-17" rpy="1.5707963267949041075 1.6653345369273824904e-16 1.5707963267948972241" />
<geometry>
<mesh filename="package:///renfort_leg.stl"/>
</geometry>
<material name="renfort_leg_material">
<color rgba="0.28235294117647058432 0.25490196078431370807 0.25490196078431370807 1.0"/>
</material>
</visual>
<collision>
<origin xyz="-0.042500000000001231237 0.047130780071020304811 -8.3266726846886740532e-17" rpy="1.5707963267949041075 1.6653345369273824904e-16 1.5707963267948972241" />
<geometry>
<mesh filename="package:///renfort_leg.stl"/>
</geometry>
</collision>
<visual>
<origin xyz="0 0 0" rpy="-3.141592653589793116 -3.6312388291892834731e-30 3.2540512340306873503e-30" />
<geometry>
<mesh filename="package:///dc15_a01_horn_idle2_dummy.stl"/>
</geometry>
<material name="dc15_a01_horn_idle2_dummy_material">
<color rgba="0.2313725490196078538 0.38039215686274507888 0.7058823529411765163 1.0"/>
</material>
</visual>
<collision>
<origin xyz="0 0 0" rpy="-3.141592653589793116 -3.6312388291892834731e-30 3.2540512340306873503e-30" />
<geometry>
<mesh filename="package:///dc15_a01_horn_idle2_dummy.stl"/>
</geometry>
</collision>
<visual>
<origin xyz="-2.7755575615628913511e-16 1.9949319973733281586e-17 0.022999999999999590217" rpy="1.570796326794896558 -1.6653345369373687299e-16 1.5707963267949092145" />
<geometry>
<mesh filename="package:///dc15_a01_horn_dummy.stl"/>
</geometry>
<material name="dc15_a01_horn_dummy_material">
<color rgba="0.49803921568627451677 0.49803921568627451677 0.49803921568627451677 1.0"/>
</material>
</visual>
<collision>
<origin xyz="-2.7755575615628913511e-16 1.9949319973733281586e-17 0.022999999999999590217" rpy="1.570796326794896558 -1.6653345369373687299e-16 1.5707963267949092145" />
<geometry>
<mesh filename="package:///dc15_a01_horn_dummy.stl"/>
</geometry>
</collision>
<visual>
<origin xyz="-0.065000000000002222666 -8.0577905459122689535e-16 0.0035000000000002529088" rpy="3.1415926535897709115 -2.2204460492284705085e-16 -1.5707963267948847896" />
<geometry>
<mesh filename="package:///dc15_a01_case_f_dummy.stl"/>
</geometry>
<material name="dc15_a01_case_f_dummy_material">
<color rgba="0.28235294117647058432 0.25490196078431370807 0.25490196078431370807 1.0"/>
</material>
</visual>
<collision>
<origin xyz="-0.065000000000002222666 -8.0577905459122689535e-16 0.0035000000000002529088" rpy="3.1415926535897709115 -2.2204460492284705085e-16 -1.5707963267948847896" />
<geometry>
<mesh filename="package:///dc15_a01_case_f_dummy.stl"/>
</geometry>
</collision>
<visual>
<origin xyz="-0.065000000000001972866 -8.9598467534202086426e-16 0.0035000000000001418865" rpy="3.1415926535897860106 1.1102230246230531168e-16 -1.5707963267949085484" />
<geometry>
<mesh filename="package:///dc15_a01_case_m_dummy.stl"/>
</geometry>
<material name="dc15_a01_case_m_dummy_material">
<color rgba="0.28235294117647058432 0.25490196078431370807 0.25490196078431370807 1.0"/>
</material>
</visual>
<collision>
<origin xyz="-0.065000000000001972866 -8.9598467534202086426e-16 0.0035000000000001418865" rpy="3.1415926535897860106 1.1102230246230531168e-16 -1.5707963267949085484" />
<geometry>
<mesh filename="package:///dc15_a01_case_m_dummy.stl"/>
</geometry>
</collision>
<visual>
<origin xyz="-0.065000000000001667555 -7.6804881898873134105e-16 0.023000000000000603295" rpy="3.1415926535897860106 -1.1102230246204449454e-16 -1.5707963267948961139" />
<geometry>
<mesh filename="package:///dc15_a01_case_b_dummy.stl"/>
</geometry>
<material name="dc15_a01_case_b_dummy_material">
<color rgba="0.28235294117647058432 0.25490196078431370807 0.25490196078431370807 1.0"/>
</material>
</visual>
<collision>
<origin xyz="-0.065000000000001667555 -7.6804881898873134105e-16 0.023000000000000603295" rpy="3.1415926535897860106 -1.1102230246204449454e-16 -1.5707963267948961139" />
<geometry>
<mesh filename="package:///dc15_a01_case_b_dummy.stl"/>
</geometry>
</collision>
<inertial>
<origin xyz="-0.039901628351740887901 -7.711330169919188967e-06 0.01140044032321648089" rpy="0 0 0"/>
<mass value="0.034530807353386039349" />
<inertia ixx="5.0157740917573055204e-06" ixy="-2.9199735831718761947e-09"  ixz="-1.4737518371922767617e-07" iyy="2.065350286021124188e-05" iyz="-5.5818119993492280584e-10" izz="1.7774415153791386099e-05" />
</inertial>
</link>

<link name="foot_module">
<visual>
<origin xyz="0 0 0" rpy="-3.141592653589793116 -4.8276505046864089964e-31 -1.2252563514645138217e-32" />
<geometry>
<mesh filename="package:///dc15_a01_horn_idle2_dummy.stl"/>
</geometry>
<material name="dc15_a01_horn_idle2_dummy_material">
<color rgba="0.2313725490196078538 0.38039215686274507888 0.7058823529411765163 1.0"/>
</material>
</visual>
<collision>
<origin xyz="0 0 0" rpy="-3.141592653589793116 -4.8276505046864089964e-31 -1.2252563514645138217e-32" />
<geometry>
<mesh filename="package:///dc15_a01_horn_idle2_dummy.stl"/>
</geometry>
</collision>
<visual>
<origin xyz="5.5511151231257827021e-17 -5.3125906451789717266e-17 -0.0051999999999999962919" rpy="-3.141592653589793116 -1.570796326794896558 0" />
<geometry>
<mesh filename="package:///foot.stl"/>
</geometry>
<material name="foot_material">
<color rgba="0.81568627450980391025 0.44313725490196076429 0.0039215686274509803377 1.0"/>
</material>
</visual>
<collision>
<origin xyz="5.5511151231257827021e-17 -5.3125906451789717266e-17 -0.0051999999999999962919" rpy="-3.141592653589793116 -1.570796326794896558 0" />
<geometry>
<mesh filename="package:///foot.stl"/>
</geometry>
</collision>
<visual>
<origin xyz="5.5511151231257827021e-17 -5.3125906451789717266e-17 -0.0051999999999999962919" rpy="-3.141592653589793116 -1.570796326794896558 0" />
<geometry>
<mesh filename="package:///foot_contact.stl"/>
</geometry>
<material name="foot_contact_material">
<color rgba="0 0 0 1.0"/>
</material>
</visual>
<collision>
<origin xyz="5.5511151231257827021e-17 -5.3125906451789717266e-17 -0.0051999999999999962919" rpy="-3.141592653589793116 -1.570796326794896558 0" />
<geometry>
<mesh filename="package:///foot_contact.stl"/>
</geometry>
</collision>
<visual>
<origin xyz="-1.6653345369377348106e-16 -7.0256300777060687324e-17 0.022999999999999826139" rpy="1.5707963267948958919 -1.7486012637846325952e-15 1.5707963267948981123" />
<geometry>
<mesh filename="package:///dc15_a01_horn_dummy.stl"/>
</geometry>
<material name="dc15_a01_horn_dummy_material">
<color rgba="0.49803921568627451677 0.49803921568627451677 0.49803921568627451677 1.0"/>
</material>
</visual>
<collision>
<origin xyz="-1.6653345369377348106e-16 -7.0256300777060687324e-17 0.022999999999999826139" rpy="1.5707963267948958919 -1.7486012637846325952e-15 1.5707963267948981123" />
<geometry>
<mesh filename="package:///dc15_a01_horn_dummy.stl"/>
</geometry>
</collision>
<inertial>
<origin xyz="-0.02539473159567097113 0.0070278635988877445964 0.011531623360498018116" rpy="0 0 0"/>
<mass value="0.050192424017228398636" />
<inertia ixx="2.0660963562483737773e-05" ixy="2.0037953448985230556e-06"  ixz="-4.0271562889860869567e-08" iyy="9.0558202848147458186e-06" iyz="1.1155254300040276711e-08" izz="2.1520203281490101475e-05" />
</inertial>
</link>

<link name="right_foot">
<inertial>
<origin xyz="0 0 0" rpy="0 0 0" />
<mass value="1e-9" />
<inertia ixx="0" ixy="0" ixz="0" iyy="0" iyz="0" izz="0" />
</inertial>
</link>
<joint name="right_foot_frame" type="fixed">
<origin xyz="-0.037499999999999200639 5.9047818717905542485e-15 0.011500000000038132497" rpy="1.5707963267948952257 -8.2376847691336273066e-15 1.57079632679489678" />
<parent link="foot_module" />
<child link="right_foot" />
<axis xyz="0 0 0"/>
</joint>

<joint name="right_ankle" type="revolute">
<origin xyz="-0.065000000000002028377 -8.9902044142498027668e-16 1.249000902703301108e-16" rpy="-1.0269562977784517112e-14 1.8977874827185263815e-15 1.0627453601663781033e-13" />
<parent link="leg_module_2" />
<child link="foot_module" />
<axis xyz="0 0 1"/>
<limit effort="1" velocity="20" lower="-1.570796326794896558" upper="1.570796326794896558"/>
<joint_properties friction="0.0"/>
</joint>

<joint name="right_knee" type="revolute">
<origin xyz="-0.065000000000000640599 -1.9689111452336760522e-16 -5.5511151231257827021e-17" rpy="1.1589216316011910219e-16 -2.0968964649445356432e-15 -1.2051470932306016186e-13" />
<parent link="leg_module" />
<child link="leg_module_2" />
<axis xyz="0 0 1"/>
<limit effort="1" velocity="20" lower="-2.0943951023931952626" upper="2.0943951023931952626"/>
<joint_properties friction="0.0"/>
</joint>

<joint name="right_hip_pitch" type="revolute">
<origin xyz="0.025000000000000216493 -0.024499999999999855227 -0.013499999999999812497" rpy="1.5707963267948970021 -8.3130108030798317137e-14 -3.1415926535897913396" />
<parent link="right_hip_pitch_roll_module" />
<child link="leg_module" />
<axis xyz="0 0 1"/>
<limit effort="1" velocity="20" lower="-0.52359877559829881566" upper="1.570796326794896558"/>
<joint_properties friction="0.0"/>
</joint>

<joint name="right_hip_roll" type="revolute">
<origin xyz="-0.033999999999999905298 0.011499999999999989397 0.011499999999999895722" rpy="-1.5707963267948961139 -1.570796326794896336 0" />
<parent link="double_u_module" />
<child link="right_hip_pitch_roll_module" />
<axis xyz="0 0 1"/>
<limit effort="1" velocity="20" lower="-1.570796326794896558" upper="0.34906585039886589561"/>
<joint_properties friction="0.0"/>
</joint>

<joint name="right_hip_yaw" type="revolute">
<origin xyz="0.00012710048502765998913 -0.031603896430576622345 0.023078922950959545463" rpy="3.1415926535897304994 -1.5078389055347532112e-14 1.5707963267948974462" />
<parent link="body_module" />
<child link="double_u_module" />
<axis xyz="0 0 1"/>
<limit effort="1" velocity="20" lower="-0.69813170079773179122" upper="0.69813170079773179122"/>
<joint_properties friction="0.0"/>
</joint>

<link name="double_u_module_2">
<visual>
<origin xyz="0.034000000000001154299 0.011500000000000549713 0.011500000000000003275" rpy="3.1051550219981292186e-16 -4.1406029711123635988e-29 1.6653345369381314598e-16" />
<geometry>
<mesh filename="package:///dc15_a01_horn_dummy.stl"/>
</geometry>
<material name="dc15_a01_horn_dummy_material">
<color rgba="0.49803921568627451677 0.49803921568627451677 0.49803921568627451677 1.0"/>
</material>
</visual>
<collision>
<origin xyz="0.034000000000001154299 0.011500000000000549713 0.011500000000000003275" rpy="3.1051550219981292186e-16 -4.1406029711123635988e-29 1.6653345369381314598e-16" />
<geometry>
<mesh filename="package:///dc15_a01_horn_dummy.stl"/>
</geometry>
</collision>
<visual>
<origin xyz="-0.1120875272750893048 0.016500000000000694667 0.011499999999999999806" rpy="3.1415926535897926719 3.989863994768643966e-17 -3.1415926535897926719" />
<geometry>
<mesh filename="package:///double_u.stl"/>
</geometry>
<material name="double_u_material">
<color rgba="0.28235294117647058432 0.25490196078431370807 0.25490196078431370807 1.0"/>
</material>
</visual>
<collision>
<origin xyz="-0.1120875272750893048 0.016500000000000694667 0.011499999999999999806" rpy="3.1415926535897926719 3.989863994768643966e-17 -3.1415926535897926719" />
<geometry>
<mesh filename="package:///double_u.stl"/>
</geometry>
</collision>
<visual>
<origin xyz="-3.4694469519536141888e-18 9.2157184661267876891e-17 0.023000225429056529031" rpy="1.570796326794896558 -1.7347234759806010223e-17 2.2204460492504915606e-16" />
<geometry>
<mesh filename="package:///dc15_a01_horn_dummy.stl"/>
</geometry>
<material name="dc15_a01_horn_dummy_material">
<color rgba="0.49803921568627451677 0.49803921568627451677 0.49803921568627451677 1.0"/>
</material>
</visual>
<collision>
<origin xyz="-3.4694469519536141888e-18 9.2157184661267876891e-17 0.023000225429056529031" rpy="1.570796326794896558 -1.7347234759806010223e-17 2.2204460492504915606e-16" />
<geometry>
<mesh filename="package:///dc15_a01_horn_dummy.stl"/>
</geometry>
</collision>
<visual>
<origin xyz="0.034000000000001175116 -0.0115000000000000345 0.011499999999999996336" rpy="1.5707963267948970021 6.9388939039125947888e-18 2.2204460492508805677e-16" />
<geometry>
<mesh filename="package:///dc15_a01_horn_idle2_dummy.stl"/>
</geometry>
<material name="dc15_a01_horn_idle2_dummy_material">
<color rgba="0.2313725490196078538 0.38039215686274507888 0.7058823529411765163 1.0"/>
</material>
</visual>
<collision>
<origin xyz="0.034000000000001175116 -0.0115000000000000345 0.011499999999999996336" rpy="1.5707963267948970021 6.9388939039125947888e-18 2.2204460492508805677e-16" />
<geometry>
<mesh filename="package:///dc15_a01_horn_idle2_dummy.stl"/>
</geometry>
</collision>
<visual>
<origin xyz="0 0 0" rpy="-3.141592653589793116 -3.8526263963279615011e-31 6.4358684515981144592e-32" />
<geometry>
<mesh filename="package:///dc15_a01_horn_idle2_dummy.stl"/>
</geometry>
<material name="dc15_a01_horn_idle2_dummy_material">
<color rgba="0.2313725490196078538 0.38039215686274507888 0.7058823529411765163 1.0"/>
</material>
</visual>
<collision>
<origin xyz="0 0 0" rpy="-3.141592653589793116 -3.8526263963279615011e-31 6.4358684515981144592e-32" />
<geometry>
<mesh filename="package:///dc15_a01_horn_idle2_dummy.stl"/>
</geometry>
</collision>
<inertial>
<origin xyz="0.016999999999973376685 8.4512528129653690951e-05 0.011584248510725111622" rpy="0 0 0"/>
<mass value="0.018818301231819770797" />
<inertia ixx="4.1671223638678117277e-06" ixy="-2.6949270449495449269e-08"  ixz="2.7039262661631231408e-08" iyy="4.6165051389302941444e-06" iyz="1.3398675452131480753e-10" izz="4.6165002022080807017e-06" />
</inertial>
</link>

<link name="left_hip_pitch_roll_module">
<visual>
<origin xyz="-0.067053147256375608687 -0.024500000000000035638 -0.032000000000000465572" rpy="3.141592653589793116 1.6028126974030637996e-15 -3.141592653589793116" />
<geometry>
<mesh filename="package:///hip_left_roll_to_pitch.stl"/>
</geometry>
<material name="hip_left_roll_to_pitch_material">
<color rgba="0.28235294117647058432 0.25490196078431370807 0.25490196078431370807 1.0"/>
</material>
</visual>
<collision>
<origin xyz="-0.067053147256375608687 -0.024500000000000035638 -0.032000000000000465572" rpy="3.141592653589793116 1.6028126974030637996e-15 -3.141592653589793116" />
<geometry>
<mesh filename="package:///hip_left_roll_to_pitch.stl"/>
</geometry>
</collision>
<visual>
<origin xyz="0.025000000000000466294 -0.0049999999999999905631 -0.0095000000000003397699" rpy="1.570796326794896558 -1.6826817716976283598e-16 3.141592653589793116" />
<geometry>
<mesh filename="package:///dc15_a01_case_f_dummy.stl"/>
</geometry>
<material name="dc15_a01_case_f_dummy_material">
<color rgba="0.28235294117647058432 0.25490196078431370807 0.25490196078431370807 1.0"/>
</material>
</visual>
<collision>
<origin xyz="0.025000000000000466294 -0.0049999999999999905631 -0.0095000000000003397699" rpy="1.570796326794896558 -1.6826817716976283598e-16 3.141592653589793116" />
<geometry>
<mesh filename="package:///dc15_a01_case_f_dummy.stl"/>
</geometry>
</collision>
<visual>
<origin xyz="0.025000000000000466294 -0.0049999999999999905631 -0.0095000000000003363004" rpy="1.570796326794896558 -1.6826817716976283598e-16 3.141592653589793116" />
<geometry>
<mesh filename="package:///dc15_a01_case_m_dummy.stl"/>
</geometry>
<material name="dc15_a01_case_m_dummy_material">
<color rgba="0.28235294117647058432 0.25490196078431370807 0.25490196078431370807 1.0"/>
</material>
</visual>
<collision>
<origin xyz="0.025000000000000466294 -0.0049999999999999905631 -0.0095000000000003363004" rpy="1.570796326794896558 -1.6826817716976283598e-16 3.141592653589793116" />
<geometry>
<mesh filename="package:///dc15_a01_case_m_dummy.stl"/>
</geometry>
</collision>
<visual>
<origin xyz="0.025000000000000473233 -0.024499999999999994005 -0.0095000000000003363004" rpy="1.5707963267948970021 -1.6653345369377957008e-16 3.141592653589793116" />
<geometry>
<mesh filename="package:///dc15_a01_case_b_dummy.stl"/>
</geometry>
<material name="dc15_a01_case_b_dummy_material">
<color rgba="0.28235294117647058432 0.25490196078431370807 0.25490196078431370807 1.0"/>
</material>
</visual>
<collision>
<origin xyz="0.025000000000000473233 -0.024499999999999994005 -0.0095000000000003363004" rpy="1.5707963267948970021 -1.6653345369377957008e-16 3.141592653589793116" />
<geometry>
<mesh filename="package:///dc15_a01_case_b_dummy.stl"/>
</geometry>
</collision>
<visual>
<origin xyz="-5.2041704279304212832e-18 6.9388939039072283776e-18 -0.0035000000000000031086" rpy="-1.1857032050430350995e-30 1.7347234760260427231e-18 1.0116605681612819211e-28" />
<geometry>
<mesh filename="package:///dc15_a01_case_f_dummy.stl"/>
</geometry>
<material name="dc15_a01_case_f_dummy_material">
<color rgba="0.28235294117647058432 0.25490196078431370807 0.25490196078431370807 1.0"/>
</material>
</visual>
<collision>
<origin xyz="-5.2041704279304212832e-18 6.9388939039072283776e-18 -0.0035000000000000031086" rpy="-1.1857032050430350995e-30 1.7347234760260427231e-18 1.0116605681612819211e-28" />
<geometry>
<mesh filename="package:///dc15_a01_case_f_dummy.stl"/>
</geometry>
</collision>
<visual>
<origin xyz="1.7347234759768070944e-18 0 -0.0035000000000000013739" rpy="1.1297491197668111264e-31 -4.43527532880738304e-30 1.2899303886838966395e-30" />
<geometry>
<mesh filename="package:///dc15_a01_case_m_dummy.stl"/>
</geometry>
<material name="dc15_a01_case_m_dummy_material">
<color rgba="0.28235294117647058432 0.25490196078431370807 0.25490196078431370807 1.0"/>
</material>
</visual>
<collision>
<origin xyz="1.7347234759768070944e-18 0 -0.0035000000000000013739" rpy="1.1297491197668111264e-31 -4.43527532880738304e-30 1.2899303886838966395e-30" />
<geometry>
<mesh filename="package:///dc15_a01_case_m_dummy.stl"/>
</geometry>
</collision>
<visual>
<origin xyz="-2.2551405187698492227e-17 6.9388939039072283776e-18 -0.022999999999999999611" rpy="-3.3306690738754597605e-16 5.0133508455734103207e-16 -5.5511151231207611094e-17" />
<geometry>
<mesh filename="package:///dc15_a01_case_b_dummy.stl"/>
</geometry>
<material name="dc15_a01_case_b_dummy_material">
<color rgba="0.28235294117647058432 0.25490196078431370807 0.25490196078431370807 1.0"/>
</material>
</visual>
<collision>
<origin xyz="-2.2551405187698492227e-17 6.9388939039072283776e-18 -0.022999999999999999611" rpy="-3.3306690738754597605e-16 5.0133508455734103207e-16 -5.5511151231207611094e-17" />
<geometry>
<mesh filename="package:///dc15_a01_case_b_dummy.stl"/>
</geometry>
</collision>
<inertial>
<origin xyz="0.011923026842605561476 -0.011606470860263526021 -0.016315085728328005549" rpy="0 0 0"/>
<mass value="0.050936078435093665173" />
<inertia ixx="1.0342471330591228627e-05" ixy="6.3706533517168801141e-07"  ixz="2.7969122185403260441e-06" iyy="1.5716551187432694573e-05" iyz="-3.3298884875073686445e-07" izz="1.3182726926082262631e-05" />
</inertial>
</link>

<link name="leg_module_3">
<visual>
<origin xyz="-0.042499999999998476496 -0.047130780071017903954 0.022999999999999853895" rpy="-1.570796326794896336 -4.966572119182832965e-16 -1.5707963267948912289" />
<geometry>
<mesh filename="package:///block_to_axis.stl"/>
</geometry>
<material name="block_to_axis_material">
<color rgba="0.81568627450980391025 0.44313725490196076429 0.0039215686274509803377 1.0"/>
</material>
</visual>
<collision>
<origin xyz="-0.042499999999998476496 -0.047130780071017903954 0.022999999999999853895" rpy="-1.570796326794896336 -4.966572119182832965e-16 -1.5707963267948912289" />
<geometry>
<mesh filename="package:///block_to_axis.stl"/>
</geometry>
</collision>
<visual>
<origin xyz="-0.042499999999999406308 0.047130780071019444388 6.9388939039072283776e-18" rpy="1.570796326794896336 -5.5322230588507908191e-16 1.570796326794896558" />
<geometry>
<mesh filename="package:///block_to_axis.stl"/>
</geometry>
<material name="block_to_axis_material">
<color rgba="0.81568627450980391025 0.44313725490196076429 0.0039215686274509803377 1.0"/>
</material>
</visual>
<collision>
<origin xyz="-0.042499999999999406308 0.047130780071019444388 6.9388939039072283776e-18" rpy="1.570796326794896336 -5.5322230588507908191e-16 1.570796326794896558" />
<geometry>
<mesh filename="package:///block_to_axis.stl"/>
</geometry>
</collision>
<visual>
<origin xyz="-0.042499999999998837319 0.047130780071017987221 -3.4694469519536141888e-17" rpy="1.5707963267948961139 1.75748440760723845e-16 1.5707963267949018871" />
<geometry>
<mesh filename="package:///renfort_leg.stl"/>
</geometry>
<material name="renfort_leg_material">
<color rgba="0.28235294117647058432 0.25490196078431370807 0.25490196078431370807 1.0"/>
</material>
</visual>
<collision>
<origin xyz="-0.042499999999998837319 0.047130780071017987221 -3.4694469519536141888e-17" rpy="1.5707963267948961139 1.75748440760723845e-16 1.5707963267949018871" />
<geometry>
<mesh filename="package:///renfort_leg.stl"/>
</geometry>
</collision>
<visual>
<origin xyz="1.7347234759768070944e-18 0 0" rpy="-3.141592653589793116 -2.0668332250037141152e-30 -6.4869956006508584081e-24" />
<geometry>
<mesh filename="package:///dc15_a01_horn_idle2_dummy.stl"/>
</geometry>
<material name="dc15_a01_horn_idle2_dummy_material">
<color rgba="0.2313725490196078538 0.38039215686274507888 0.7058823529411765163 1.0"/>
</material>
</visual>
<collision>
<origin xyz="1.7347234759768070944e-18 0 0" rpy="-3.141592653589793116 -2.0668332250037141152e-30 -6.4869956006508584081e-24" />
<geometry>
<mesh filename="package:///dc15_a01_horn_idle2_dummy.stl"/>
</geometry>
</collision>
<visual>
<origin xyz="-6.9735883734267645195e-16 2.1575623232461538237e-16 0.022999999999999840017" rpy="1.57079632679489678 -9.441717580708686317e-17 1.5707963267948974462" />
<geometry>
<mesh filename="package:///dc15_a01_horn_dummy.stl"/>
</geometry>
<material name="dc15_a01_horn_dummy_material">
<color rgba="0.49803921568627451677 0.49803921568627451677 0.49803921568627451677 1.0"/>
</material>
</visual>
<collision>
<origin xyz="-6.9735883734267645195e-16 2.1575623232461538237e-16 0.022999999999999840017" rpy="1.57079632679489678 -9.441717580708686317e-17 1.5707963267948974462" />
<geometry>
<mesh filename="package:///dc15_a01_horn_dummy.stl"/>
</geometry>
</collision>
<visual>
<origin xyz="-0.064999999999998406275 -1.2056328158038809306e-16 0.0034999999999999892308" rpy="3.1415926535897922278 5.3850638565700636271e-16 -1.5707963267948883423" />
<geometry>
<mesh filename="package:///dc15_a01_case_f_dummy.stl"/>
</geometry>
<material name="dc15_a01_case_f_dummy_material">
<color rgba="0.28235294117647058432 0.25490196078431370807 0.25490196078431370807 1.0"/>
</material>
</visual>
<collision>
<origin xyz="-0.064999999999998406275 -1.2056328158038809306e-16 0.0034999999999999892308" rpy="3.1415926535897922278 5.3850638565700636271e-16 -1.5707963267948883423" />
<geometry>
<mesh filename="package:///dc15_a01_case_f_dummy.stl"/>
</geometry>
</collision>
<visual>
<origin xyz="-0.064999999999998267497 -6.6786853825107073135e-17 0.0034999999999999822919" rpy="3.1415926535897922278 4.2748408319437760574e-16 -1.5707963267948930053" />
<geometry>
<mesh filename="package:///dc15_a01_case_m_dummy.stl"/>
</geometry>
<material name="dc15_a01_case_m_dummy_material">
<color rgba="0.28235294117647058432 0.25490196078431370807 0.25490196078431370807 1.0"/>
</material>
</visual>
<collision>
<origin xyz="-0.064999999999998267497 -6.6786853825107073135e-17 0.0034999999999999822919" rpy="3.1415926535897922278 4.2748408319437760574e-16 -1.5707963267948930053" />
<geometry>
<mesh filename="package:///dc15_a01_case_m_dummy.stl"/>
</geometry>
</collision>
<visual>
<origin xyz="-0.064999999999998253619 -7.0689981646054889097e-17 0.022999999999999853895" rpy="-3.141592653589793116 -1.6605126655691724991e-17 -1.5707963267948930053" />
<geometry>
<mesh filename="package:///dc15_a01_case_b_dummy.stl"/>
</geometry>
<material name="dc15_a01_case_b_dummy_material">
<color rgba="0.28235294117647058432 0.25490196078431370807 0.25490196078431370807 1.0"/>
</material>
</visual>
<collision>
<origin xyz="-0.064999999999998253619 -7.0689981646054889097e-17 0.022999999999999853895" rpy="-3.141592653589793116 -1.6605126655691724991e-17 -1.5707963267948930053" />
<geometry>
<mesh filename="package:///dc15_a01_case_b_dummy.stl"/>
</geometry>
</collision>
<inertial>
<origin xyz="-0.039901628351738709088 -7.711330169372595218e-06 0.011400440323216404562" rpy="0 0 0"/>
<mass value="0.034530807353386039349" />
<inertia ixx="5.0157740917570929151e-06" ixy="-2.9199735831070583219e-09"  ixz="-1.4737518371936669545e-07" iyy="2.0653502860209324197e-05" iyz="-5.5818119994679543257e-10" izz="1.7774415153789908874e-05" />
</inertial>
</link>

<link name="leg_module_4">
<visual>
<origin xyz="-0.042500000000000301426 -0.047130780071021040334 0.023000000000000506151" rpy="-1.5707963267949101027 -1.3877787807783265195e-15 -1.5707963267948956698" />
<geometry>
<mesh filename="package:///block_to_axis.stl"/>
</geometry>
<material name="block_to_axis_material">
<color rgba="0.81568627450980391025 0.44313725490196076429 0.0039215686274509803377 1.0"/>
</material>
</visual>
<collision>
<origin xyz="-0.042500000000000301426 -0.047130780071021040334 0.023000000000000506151" rpy="-1.5707963267949101027 -1.3877787807783265195e-15 -1.5707963267948956698" />
<geometry>
<mesh filename="package:///block_to_axis.stl"/>
</geometry>
</collision>
<visual>
<origin xyz="-0.042499999999999593658 0.04713078007102119299 4.9266146717741321481e-16" rpy="1.5707963267949105468 1.6098233857064517401e-15 1.5707963267948970021" />
<geometry>
<mesh filename="package:///block_to_axis.stl"/>
</geometry>
<material name="block_to_axis_material">
<color rgba="0.81568627450980391025 0.44313725490196076429 0.0039215686274509803377 1.0"/>
</material>
</visual>
<collision>
<origin xyz="-0.042499999999999593658 0.04713078007102119299 4.9266146717741321481e-16" rpy="1.5707963267949105468 1.6098233857064517401e-15 1.5707963267948970021" />
<geometry>
<mesh filename="package:///block_to_axis.stl"/>
</geometry>
</collision>
<visual>
<origin xyz="-0.042499999999999579781 0.047130780071021179112 4.9960036108132044319e-16" rpy="1.5707963267949101027 1.2212453270876577978e-15 1.570796326794896558" />
<geometry>
<mesh filename="package:///renfort_leg.stl"/>
</geometry>
<material name="renfort_leg_material">
<color rgba="0.28235294117647058432 0.25490196078431370807 0.25490196078431370807 1.0"/>
</material>
</visual>
<collision>
<origin xyz="-0.042499999999999579781 0.047130780071021179112 4.9960036108132044319e-16" rpy="1.5707963267949101027 1.2212453270876577978e-15 1.570796326794896558" />
<geometry>
<mesh filename="package:///renfort_leg.stl"/>
</geometry>
</collision>
<visual>
<origin xyz="1.3877787807814456755e-17 0 6.9388939039072283776e-18" rpy="3.141592653589793116 -1.1355857537972441971e-32 2.3665827156018266993e-30" />
<geometry>
<mesh filename="package:///dc15_a01_horn_idle2_dummy.stl"/>
</geometry>
<material name="dc15_a01_horn_idle2_dummy_material">
<color rgba="0.2313725490196078538 0.38039215686274507888 0.7058823529411765163 1.0"/>
</material>
</visual>
<collision>
<origin xyz="1.3877787807814456755e-17 0 6.9388939039072283776e-18" rpy="3.141592653589793116 -1.1355857537972441971e-32 2.3665827156018266993e-30" />
<geometry>
<mesh filename="package:///dc15_a01_horn_idle2_dummy.stl"/>
</geometry>
</collision>
<visual>
<origin xyz="1.0547118733938987134e-15 -9.5626631613221491079e-17 0.022999999999999867772" rpy="1.5707963267949101027 9.9920072216262885625e-16 1.570796326794896558" />
<geometry>
<mesh filename="package:///dc15_a01_horn_dummy.stl"/>
</geometry>
<material name="dc15_a01_horn_dummy_material">
<color rgba="0.49803921568627451677 0.49803921568627451677 0.49803921568627451677 1.0"/>
</material>
</visual>
<collision>
<origin xyz="1.0547118733938987134e-15 -9.5626631613221491079e-17 0.022999999999999867772" rpy="1.5707963267949101027 9.9920072216262885625e-16 1.570796326794896558" />
<geometry>
<mesh filename="package:///dc15_a01_horn_dummy.stl"/>
</geometry>
</collision>
<visual>
<origin xyz="-0.065000000000000099365 1.6102570665754711854e-15 0.0035000000000008496537" rpy="3.1415926535897797933 -1.1102230246251936169e-15 -1.5707963267948961139" />
<geometry>
<mesh filename="package:///dc15_a01_case_f_dummy.stl"/>
</geometry>
<material name="dc15_a01_case_f_dummy_material">
<color rgba="0.28235294117647058432 0.25490196078431370807 0.25490196078431370807 1.0"/>
</material>
</visual>
<collision>
<origin xyz="-0.065000000000000099365 1.6102570665754711854e-15 0.0035000000000008496537" rpy="3.1415926535897797933 -1.1102230246251936169e-15 -1.5707963267948961139" />
<geometry>
<mesh filename="package:///dc15_a01_case_f_dummy.stl"/>
</geometry>
</collision>
<visual>
<origin xyz="-0.065000000000000154876 1.6102570665754711854e-15 0.0035000000000008427148" rpy="3.1415926535897797933 -1.1102230246251936169e-15 -1.5707963267948961139" />
<geometry>
<mesh filename="package:///dc15_a01_case_m_dummy.stl"/>
</geometry>
<material name="dc15_a01_case_m_dummy_material">
<color rgba="0.28235294117647058432 0.25490196078431370807 0.25490196078431370807 1.0"/>
</material>
</visual>
<collision>
<origin xyz="-0.065000000000000154876 1.6102570665754711854e-15 0.0035000000000008427148" rpy="3.1415926535897797933 -1.1102230246251936169e-15 -1.5707963267948961139" />
<geometry>
<mesh filename="package:///dc15_a01_case_m_dummy.stl"/>
</geometry>
</collision>
<visual>
<origin xyz="-0.065000000000000182632 1.6221832904728117342e-15 0.023000000000000728195" rpy="3.1415926535897797933 -1.1102230246251936169e-15 -1.5707963267948961139" />
<geometry>
<mesh filename="package:///dc15_a01_case_b_dummy.stl"/>
</geometry>
<material name="dc15_a01_case_b_dummy_material">
<color rgba="0.28235294117647058432 0.25490196078431370807 0.25490196078431370807 1.0"/>
</material>
</visual>
<collision>
<origin xyz="-0.065000000000000182632 1.6221832904728117342e-15 0.023000000000000728195" rpy="3.1415926535897797933 -1.1102230246251936169e-15 -1.5707963267948961139" />
<geometry>
<mesh filename="package:///dc15_a01_case_b_dummy.stl"/>
</geometry>
</collision>
<inertial>
<origin xyz="-0.039901628351739659717 -7.7113301683977992091e-06 0.01140044032321694753" rpy="0 0 0"/>
<mass value="0.034530807353386039349" />
<inertia ixx="5.0157740917571699951e-06" ixy="-2.9199735827624379215e-09"  ixz="-1.4737518371923995815e-07" iyy="2.0653502860210828527e-05" iyz="-5.5818119989639914355e-10" izz="1.7774415153791016793e-05" />
</inertial>
</link>

<link name="foot_module_2">
<visual>
<origin xyz="0 0 0" rpy="3.141592653589793116 -4.8276505048317026277e-31 5.0037344593007477894e-30" />
<geometry>
<mesh filename="package:///dc15_a01_horn_idle2_dummy.stl"/>
</geometry>
<material name="dc15_a01_horn_idle2_dummy_material">
<color rgba="0.2313725490196078538 0.38039215686274507888 0.7058823529411765163 1.0"/>
</material>
</visual>
<collision>
<origin xyz="0 0 0" rpy="3.141592653589793116 -4.8276505048317026277e-31 5.0037344593007477894e-30" />
<geometry>
<mesh filename="package:///dc15_a01_horn_idle2_dummy.stl"/>
</geometry>
</collision>
<visual>
<origin xyz="0 -4.9439619065339002191e-17 -0.0051999999999999754752" rpy="-3.141592653589793116 -1.570796326794896558 0" />
<geometry>
<mesh filename="package:///foot.stl"/>
</geometry>
<material name="foot_material">
<color rgba="0.81568627450980391025 0.44313725490196076429 0.0039215686274509803377 1.0"/>
</material>
</visual>
<collision>
<origin xyz="0 -4.9439619065339002191e-17 -0.0051999999999999754752" rpy="-3.141592653589793116 -1.570796326794896558 0" />
<geometry>
<mesh filename="package:///foot.stl"/>
</geometry>
</collision>
<visual>
<origin xyz="0 -4.9439619065339002191e-17 -0.0051999999999999754752" rpy="-3.141592653589793116 -1.570796326794896558 0" />
<geometry>
<mesh filename="package:///foot_contact.stl"/>
</geometry>
<material name="foot_contact_material">
<color rgba="0 0 0 1.0"/>
</material>
</visual>
<collision>
<origin xyz="0 -4.9439619065339002191e-17 -0.0051999999999999754752" rpy="-3.141592653589793116 -1.570796326794896558 0" />
<geometry>
<mesh filename="package:///foot_contact.stl"/>
</geometry>
</collision>
<visual>
<origin xyz="-8.3266726846886740532e-17 -3.1441863002079628586e-17 0.022999999999999826139" rpy="1.5707963267948958919 -1.7486012637846381172e-15 1.5707963267948981123" />
<geometry>
<mesh filename="package:///dc15_a01_horn_dummy.stl"/>
</geometry>
<material name="dc15_a01_horn_dummy_material">
<color rgba="0.49803921568627451677 0.49803921568627451677 0.49803921568627451677 1.0"/>
</material>
</visual>
<collision>
<origin xyz="-8.3266726846886740532e-17 -3.1441863002079628586e-17 0.022999999999999826139" rpy="1.5707963267948958919 -1.7486012637846381172e-15 1.5707963267948981123" />
<geometry>
<mesh filename="package:///dc15_a01_horn_dummy.stl"/>
</geometry>
</collision>
<inertial>
<origin xyz="-0.025394731595671026642 0.0070278635988877489332 0.011531623360498038933" rpy="0 0 0"/>
<mass value="0.050192424017228398636" />
<inertia ixx="2.0660963562483744549e-05" ixy="2.0037953448985234791e-06"  ixz="-4.0271562889861028385e-08" iyy="9.0558202848147525949e-06" iyz="1.1155254300039740698e-08" izz="2.1520203281490104863e-05" />
</inertial>
</link>

<link name="left_foot">
<inertial>
<origin xyz="0 0 0" rpy="0 0 0" />
<mass value="1e-9" />
<inertia ixx="0" ixy="0" ixz="0" iyy="0" iyz="0" izz="0" />
</inertial>
</link>
<joint name="left_foot_frame" type="fixed">
<origin xyz="-0.037499999999999367173 0.0050000000000035302664 0.011500000000004340084" rpy="1.5707963267948952257 -1.1420177484200466381e-14 1.5707963267948961139" />
<parent link="foot_module_2" />
<child link="left_foot" />
<axis xyz="0 0 0"/>
</joint>

<joint name="left_ankle" type="revolute">
<origin xyz="-0.065000000000000154876 1.6067876196235175712e-15 8.6042284408449631883e-16" rpy="-1.1368826724137153788e-14 1.6596211705633574847e-14 -2.1322488822902390562e-14" />
<parent link="leg_module_4" />
<child link="foot_module_2" />
<axis xyz="0 0 1"/>
<limit effort="1" velocity="20" lower="-1.570796326794896558" upper="1.570796326794896558"/>
<joint_properties friction="0.0"/>
</joint>

<joint name="left_knee" type="revolute">
<origin xyz="-0.064999999999998281375 -6.7220534694101274908e-17 0" rpy="5.970893051203023059e-16 -1.4853578868213746426e-14 -7.8207310266750229308e-08" />
<parent link="leg_module_3" />
<child link="leg_module_4" />
<axis xyz="0 0 1"/>
<limit effort="1" velocity="20" lower="-2.0943951023931952626" upper="2.0943951023931952626"/>
<joint_properties friction="0.0"/>
</joint>

<joint name="left_hip_pitch" type="revolute">
<origin xyz="0.025000000000000459355 -0.0015000000000000152101 -0.0095000000000003380352" rpy="-1.57079632679489678 7.8207331219164669488e-08 -3.141592653589793116" />
<parent link="left_hip_pitch_roll_module" />
<child link="leg_module_3" />
<axis xyz="0 0 1"/>
<limit effort="1" velocity="20" lower="-0.52359877559829881566" upper="1.570796326794896558"/>
<joint_properties friction="0.0"/>
</joint>

<joint name="left_hip_roll" type="revolute">
<origin xyz="0.034000000000001175116 -0.0115000000000000345 0.011499999999999996336" rpy="1.570796326794896558 -1.570796326794896558 0" />
<parent link="double_u_module_2" />
<child link="left_hip_pitch_roll_module" />
<axis xyz="0 0 1"/>
<limit effort="1" velocity="20" lower="-1.570796326794896558" upper="0.34906585039886589561"/>
<joint_properties friction="0.0"/>
</joint>

<joint name="left_hip_yaw" type="revolute">
<origin xyz="0.00012710048502761662104 0.018396103569423387369 0.023078922950960294863" rpy="3.1415926535897309435 -1.5078389055347532112e-14 1.5707963267948974462" />
<parent link="body_module" />
<child link="double_u_module_2" />
<axis xyz="0 0 1"/>
<limit effort="1" velocity="20" lower="-0.69813170079773179122" upper="0.69813170079773179122"/>
<joint_properties friction="0.0"/>
</joint>

<link name="head_link">
<visual>
<origin xyz="-2.2204460492503130808e-16 -1.0408340855860842566e-16 0.022999999999999996142" rpy="-1.570796326794896558 -2.2021623822161954679e-28 -3.141592653589793116" />
<geometry>
<mesh filename="package:///axis_to_axis.stl"/>
</geometry>
<material name="axis_to_axis_material">
<color rgba="0.28235294117647058432 0.25490196078431370807 0.25490196078431370807 1.0"/>
</material>
</visual>
<collision>
<origin xyz="-2.2204460492503130808e-16 -1.0408340855860842566e-16 0.022999999999999996142" rpy="-1.570796326794896558 -2.2021623822161954679e-28 -3.141592653589793116" />
<geometry>
<mesh filename="package:///axis_to_axis.stl"/>
</geometry>
</collision>
<visual>
<origin xyz="-2.2898349882893853646e-16 -0.064999999999999058531 0.022999999999999996142" rpy="1.570796326794896558 2.0543045052719165412e-28 -1.1102230246246678164e-16" />
<geometry>
<mesh filename="package:///dc15_a01_horn_dummy.stl"/>
</geometry>
<material name="dc15_a01_horn_dummy_material">
<color rgba="0.49803921568627451677 0.49803921568627451677 0.49803921568627451677 1.0"/>
</material>
</visual>
<collision>
<origin xyz="-2.2898349882893853646e-16 -0.064999999999999058531 0.022999999999999996142" rpy="1.570796326794896558 2.0543045052719165412e-28 -1.1102230246246678164e-16" />
<geometry>
<mesh filename="package:///dc15_a01_horn_dummy.stl"/>
</geometry>
</collision>
<visual>
<origin xyz="-1.0755285551056203985e-16 3.8163916471489756077e-16 0" rpy="1.570796326794896558 3.3807740382092691183e-30 0" />
<geometry>
<mesh filename="package:///renfort_head_link.stl"/>
</geometry>
<material name="renfort_head_link_material">
<color rgba="0.28235294117647058432 0.25490196078431370807 0.25490196078431370807 1.0"/>
</material>
</visual>
<collision>
<origin xyz="-1.0755285551056203985e-16 3.8163916471489756077e-16 0" rpy="1.570796326794896558 3.3807740382092691183e-30 0" />
<geometry>
<mesh filename="package:///renfort_head_link.stl"/>
</geometry>
</collision>
<visual>
<origin xyz="-2.2204460492503130808e-16 -9.7144514654701197287e-17 0.022999999999999996142" rpy="1.570796326794896558 2.0543045052719165412e-28 -1.1102230246246678164e-16" />
<geometry>
<mesh filename="package:///dc15_a01_horn_dummy.stl"/>
</geometry>
<material name="dc15_a01_horn_dummy_material">
<color rgba="0.49803921568627451677 0.49803921568627451677 0.49803921568627451677 1.0"/>
</material>
</visual>
<collision>
<origin xyz="-2.2204460492503130808e-16 -9.7144514654701197287e-17 0.022999999999999996142" rpy="1.570796326794896558 2.0543045052719165412e-28 -1.1102230246246678164e-16" />
<geometry>
<mesh filename="package:///dc15_a01_horn_dummy.stl"/>
</geometry>
</collision>
<visual>
<origin xyz="3.4694469519536141888e-18 -0.06499999999999912792 3.4694469519536141888e-18" rpy="-3.141592653589793116 -2.9383826821945038949e-16 -2.2204460492499677077e-16" />
<geometry>
<mesh filename="package:///dc15_a01_horn_idle2_dummy.stl"/>
</geometry>
<material name="dc15_a01_horn_idle2_dummy_material">
<color rgba="0.2313725490196078538 0.38039215686274507888 0.7058823529411765163 1.0"/>
</material>
</visual>
<collision>
<origin xyz="3.4694469519536141888e-18 -0.06499999999999912792 3.4694469519536141888e-18" rpy="-3.141592653589793116 -2.9383826821945038949e-16 -2.2204460492499677077e-16" />
<geometry>
<mesh filename="package:///dc15_a01_horn_idle2_dummy.stl"/>
</geometry>
</collision>
<visual>
<origin xyz="0 0 0" rpy="3.141592653589793116 2.8115191019968956248e-32 0" />
<geometry>
<mesh filename="package:///dc15_a01_horn_idle2_dummy.stl"/>
</geometry>
<material name="dc15_a01_horn_idle2_dummy_material">
<color rgba="0.2313725490196078538 0.38039215686274507888 0.7058823529411765163 1.0"/>
</material>
</visual>
<collision>
<origin xyz="0 0 0" rpy="3.141592653589793116 2.8115191019968956248e-32 0" />
<geometry>
<mesh filename="package:///dc15_a01_horn_idle2_dummy.stl"/>
</geometry>
</collision>
<visual>
<origin xyz="0 -9.0205620750793968909e-17 0" rpy="1.570796326794896558 2.1124562256396357684e-28 1.2621774483536382266e-29" />
<geometry>
<mesh filename="package:///axis_to_axis.stl"/>
</geometry>
<material name="axis_to_axis_material">
<color rgba="0.28235294117647058432 0.25490196078431370807 0.25490196078431370807 1.0"/>
</material>
</visual>
<collision>
<origin xyz="0 -9.0205620750793968909e-17 0" rpy="1.570796326794896558 2.1124562256396357684e-28 1.2621774483536382266e-29" />
<geometry>
<mesh filename="package:///axis_to_axis.stl"/>
</geometry>
</collision>
<inertial>
<origin xyz="-2.4651560370069545292e-14 -0.032499754096266757208 0.011652192306627142532" rpy="0 0 0"/>
<mass value="0.020865926048949740013" />
<inertia ixx="1.42994772506051681e-05" ixy="2.0155873217263239464e-21"  ixz="6.4034090809152329685e-18" iyy="4.8005448764253543008e-06" iyz="-5.9496902423886982486e-11" izz="1.0668759971070639146e-05" />
</inertial>
</link>

<link name="head_pitch_yaw">
<visual>
<origin xyz="0.043000000000002480682 0.0001000000000004851175 -0.011500000000000454303" rpy="1.5707963267948972241 1.7877175507189012539e-16 -1.570796326794896558" />
<geometry>
<mesh filename="package:///head_roll_pitch.stl"/>
</geometry>
<material name="head_roll_pitch_material">
<color rgba="0.64705882352941179736 0.64705882352941179736 0.64705882352941179736 1.0"/>
</material>
</visual>
<collision>
<origin xyz="0.043000000000002480682 0.0001000000000004851175 -0.011500000000000454303" rpy="1.5707963267948972241 1.7877175507189012539e-16 -1.570796326794896558" />
<geometry>
<mesh filename="package:///head_roll_pitch.stl"/>
</geometry>
</collision>
<visual>
<origin xyz="0.034499999999999420019 3.4694469519536141888e-17 -0.011500000000000006745" rpy="-1.0384614260316070598e-30 1.570796326794896558 0" />
<geometry>
<mesh filename="package:///dc15_a01_case_f_dummy.stl"/>
</geometry>
<material name="dc15_a01_case_f_dummy_material">
<color rgba="0.28235294117647058432 0.25490196078431370807 0.25490196078431370807 1.0"/>
</material>
</visual>
<collision>
<origin xyz="0.034499999999999420019 3.4694469519536141888e-17 -0.011500000000000006745" rpy="-1.0384614260316070598e-30 1.570796326794896558 0" />
<geometry>
<mesh filename="package:///dc15_a01_case_f_dummy.stl"/>
</geometry>
</collision>
<visual>
<origin xyz="0.034499999999999420019 3.4694469519536141888e-17 -0.011500000000000006745" rpy="-1.0384614260316070598e-30 1.5707963267948961139 0" />
<geometry>
<mesh filename="package:///dc15_a01_case_m_dummy.stl"/>
</geometry>
<material name="dc15_a01_case_m_dummy_material">
<color rgba="0.28235294117647058432 0.25490196078431370807 0.25490196078431370807 1.0"/>
</material>
</visual>
<collision>
<origin xyz="0.034499999999999420019 3.4694469519536141888e-17 -0.011500000000000006745" rpy="-1.0384614260316070598e-30 1.5707963267948961139 0" />
<geometry>
<mesh filename="package:///dc15_a01_case_m_dummy.stl"/>
</geometry>
</collision>
<visual>
<origin xyz="0.014999999999999735767 7.2858385991025897965e-17 -0.011500000000000003275" rpy="-1.0384614260316070598e-30 1.570796326794896558 0" />
<geometry>
<mesh filename="package:///dc15_a01_case_b_dummy.stl"/>
</geometry>
<material name="dc15_a01_case_b_dummy_material">
<color rgba="0.28235294117647058432 0.25490196078431370807 0.25490196078431370807 1.0"/>
</material>
</visual>
<collision>
<origin xyz="0.014999999999999735767 7.2858385991025897965e-17 -0.011500000000000003275" rpy="-1.0384614260316070598e-30 1.570796326794896558 0" />
<geometry>
<mesh filename="package:///dc15_a01_case_b_dummy.stl"/>
</geometry>
</collision>
<visual>
<origin xyz="-1.3877787807814456755e-17 3.4694469519536141888e-18 -0.0035000000000000083128" rpy="3.8285686989269395741e-16 -1.8369701987209951748e-16 1.0384614260316070598e-30" />
<geometry>
<mesh filename="package:///dc15_a01_case_f_dummy.stl"/>
</geometry>
<material name="dc15_a01_case_f_dummy_material">
<color rgba="0.28235294117647058432 0.25490196078431370807 0.25490196078431370807 1.0"/>
</material>
</visual>
<collision>
<origin xyz="-1.3877787807814456755e-17 3.4694469519536141888e-18 -0.0035000000000000083128" rpy="3.8285686989269395741e-16 -1.8369701987209951748e-16 1.0384614260316070598e-30" />
<geometry>
<mesh filename="package:///dc15_a01_case_f_dummy.stl"/>
</geometry>
</collision>
<visual>
<origin xyz="-1.3877787807814456755e-17 3.4694469519536141888e-18 -0.0034999999999999996392" rpy="1.4442762621570761677e-32 1.6187678482638252831e-30 1.0384614260316070598e-30" />
<geometry>
<mesh filename="package:///dc15_a01_case_m_dummy.stl"/>
</geometry>
<material name="dc15_a01_case_m_dummy_material">
<color rgba="0.28235294117647058432 0.25490196078431370807 0.25490196078431370807 1.0"/>
</material>
</visual>
<collision>
<origin xyz="-1.3877787807814456755e-17 3.4694469519536141888e-18 -0.0034999999999999996392" rpy="1.4442762621570761677e-32 1.6187678482638252831e-30 1.0384614260316070598e-30" />
<geometry>
<mesh filename="package:///dc15_a01_case_m_dummy.stl"/>
</geometry>
</collision>
<visual>
<origin xyz="5.5511151231257827021e-17 1.0408340855860842566e-17 -0.023000000000000003081" rpy="3.8285686989269395741e-16 -1.8369701987209951748e-16 1.0384614260316070598e-30" />
<geometry>
<mesh filename="package:///dc15_a01_case_b_dummy.stl"/>
</geometry>
<material name="dc15_a01_case_b_dummy_material">
<color rgba="0.28235294117647058432 0.25490196078431370807 0.25490196078431370807 1.0"/>
</material>
</visual>
<collision>
<origin xyz="5.5511151231257827021e-17 1.0408340855860842566e-17 -0.023000000000000003081" rpy="3.8285686989269395741e-16 -1.8369701987209951748e-16 1.0384614260316070598e-30" />
<geometry>
<mesh filename="package:///dc15_a01_case_b_dummy.stl"/>
</geometry>
</collision>
<inertial>
<origin xyz="0.0097975107666698930953 -0.0075633013912249939456 -0.011415050767009856172" rpy="0 0 0"/>
<mass value="0.056026571436010752514" />
<inertia ixx="1.118865766173317961e-05" ixy="7.0167085312188921215e-09"  ixz="5.368679164978799047e-08" iyy="1.5064807078385244779e-05" iyz="2.327786748682623141e-09" izz="2.0630626443344870932e-05" />
</inertial>
</link>

<link name="head_assembly">
<visual>
<origin xyz="-6.9388939039072283776e-17 -8.6736173798840354721e-19 -0.0052000000000000379252" rpy="1.074387506873181446e-27 1.3183898417350825914e-16 -6.8925294757635379515e-27" />
<geometry>
<mesh filename="package:///head.stl"/>
</geometry>
<material name="head_material">
<color rgba="0.91764705882352937127 0.91764705882352937127 0.91764705882352937127 1.0"/>
</material>
</visual>
<collision>
<origin xyz="-6.9388939039072283776e-17 -8.6736173798840354721e-19 -0.0052000000000000379252" rpy="1.074387506873181446e-27 1.3183898417350825914e-16 -6.8925294757635379515e-27" />
<geometry>
<mesh filename="package:///head.stl"/>
</geometry>
</collision>
<visual>
<origin xyz="0 0 -2.7755575615628913511e-17" rpy="3.141592653589793116 2.9520654187567551156e-30 -6.0461138453829856947e-32" />
<geometry>
<mesh filename="package:///dc15_a01_horn_idle2_dummy.stl"/>
</geometry>
<material name="dc15_a01_horn_idle2_dummy_material">
<color rgba="0.2313725490196078538 0.38039215686274507888 0.7058823529411765163 1.0"/>
</material>
</visual>
<collision>
<origin xyz="0 0 -2.7755575615628913511e-17" rpy="3.141592653589793116 2.9520654187567551156e-30 -6.0461138453829856947e-32" />
<geometry>
<mesh filename="package:///dc15_a01_horn_idle2_dummy.stl"/>
</geometry>
</collision>
<inertial>
<origin xyz="0.0076772756496754999272 -7.5447219088714358496e-05 0.0066513802849240619142" rpy="0 0 0"/>
<mass value="0.16981152778281508042" />
<inertia ixx="0.00024450510017806929494" ixy="8.3049626862206443109e-07"  ixz="4.488134437062265124e-06" iyy="0.00040969787791048616066" iyz="7.2369028658580094104e-08" izz="0.00061408974105607019509" />
</inertial>
</link>

<link name="head">
<inertial>
<origin xyz="0 0 0" rpy="0 0 0" />
<mass value="1e-9" />
<inertia ixx="0" ixy="0" ixz="0" iyy="0" iyz="0" izz="0" />
</inertial>
</link>
<joint name="head_frame" type="fixed">
<origin xyz="-7.9797279894933126343e-17 8.6736173798840354721e-19 -0.0076000000000000789147" rpy="-3.141592653589793116 1.3183898417348306489e-16 -2.0261749666996487726e-26" />
<parent link="head_assembly" />
<child link="head" />
<axis xyz="0 0 0"/>
</joint>

<joint name="head_yaw" type="revolute">
<origin xyz="0.037999999999999423128 3.4694469519536141888e-17 -0.011500000000000006745" rpy="1.570796326794896558 1.5530065672147715551e-15 -1.570796326794896558" />
<parent link="head_pitch_yaw" />
<child link="head_assembly" />
<axis xyz="0 0 1"/>
<limit effort="1" velocity="20" lower="-2.0943951023931952626" upper="2.0943951023931952626"/>
<joint_properties friction="0.0"/>
</joint>

<joint name="head_pitch" type="revolute">
<origin xyz="3.4694469519536141888e-18 -0.064999999999999141798 3.4694469519536141888e-18" rpy="3.1415926535897926719 -1.6569800610870191142e-15 -1.570796326794896336" />
<parent link="head_link" />
<child link="head_pitch_yaw" />
<axis xyz="0 0 1"/>
<limit effort="1" velocity="20" lower="-0.69813170079773179122" upper="0.69813170079773179122"/>
<joint_properties friction="0.0"/>
</joint>

<joint name="neck_pitch" type="revolute">
<origin xyz="0.03062710048502576346 -0.018103896430577137711 0.055078922950960805538" rpy="-1.570796326794881459 -6.2505556286397272481e-14 1.0547118733946938852e-15" />
<parent link="body_module" />
<child link="head_link" />
<axis xyz="0 0 1"/>
<limit effort="1" velocity="20" lower="-1.3089969389957472057" upper="0.1745329251994329478"/>
<joint_properties friction="0.0"/>
</joint>


</robot>
