<mujoco model="onshape">
  <compiler angle="radian"/>
  <asset>
    <mesh name="cage" file="cage.stl"/>
    <mesh name="body_part" file="body_part.stl"/>
    <mesh name="front_cover" file="front_cover.stl"/>
    <mesh name="dc15_a01_case_f_dummy" file="dc15_a01_case_f_dummy.stl"/>
    <mesh name="dc15_a01_case_m_dummy" file="dc15_a01_case_m_dummy.stl"/>
    <mesh name="dc15_a01_case_b_dummy" file="dc15_a01_case_b_dummy.stl"/>
    <mesh name="dc15_a01_horn_dummy" file="dc15_a01_horn_dummy.stl"/>
    <mesh name="double_u" file="double_u.stl"/>
    <mesh name="dc15_a01_horn_idle2_dummy" file="dc15_a01_horn_idle2_dummy.stl"/>
    <mesh name="hip_right_roll_to_pitch" file="hip_right_roll_to_pitch.stl"/>
    <mesh name="block_to_axis" file="block_to_axis.stl"/>
    <mesh name="renfort" file="renfort.stl"/>
    <mesh name="foot" file="foot.stl"/>
    <mesh name="foot_contact" file="foot_contact.stl"/>
    <mesh name="hip_left_roll_to_pitch" file="hip_left_roll_to_pitch.stl"/>
    <mesh name="axis_to_axis" file="axis_to_axis.stl"/>
    <mesh name="part_1" file="part_1.stl"/>
  </asset>
  <default>
    <geom contype="1" conaffinity="1" solref=".004 1" />
    <joint damping="0.09" frictionloss="0.1"/>
    <!-- <position kp="10" forcerange="-5.0 5.0"/>
    <position kp="10" forcerange="-0.58 0.58"/> -->
    <position kp="10" forcerange="-2 2"/>
  </default>
  <worldbody>
    <body name="base" pos="0 0 0.19">
      <freejoint />
      <geom pos="-0.0498729 -0.114143 0.0150789" quat="0.707107 0 0 0.707107" type="mesh" rgba="0.647059 0.647059 0.647059 1" mesh="cage"/>
      <geom pos="0.0001271 -0.0066039 0.0230789" quat="0.707107 0 0 0.707107" type="mesh" rgba="0 0 0 1" mesh="body_part"/>
      <geom pos="-0.0498729 -0.114143 0.0150789" quat="0.707107 0 0 0.707107" type="mesh" rgba="0.647059 0.647059 0.647059 1" mesh="front_cover"/>
      <geom pos="0.0001271 -0.0066039 -0.00492108" quat="0.707107 0 0 0.707107" type="mesh" rgba="0 0 0 1" mesh="body_part"/>
      <geom pos="0.0001271 -0.0316039 0.0195789" quat="0 0 0 -1" type="mesh" rgba="0.282353 0.254902 0.254902 1" mesh="dc15_a01_case_f_dummy"/>
      <geom pos="0.0001271 -0.0316039 0.0195789" quat="0 0 0 -1" type="mesh" rgba="0.282353 0.254902 0.254902 1" mesh="dc15_a01_case_m_dummy"/>
      <geom pos="0.0001271 -0.0316039 7.8923e-05" quat="0 0 0 -1" type="mesh" rgba="0.282353 0.254902 0.254902 1" mesh="dc15_a01_case_b_dummy"/>
      <geom pos="0.0001271 0.0183961 0.0195789" quat="1 0 0 0" type="mesh" rgba="0.282353 0.254902 0.254902 1" mesh="dc15_a01_case_f_dummy"/>
      <geom pos="0.0001271 0.0183961 0.0195789" quat="1 0 0 0" type="mesh" rgba="0.282353 0.254902 0.254902 1" mesh="dc15_a01_case_m_dummy"/>
      <geom pos="0.0001271 0.0183961 7.8923e-05" quat="1 0 0 0" type="mesh" rgba="0.282353 0.254902 0.254902 1" mesh="dc15_a01_case_b_dummy"/>
      <geom pos="0.0306271 -0.0146039 0.0550789" quat="0.5 0.5 0.5 -0.5" type="mesh" rgba="0.282353 0.254902 0.254902 1" mesh="dc15_a01_case_f_dummy"/>
      <geom pos="0.0306271 -0.0146039 0.0550789" quat="0.5 0.5 0.5 -0.5" type="mesh" rgba="0.282353 0.254902 0.254902 1" mesh="dc15_a01_case_m_dummy"/>
      <geom pos="0.0306271 0.0048961 0.0550789" quat="0.5 0.5 0.5 -0.5" type="mesh" rgba="0.282353 0.254902 0.254902 1" mesh="dc15_a01_case_b_dummy"/>
      <body name="double_u_module" pos="0.0001271 -0.0316039 0.0230789" quat="0 0.707107 0.707107 0">
        <inertial pos="-0.017 -9.73831e-05 0.0115977" quat="0.262978 0.63443 0.278372 0.671454" mass="0.0166733" diaginertia="4.08774e-06 4.08583e-06 3.39689e-06"/>
        <joint name="right_hip_yaw" pos="0 0 0" axis="0 0 1" range="-0.698132 0.698132" />
        <geom pos="0 0 0.023" quat="0.707107 0.707107 0 0" type="mesh" rgba="0.498039 0.498039 0.498039 1" mesh="dc15_a01_horn_dummy"/>
        <geom pos="-0.146088 0 0.028" quat="0 0 -0.707107 -0.707107" type="mesh" rgba="0.282353 0.254902 0.254902 1" mesh="double_u"/>
        <geom pos="-0.034 -0.0115002 0.0115" quat="0 1 0 0" type="mesh" rgba="0.498039 0.498039 0.498039 1" mesh="dc15_a01_horn_dummy"/>
        <geom quat="0 -1 0 0" type="mesh" rgba="0.231373 0.380392 0.705882 1" mesh="dc15_a01_horn_idle2_dummy"/>
        <geom pos="-0.034 0.0115 0.0115" quat="0.707107 -0.707107 0 0" type="mesh" rgba="0.231373 0.380392 0.705882 1" mesh="dc15_a01_horn_idle2_dummy"/>
        <body name="right_hip_pitch_roll_module" pos="-0.034 0.0115 0.0115" quat="0.5 -0.5 -0.5 -0.5">
          <inertial pos="0.0119001 -0.0118787 -0.00623459" quat="0.66281 0.361087 0.33216 0.565658" mass="0.0519584" diaginertia="1.63986e-05 1.54312e-05 8.94567e-06"/>
          <joint name="right_hip_roll" pos="0 0 0" axis="0 0 1" range="-1.5708 0.349066" />
          <geom pos="-0.0670531 -0.0245 0.009" quat="1 0 0 0" type="mesh" rgba="0.282353 0.254902 0.254902 1" mesh="hip_right_roll_to_pitch"/>
          <geom pos="0 0 -0.0035" type="mesh" rgba="0.282353 0.254902 0.254902 1" mesh="dc15_a01_case_f_dummy"/>
          <geom pos="0 0 -0.0035" type="mesh" rgba="0.282353 0.254902 0.254902 1" mesh="dc15_a01_case_m_dummy"/>
          <geom pos="0 0 -0.023" type="mesh" rgba="0.282353 0.254902 0.254902 1" mesh="dc15_a01_case_b_dummy"/>
          <geom pos="0.025 -0.021 -0.0135" quat="0 0 0.707107 -0.707107" type="mesh" rgba="0.282353 0.254902 0.254902 1" mesh="dc15_a01_case_f_dummy"/>
          <geom pos="0.025 -0.021 -0.0135" quat="0 0 0.707107 -0.707107" type="mesh" rgba="0.282353 0.254902 0.254902 1" mesh="dc15_a01_case_m_dummy"/>
          <geom pos="0.025 -0.0015 -0.0135" quat="0 0 0.707107 -0.707107" type="mesh" rgba="0.282353 0.254902 0.254902 1" mesh="dc15_a01_case_b_dummy"/>
          <body name="leg_module" pos="0.025 -0.0245 -0.0135" quat="0 0 -0.707107 -0.707107">
            <inertial pos="-0.0406621 -8.08266e-06 0.0113968" quat="0.502929 0.496962 0.497168 0.502906" mass="0.0329444" diaginertia="1.91798e-05 1.68759e-05 4.37416e-06"/>
            <joint name="right_hip_pitch" pos="0 0 0" axis="0 0 1" range="-0.523599 1.5708" />
            <geom pos="-0.0425 -0.0471308 0.023" quat="0.5 -0.5 0.5 -0.5" type="mesh" rgba="0.815686 0.443137 0.00392157 1" mesh="block_to_axis"/>
            <geom pos="-0.0425 0.0471308 0" quat="0.5 0.5 0.5 0.5" type="mesh" rgba="0.815686 0.443137 0.00392157 1" mesh="block_to_axis"/>
            <geom pos="-0.0425 0.0471308 0" quat="0.5 0.5 0.5 0.5" type="mesh" rgba="0.282353 0.254902 0.254902 1" mesh="renfort"/>
            <geom quat="0 -1 0 0" type="mesh" rgba="0.231373 0.380392 0.705882 1" mesh="dc15_a01_horn_idle2_dummy"/>
            <geom pos="0 0 0.023" quat="0.5 0.5 0.5 0.5" type="mesh" rgba="0.498039 0.498039 0.498039 1" mesh="dc15_a01_horn_dummy"/>
            <geom pos="-0.065 0 0.0035" quat="0 0.707107 -0.707107 0" type="mesh" rgba="0.282353 0.254902 0.254902 1" mesh="dc15_a01_case_f_dummy"/>
            <geom pos="-0.065 0 0.0035" quat="0 0.707107 -0.707107 0" type="mesh" rgba="0.282353 0.254902 0.254902 1" mesh="dc15_a01_case_m_dummy"/>
            <geom pos="-0.065 0 0.023" quat="0 0.707107 -0.707107 0" type="mesh" rgba="0.282353 0.254902 0.254902 1" mesh="dc15_a01_case_b_dummy"/>
            <body name="leg_module_2" pos="-0.065 0 0" quat="1 0 0 0">
              <inertial pos="-0.0406621 -8.08266e-06 0.0113968" quat="0.502929 0.496962 0.497168 0.502906" mass="0.0329444" diaginertia="1.91798e-05 1.68759e-05 4.37416e-06"/>
              <joint name="right_knee" pos="0 0 0" axis="0 0 1" range="-2.0944 2.0944" />
              <geom pos="-0.0425 -0.0471308 0.023" quat="0.5 -0.5 0.5 -0.5" type="mesh" rgba="0.815686 0.443137 0.00392157 1" mesh="block_to_axis"/>
              <geom pos="-0.0425 0.0471308 0" quat="0.5 0.5 0.5 0.5" type="mesh" rgba="0.815686 0.443137 0.00392157 1" mesh="block_to_axis"/>
              <geom pos="-0.0425 0.0471308 0" quat="0.5 0.5 0.5 0.5" type="mesh" rgba="0.282353 0.254902 0.254902 1" mesh="renfort"/>
              <geom quat="0 -1 0 0" type="mesh" rgba="0.231373 0.380392 0.705882 1" mesh="dc15_a01_horn_idle2_dummy"/>
              <geom pos="0 0 0.023" quat="0.5 0.5 0.5 0.5" type="mesh" rgba="0.498039 0.498039 0.498039 1" mesh="dc15_a01_horn_dummy"/>
              <geom pos="-0.065 0 0.0035" quat="0 0.707107 -0.707107 0" type="mesh" rgba="0.282353 0.254902 0.254902 1" mesh="dc15_a01_case_f_dummy"/>
              <geom pos="-0.065 0 0.0035" quat="0 0.707107 -0.707107 0" type="mesh" rgba="0.282353 0.254902 0.254902 1" mesh="dc15_a01_case_m_dummy"/>
              <geom pos="-0.065 0 0.023" quat="0 0.707107 -0.707107 0" type="mesh" rgba="0.282353 0.254902 0.254902 1" mesh="dc15_a01_case_b_dummy"/>
              <body name="foot_module" pos="-0.065 0 0" quat="1 0 0 0">
                <inertial pos="-0.0255887 0.00684095 0.0115315" quat="0.441952 0.522609 -0.47562 0.552579" mass="0.0517101" diaginertia="2.16197e-05 2.10014e-05 8.42609e-06"/>
                <joint name="right_ankle" pos="0 0 0" axis="0 0 1" range="-1.5708 1.5708" />
                <geom quat="0 1 0 0" type="mesh" rgba="0.231373 0.380392 0.705882 1" mesh="dc15_a01_horn_idle2_dummy"/>
                <geom pos="0 0 -0.0052" quat="0 -0.707107 0 -0.707107" type="mesh" rgba="0.815686 0.443137 0.00392157 1" mesh="foot"/>
                <geom pos="0 0 -0.0052" quat="0 -0.707107 0 -0.707107" type="mesh" rgba="0 0 0 1" mesh="foot_contact"/>
                <geom pos="0 0 0.023" quat="0.5 0.5 0.5 0.5" type="mesh" rgba="0.498039 0.498039 0.498039 1" mesh="dc15_a01_horn_dummy"/>
              </body>
            </body>
          </body>
        </body>
      </body>
      <body name="double_u_module_2" pos="0.0001271 0.0183961 0.0230789" quat="0 0.707107 0.707107 0">
        <inertial pos="0.017 9.76811e-05 0.0115974" quat="-0.277951 0.671628 -0.262656 0.634563" mass="0.0166733" diaginertia="4.08774e-06 4.08583e-06 3.39689e-06"/>
        <joint name="left_hip_yaw" pos="0 0 0" axis="0 0 1" range="-0.698132 0.698132" />
        <geom pos="0.034 0.0115 0.0115" type="mesh" rgba="0.498039 0.498039 0.498039 1" mesh="dc15_a01_horn_dummy"/>
        <geom pos="-0.112088 0.0165 0.0115" quat="0 0 -1 0" type="mesh" rgba="0.282353 0.254902 0.254902 1" mesh="double_u"/>
        <geom pos="0 0 0.0230002" quat="0.707107 0.707107 0 0" type="mesh" rgba="0.498039 0.498039 0.498039 1" mesh="dc15_a01_horn_dummy"/>
        <geom pos="0.034 -0.0115 0.0115" quat="0.707107 0.707107 0 0" type="mesh" rgba="0.231373 0.380392 0.705882 1" mesh="dc15_a01_horn_idle2_dummy"/>
        <geom quat="0 -1 0 0" type="mesh" rgba="0.231373 0.380392 0.705882 1" mesh="dc15_a01_horn_idle2_dummy"/>
        <body name="left_hip_pitch_roll_module" pos="0.034 -0.0115 0.0115" quat="0.5 0.5 -0.5 0.5">
          <inertial pos="0.0119001 -0.0116852 -0.016572" quat="0.364381 0.640328 0.597167 0.317172" mass="0.0519584" diaginertia="1.64729e-05 1.55514e-05 8.91006e-06"/>
          <joint name="left_hip_roll" pos="0 0 0" axis="0 0 1" range="-1.5708 0.349066" />
          <geom pos="-0.0670531 -0.0245 -0.032" quat="0 0 -1 0" type="mesh" rgba="0.282353 0.254902 0.254902 1" mesh="hip_left_roll_to_pitch"/>
          <geom pos="0.025 -0.005 -0.0095" quat="0 0 0.707107 0.707107" type="mesh" rgba="0.282353 0.254902 0.254902 1" mesh="dc15_a01_case_f_dummy"/>
          <geom pos="0.025 -0.005 -0.0095" quat="0 0 0.707107 0.707107" type="mesh" rgba="0.282353 0.254902 0.254902 1" mesh="dc15_a01_case_m_dummy"/>
          <geom pos="0.025 -0.0245 -0.0095" quat="0 0 0.707107 0.707107" type="mesh" rgba="0.282353 0.254902 0.254902 1" mesh="dc15_a01_case_b_dummy"/>
          <geom pos="0 0 -0.0035" type="mesh" rgba="0.282353 0.254902 0.254902 1" mesh="dc15_a01_case_f_dummy"/>
          <geom pos="0 0 -0.0035" type="mesh" rgba="0.282353 0.254902 0.254902 1" mesh="dc15_a01_case_m_dummy"/>
          <geom pos="0 0 -0.023" type="mesh" rgba="0.282353 0.254902 0.254902 1" mesh="dc15_a01_case_b_dummy"/>
          <body name="leg_module_3" pos="0.025 -0.0015 -0.0095" quat="-2.76505e-08 -2.76505e-08 -0.707107 0.707107">
            <inertial pos="-0.0406621 -8.08266e-06 0.0113968" quat="0.502929 0.496962 0.497168 0.502906" mass="0.0329444" diaginertia="1.91798e-05 1.68759e-05 4.37416e-06"/>
            <joint name="left_hip_pitch" pos="0 0 0" axis="0 0 1" range="-0.523599 1.5708" />
            <geom pos="-0.0425 -0.0471308 0.023" quat="0.5 -0.5 0.5 -0.5" type="mesh" rgba="0.815686 0.443137 0.00392157 1" mesh="block_to_axis"/>
            <geom pos="-0.0425 0.0471308 0" quat="0.5 0.5 0.5 0.5" type="mesh" rgba="0.815686 0.443137 0.00392157 1" mesh="block_to_axis"/>
            <geom pos="-0.0425 0.0471308 0" quat="0.5 0.5 0.5 0.5" type="mesh" rgba="0.282353 0.254902 0.254902 1" mesh="renfort"/>
            <geom quat="0 -1 0 0" type="mesh" rgba="0.231373 0.380392 0.705882 1" mesh="dc15_a01_horn_idle2_dummy"/>
            <geom pos="0 0 0.023" quat="0.5 0.5 0.5 0.5" type="mesh" rgba="0.498039 0.498039 0.498039 1" mesh="dc15_a01_horn_dummy"/>
            <geom pos="-0.065 0 0.0035" quat="0 0.707107 -0.707107 0" type="mesh" rgba="0.282353 0.254902 0.254902 1" mesh="dc15_a01_case_f_dummy"/>
            <geom pos="-0.065 0 0.0035" quat="0 0.707107 -0.707107 0" type="mesh" rgba="0.282353 0.254902 0.254902 1" mesh="dc15_a01_case_m_dummy"/>
            <geom pos="-0.065 0 0.023" quat="0 -0.707107 0.707107 0" type="mesh" rgba="0.282353 0.254902 0.254902 1" mesh="dc15_a01_case_b_dummy"/>
            <body name="leg_module_4" pos="-0.065 0 0" quat="1 0 0 -3.91037e-08">
              <inertial pos="-0.0406621 -8.08266e-06 0.0113968" quat="0.502929 0.496962 0.497168 0.502906" mass="0.0329444" diaginertia="1.91798e-05 1.68759e-05 4.37416e-06"/>
              <joint name="left_knee" pos="0 0 0" axis="0 0 1" range="-2.0944 2.0944" />
              <geom pos="-0.0425 -0.0471308 0.023" quat="0.5 -0.5 0.5 -0.5" type="mesh" rgba="0.815686 0.443137 0.00392157 1" mesh="block_to_axis"/>
              <geom pos="-0.0425 0.0471308 0" quat="0.5 0.5 0.5 0.5" type="mesh" rgba="0.815686 0.443137 0.00392157 1" mesh="block_to_axis"/>
              <geom pos="-0.0425 0.0471308 0" quat="0.5 0.5 0.5 0.5" type="mesh" rgba="0.282353 0.254902 0.254902 1" mesh="renfort"/>
              <geom quat="0 1 0 0" type="mesh" rgba="0.231373 0.380392 0.705882 1" mesh="dc15_a01_horn_idle2_dummy"/>
              <geom pos="0 0 0.023" quat="0.5 0.5 0.5 0.5" type="mesh" rgba="0.498039 0.498039 0.498039 1" mesh="dc15_a01_horn_dummy"/>
              <geom pos="-0.065 0 0.0035" quat="0 0.707107 -0.707107 0" type="mesh" rgba="0.282353 0.254902 0.254902 1" mesh="dc15_a01_case_f_dummy"/>
              <geom pos="-0.065 0 0.0035" quat="0 0.707107 -0.707107 0" type="mesh" rgba="0.282353 0.254902 0.254902 1" mesh="dc15_a01_case_m_dummy"/>
              <geom pos="-0.065 0 0.023" quat="0 0.707107 -0.707107 0" type="mesh" rgba="0.282353 0.254902 0.254902 1" mesh="dc15_a01_case_b_dummy"/>
              <body name="foot_module_2" pos="-0.065 0 0" quat="1 0 0 0">
                <inertial pos="-0.0255887 0.00684095 0.0115315" quat="0.441952 0.522609 -0.47562 0.552579" mass="0.0517101" diaginertia="2.16197e-05 2.10014e-05 8.42609e-06"/>
                <joint name="left_ankle" pos="0 0 0" axis="0 0 1" range="-1.5708 1.5708" />
                <geom quat="0 1 0 0" type="mesh" rgba="0.231373 0.380392 0.705882 1" mesh="dc15_a01_horn_idle2_dummy"/>
                <geom pos="0 0 -0.0052" quat="0 -0.707107 0 -0.707107" type="mesh" rgba="0.815686 0.443137 0.00392157 1" mesh="foot"/>
                <geom pos="0 0 -0.0052" quat="0 -0.707107 0 -0.707107" type="mesh" rgba="0 0 0 1" mesh="foot_contact"/>
                <geom pos="0 0 0.023" quat="0.5 0.5 0.5 0.5" type="mesh" rgba="0.498039 0.498039 0.498039 1" mesh="dc15_a01_horn_dummy"/>
              </body>
            </body>
          </body>
        </body>
      </body>
      <body name="head_link" pos="0.0306271 -0.0181039 0.0550789" quat="0.707107 -0.707107 0 0">
        <inertial pos="0 -0.0324998 0.0116479" quat="0.707103 0.70711 0 0" mass="0.0219844" diaginertia="1.41577e-05 1.09184e-05 4.64849e-06"/>
        <joint name="head_pitch1" pos="0 0 0" axis="0 0 1" range="-1.309 0.174533" />
        <geom pos="0 0 0.023" quat="0 0 0.707107 -0.707107" type="mesh" rgba="0.282353 0.254902 0.254902 1" mesh="axis_to_axis"/>
        <geom pos="0 -0.065 0.023" quat="0.707107 0.707107 0 0" type="mesh" rgba="0.498039 0.498039 0.498039 1" mesh="dc15_a01_horn_dummy"/>
        <geom pos="0.0471308 -0.0225 0" quat="0.707107 0.707107 0 0" type="mesh" rgba="0.282353 0.254902 0.254902 1" mesh="renfort"/>
        <geom pos="0 0 0.023" quat="0.707107 0.707107 0 0" type="mesh" rgba="0.498039 0.498039 0.498039 1" mesh="dc15_a01_horn_dummy"/>
        <geom pos="0 -0.065 0" quat="0 -1 0 0" type="mesh" rgba="0.231373 0.380392 0.705882 1" mesh="dc15_a01_horn_idle2_dummy"/>
        <geom quat="0 1 0 0" type="mesh" rgba="0.231373 0.380392 0.705882 1" mesh="dc15_a01_horn_idle2_dummy"/>
        <geom quat="0.707107 0.707107 0 0" type="mesh" rgba="0.282353 0.254902 0.254902 1" mesh="axis_to_axis"/>
        <body name="head_pitch_yaw" pos="0 -0.065 0" quat="0 -0.707107 0.707107 0">
          <inertial pos="0.0133989 -0.0075371 -0.0113661" quat="0.000912697 0.71103 -7.82391e-05 0.703161" mass="0.0355313" diaginertia="1.11015e-05 8.95294e-06 4.73595e-06"/>
          <joint name="head_pitch2" pos="0 0 0" axis="0 0 1" range="-1.309 0.698132" />
          <geom pos="0.0345 0 -0.0115" quat="0.707107 0 0.707107 0" type="mesh" rgba="0.282353 0.254902 0.254902 1" mesh="dc15_a01_case_f_dummy"/>
          <geom pos="0.0345 0 -0.0115" quat="0.707107 0 0.707107 0" type="mesh" rgba="0.282353 0.254902 0.254902 1" mesh="dc15_a01_case_m_dummy"/>
          <geom pos="0.015 0 -0.0115" quat="0.707107 0 0.707107 0" type="mesh" rgba="0.282353 0.254902 0.254902 1" mesh="dc15_a01_case_b_dummy"/>
          <geom pos="0 0 -0.0035" type="mesh" rgba="0.282353 0.254902 0.254902 1" mesh="dc15_a01_case_f_dummy"/>
          <geom pos="0 0 -0.0035" type="mesh" rgba="0.282353 0.254902 0.254902 1" mesh="dc15_a01_case_m_dummy"/>
          <geom pos="0 0 -0.023" type="mesh" rgba="0.282353 0.254902 0.254902 1" mesh="dc15_a01_case_b_dummy"/>
          <body name="head_assembly" pos="0.038 0 -0.0115" quat="0.5 0.5 -0.5 -0.5">
            <inertial pos="0.00767976 -7.54716e-05 0.0068537" quat="0.00192719 0.711388 -0.00162056 0.702795" mass="0.169757" diaginertia="0.000614139 0.000409695 0.000244442"/>
            <joint name="head_yaw" pos="0 0 0" axis="0 0 1" range="-2.0944 2.0944" />
            <geom pos="0 0 -0.005" type="mesh" rgba="0.917647 0.917647 0.917647 1" mesh="part_1"/>
            <geom quat="0 1 0 0" type="mesh" rgba="0.231373 0.380392 0.705882 1" mesh="dc15_a01_horn_idle2_dummy"/>
          </body>
        </body>
      </body>
    </body>
  </worldbody>
  <actuator>
    <position name="left_hip_yaw"    joint="left_hip_yaw"    inheritrange="1"/>
    <position name="left_hip_roll"   joint="left_hip_roll"   inheritrange="1"/>
    <position name="left_hip_pitch"  joint="left_hip_pitch"  inheritrange="1"/>
    <position name="left_knee"       joint="left_knee"       inheritrange="1"/>
    <position name="left_ankle"      joint="left_ankle"      inheritrange="1"/>
    <position name="right_hip_roll"  joint="right_hip_roll"  inheritrange="1"/>
    <position name="right_hip_yaw"   joint="right_hip_yaw"   inheritrange="1"/>
    <position name="right_hip_pitch" joint="right_hip_pitch" inheritrange="1"/>
    <position name="right_knee"      joint="right_knee"      inheritrange="1"/>
    <position name="right_ankle"     joint="right_ankle"     inheritrange="1"/>
    <position name="head_pitch1"     joint="head_pitch1"     inheritrange="1"/>
    <position name="head_pitch2"     joint="head_pitch2"     inheritrange="1"/>
    <position name="head_yaw"        joint="head_yaw"        inheritrange="1"/>
  </actuator>
</mujoco>